Workbook

Sheet ESTRATÈGIA
C3: ESQUEMA CONCEPTUAL PER A LA ELABORACIÓ DEL PLA ESTRATÈGIC EN EL MARC
C4: DELS ESTÀNDARDS OBERTS PER A LA GESTIÓ ADAPTATIVA A CATALUNYA

Sheet INSTRUCCIONS
A1: PESTANYA DE PRIORITZACIÓ
A2: Llistat elements: | B2: Tasca 1: Revisar el llistat d'elements prioritzats per tal d'avaluar si cal afegir-ne algun o treure'n algun. A la columna comentaris cal argumentar, breument, el perquè de la decisió.
A4: Llistat amenaces: | B4: Tasca 2: A partir de la taxonomia d'amenaces que es troba a la pestanya final, cal omplir les tres columnes (E, F i G) amb les tres principals amenaces per a la conservació de l'element. S'afegeixi una darrera columna per si hi ha amenaces que no es troben incloses a la taxonomia.
A6: PESTANYA DEL PLA
A7: Explicacions:
B8: 7 Eixos temàtics: NATURA, CULTURA, CONEIXEMENT, DESENVOLUPAMENT LOCAL, ÚS PÚBLIC I SOCIAL, EDUCACIÓ, VOLUNTARIAT I COMUNICACIÓ, GESTIÓ I ADMINISTRACIÓ
B9: Els objectius generals estan directament associats als objectius generals dels Plans de Protecció del medi natural i del paisatge. NO ES PODEN RETOCAR
B10: Objectius estratègics: definits en un grup de treball intern de serveis Centrals i dels Parcs durant l'any 2023. NO ES PODEN RETOCAR
B11: Objectius operacionals: definits en un grup de treball intern de serveis Centrals i dels Parcs durant l'any 2023
A14: Tasques a realitzar:
A15: Objectius operacionals: | B15: El llistat d'objectius operacionals té una columna al costat (columna I) on s'indica si l'objectiu és obligatori de mantenir al Pla estratègic o no.
B16: Tasca 1: Columna I. Revisar els que es posa com a obligatoris per veure si són realment aplicables a l'espai o no.
B17: Tasca 2: Columna I. Revisar els que posa "Optatiu" per identificar els que són aplicables o no a l'espai. O, també, determinar si algun d'ells seria aplicable o es pot concretar millor el redactat de l'objectiu.
B18: Tasca 3: Columna J. En ambdós casos, cal posar a la columna J, el redactat final de l'objectiu concretat a l'espai. En el cas de que l'objectiu s'elimina, posar "NA". Ara es reprodueix el redactat dels objectius operacionals derivats del grup de treball esmentat
B19: Tasca 4: Columna K. Per tots els casos en que hi ha modificació respecte al redactat original de l'objectiu operatiu -i, també, en el cas que es consideri que s'ha d'eliminar-, a la columna K cal redactar molt breument el motiu pel qual es prèn la decisió.
B20: Tasca 5: Columna L. Incloure un Si/No avaluant si l'objectiu operatiu podria tenir mesures a incorporar a la programació d'actuacions de l'espai (Si) o, per altra banda, el seu assoliment depèn d'altres òrgans, com l'ACA o altres serveis dins la DGPAMN (No).
B21: Tasca 6: Columna M. Definir la prioritat que hauria de tenir l'assoliment de l'objectiu (màxima, si cal assolir en els propers 4 anys, o altrament alta, mitja o baixa). També hi ha l'opció de prioritat a assolir a més llarg termini.
A22: Propostes genèriques d'accions: | B22: Tasca 7: Columna N. En aquesta columna cal introduir les accions, de manera genèrica, que caldria aplicar a l'espai per tal d'assolir l'objectiu operatiu. No es tracta d'un llistat d'accions concretes si no, més aviat, accions generals que acabarien concretant-se en la programació anual. PER A INICIAR AMB LA TAULA US PODEU BASAR MOLT EN LA FEINA JA FETA DE PRIORITZACIÓ DE MESURES PEL MAP
B23: En el cas dels objectius operatius que s'ha considerat que no són aplicables a l'espai, cal avaluar si podrien tenir alguna acció que sí tindria sentit d'incloure al Pla estratègic tot i que l'objectiu de manera global no hi seria d'aplicació.
A24: Indicadors: | B24: Tasca 8: Columna Q. Posar un indicador SMART per avaluar el compliment de la mesura proposada a la columna N | C24: Qualitatius o quantitatius
A25: Fites a assolir en 4 anys: | B25: Tasca 9: Posar un valor de l'indicador a assolir: valor mínim necessari (columna R) o valor desitjable (columna S).
A26: Hores de dedicació: | B26: Tasca 10: Columna T. Realitzar una aproximació el més acurada que es pugui de les hores del personal de gestió de l'espai que cal destinar per a la realització de l'acció.
A27: Àrea responsable: | B27: Tasca 11: Columna U. Indicar quina àrea de l'equip de gestió és responsable de coordinar l'execució de l'acció.
A28: Persona responsable: | B28: Tasca 12: Columna V. Indicar quina persona dins l'àrea seria l'encarregada.
A30: PESTANYA DEL VINCLE
A31: Definir vincle amenaça vs. Obj. Operatiu | B31: Tasca 1: Establir / Revisar el vincle entre les amenaces identificades a la pestanya de priorització i els objectius operatius definits a la columna J de la pestanya Pla. La columna B conté el llistat dels objectius operatius tal i com quedaran definits després de la vostra revisió.
B32: Tasca 2: En cas que es pugui, definir l'amenaça / factor / causa concret a la que atén l'objectiu definit al Pla. Poden ser més d'una.
B33: És important que es visualitzi a quina amenaça es dirigeix l'objectiu operatiu que es proposa al Pla, tot i que, no sempre hi ha d'haver un vincle clar. Pot haver-hi algun objectiu sense amenaça vinculada.

Sheet PRIORITZACIÓ
A1: Element prioritzat a la proposta inicial | B1: canvi a no | C1: Element prioritzat | D1: Hàbitat no present al PNIN/Ni surt a la nostra llista
B2: manté o afegim a sí | D2: No surt prioritzat amb els nostres criteris
B3: Dubtós | D3: Ens surt prioritzat amb els nostres criteris
A4: Llistats corresponent a l'espai de Natura 2000 ES5120014"L'Albera"
A5: LLISTAT D'ELEMENTS PRESENT A L'ESPAI | E5: AMENACES PER A CADA ELEMENT
A6: Hàbitats d'interès comunitari | B6: Prioritzat | C6: Puntuació índex rellevància | D6: Comentaris en cas de canvi en la priorització | E6: Amenaça 1 segons taxonomia | F6: Amenaça 2 segons taxonomia | G6: Amenaça 3 segons taxonomia | H6: Altres amenaces
A7: 1120p - Alguers de posidònia | B7: No | D7: Hàbitat no present al PNIN | J7: Nota: La priorització d'elements actual inclou els Elements Clau que es van determinar en l'instrument de gestió aprovat amb l'Acord de Govern 150/2014 (Annex 6)
A8: 1170 - Fons marins rocosos i concrecions biogèniques sublitorals | B8: No | D8: Hàbitat no present al PNIN | J8: Aquest Acord era per les Zones Especials de Conservació, no per les ZEPA i, per tant, no es va fer l'exercici de priorització de les aus.
A9: 1240 - Penya-segats de les costes mediterrànies colonitzats per vegetació, amb ensopegueres (Limonium spp.) endèmiques | B9: No | C9: 4.125 | D9: Hàbitat no present al PNIN | J9: També inclou el primer quartil de l'exercici de la UIC per prioritzar els elements present a cada espai de Natura 2000, és a dir, el 25% dels
A10: 2110 - Dunes movents embrionàries | B10: No | D10: Hàbitat no present al PNIN | J10: elements amb major índex de rellevància a l'espai. Veure document metodològic aquí:
A11: 2120 - Dunes movents del cordó litoral, amb borró (Ammophila arenaria) | B11: No | D11: Hàbitat no present al PNIN | J11: https://gencat.sharepoint.com/sites/Informaciiconeixementpatrimoninatural2/Documents%20compartits/Forms/AllItems.aspx?csf=1&web=1&e=3x4ZkK&ovuser=3b9427dc%2Dd30e%2D43bc%2D8c06%2Dff7253676fec%2Cjordiparpal%40gencat%2Ecat&OR=Teams%2DHL&CT=1713942253212&clic
A12: 3170p - Basses i tolls temporers mediterranis | B12: Si | E12: Ramaderia | F12: Activitat agrícola | G12: Impactes del canvi climàtic relatius a l'alteració del règim de precipitació i sequera | H12: Producció d'energia renovable | J12: El llistat original d'elements prové de les taules del MAP que heu estat treballant amb el SENP
A13: 3250 - Rius mediterranis amb vegetació del Glaucion flavi | B13: No
A14: 3260 - Rius de terra baixa i de la muntanya mitjana amb vegetació submersa o parcialment flotant (Ranunculion fluitantis i Callitricho-Batrachion) | B14: No
A15: 3270 - Rius amb vores llotoses colonitzades per herbassars nitròfils del Chenopodion rubri (p.p.) i del Bidention (p.p.) | B15: No
A16: 3290 - Rius mediterranis intermitents, amb gespes nitròfiles del Paspalo-Agrostidion | B16: No | D16: No surt prioritzat amb els nostres criteris
A17: 6420 - Jonqueres i herbassars graminoides humits, mediterranis, del Molinio-Holoschoenion | B17: No | C17: 3.625 | D17: No surt prioritzat amb els nostres criteris
A18: 6510 - Prats de dall de terra baixa i de la muntanya mitjana (Arrhenatherion) | B18: No | C18: 3.375 | D18: No surt prioritzat amb els nostres criteris, ni és present al PNIN.
A19: 8130 - Tarteres de l'Europa meridional amb vegetació poc o molt termòfila | B19: No
A20: 8220 - Costers rocosos silicis amb vegetació rupícola | B20: No | C20: 2.875 | D20: Hàbitat no present al PNIN
A21: 9120 - Fagedes acidòfiles | B21: No | C21: 3.875 | D21: No surt prioritzat amb els nostres criteris
A22: 91E0p - Vernedes i altres boscos de ribera afins (Alno-Padion) | B22: Si | C22: 3.625 | E22: Impactes del canvi climàtic relatius a l'alteració del règim de precipitació i sequera | F22: Gestió de l'aigua | G22: Treballs forestals
A23: 9260 - Castanyedes | B23: No
A24: 92A0 - Alberedes, salzedes i altres boscos de ribera | B24: No
A25: 92D0 - Bosquines i matollars meridionals de rambles, rieres i llocs humits (Nerio-Tamaricetea) | B25: No | C25: 4.75 | D25: No surt prioritzat amb els nostres criteris
A26: 9330 - Suredes | B26: Si | C26: 3.875 | E26: Impactes del canvi climàtic relatius a l'alteració del règim de precipitació i sequera | F26: Ramaderia | G26: Treballs forestals | H26: Incendis
A27: 9340 - Alzinars i carrascars | B27: No | C27: 4 | D27: No surt prioritzat amb els nostres criteris
A28: 9380 - Grevoledes | B28: Si | E28: Impactes del canvi climàtic relatius a l'alteració del règim de precipitació i sequera | F28: Impactes del canvi climàtic relatius a l'alteració del règim de temperatures | G28: Recol·lecció de vegetals | H28: Treballs forestals
A29: 9540 - Pinedes mediterrànies | B29: No
A30: Espècies presents a l'espai | B30: Prioritzat | C30: Puntuació índex rellevància | D30: Comentaris en cas de canvi en la priorització | E30: Amenaça 1 segons taxonomia | F30: Amenaça 2 segons taxonomia | G30: Amenaça 3 segons taxonomia | H30: Altres amenaces
A31: Accipiter gentilis gentilis | B31: No
A32: Alcedo atthis | B32: No
A33: Alectoris rufa | B33: Dubtós | C33: 2 | D33: No surt prioritzat amb els nostres criteris
A34: Alytes obstetricans | B34: No
A35: Anas platyrhynchos | B35: No
A36: Anthus campestris | B36: No
A37: Aquila chrysaetos | B37: Si | D37: Ens surt prioritzat amb els nostres criteris | E37: Molèsties per activitats recreatives | F37: Producció d'energia renovable
A38: Aquila fasciata | B38: Si | C38: 2.111 | E38: Molèsties per activitats recreatives | F38: Producció d'energia renovable
A39: Austropotamobius pallipes | B39: Si | C39: 1.833 | E39: Impactes del canvi climàtic relatius a l'alteració del règim de precipitació i sequera | F39: Gestió de l'aigua | G39: Espècies invasores
A40: Barbastella barbastellus | B40: Si | D40: Ens surt prioritzat amb els nostres criteris | E40: Producció d'energia renovable
...

Sheet Full2
A3: Hàbitats d'interès comunitari | B3: Amenaça 1 | C3: Amenaça 2 | D3: Amenaça 3 | E3: Altres amenaces
A4: 3170p - Basses i tolls temporers mediterranis | B4: Ramaderia | C4: Activitat agrícola | D4: Impactes del canvi climàtic relatius a l'alteració del règim de precipitació i sequera
A5: 91E0p - Vernedes i altres boscos de ribera afins (Alno-Padion) | B5: Impactes del canvi climàtic relatius a l'alteració del règim de precipitació i sequera | C5: Gestió de l'aigua | D5: Treballs forestals
A6: 9330 - Suredes | B6: Impactes del canvi climàtic relatius a l'alteració del règim de precipitació i sequera | C6: Ramaderia | D6: Treballs forestals | E6: Incendis
A7: 9380 - Grevoledes | B7: Impactes del canvi climàtic relatius a l'alteració del règim de precipitació i sequera | C7: Impactes del canvi climàtic relatius a l'alteració del règim de temperatures | D7: Recol·lecció de vegetals | E7: Treballs forestals
A8: Espècies presents a l'espai | B8: Amenaça 1 | C8: Amenaça 2 | D8: Amenaça 3 | E8: Altres amenaces
A9: Aquila chrysaetos | B9: Molèsties per activitats recreatives | C9: Producció d'energia renovable
A10: Aquila fasciata | B10: Molèsties per activitats recreatives | C10: Producció d'energia renovable
A11: Austropotamobius pallipes | B11: Impactes del canvi climàtic relatius a l'alteració del règim de precipitació i sequera | C11: Gestió de l'aigua | D11: Espècies invasores
A12: Barbastella barbastellus | B12: Producció d'energia renovable
A13: Barbus meridionalis | B13: Impactes del canvi climàtic relatius a l'alteració del règim de precipitació i sequera | C13: Gestió de l'aigua
A14: Canis lupus | B14: Ramaderia | C14: Caça i recol·lecció d'animals
A15: Cerambyx cerdo | B15: Impactes del canvi climàtic relatius a l'alteració del règim de precipitació i sequera | C15: Gestió d'hàbitats
A16: Cinclus cinclus | B16: Gestió de l'aigua
A17: Felis silvestris | B17: Introducció de genotips aliens
A18: Hericium erinaceus | B18: Recol·lecció de vegetals | C18: Gestió d'hàbitats
A19: Hoplia coerulea | B19: Gestió d'hàbitats
A20: Isoetes durieui | B20: Impactes del canvi climàtic relatius a l'alteració del règim de precipitació i sequera | C20: Ramaderia | D20: Activitat agrícola | E20: Gestió de l'aigua
A21: Lacerta bilineata | B21: No especificada
A22: Lucanus cervus | B22: Impactes del canvi climàtic relatius a l'alteració del règim de precipitació i sequera | C22: Gestió d'hàbitats
A23: Marsilea strigosa | B23: Impactes del canvi climàtic relatius a l'alteració del règim de precipitació i sequera | C23: Ramaderia | D23: Activitat agrícola
A24: Mauremys leprosa | B24: Impactes del canvi climàtic relatius a l'alteració del règim de precipitació i sequera | C24: Gestió de l'aigua
A25: Melanargia occitanica | B25: No especificada
A26: Miniopterus schreibersii | B26: Producció d'energia renovable
A27: Mustela putorius | B27: Vials de transport | C27: Espècies invasores
A28: Myotis alcathoe | B28: Producció d'energia renovable | C28: Impactes del canvi climàtic relatius a l'alteració del règim de precipitació i sequera | D28: Impactes del canvi climàtic relatius a l'alteració del règim de temperatures | E28: Treballs forestals
A29: Myotis bechsteinii | B29: Producció d'energia renovable
A30: Myotis blythii | B30: Producció d'energia renovable
A31: Myotis emarginatus | B31: Producció d'energia renovable
A32: Nyctalus leisleri | B32: Producció d'energia renovable
A33: Osmoderma eremita | B33: No especificada
A34: Osmunda regalis | B34: Impactes del canvi climàtic relatius a l'alteració del règim de precipitació i sequera | C34: Gestió de l'aigua | D34: Foc
A35: Osphya aeneipennis | B35: No especificada
A36: Pedicularis comosa sp. Asparagoides | B36: No especificada
A37: Rana temporaria | B37: Impactes del canvi climàtic relatius a l'alteració del règim de precipitació i sequera | C37: Impactes del canvi climàtic relatius a l'alteració del règim de temperatures | D37: Ramaderia
A38: Ranunculus nodiflorus | B38: Impactes del canvi climàtic relatius a l'alteració del règim de precipitació i sequera | C38: Ramaderia
A39: Rhinolophus euryale | B39: Producció d'energia renovable
A40: Rhinolophus ferrumequinum | B40: Producció d'energia renovable
A41: Rosalia alpina | B41: Impactes del canvi climàtic relatius a l'alteració del règim de precipitació i sequera | C41: Gestió d'hàbitats
A42: Saxifraga fragosoi | B42: Impactes del canvi climàtic relatius a l'alteració del règim de precipitació i sequera | C42: Foc
...

Sheet Analisi_Prioritat_Grup
A2: Grups | B2: Espècie | C2: Normatives | D2: Feina Feta | E2: AVALUACIÓ
A3: Amfibis | B3: Alytes obstetricans | C3: 10 | D3: 2 | E3: 8 | I3: 33 elements prioritaris
A4: Aus | B4: Aquila chrysaetos | C4: 8 | D4: 1 | E4: 7 | I4: Invertebrats | J4: =COUNTIF($A$3:$A$35,I4) -> 5
A5: Aus | B5: Aquila fasciata | C5: 13 | D5: 6 | E5: 7 | F5: EN | I5: Peixos | J5: =COUNTIF($A$3:$A$35,I5) -> 1
A6: Invertebrats | B6: Austropotamobius pallipes | C6: 7 | D6: 5 | E6: 2 | F6: EN | I6: Amfibis | J6: =COUNTIF($A$3:$A$35,I6) -> 3
A7: Mamífers | B7: Barbastella barbastellus | C7: 10 | D7: 2 | E7: 8 | F7: VU | I7: Rèptils | J7: =COUNTIF($A$3:$A$35,I7) -> 3
A8: Peixos | B8: Barbus meridionalis | C8: 6 | D8: 0 | E8: 6 | I8: Mamífers | J8: =COUNTIF($A$3:$A$35,I8) -> 12
A9: Mamífers | B9: Canis lupus | C9: 11 | D9: 4 | E9: 7 | I9: Plantes vasculars | J9: =COUNTIF($A$3:$A$35,I9) -> 4
A10: Invertebrats | B10: Cerambyx cerdo | C10: 11 | D10: 2 | E10: 9 | F10: VU | I10: Aus | J10: =COUNTIF($A$3:$A$35,I10) -> 2
A11: Mamífers | B11: Felis silvestris | C11: 10 | D11: 4 | E11: 6 | I11: Pteridòfits | J11: =COUNTIF($A$3:$A$35,I11) -> 3
A12: Mamífers | B12: Glis glis | C12: 5 | D12: 3 | E12: 2 | J12: =SUM(J4:J11) -> 33
A13: Amfibis | B13: Hyla meridionalis | C13: 11 | D13: 2 | E13: 9
A14: Pteridòfits | B14: Isoetes durieui | C14: 8 | D14: 1 | E14: 7 | F14: VU
A15: Rèptils | B15: Lacerta bilineata (ex viridis) | C15: 10 | D15: 0 | E15: 10
A16: Plantes vasculars | B16: Limonium geronense | C16: 7 | D16: 1 | E16: 6 | F16: VU
A17: Invertebrats | B17: Lucanus cervus | C17: 10 | D17: 2 | E17: 8 | F17: VU
A18: Pteridòfits | B18: Marsilea strigosa | C18: 8 | D18: 2 | E18: 6 | F18: EN
A19: Rèptils | B19: Mauremys leprosa | C19: 11 | D19: 0 | E19: 11
A20: Mamífers | B20: Miniopterus schreibersii | C20: 12 | D20: 4 | E20: 8 | F20: VU
A21: Mamífers | B21: Mustela putorius | C21: 9 | D21: 4 | E21: 5 | F21: EN
A22: Mamífers | B22: Myotis bechsteini | C22: 12 | D22: 4 | E22: 8 | F22: EN
A23: Mamífers | B23: Myotis blythii | C23: 12 | D23: 2 | E23: 10 | F23: VU
A24: Mamífers | B24: Myotis emarginatus | C24: 12 | D24: 2 | E24: 10 | F24: VU
A25: Mamífers | B25: Neomys milleri | C25: 7 | D25: 1 | E25: 6 | F25: VU
A26: Invertebrats | B26: Osmoderma eremita | C26: 15 | D26: 4 | E26: 11 | F26: EN
A27: Pteridòfits | B27: Osmunda regalis | C27: 5 | D27: 0 | E27: 5
A28: Plantes vasculars | B28: Pedicularis comosa ssp asparagoides | C28: 10 | D28: 1 | E28: 9 | F28: VU
A29: Mamífers | B29: Rhinolophus eurylae | C29: 13 | D29: 4 | E29: 9 | F29: EN
A30: Mamífers | B30: Rhinolophus ferrumequinum | C30: 12 | D30: 4 | E30: 8 | F30: VU
A31: Invertebrats | B31: Rosalia alpina | C31: 13 | D31: 2 | E31: 11 | F31: EN
A32: Plantes vasculars | B32: Saxifraga fragosoi | C32: 7 | D32: 2 | E32: 5 | F32: VU | I32: EN | J32: =COUNTIF($F$3:$F$35,"EN") -> 9
A33: Plantes vasculars | B33: Spiranthes aestivalis | C33: 8 | D33: 1 | E33: 7 | F33: VU | I33: VU | J33: =COUNTIF($F$3:$F$35,"VU") -> 13
A34: Rèptils | B34: Testudo hermanni | C34: 17 | D34: 5 | E34: 12 | F34: EN | I34: No amenaçades Cat/Es | J34: =COUNTIF($F$3:$F$35,"") -> 11
A35: Amfibis | B35: Triturus marmoratus | C35: 10 | D35: 2 | E35: 8

Sheet PLA
A1: MODEL DE PLA ESTRATÈGIC PELS ENP | I1: canviat optatiu-obligatori | J1: text modificat
B2: Espai natural protegit: | C2: L'Albera | J2: No aplicable (NA)
S3: Fita a assolir en 4 anys | U3: Gestió interna | Y3: Anualitat
A4: EIXOS | C4: OBJECTIUS Generals (PP) | E4: OBJECTIUS Estratègics | G4: OBJECTIUS operatius | H4: Comú / Específic | I4: Obligatori / Optatiu | J4: Objectiu operatiu concret a l'espai | K4: Explicació de la decisió presa en el cas de canvis respecte al llistat inicial (columna G) | L4: Objectiu amb mesures incorporables a la planificació anual de la gestió de l'espai? | M4: Prioritat | N4: Propostes genèriques d'accions | O4: Marc de referència | P4: Resultats derivats | Q4: Accions (afegit Albera) | R4: indicadors | S4: Mínima | T4: Màxim (Desitjable) | U4: Hores de dedicació (hores/setmana) | V4: Total hores període (hores) | W4: Àrea responsable | X4: Persona responsable | Y4: 2025 | Z4: 2026 | AA4: 2027 | AB4: 2028
A5: NATURA | B5: 1 | C5: CONSERVAR LA NATURA i restaurar els ecosistemes, els processos naturals i seminaturals, la biodiversitat i la geodiversitat associada. | D5: 01.1 | E5: Adequar i fer eficient la conservació dels elements objecte de gestió prioritària marcats per la DG a l'ENP | F5: 01.1.1 | G5: Implementar i executar plans de gestió específics per a hàbitats i espècies de conservació prioritària dins l'ENP | H5: Comú | I5: Obligatori | J5: =G5 -> Implementar i executar plans de gestió específics per a hàbitats i espècies de conservació prioritària dins l'ENP | M5: MÀXIMA | N5: *Realització d'accions per a la millora dels elements prioritzats a l'espai *Elaboració de plans de gestió per elements prioritzats a l'espai | O5: MAP | P5: SFF: Elaboració de plans de gestió específics per a espècies de conservació prioritària i directrius de gestió d'hàbitats. SFF/SENP: Definir a nivell de cluster quins son els que es poden elaborar conjuntament. | Q5: Millora del coneixement de la distribució i població (o superfície) dels elements priorizats. | R5: % d'elements prioritzats dels quals s'ha millorat el coneixent en base a les aproximacions següents: (1) Increment anual del 25% de N elements amb informació/N total elements prioritzats a l'espai (any 2029 -> Inexistència de cap element prioritzat sense 'feina feta' ). 2) Distribució: Tots els quadrats 1x1 de l'ENP tenen informació de la distribució dels elements prioritzats. 3) Es coneixen densitats poblacionals/estimes per totes les sp catalogades 'En Perill' i s'estableix periodicitat seguiment/sp. 4) Es prospecta el 50% d'hàbitat no prospectat per a una sp 5) Almenys 1 vegada es fa una anàlisi poblacional per a sp que no es coneix la distribució (òliba) | S5: 0.5 | T5: 1 | U5: 15 | V5: =PLA!U5*Llistes!$L$11*Llistes!$L$12 -> 2000 | W5: Patrimoni natural | X5: =IF(W5=Llistes!$K$2,Llistes!$L$2,IF(W5=Llistes!$K$3,Llistes!$L$3,IF(W5=Llistes!$K$4,Llistes!$L$4,IF(W5=Llistes!$K$5,Llistes!$L$5,IF(W5=Llistes!$K$6,Llistes!$L$6,IF(W5=Llistes!$K$7,Llistes!$L$7,"")))))) -> Pau Federico | Y5: X | Z5: X | AA5: X | AB5: X
A6: NATURA | F6: 01.1.1 | G6: Implementar i executar plans de gestió específics per a hàbitats i espècies de conservació prioritària dins l'ENP | H6: Comú | I6: Obligatori | J6: =G6 -> Implementar i executar plans de gestió específics per a hàbitats i espècies de conservació prioritària dins l'ENP | M6: MÀXIMA | Q6: Desplegament del MAP a l'espai XN2000 Basses Albera | R6: Nombre d'accions del MAP que s'han començat a desenvolupar | S6: 0.3 | T6: 0.6 | U6: 7.8 | V6: =PLA!U6*Llistes!$L$11*Llistes!$L$12 -> 1040 | W6: XN2000 | X6: =IF(W6=Llistes!$K$2,Llistes!$L$2,IF(W6=Llistes!$K$3,Llistes!$L$3,IF(W6=Llistes!$K$4,Llistes!$L$4,IF(W6=Llistes!$K$5,Llistes!$L$5,IF(W6=Llistes!$K$6,Llistes!$L$6,IF(W6=Llistes!$K$7,Llistes!$L$7,"")))))) -> Montse Pascual | Y6: X | Z6: X | AA6: X | AB6: X
A7: NATURA | F7: 01.1.1 | G7: Implementar i executar plans de gestió específics per a hàbitats i espècies de conservació prioritària dins l'ENP | H7: Comú | I7: Obligatori | J7: =G7 -> Implementar i executar plans de gestió específics per a hàbitats i espècies de conservació prioritària dins l'ENP | M7: MÀXIMA | Q7: Redacció del projecte de restauració de depressions. | R7: S'ha redactat el projecte | T7: Sí | U7: 0.15 | V7: =PLA!U7*Llistes!$L$11*Llistes!$L$12 -> 20 | W7: XN2000 | X7: =IF(W7=Llistes!$K$2,Llistes!$L$2,IF(W7=Llistes!$K$3,Llistes!$L$3,IF(W7=Llistes!$K$4,Llistes!$L$4,IF(W7=Llistes!$K$5,Llistes!$L$5,IF(W7=Llistes!$K$6,Llistes!$L$6,IF(W7=Llistes!$K$7,Llistes!$L$7,"")))))) -> Montse Pascual | Y7: X | Z7: X | AA7: X | AB7: X
A8: NATURA | F8: 01.1.1 | G8: Implementar i executar plans de gestió específics per a hàbitats i espècies de conservació prioritària dins l'ENP | H8: Comú | I8: Obligatori | J8: =G8 -> Implementar i executar plans de gestió específics per a hàbitats i espècies de conservació prioritària dins l'ENP | M8: MÀXIMA | Q8: Execució del projecte de restauració de depressions | R8: S'ha executat el projecte | T8: Sí | U8: 0.15 | V8: =PLA!U8*Llistes!$L$11*Llistes!$L$12 -> 20 | W8: XN2000 | X8: =IF(W8=Llistes!$K$2,Llistes!$L$2,IF(W8=Llistes!$K$3,Llistes!$L$3,IF(W8=Llistes!$K$4,Llistes!$L$4,IF(W8=Llistes!$K$5,Llistes!$L$5,IF(W8=Llistes!$K$6,Llistes!$L$6,IF(W8=Llistes!$K$7,Llistes!$L$7,"")))))) -> Montse Pascual | Y8: X | Z8: X | AA8: X | AB8: X
A9: NATURA | F9: 01.1.1 | G9: Implementar i executar plans de gestió específics per a hàbitats i espècies de conservació prioritària dins l'ENP | H9: Comú | I9: Obligatori | J9: =G9 -> Implementar i executar plans de gestió específics per a hàbitats i espècies de conservació prioritària dins l'ENP | M9: MÀXIMA | Q9: Redacció del projecte executiu de restauració de Garbet | R9: S'ha redactat el projecte executiu | T9: Sí | U9: 0.15 | V9: =PLA!U9*Llistes!$L$11*Llistes!$L$12 -> 20 | W9: XN2000 | X9: =IF(W9=Llistes!$K$2,Llistes!$L$2,IF(W9=Llistes!$K$3,Llistes!$L$3,IF(W9=Llistes!$K$4,Llistes!$L$4,IF(W9=Llistes!$K$5,Llistes!$L$5,IF(W9=Llistes!$K$6,Llistes!$L$6,IF(W9=Llistes!$K$7,Llistes!$L$7,"")))))) -> Montse Pascual | Y9: X | Z9: X | AA9: X | AB9: X
A10: NATURA | F10: 01.1.1 | G10: Implementar i executar plans de gestió específics per a hàbitats i espècies de conservació prioritària dins l'ENP | H10: Comú | I10: Obligatori | J10: =G10 -> Implementar i executar plans de gestió específics per a hàbitats i espècies de conservació prioritària dins l'ENP | M10: MÀXIMA | Q10: Execució del projecte de restauració de Garbet | R10: S'ha executat el projecte | T10: Sí | U10: 0.15 | V10: =PLA!U10*Llistes!$L$11*Llistes!$L$12 -> 20 | W10: XN2000 | X10: =IF(W10=Llistes!$K$2,Llistes!$L$2,IF(W10=Llistes!$K$3,Llistes!$L$3,IF(W10=Llistes!$K$4,Llistes!$L$4,IF(W10=Llistes!$K$5,Llistes!$L$5,IF(W10=Llistes!$K$6,Llistes!$L$6,IF(W10=Llistes!$K$7,Llistes!$L$7,"")))))) -> Montse Pascual | Y10: X | Z10: X | AA10: X | AB10: X
A11: NATURA | F11: 01.1.1 | G11: Implementar i executar plans de gestió específics per a hàbitats i espècies de conservació prioritària dins l'ENP | H11: Comú | I11: Obligatori | J11: =G11 -> Implementar i executar plans de gestió específics per a hàbitats i espècies de conservació prioritària dins l'ENP | M11: MÀXIMA | N11: *Realització d'accions per a la millora dels elements prioritzats a l'espai *Elaboració de plans de gestió per elements prioritzats a l'espai | Q11: Realització d'accions per a la millora dels elements prioritzats a l'espai | R11: S'ha realitzat com a mínim 1 acció/sp | S11: 1 acció/ 50% sp prioritzades | T11: 1 acció/ 100% sp prioritzades | U11: 7.02 | V11: =PLA!U11*Llistes!$L$11*Llistes!$L$12 -> 936 | W11: Patrimoni natural | X11: =IF(W11=Llistes!$K$2,Llistes!$L$2,IF(W11=Llistes!$K$3,Llistes!$L$3,IF(W11=Llistes!$K$4,Llistes!$L$4,IF(W11=Llistes!$K$5,Llistes!$L$5,IF(W11=Llistes!$K$6,Llistes!$L$6,IF(W11=Llistes!$K$7,Llistes!$L$7,"")))))) -> Pau Federico | Y11: X | Z11: X | AA11: X | AB11: X
A12: NATURA | F12: 01.1.1 | G12: Implementar i executar plans de gestió específics per a hàbitats i espècies de conservació prioritària dins l'ENP | H12: Comú | I12: Obligatori | J12: =G12 -> Implementar i executar plans de gestió específics per a hàbitats i espècies de conservació prioritària dins l'ENP | M12: ALTA | Q12: Seguiment rompudes i efectes dels treballs forestals sobre tortuga mediterrània en XN2000 | R12: Nombre d'expedients | S12: Al 50% dels expedients se'ls fa un seguiment | T12: Al 100% dels expedients se'ls fa un seguiment | U12: 0.15 | V12: =PLA!U12*Llistes!$L$11*Llistes!$L$12 -> 20 | W12: XN2000 | X12: =IF(W12=Llistes!$K$2,Llistes!$L$2,IF(W12=Llistes!$K$3,Llistes!$L$3,IF(W12=Llistes!$K$4,Llistes!$L$4,IF(W12=Llistes!$K$5,Llistes!$L$5,IF(W12=Llistes!$K$6,Llistes!$L$6,IF(W12=Llistes!$K$7,Llistes!$L$7,"")))))) -> Montse Pascual
A13: NATURA | F13: 01.1.2 | G13: Adaptar i executar plans de gestió específics per a elements geològics de conservació prioritària dins l'ENP | H13: Comú | I13: Obligatori
A14: NATURA | D14: 01.2 | E14: Executar les mesures de gestió directa previstes en els intruments de planificació per la conservació i la gestió adaptativa dels elements clau de l'ENP | F14: 01.2.1 | G14: Implementar la metodologia de gestió adaptativa (Estàndards Oberts de Gestió Adaptativa a Catalunya) en tots els processos de l'ENP | H14: Comú | I14: Obligatori | J14: =G14 -> Implementar la metodologia de gestió adaptativa (Estàndards Oberts de Gestió Adaptativa a Catalunya) en tots els processos de l'ENP | M14: ALTA | N14: *Definició d'un protocol per tal d'incorporar la metodologia dels Estàndards Oberts pels processos més rellevants per a la conservació a l'espai | O14: ESNATURA | P14: SENP: Elaboració d'un manual per la implementació dels OSAM | Q14: Aplicació de la metodologia dels Estàndards Oberts pels processos més rellevants per a la conservació a l'espai | R14: 1) S'analitzen els resultats a través dels indicadors 2) La planificació s'adapta en funció dels resultats. 3) S'avalua el grau de millora de les amenaces/factors de canvi | S14: Per al 50% de les accions | T14: Per al 100% de les accions | U14: 0.15 | V14: =PLA!U14*Llistes!$L$11*Llistes!$L$12 -> 20 | W14: Direcció | X14: =IF(W14=Llistes!$K$2,Llistes!$L$2,IF(W14=Llistes!$K$3,Llistes!$L$3,IF(W14=Llistes!$K$4,Llistes!$L$4,IF(W14=Llistes!$K$5,Llistes!$L$5,IF(W14=Llistes!$K$6,Llistes!$L$6,IF(W14=Llistes!$K$7,Llistes!$L$7,"")))))) -> Gerard Carrion | Y14: X | Z14: X | AA14: X | AB14: X
A15: NATURA | F15: 01.2.1 | G15: Implementar la metodologia de gestió adaptativa (Estàndards Oberts de Gestió Adaptativa a Catalunya) en tots els processos de l'ENP | H15: Comú | I15: Obligatori | J15: =G15 -> Implementar la metodologia de gestió adaptativa (Estàndards Oberts de Gestió Adaptativa a Catalunya) en tots els processos de l'ENP | M15: ALTA | Q15: Aplicació de la metodologia dels Estàndards Oberts pels processos més rellevants per a la conservació a l'espai de XN2000 Basses de l'Albera | R15: S'aplica la metodologia dels estàndars oberts | T15: Sí | U15: 0.15 | V15: =PLA!U15*Llistes!$L$11*Llistes!$L$12 -> 20 | W15: XN2000 | X15: =IF(W15=Llistes!$K$2,Llistes!$L$2,IF(W15=Llistes!$K$3,Llistes!$L$3,IF(W15=Llistes!$K$4,Llistes!$L$4,IF(W15=Llistes!$K$5,Llistes!$L$5,IF(W15=Llistes!$K$6,Llistes!$L$6,IF(W15=Llistes!$K$7,Llistes!$L$7,"")))))) -> Montse Pascual | Y15: X | Z15: X | AA15: X | AB15: X
A16: NATURA | F16: 01.2.2 | G16: Executar les mesures previstes en els plans de conservació o recuperació d'espècies amenaçades de forma coordinada amb el Servei de Flora i Fauna en l'àmbit de l'ENP | H16: Comú | I16: Obligatori | J16: =G16 -> Executar les mesures previstes en els plans de conservació o recuperació d'espècies amenaçades de forma coordinada amb el Servei de Flora i Fauna en l'àmbit de l'ENP | M16: MÀXIMA | N16: * Implicació i participació en la redacció dels plans de conservació /recuperació d'espècies amenaçades | Q16: Implicació i participació en la redacció dels plans de conservació /recuperació d'espècies amenaçades | R16: 1) Nombre de plans de conservació/recuperació en els que l'ENP hi participa | S16: 1) Participació en el 50% dels plans d'sp amenaçades (EN i VU), 11 | T16: 1) Participació en el 100% dels plans d'sp amenaçades (EN i VU),22 | U16: 3 | V16: =PLA!U16*Llistes!$L$11*Llistes!$L$12 -> 400 | W16: Patrimoni natural | X16: =IF(W16=Llistes!$K$2,Llistes!$L$2,IF(W16=Llistes!$K$3,Llistes!$L$3,IF(W16=Llistes!$K$4,Llistes!$L$4,IF(W16=Llistes!$K$5,Llistes!$L$5,IF(W16=Llistes!$K$6,Llistes!$L$6,IF(W16=Llistes!$K$7,Llistes!$L$7,"")))))) -> Pau Federico | Y16: X | Z16: X | AA16: X | AB16: X
A17: NATURA | F17: 01.2.2 | G17: Executar les mesures previstes en els plans de conservació o recuperació d'espècies amenaçades de forma coordinada amb el Servei de Flora i Fauna en l'àmbit de l'ENP | H17: Comú | I17: Obligatori | J17: =G17 -> Executar les mesures previstes en els plans de conservació o recuperació d'espècies amenaçades de forma coordinada amb el Servei de Flora i Fauna en l'àmbit de l'ENP | M17: MÀXIMA | N17: * Execució de les accions dins els plans que pertoquin a cada espai (incorporar totes les mesures que surten als plans ja aprovats que tenen incidència a l'espai) | Q17: Execució de les accions dins els plans que pertoquin a cada espai (incorporar totes les mesures que surten als plans ja aprovats que tenen incidència a l'espai) | R17: Nombre d'accions que provenen de l'aplicació de plans de conservació/recuperació | S17: 5 accions | T17: 10 accions | U17: 3 | V17: =PLA!U17*Llistes!$L$11*Llistes!$L$12 -> 400 | W17: Patrimoni natural | X17: =IF(W17=Llistes!$K$2,Llistes!$L$2,IF(W17=Llistes!$K$3,Llistes!$L$3,IF(W17=Llistes!$K$4,Llistes!$L$4,IF(W17=Llistes!$K$5,Llistes!$L$5,IF(W17=Llistes!$K$6,Llistes!$L$6,IF(W17=Llistes!$K$7,Llistes!$L$7,"")))))) -> Pau Federico | Y17: X | Z17: X | AA17: X | AB17: X
A18: NATURA | F18: 01.2.2 | G18: Executar les mesures previstes en els plans de conservació o recuperació d'espècies amenaçades de forma coordinada amb el Servei de Flora i Fauna en l'àmbit de l'ENP | H18: Comú | I18: Obligatori | J18: =G18 -> Executar les mesures previstes en els plans de conservació o recuperació d'espècies amenaçades de forma coordinada amb el Servei de Flora i Fauna en l'àmbit de l'ENP | M18: MÀXIMA | N18: * Col.laboració en l'obtenció de la informació necessària dins els espais per al desenvolupament dels Plans | O18: MAP Catàlegs | P18: SFF: Elaboració de plans de conservació o recuperació d'espècies protegides | Q18: Col·laboració en l'obtenció de la informació necessària dins els espais per al desenvolupament dels Plans | R18: Nombre d'sp amenaçades prioritzades amb les quals treballa l'ENP | S18: 50% sp amenaçades prioritzades | T18: 100% sp amenaçades prioritzades | U18: 3 | V18: =PLA!U18*Llistes!$L$11*Llistes!$L$12 -> 400 | W18: Patrimoni natural | X18: =IF(W18=Llistes!$K$2,Llistes!$L$2,IF(W18=Llistes!$K$3,Llistes!$L$3,IF(W18=Llistes!$K$4,Llistes!$L$4,IF(W18=Llistes!$K$5,Llistes!$L$5,IF(W18=Llistes!$K$6,Llistes!$L$6,IF(W18=Llistes!$K$7,Llistes!$L$7,"")))))) -> Pau Federico | Y18: X | Z18: X | AA18: X | AB18: X
A19: NATURA | F19: 01.2.3 | G19: Executar les mesures de gestió previstes en els plans de control i erradicació d'espècies exòtiques de forma coordinada amb el Servei de Flora i Fauna en l'àmbit de l'ENP | H19: Comú | I19: Obligatori | J19: =G19 -> Executar les mesures de gestió previstes en els plans de control i erradicació d'espècies exòtiques de forma coordinada amb el Servei de Flora i Fauna en l'àmbit de l'ENP | M19: MÀXIMA | N19: * Implicació i participació en la redacció (cal identificar els plans que estan ja en marxa o previstos i posar les mesures concretes) * Execució de les accions dins els plans que pertoquin a cada espai * Col.laboració en l'obtenció de la informació necessària dins els espais per al desenvolupament dels Plans | Q19: Col·laboració amb el Servei de Fauna i Flora en les actuacions de gestió de les espècies exòtiques invasores dins de l'ENP. (Opuntia, bambú, estramoni, Solanum sisymbriifolium, coipú, visó americà, ailant, cortaderia i robínia) (XN2000) | R19: Nombre d'EEI prioritzades en l'ENP que es gestionen | S19: 3 EEI | T19: 6 EEI | U19: 1.02 | V19: =PLA!U19*Llistes!$L$11*Llistes!$L$12 -> 136 | W19: Patrimoni natural | X19: =IF(W19=Llistes!$K$2,Llistes!$L$2,IF(W19=Llistes!$K$3,Llistes!$L$3,IF(W19=Llistes!$K$4,Llistes!$L$4,IF(W19=Llistes!$K$5,Llistes!$L$5,IF(W19=Llistes!$K$6,Llistes!$L$6,IF(W19=Llistes!$K$7,Llistes!$L$7,"")))))) -> Pau Federico | Y19: X | Z19: X | AA19: X | AB19: X
A20: NATURA | F20: 01.2.3 | G20: Executar les mesures de gestió previstes en els plans de control i erradicació d'espècies exòtiques de forma coordinada amb el Servei de Flora i Fauna en l'àmbit de l'ENP | H20: Comú | I20: Obligatori | J20: =G20 -> Executar les mesures de gestió previstes en els plans de control i erradicació d'espècies exòtiques de forma coordinada amb el Servei de Flora i Fauna en l'àmbit de l'ENP | M20: MÀXIMA | N20: * Implicació i participació en la redacció (cal identificar els plans que estan ja en marxa o previstos i posar les mesures concretes) * Execució de les accions dins els plans que pertoquin a cada espai * Col.laboració en l'obtenció de la informació necessària dins els espais per al desenvolupament dels Plans | O20: ESNATURA MAP | P20: SFF: Elaboració de plans de control i erradicació d'espècies exòtiques | Q20: Coordinació i realització d'accions de gestió d'espècies exòtiques invasores dins de l'ENP (Opuntia, bambú, estramoni, Solanum sisymbriifolium, coipú) (XN2000). | R20: Nombre de reunions/any vinculades a EEI en què l'ENP participa o impulsades pel ENP | S20: 1 reunions/any | T20: 3 reunions/any | U20: 0.15 | V20: =PLA!U20*Llistes!$L$11*Llistes!$L$12 -> 20 | W20: Patrimoni natural | X20: =IF(W20=Llistes!$K$2,Llistes!$L$2,IF(W20=Llistes!$K$3,Llistes!$L$3,IF(W20=Llistes!$K$4,Llistes!$L$4,IF(W20=Llistes!$K$5,Llistes!$L$5,IF(W20=Llistes!$K$6,Llistes!$L$6,IF(W20=Llistes!$K$7,Llistes!$L$7,"")))))) -> Pau Federico | Y20: X | Z20: X | AA20: X | AB20: X
A21: NATURA | F21: 01.2.4 | G21: Desplegar els objectius i tasques recollits en els instruments de referència i compromisos internacionals | H21: Específic | I21: Optatiu | J21: =G21 -> Desplegar els objectius i tasques recollits en els instruments de referència i compromisos internacionals | M21: MITJANA | N21: * Desplegament dels objectius recollits en l'Estratègia de la Xarxa d'àrees marines protegides del Mediterrani (MedPAN network) * Col·laboració en el compliment dels objectius i tasques derivats de la Mediterranean Climate Action Partnership en matèria de biodiversitat i canvi climàtic i els seus impactes sobre la sequera, calor i incendis * Col·laboració en la implementació pràctica de projectes de l'àrea internacional i dels compromisos amb les entitats membres UICN, Euroregió Pirineus Mediterrània | Q21: Col·laboració amb altres unitats per a l'assoliment d'objectius i compromisos internacionals, quan aquestes ho demanin. | R21: Nombre de reunions i/o accions vinculades a compromisos internacionals | S21: 1 reunions/any | T21: 3 reunions/any | U21: 0.15 | V21: =PLA!U21*Llistes!$L$11*Llistes!$L$12 -> 20 | W21: Direcció | X21: =IF(W21=Llistes!$K$2,Llistes!$L$2,IF(W21=Llistes!$K$3,Llistes!$L$3,IF(W21=Llistes!$K$4,Llistes!$L$4,IF(W21=Llistes!$K$5,Llistes!$L$5,IF(W21=Llistes!$K$6,Llistes!$L$6,IF(W21=Llistes!$K$7,Llistes!$L$7,"")))))) -> Gerard Carrion | Y21: X | Z21: X | AA21: X | AB21: X
A22: NATURA | F22: 01.2.4 | G22: Desplegar els objectius i tasques recollits en els instruments de referència i compromisos internacionals | H22: Específic | I22: Optatiu | J22: =G22 -> Desplegar els objectius i tasques recollits en els instruments de referència i compromisos internacionals | M22: MITJANA | Q22: Seguiment dels ajuts d’espais naturals i d’actuacions en espais de la XN2000. | R22: Percentatge d’ajuts sobre els que es fa seguiment | S22: 0.5 | T22: 1 | U22: 0.15 | V22: =PLA!U22*Llistes!$L$11*Llistes!$L$12 -> 20 | W22: XN2000 | X22: =IF(W22=Llistes!$K$2,Llistes!$L$2,IF(W22=Llistes!$K$3,Llistes!$L$3,IF(W22=Llistes!$K$4,Llistes!$L$4,IF(W22=Llistes!$K$5,Llistes!$L$5,IF(W22=Llistes!$K$6,Llistes!$L$6,IF(W22=Llistes!$K$7,Llistes!$L$7,"")))))) -> Montse Pascual
D23: 01.3 | E23: Crear ecosistemes complexes, resilients, i d'alta biodiversitat per garantir la recuperació dels processos ecosistèmics | F23: 01.3.1 | G23: Identificar espais pel foment de la dinàmica natural i l'aprofitament no extractiu | H23: Comú | I23: Obligatori | J23: Identificar espais pel foment de la dinàmica natural i l'aprofitament no extractiu | M23: ALTA | N23: *Afavorir la creació d'hàbitats per a la conservació d'espècies | Q23: Afavorir la creació d'hàbitats per a la conservació d'espècies | R23: Nombre d'hectàrees creades per a la conservació | S23: 2 ha | T23: 5 ha | U23: 0.3 | V23: =PLA!U23*Llistes!$L$11*Llistes!$L$12 -> 40 | W23: Patrimoni natural | X23: =IF(W23=Llistes!$K$2,Llistes!$L$2,IF(W23=Llistes!$K$3,Llistes!$L$3,IF(W23=Llistes!$K$4,Llistes!$L$4,IF(W23=Llistes!$K$5,Llistes!$L$5,IF(W23=Llistes!$K$6,Llistes!$L$6,IF(W23=Llistes!$K$7,Llistes!$L$7,"")))))) -> Pau Federico
A24: NATURA | F24: 01.3.1 | G24: Identificar espais pel foment de la dinàmica natural i l'aprofitament no extractiu | H24: Comú | I24: Obligatori | J24: =G23 -> Identificar espais pel foment de la dinàmica natural i l'aprofitament no extractiu | M24: ALTA | N24: *Participar en la identificació d'espais pel foment de la dinàmica natural i l'aprofitament no extractiu dins l'ENP en base a uns criteris metodològics predefinits | O24: ESNATURA | P24: SENP/SFF: Definir criteris metodològics | Q24: Participació en la identificació d'espais pel foment de la dinàmica natural i l'aprofitament no extractiu dins l'ENP en base a uns criteris metodològics predefinits | R24: Nombre d'hores dedicades a la identificació d'espais per a dinàmica natural | S24: 1 hora/any | T24: 3 hores/any | U24: 0.045 | V24: =PLA!U24*Llistes!$L$11*Llistes!$L$12 -> 6 | W24: Patrimoni natural | X24: =IF(W24=Llistes!$K$2,Llistes!$L$2,IF(W24=Llistes!$K$3,Llistes!$L$3,IF(W24=Llistes!$K$4,Llistes!$L$4,IF(W24=Llistes!$K$5,Llistes!$L$5,IF(W24=Llistes!$K$6,Llistes!$L$6,IF(W24=Llistes!$K$7,Llistes!$L$7,"")))))) -> Pau Federico | Y24: X | Z24: X | AA24: X | AB24: X
A25: NATURA | F25: 01.3.2 | G25: Afavorir la maduresa dels sistemes forestals | H25: Específic | I25: Obligatori | J25: =G25 -> Afavorir la maduresa dels sistemes forestals | M25: ALTA | N25: *Participar i impulsar la planificació i execució d'accions d'acceleració de la maduresa forestal en zones boscoses dins l'ENP en base als criteris metodològics predefinits | O25: MAP | P25: SENP/SFF: Definir criteris metodològics | Q25: Execució d'accions d'acceleració de la maduresa forestal en zones boscoses dins l'ENP en base als criteris metodològics predefinits | R25: Nombre d'hectàrees destinades a a maduresa forestal contemplades en els PTGiMF. | S25: 25% de les actuacions previstes als PTGiMF | T25: 50% de les actuacions previstes als PTGiMF | U25: 0.045 | V25: =PLA!U25*Llistes!$L$11*Llistes!$L$12 -> 6 | W25: Direcció | X25: =IF(W25=Llistes!$K$2,Llistes!$L$2,IF(W25=Llistes!$K$3,Llistes!$L$3,IF(W25=Llistes!$K$4,Llistes!$L$4,IF(W25=Llistes!$K$5,Llistes!$L$5,IF(W25=Llistes!$K$6,Llistes!$L$6,IF(W25=Llistes!$K$7,Llistes!$L$7,"")))))) -> Gerard Carrion | Y25: X | AA25: X
A26: NATURA | F26: 01.3.3 | G26: Generar pertorbacions controlades | H26: Específic | I26: Optatiu | J26: =G26 -> Generar pertorbacions controlades | K26: No hi ha zones compatibles amb cremes controlades dins del PNIN, ara mateix. Sí que es fan en zones de XN2000 | M26: MITJANA | N26: *Elaboració d'una planificació d'actuacions de simulació d'incendis forestals naturals (cremes controlades) dins l'espai en base als criteris metodològics predefinits. *Realització dels estudis necessaris i participació en la reintroducció de grans herbívors, carnívors o carronyaires dins l'ENP en base als criteris metodològics predefinits. | O26: MAP | P26: SENP/SFF: Definir criteris metodològics | Q26: Col·laboració amb Bombers i GEPIF per a la realització de cremes controlades en àmbits compatibles | R26: Nombre d'hectàrees destinades a cremes controlades | S26: 0,5 ha | T26: 1,5 ha | U26: 0.045 | V26: =PLA!U26*Llistes!$L$11*Llistes!$L$12 -> 6 | W26: Direcció | X26: =IF(W26=Llistes!$K$2,Llistes!$L$2,IF(W26=Llistes!$K$3,Llistes!$L$3,IF(W26=Llistes!$K$4,Llistes!$L$4,IF(W26=Llistes!$K$5,Llistes!$L$5,IF(W26=Llistes!$K$6,Llistes!$L$6,IF(W26=Llistes!$K$7,Llistes!$L$7,"")))))) -> Gerard Carrion | Y26: X | Z26: X | AA26: X | AB26: X
A27: NATURA | F27: 01.3.4 | G27: Restaurar la dinàmica natural dels rius | H27: Específic | I27: Optatiu
A28: NATURA | F28: 01.3.5 | G28: Fomentar el paisatge en mosaïc | H28: Específic | I28: Obligatori | J28: =G28 -> Fomentar el paisatge en mosaïc | M28: ALTA | N28: *Realització d'accions per gestionar l'herbivoria domèstica associada a la ramaderia extensiva *Aplicació dels criteris metodològics predefinits en un manual tècnic de bones pràctiques en ramaderia extensiva i recuperació i manteniment de pastures aplicat a l'ENP. *Coordinació i gestió dels ramats locals en actuacions de restauració de pastures i desembosc. | O28: ESNATURA | P28: SENP/SFF: Definir criteris metodològics | Q28: Col·laboració amb el sector ramader per mantenir i millorar les pastures, especialment en zones culminals d'interès per a la prevenció d'incendis. | R28: Nombre hectàrees desbrossades per mantenir les pastures per a la prevenció d'incendis | S28: 0,5 ha | T28: 1 ha | U28: 0.045 | V28: =PLA!U28*Llistes!$L$11*Llistes!$L$12 -> 6 | W28: Direcció | X28: =IF(W28=Llistes!$K$2,Llistes!$L$2,IF(W28=Llistes!$K$3,Llistes!$L$3,IF(W28=Llistes!$K$4,Llistes!$L$4,IF(W28=Llistes!$K$5,Llistes!$L$5,IF(W28=Llistes!$K$6,Llistes!$L$6,IF(W28=Llistes!$K$7,Llistes!$L$7,"")))))) -> Gerard Carrion | Y28: X | Z28: X | AA28: X | AB28: X
A29: NATURA | F29: 01.3.6 | G29: Gestionar i intervenir en la dinàmica de poblacions de fauna que no tenen depredador natural | H29: Específic | I29: Optatiu
A30: NATURA | F30: 01.3.7 | G30: Afavorir la connectivitat ecològica del territori | H30: Comú | I30: Obligatori
A31: NATURA | D31: 01.4 | E31: Alinear l'activitat de propietaris i gestors del territori amb la conservació, millora i restauració dels valors de l'ENP | F31: 01.4.1 | G31: Fomentar acords de custòdia en espais d'alt valor dins l'ENP per a la gestió dels elements prioritaris | H31: Comú | I31: Obligatori | J31: =G31 -> Fomentar acords de custòdia en espais d'alt valor dins l'ENP per a la gestió dels elements prioritaris | M31: MÀXIMA | N31: *Realització d'acords de custòdia aplicant el model d'acord elaborat per Serveis Centrals | O31: MAP | P31: SENP/SENP: Dissenyar el protocol i elaborar un model d'acord | Q31: Exploració de la via dels acords de custòdia en espais d'alt valor dins l'ENP. | R31: Establiment d'acords de custòdia en alguna de les finques privades | S31: 1 | T31: 2 | U31: 0.045 | V31: =PLA!U31*Llistes!$L$11*Llistes!$L$12 -> 6 | W31: Direcció | X31: =IF(W31=Llistes!$K$2,Llistes!$L$2,IF(W31=Llistes!$K$3,Llistes!$L$3,IF(W31=Llistes!$K$4,Llistes!$L$4,IF(W31=Llistes!$K$5,Llistes!$L$5,IF(W31=Llistes!$K$6,Llistes!$L$6,IF(W31=Llistes!$K$7,Llistes!$L$7,"")))))) -> Gerard Carrion
A32: NATURA | F32: 01.4.1 | G32: Fomentar acords de custòdia en espais d'alt valor dins l'ENP per a la gestió dels elements prioritaris | H32: Comú | I32: Obligatori | J32: =G32 -> Fomentar acords de custòdia en espais d'alt valor dins l'ENP per a la gestió dels elements prioritaris | M32: MÀXIMA | N32: *Realització d'acords de custòdia aplicant el model d'acord elaborat per Serveis Centrals | O32: MAP | P32: SENP/SENP: Dissenyar el protocol i elaborar un model d'acord | Q32: Redacció dels plans de gestió de les 3 finques privades incloses al PNIN, de forma consensuada amb la propietat. | R32: Nombre plans de gestió de les finques privades aprovats | S32: 1 | T32: 3 | U32: 0.045 | V32: =PLA!U32*Llistes!$L$11*Llistes!$L$12 -> 6 | W32: Direcció | X32: =IF(W32=Llistes!$K$2,Llistes!$L$2,IF(W32=Llistes!$K$3,Llistes!$L$3,IF(W32=Llistes!$K$4,Llistes!$L$4,IF(W32=Llistes!$K$5,Llistes!$L$5,IF(W32=Llistes!$K$6,Llistes!$L$6,IF(W32=Llistes!$K$7,Llistes!$L$7,"")))))) -> Gerard Carrion | Y32: X | Z32: X
A33: NATURA | F33: 01.4.2 | G33: Fomentar bones pràctiques entre els col·lectius de propietaris i gestors del territori | H33: Comú | I33: Obligatori | J33: =G33 -> Fomentar bones pràctiques entre els col·lectius de propietaris i gestors del territori | M33: ALTA | N33: *Realització d'actuacions demostratives en finques pròpies per al foment de bones pràctiques | Q33: Realització d'actuacions demostratives que permetin millorar la gestió d'hàbitats i espècies en altres llocs de l'espai, o zones semblants. | R33: Nombre actuacions destinades a accions demostratives | S33: 1 | T33: 2 | U33: 0.15 | V33: =PLA!U33*Llistes!$L$11*Llistes!$L$12 -> 20 | W33: Patrimoni natural | X33: =IF(W33=Llistes!$K$2,Llistes!$L$2,IF(W33=Llistes!$K$3,Llistes!$L$3,IF(W33=Llistes!$K$4,Llistes!$L$4,IF(W33=Llistes!$K$5,Llistes!$L$5,IF(W33=Llistes!$K$6,Llistes!$L$6,IF(W33=Llistes!$K$7,Llistes!$L$7,"")))))) -> Pau Federico | Y33: X | AA33: X
A34: NATURA
F35: 01.4.3 | G35: Impulsar la coordinació amb els ens locals en la gestió finques públiques situades dins d’ENP | H35: Específic | I35: Optatiu
A36: NATURA | B36: 2 | C36: ADAPTAR ELS ECOSISTEMES AL CANVI CLIMÀTIC i millorar-ne la resiliència en front dels riscos associats. | D36: 02.1 | E36: Planificar l'adaptació dels sistemes naturals al canvi climàtic | F36: 02.1.1 | G36: Adaptar i implementar el Pla d'adaptació de l'ENP al canvi climàtic | H36: Comú | I36: Obligatori | J36: Redactar i implementar el Pla d'adaptació de l'ENP al canvi climàtic | K36: No disposem de cap Pla d'adaptació de l'ENP al canvi climàtic, de manera que primer caldrà redactar-lo. | M36: ALTA | N36: *Planificació del sistema d'espais oberts *Creació de zones de laminació per defensa de inundacions *Creació i manteniment d'espais dunars de protecció de temporals | Q36: Redacció del Pla d'adaptació del PNIN al canvi climàtic. | R36: S'ha redactat el Pla d'adaptació del PNIN al canvi climàtic | T36: Sí | U36: 0.51 | V36: =PLA!U36*Llistes!$L$11*Llistes!$L$12 -> 68 | W36: Direcció | X36: =IF(W36=Llistes!$K$2,Llistes!$L$2,IF(W36=Llistes!$K$3,Llistes!$L$3,IF(W36=Llistes!$K$4,Llistes!$L$4,IF(W36=Llistes!$K$5,Llistes!$L$5,IF(W36=Llistes!$K$6,Llistes!$L$6,IF(W36=Llistes!$K$7,Llistes!$L$7,"")))))) -> Gerard Carrion | Y36: X | Z36: X
A37: NATURA | F37: 02.1.1 | G37: Adaptar i implementar el Pla d'adaptació de l'ENP al canvi climàtic | H37: Comú | I37: Obligatori | J37: Redactar i implementar el Pla d'adaptació de l'ENP al canvi climàtic | K37: No disposem de cap Pla d'adaptació de l'ENP al canvi climàtic, de manera que primer caldrà redactar-lo. | M37: ALTA | N37: *Planificació del sistema d'espais oberts *Creació de zones de laminació per defensa de inundacions *Creació i manteniment d'espais dunars de protecció de temporals | Q37: Donar a conèixer el Pla entre els propietaris perquè puguin integrar les mesures proposades a la gestió de les seves finques. | R37: Nombre de propietats informades sobre el Pla d'adaptació al canvi climàtic | S37: 1 | T37: 3 (les que tinguin Pla de Gestió) | U37: 0.045 | V37: =PLA!U37*Llistes!$L$11*Llistes!$L$12 -> 6 | W37: Direcció | X37: =IF(W37=Llistes!$K$2,Llistes!$L$2,IF(W37=Llistes!$K$3,Llistes!$L$3,IF(W37=Llistes!$K$4,Llistes!$L$4,IF(W37=Llistes!$K$5,Llistes!$L$5,IF(W37=Llistes!$K$6,Llistes!$L$6,IF(W37=Llistes!$K$7,Llistes!$L$7,"")))))) -> Gerard Carrion | AA37: X
A38: NATURA | F38: 02.1.1 | G38: Adaptar i implementar el Pla d'adaptació de l'ENP al canvi climàtic | H38: Comú | I38: Obligatori | J38: Redactar i implementar el Pla d'adaptació de l'ENP al canvi climàtic | K38: No disposem de cap Pla d'adaptació de l'ENP al canvi climàtic, de manera que primer caldrà redactar-lo. | M38: ALTA | N38: *Planificació del sistema d'espais oberts *Creació de zones de laminació per defensa de inundacions *Creació i manteniment d'espais dunars de protecció de temporals | P38: OCCC/SENP: Elaboració del model de Pla d'adaptació dels ENP al canvi climàtic | Q38: Implementació de les mesures d'adaptació del PNIN al canvi climàtic | R38: Nombre de mesures implementades relacionades amb l'adaptació al canvi climàtic | S38: 1 | T38: 4 | U38: 0.045 | V38: =PLA!U38*Llistes!$L$11*Llistes!$L$12 -> 6 | W38: Direcció | X38: =IF(W38=Llistes!$K$2,Llistes!$L$2,IF(W38=Llistes!$K$3,Llistes!$L$3,IF(W38=Llistes!$K$4,Llistes!$L$4,IF(W38=Llistes!$K$5,Llistes!$L$5,IF(W38=Llistes!$K$6,Llistes!$L$6,IF(W38=Llistes!$K$7,Llistes!$L$7,"")))))) -> Gerard Carrion | AA38: X | AB38: X
A39: NATURA | F39: 02.1.2 | G39: Gestionar i planificar els recursos hídrics de l'ENP | H39: Comú | I39: Obligatori | J39: =G39 -> Gestionar i planificar els recursos hídrics de l'ENP | K39: Gestió i manteniment de les fonts i punts d'aigua del PNIN perquè els recursos hídrics estiguin disponibles tant per als hàbitats i les espècies, com per als usos humans (ramaderia, aigua de boca...). | M39: MÀXIMA | Q39: Revisió de les fonts i punts d'aigua per assegurar el seu manteniment (XN2000) | R39: Nombre de fonts i punts d'aigua revisats | S39: 5 | T39: 10 | U39: 1.02 | V39: =PLA!U39*Llistes!$L$11*Llistes!$L$12 -> 136 | W39: Manteniment | X39: =IF(W39=Llistes!$K$2,Llistes!$L$2,IF(W39=Llistes!$K$3,Llistes!$L$3,IF(W39=Llistes!$K$4,Llistes!$L$4,IF(W39=Llistes!$K$5,Llistes!$L$5,IF(W39=Llistes!$K$6,Llistes!$L$6,IF(W39=Llistes!$K$7,Llistes!$L$7,"")))))) -> Sergi Roura | Y39: X | Z39: X | AA39: X | AB39: X
A40: NATURA | F40: 02.1.2 | G40: Gestionar i planificar els recursos hídrics de l'ENP | H40: Comú | I40: Obligatori | J40: =G40 -> Gestionar i planificar els recursos hídrics de l'ENP | K40: Gestió i manteniment de les fonts i punts d'aigua del PNIN perquè els recursos hídrics estiguin disponibles tant per als hàbitats i les espècies, com per als usos humans (ramaderia, aigua de boca...). | M40: MÀXIMA | Q40: Manteniment de GR, itineraris, camins d’accés a dòlmens i menhirs (XN2000) | R40: Nombre de camins, dòlmens i menhirs revisats | U40: 1.02 | V40: =PLA!U40*Llistes!$L$11*Llistes!$L$12 -> 136 | W40: Manteniment | X40: =IF(W40=Llistes!$K$2,Llistes!$L$2,IF(W40=Llistes!$K$3,Llistes!$L$3,IF(W40=Llistes!$K$4,Llistes!$L$4,IF(W40=Llistes!$K$5,Llistes!$L$5,IF(W40=Llistes!$K$6,Llistes!$L$6,IF(W40=Llistes!$K$7,Llistes!$L$7,"")))))) -> Sergi Roura
...

Sheet Transposicio_Pla_Doc
A1: EIXOS | C1: OBJECTIUS Generals (PP) | E1: Objectiu Estratègic | F1: Codi | G1: Objectiu operatiu | H1: Accions (afegit Albera) | I1: Indicadors | J1: Valor mínim | K1: Valor objectiu | L1: Objectiu operatiu | M1: Comú / Específic | N1: Obligatori / Optatiu | O1: Explicació de la decisió presa en el cas de canvis respecte al llistat inicial (columna G) | P1: Objectiu amb mesures incorporables a la planificació anual de la gestió de l'espai? | Q1: Prioritat | R1: Propostes genèriques d'accions | S1: Marc de referència | T1: Resultats derivats | U1: Hores de dedicació (hores/setmana) | V1: Total hores període (hores) | W1: Àrea responsable | X1: Persona responsable | Y1: 2025 | Z1: 2026 | AA1: 2027 | AB1: 2028
A2: NATURA | B2: 1 | C2: CONSERVAR LA NATURA i restaurar els ecosistemes, els processos naturals i seminaturals, la biodiversitat i la geodiversitat associada. | D2: 01.1 | E2: Adequar i fer eficient la conservació dels elements objecte de gestió prioritària marcats per la DG a l'ENP | F2: 01.1.1 | G2: =L2 -> Implementar i executar plans de gestió específics per a hàbitats i espècies de conservació prioritària dins l'ENP | H2: Millora del coneixement de la distribució i població (o superfície) dels elements priorizats. | I2: % d'elements prioritzats dels quals s'ha millorat el coneixent en base a les aproximacions següents: (1) Increment anual del 25% de N elements amb informació/N total elements prioritzats a l'espai (any 2029 -> Inexistència de cap element prioritzat sense 'feina feta' ). 2) Distribució: Tots els quadrats 1x1 de l'ENP tenen informació de la distribució dels elements prioritzats. 3) Es coneixen densitats poblacionals/estimes per totes les sp catalogades 'En Perill' i s'estableix periodicitat seguiment/sp. 4) Es prospecta el 50% d'hàbitat no prospectat per a una sp 5) Almenys 1 vegada es fa una anàlisi poblacional per a sp que no es coneix la distribució (òliba) | J2: 0.5 | K2: 1 | L2: Implementar i executar plans de gestió específics per a hàbitats i espècies de conservació prioritària dins l'ENP | M2: Comú | N2: Obligatori | Q2: MÀXIMA | R2: *Realització d'accions per a la millora dels elements prioritzats a l'espai *Elaboració de plans de gestió per elements prioritzats a l'espai | S2: MAP | T2: SFF: Elaboració de plans de gestió específics per a espècies de conservació prioritària i directrius de gestió d'hàbitats. SFF/SENP: Definir a nivell de cluster quins son els que es poden elaborar conjuntament. | U2: 15 | V2: =PLA!U5*Llistes!$L$11*Llistes!$L$12 -> 2000 | W2: Patrimoni natural | X2: =IF(W2=Llistes!$K$2,Llistes!$L$2,IF(W2=Llistes!$K$3,Llistes!$L$3,IF(W2=Llistes!$K$4,Llistes!$L$4,IF(W2=Llistes!$K$5,Llistes!$L$5,IF(W2=Llistes!$K$6,Llistes!$L$6,IF(W2=Llistes!$K$7,Llistes!$L$7,"")))))) -> Pau Federico | Y2: X | Z2: X | AA2: X | AB2: X
A3: NATURA | F3: 01.1.1 | G3: =L3 -> Implementar i executar plans de gestió específics per a hàbitats i espècies de conservació prioritària dins l'ENP | H3: Desplegament del MAP a l'espai XN2000 Basses Albera | I3: Nombre d'accions del MAP que s'han començat a desenvolupar | J3: 0.3 | K3: 0.6 | L3: Implementar i executar plans de gestió específics per a hàbitats i espècies de conservació prioritària dins l'ENP | M3: Comú | N3: Obligatori | Q3: MÀXIMA | U3: 7.8 | V3: =PLA!U6*Llistes!$L$11*Llistes!$L$12 -> 1040 | W3: XN2000 | X3: =IF(W3=Llistes!$K$2,Llistes!$L$2,IF(W3=Llistes!$K$3,Llistes!$L$3,IF(W3=Llistes!$K$4,Llistes!$L$4,IF(W3=Llistes!$K$5,Llistes!$L$5,IF(W3=Llistes!$K$6,Llistes!$L$6,IF(W3=Llistes!$K$7,Llistes!$L$7,"")))))) -> Montse Pascual | Y3: X | Z3: X | AA3: X | AB3: X
A4: NATURA | F4: 01.1.1 | G4: =L4 -> Implementar i executar plans de gestió específics per a hàbitats i espècies de conservació prioritària dins l'ENP | H4: Redacció del projecte de restauració de depressions. | I4: S'ha redactat el projecte | K4: Sí | L4: Implementar i executar plans de gestió específics per a hàbitats i espècies de conservació prioritària dins l'ENP | M4: Comú | N4: Obligatori | Q4: MÀXIMA | U4: 0.15 | V4: =PLA!U7*Llistes!$L$11*Llistes!$L$12 -> 20 | W4: XN2000 | X4: =IF(W4=Llistes!$K$2,Llistes!$L$2,IF(W4=Llistes!$K$3,Llistes!$L$3,IF(W4=Llistes!$K$4,Llistes!$L$4,IF(W4=Llistes!$K$5,Llistes!$L$5,IF(W4=Llistes!$K$6,Llistes!$L$6,IF(W4=Llistes!$K$7,Llistes!$L$7,"")))))) -> Montse Pascual | Y4: X | Z4: X | AA4: X | AB4: X
A5: NATURA | F5: 01.1.1 | G5: =L5 -> Implementar i executar plans de gestió específics per a hàbitats i espècies de conservació prioritària dins l'ENP | H5: Execució del projecte de restauració de depressions | I5: S'ha executat el projecte | K5: Sí | L5: Implementar i executar plans de gestió específics per a hàbitats i espècies de conservació prioritària dins l'ENP | M5: Comú | N5: Obligatori | Q5: MÀXIMA | U5: 0.15 | V5: =PLA!U8*Llistes!$L$11*Llistes!$L$12 -> 20 | W5: XN2000 | X5: =IF(W5=Llistes!$K$2,Llistes!$L$2,IF(W5=Llistes!$K$3,Llistes!$L$3,IF(W5=Llistes!$K$4,Llistes!$L$4,IF(W5=Llistes!$K$5,Llistes!$L$5,IF(W5=Llistes!$K$6,Llistes!$L$6,IF(W5=Llistes!$K$7,Llistes!$L$7,"")))))) -> Montse Pascual | Y5: X | Z5: X | AA5: X | AB5: X
A6: NATURA | F6: 01.1.1 | G6: =L6 -> Implementar i executar plans de gestió específics per a hàbitats i espècies de conservació prioritària dins l'ENP | H6: Redacció del projecte executiu de restauració de Garbet | I6: S'ha redactat el projecte executiu | K6: Sí | L6: Implementar i executar plans de gestió específics per a hàbitats i espècies de conservació prioritària dins l'ENP | M6: Comú | N6: Obligatori | Q6: MÀXIMA | U6: 0.15 | V6: =PLA!U9*Llistes!$L$11*Llistes!$L$12 -> 20 | W6: XN2000 | X6: =IF(W6=Llistes!$K$2,Llistes!$L$2,IF(W6=Llistes!$K$3,Llistes!$L$3,IF(W6=Llistes!$K$4,Llistes!$L$4,IF(W6=Llistes!$K$5,Llistes!$L$5,IF(W6=Llistes!$K$6,Llistes!$L$6,IF(W6=Llistes!$K$7,Llistes!$L$7,"")))))) -> Montse Pascual | Y6: X | Z6: X | AA6: X | AB6: X
A7: NATURA | F7: 01.1.1 | G7: =L7 -> Implementar i executar plans de gestió específics per a hàbitats i espècies de conservació prioritària dins l'ENP | H7: Execució del projecte de restauració de Garbet | I7: S'ha executat el projecte | K7: Sí | L7: Implementar i executar plans de gestió específics per a hàbitats i espècies de conservació prioritària dins l'ENP | M7: Comú | N7: Obligatori | Q7: MÀXIMA | U7: 0.15 | V7: =PLA!U10*Llistes!$L$11*Llistes!$L$12 -> 20 | W7: XN2000 | X7: =IF(W7=Llistes!$K$2,Llistes!$L$2,IF(W7=Llistes!$K$3,Llistes!$L$3,IF(W7=Llistes!$K$4,Llistes!$L$4,IF(W7=Llistes!$K$5,Llistes!$L$5,IF(W7=Llistes!$K$6,Llistes!$L$6,IF(W7=Llistes!$K$7,Llistes!$L$7,"")))))) -> Montse Pascual | Y7: X | Z7: X | AA7: X | AB7: X
