Workbook

Sheet ESTRATÈGIA
C3: ESQUEMA CONCEPTUAL PER A LA ELABORACIÓ DEL PLA ESTRATÈGIC EN EL MARC
C4: DELS ESTÀNDARDS OBERTS PER A LA GESTIÓ ADAPTATIVA A CATALUNYA

Sheet INSTRUCCIONS
A1: PESTANYA DE PRIORITZACIÓ
A2: Llistat elements: | B2: Tasca 1: Revisar el llistat d'elements prioritzats per tal d'avaluar si cal afegir-ne algun o treure'n algun. A la columna comentaris cal argumentar, breument, el perquè de la decisió.
A4: Llistat amenaces: | B4: Tasca 2: A partir de la taxonomia d'amenaces que es troba a la pestanya final, cal omplir les tres columnes (E, F i G) amb les tres principals amenaces per a la conservació de l'element. S'afegeixi una darrera columna per si hi ha amenaces que no es troben incloses a la taxonomia.
A6: PESTANYA DEL PLA
A7: Explicacions:
B8: 7 Eixos temàtics
B9: Els objectius generals estan directament associats als objectius generals dels Plans de Protecció del medi naatural i del paisatge. NO ES PODEN RETOCAR
B10: Objectius estratègics: definits en un grup de treball intern de serveis Centrals i dels Parcs durant l'any 2023. NO ES PODEN RETOCAR
B11: Objectius operacionals: definits en un grup de treball intern de serveis Centrals i dels Parcs durant l'any 2023
A14: Tasques a realitzar:
A15: Objectius operacionals: | B15: El llistat d'objectius operacionals té una columna al costa (columna I) on s'indica si l'objectiu és obligatori de mantenir al Pla estratègic o no.
B16: Tasca 1: Columna I. Revisar els que es posa com a obligatoris per veure si són realment aplicables a l'espai o no.
B17: Tasca 2: Columna I. Revisar els que posa "Opcional" per identificar els que són aplicables o no a l'espai. O, també, determinar si algun d'ells seria aplicable o es pot concretar millor el redactat de l'objectiu.
B18: Tasca 3: Columna J. En ambdós casos, cal posar a la columna J, el redactat final de l'objectiu concretat a l'espai. En el cas de que l'objectiu s'elimina, posar "NA". Ara es reprodueix el redactat dels objectius operacionals derivats del grup de treball esmentat
B19: Tasca 4: Columna K. Per tots els casos en que hi ha modificació respecte al redactat original de l'objectiu operatiu -i, també, en el cas que es consideri que s'ha d'eliminar-, a la columna K cal redactar molt breument el motiu pel qual es prèn la decisió.
B20: Tasca 5: Columna L. Incloure un Si/No avaluant si l'objectiu operatiu podria tenir mesures a incorporar a la programació d'actuacions de l'espai (Si) o, per altra banda, el seu assoliment depèn d'altres òrgans, com l'ACA o altres serveis dins la DGPAMN (No).
B21: Tasca 6: Columna M. Definir la prioritat que hauria de tenir l'assoliment de l'objectiu (màxima, si cal assolir en els propers 4 anys, o altrament alta, mitja o baixa). També hi ha l'opció de prioritat a assolir a més llarg termini.
A22: Propostes genèriques d'accions: | B22: Tasca 7: Columna N. En aquest columna cal introduir les accions, de manera genèrica, que caldria aplicar a l'espai per tal d'assolir l'objectiu operatiu. No es tracta d'un llistat d'accions concretes si no, més aviat, accions generals que acabarien concretant-se en la programació anual. PER A INICIAR AMB LA TAULA US PODEU BASAR MOLT EN LA FEINA JA FETA DE PRIORITZACIÓ DE MESURES PEL MAP
B23: En el cas dels objectius operatius que s'ha considerat que no són aplicables a l'espai, cal avaluar si podrien tenir alguna acció que sí tindria sentit d'incloure al Pla estratègic tot i que l'objectiu de manera global no hi ´seria d'aplicació.
A24: Indicadors: | B24: Tasca 8: Columna Q. Posar un indicar SMART per avaluar el compliment de la mesura proposada a la columna N
A25: Fites a assolir en 4 anys: | B25: Tasca 9: Posar un valor de l'indicador a asolir: valor mínim necessari (columna R) o valor desitjable (columna S).
A26: Hores de dedicació: | B26: Tasca 10: Columna T. Realitzar una aproximació el més acurada que es pugui de les hores del personal de gestió de l'espai que cal destinar per a la realització de l'acció.
A27: Àrea responsable: | B27: Tasca 11: Columna U. Indicar quina àrea de l'equip de gestió és responsable de coordinar l'execució de l'acció.
A28: Persona responsable: | B28: Tasca 12: Columna V. Indicar quina persona dins l'àrea seria l'encarregada.
A30: PESTANYA DEL VINCLE
A31: Definir vincle amenaça vs. Obj. Operatiu | B31: Tasca 1: Establir / Revisar el vincle entre les amenaces identificades a la pestanya de priorització i els objectius operatius definits a la columna J de la pestanya Pla. La columna B conté el llistat dels objectius operatius tal i com quedaran definits després de la vostra revisió.
B32: Tasca 2: En cas que es pugui, definir l'amenaça / factor / causa concret a la que atén l'objectiu definit al Pla. Poden ser més d'una.
B33: És important que es visualitzi a quina amenaça es dirigeix l'objectiu operatiu que es proposa al Pla, tot i que, no sempre hi ha d'haver un vincle clar. Pot haver algun objectiu sense amenaça vinculada.

Sheet PRIORITZACIÓ
A2: Llistats corresponent a l'espai de Natura 2000 ES5120001 "Alta Garrotxa-Massís de les Salines"
A3: LLISTAT D'ELEMENTS PRESENT A L'ESPAI | I3: AMENACES PER A CADA ELEMENT
A4: Hàbitats d'interès comunitari | B4: PP 6.2 i 6.3 | C4: PP A8 | D4: MAP | E4: 25% IdR | F4: Puntuació IdR | G4: PRIORITARI PE | H4: Comentaris en cas de canvi en la priorització | I4: Amenaça 1 segons taxonomia | J4: Amenaça 2 segons taxonomia | K4: Amenaça 3 segons taxonomia | L4: Altres amenaces | N4: Nota: La priorització d'elements actual inclou els Elements Clau que es van determinar en l'instrument de gestió aprovat amb l'Acord de Govern 150/2014 (Annex 6)
A5: 3130 - Aigües estagnants oligotròfiques o mesotròfiques amb vegetació de Littorelletea uniflorae i/o Isoëto-nanojuncetea | C5: Si | D5: Si | G5: Sí | I5: Desaparició d'activitats tradicionals | J5: Gestió de l'aigua | K5: Ramaderia | N5: Aquest Acord era per les Zones Especials de Conservació, no per les ZEPA i, per tant, no es va fer l'exercici de priorització de les aus.
A6: 3140 - Aigües oligomesotròfiques calcàries amb vegetació bèntica de Chara spp. | C6: Si | D6: Si | G6: Sí | I6: Desaparició d'activitats tradicionals | J6: Gestió de l'aigua | K6: Ramaderia | N6: També inclou el primer quartil de l'exercici de la UIC per prioritzar els elements present a cada espai de Natura 2000, és a dir, el 25% dels
A7: 3240 - Rius de tipus alpí amb bosquines de muntanya | B7: Si | C7: Si | D7: Si | G7: Sí | I7: Impactes del canvi climàtic relatius a l'alteració del règim de precipitació i sequera | J7: Molèsties per activitats recreatives | K7: Gestió de l'aigua | N7: elements amb major índex de rellevància a l'espai. Veure document metodològic aquí:
A8: 3250 - Rius mediterranis amb vegetació del Glaucion flavi | C8: Si | D8: Si | G8: Sí | I8: Impactes del canvi climàtic relatius a l'alteració del règim de precipitació i sequera | J8: Molèsties per activitats recreatives | K8: Gestió de l'aigua
A9: 3260 - Rius de terra baixa i de la muntanya mitjana amb vegetació submersa o parcialment flotant (Ranunculion fluitantis i Callitricho-Batrachion) | C9: Si | D9: Si | G9: Sí | I9: Impactes del canvi climàtic relatius a l'alteració del règim de precipitació i sequera | J9: Molèsties per activitats recreatives | K9: Gestió de l'aigua | N9: https://gencat.sharepoint.com/sites/Informaciiconeixementpatrimoninatural2/Documents%20compartits/Forms/AllItems.aspx?csf=1&web=1&e=3x4ZkK&ovuser=3b9427dc%2Dd30e%2D43bc%2D8c06%2Dff7253676fec%2Cjordiparpal%40gencat%2Ecat&OR=Teams%2DHL&CT=1713942253212&clic
A10: 3270 - Rius amb vores llotoses colonitzades per herbassars nitròfils del Chenopodion rubri (p.p.) i del Bidention (p.p.) | C10: Si | D10: Si | G10: Sí | I10: Impactes del canvi climàtic relatius a l'alteració del règim de precipitació i sequera | J10: Molèsties per activitats recreatives | K10: Gestió de l'aigua
A11: 4030 - Landes atlàntiques i subatlàntiques seques | B11: Si | C11: Si | D11: Si | E11: Si | G11: Sí | I11: Desaparició d'activitats tradicionals | J11: Espècies invasores | K11: Impactes del canvi climàtic relatius a l'alteració del règim de precipitació i sequera
A12: 4090 - Matollars xerocàntics endèmics oromediterranis | C12: Si | D12: Si | E12: Si | G12: Dubtós | H12: Molt poc representatiu per superfície
A13: 5110 - Boixedes xerotermòfiles permanents, dels vessants rocosos | C13: Si | D13: Si | G13: Sí | I13: Desaparició d'activitats tradicionals | J13: Espècies invasores | K13: Plagues i patògens
A14: 5130 - Formacions de Juniperus communis colonitzadores de landes o de pastures calcícoles | C14: Si | D14: Si | E14: Si | G14: No | H14: Espècie colonitzadora d'espais oberts molt abundant
A15: 5210 - Màquies i garrigues amb Juniperus spp. arborescents, no dunars | C15: Si | D15: Si | G15: No | H15: Espècie colonitzadora d'espais oberts molt abundant
A16: 6110p - Prats calcàris o basòfils d'Alysso-Sedion albi (*) | C16: Si | D16: Si | G16: Sí | I16: Desaparició d'activitats tradicionals | J16: Espècies invasores | K16: Impactes del canvi climàtic relatius a l'alteració del règim de precipitació i sequera
A17: 6210 - Prats -i fàcies emmatades- medioeuropeus, seminaturals, sobre substrat calcari (Festuco-Brometea) | B17: Si | C17: Si | D17: Si | E17: Si | G17: Sí | I17: Desaparició d'activitats tradicionals | J17: Espècies invasores | K17: Impactes del canvi climàtic relatius a l'alteració del règim de precipitació i sequera
A18: 6410 - Herbassars de Molinia coerulea en sòls calcaris torbosos o argil·lollimosos (Molinion caeruleae) | C18: Si | D18: Si | G18: Sí | I18: Desaparició d'activitats tradicionals | J18: Espècies invasores | K18: Impactes del canvi climàtic relatius a l'alteració del règim de precipitació i sequera
A19: 6420 - Jonqueres i herbassars graminoides humits, mediterranis, del Molinio-Holoschoenion | C19: Si | D19: Si | G19: Sí | I19: Gestió de l'aigua | J19: Desaparició d'activitats tradicionals
A20: 6430 - Herbassars higròfils, tant de marges i vorades com de l'alta muntanya | C20: Si | D20: Si | G20: No | H20: Fitxa ZEC posa 0 ha. No surt a la memòria hàbitats de la AG | I20: Desaparició d'activitats tradicionals | J20: Gestió de l'aigua | K20: Impactes del canvi climàtic relatius a l'alteració del règim de precipitació i sequera
A21: 6510 - Prats de dall de terra baixa i de la muntanya mitjana (Arrhenatherion) | C21: Si | D21: Si | E21: Si | G21: No | H21: Index de rellevància molt elevat però no hi ha a l'espai | I21: Desaparició d'activitats tradicionals | J21: Ramaderia
A22: 7220p - Fonts petrificants amb formació de travertí (Cratoneurion commutati) | C22: Si | D22: Si | G22: Sí | I22: Gestió de l'aigua | J22: Àrees recretives i turístiques | K22: Impactes del canvi climàtic relatius a l'alteració del règim de precipitació i sequera
A23: 8130 - Tarteres de l'Europa meridional amb vegetació poc o molt termòfila | B23: Si | C23: Si | D23: Si | E23: Si | G23: Dubtós | H23: element clau però sense accions associades | I23: Àrees recretives i turístiques | J23: Espècies desestabilitzades
A24: 8210 - Costers rocosos calcaris amb vegetació rupícola | C24: Si | D24: Si | G24: Sí | I24: Molèsties per activitats recreatives
A25: 8220 - Costers rocosos silicis amb vegetació rupícola | C25: Si | D25: Si | G25: No | H25: No és representatiu a l'espai
A26: 8310 - Coves no explotades pel turisme | C26: Si | D26: Si | E26: Si | G26: Sí | I26: Molèsties per activitats recreatives
A27: 9120 - Fagedes acidòfiles | B27: Si | C27: Si | D27: Si | G27: Sí | I27: Treballs forestals | J27: Impactes del canvi climàtic relatius a l'alteració del règim de precipitació i sequera | K27: Impactes del canvi climàtic relatius a l'alteració del règim de temperatures
A28: 9130 - Fagedes neutròfiles | B28: Si | C28: Si | D28: Si | G28: Sí | I28: Treballs forestals | J28: Impactes del canvi climàtic relatius a l'alteració del règim de precipitació i sequera | K28: Impactes del canvi climàtic relatius a l'alteració del règim de temperatures
A29: 9150 - Fagedes calcícoles xerotermòfiles | B29: Si | C29: Si | D29: Si | E29: Si | G29: Sí | I29: Treballs forestals | J29: Impactes del canvi climàtic relatius a l'alteració del règim de precipitació i sequera | K29: Impactes del canvi climàtic relatius a l'alteració del règim de temperatures
A30: 9160 - Rouredes de roure pènol i boscos mixtos del Carpinion betuli | B30: Si | C30: Si | D30: Si | E30: Si | G30: Sí | I30: Treballs forestals | J30: Impactes del canvi climàtic relatius a l'alteració del règim de precipitació i sequera | K30: Impactes del canvi climàtic relatius a l'alteració del règim de temperatures
A31: 9180p - Boscos de vessants rostos, tarteres o barrancs, del Tilio-Acerion | D31: Si | E31: Si | G31: No | H31: NO present a l'espai | I31: Treballs forestals | J31: Impactes del canvi climàtic relatius a l'alteració del règim de precipitació i sequera | K31: Impactes del canvi climàtic relatius a l'alteració del règim de temperatures
A32: 91E0p - Vernedes i altres boscos de ribera afins (Alno-Padion) | B32: Si | C32: Si | D32: Si | E32: Si | G32: Sí | I32: Gestió de l'aigua | J32: Espècies invasores | K32: Àrees recretives i turístiques
A33: 9240 - Rouredes ibèriques de roure valencià (Quercus faginea) i roure africà (Quercus canariensis) | B33: Si | C33: Si | D33: Si | E33: Si | G33: Sí | I33: Treballs forestals | J33: Impactes del canvi climàtic relatius a l'alteració del règim de precipitació i sequera | K33: Impactes del canvi climàtic relatius a l'alteració del règim de temperatures
A34: 9260 - Castanyedes | B34: Si | C34: Si | D34: Si | E34: Si | G34: No | H34: Poc representatiu a l'espai | I34: Treballs forestals | J34: Impactes del canvi climàtic relatius a l'alteració del règim de precipitació i sequera | K34: Impactes del canvi climàtic relatius a l'alteració del règim de temperatures
A35: 9330 - Suredes | C35: Si | D35: Si | E35: Si | G35: No | H35: NO present a l'espai
A36: 9340 - Alzinars i carrascars | B36: Si | C36: Si | D36: Si | E36: Si | G36: Sí | I36: Desaparició d'activitats tradicionals | J36: Impactes del canvi climàtic relatius a l'alteració del règim de precipitació i sequera | K36: Impactes del canvi climàtic relatius a l'alteració del règim de temperatures
A37: 9530p - Pinedes submediterrànies de pinassa (Pinus nigra subsp. salzmannii) | B37: Si | C37: Si | D37: Si | E37: Si | G37: No | H37: Poca superfície a l'espai | I37: Treballs forestals | J37: Impactes del canvi climàtic relatius a l'alteració del règim de precipitació i sequera | K37: Impactes del canvi climàtic relatius a l'alteració del règim de temperatures
A38: 9540 - Pinedes mediterrànies | C38: Si | D38: Si | E38: Si | G38: Dubtós | H38: rellevant per gestió risc d'incendis | I38: Treballs forestals | J38: Impactes del canvi climàtic relatius a l'alteració del règim de precipitació i sequera | K38: Impactes del canvi climàtic relatius a l'alteració del règim de temperatures
A39: 9580p - Boscs mediterranis de Taxus baccata (*) | B39: Si | C39: Si | D39: Si | E39: Si | G39: Sí | I39: Treballs forestals | J39: Impactes del canvi climàtic relatius a l'alteració del règim de precipitació i sequera | K39: Impactes del canvi climàtic relatius a l'alteració del règim de temperatures
A40: Espècies presents a l'espai | B40: PP 6.2 i 6.3 | C40: PP A8 | D40: MAP | E40: 25% IdR | F40: Puntuació IdR | G40: PRIORITARI PE | H40: Comentaris en cas de canvi en la priorització | I40: Gestió de l'aigua | J40: Espècies invasores | K40: Àrees recretives i turístiques | L40: Altres amenaces
A41: Abida gittenbergeri | B41: Si | G41: Sí | I41: Treballs forestals | J41: Impactes del canvi climàtic relatius a l'alteració del règim de precipitació i sequera
...

Sheet PLA
A1: MODEL DE PLA ESTRATÈGIC PELS ENP
B2: Espai natural protegit: | C2: Alta Garrotxa
W3: Fita a assolir en 4 anys | Y3: Calendarització interna | AD3: Gestió interna
A4: EIXOS | C4: Objectius generals (PP) | E4: Objectius estratègics | G4: OBJECTIUS operatius | H4: Comú / Específic | I4: Obligatori / Optatiu | J4: Marc de referència | K4: Resultats derivats | L4: Objectius operatius Alta Garrotxa | M4: Justificació del canvi o no inclusió d'un OP | N4: Objectiu aplicable amb accions que depenen de l'AG | O4: Objectiu aplicable amb accions que depenen de la Direcció General de PAMN | P4: Prioritat | Q4: Proposta d'accions | R4: Proposta concreta d'accions | S4: Mesures MAP Traslladar observacions en vermell al MAP de l'Alta Garrotxa | T4: Mesures PPAG | U4: Mesures d'altres plans | V4: Indicadors | W4: Valor mínim | X4: Valor objectiu (desitjable) | Y4: Executat/ en curs | Z4: 2026/27 | AA4: 2027/28 | AB4: 2028/29 | AC4: 2029/30 | AD4: Hores de dedicació | AE4: Àrea responsable | AF4: Persona responsable
A5: NATURA | B5: 1 | C5: CONSERVAR LA NATURA i restaurar els ecosistemes, els processos naturals i seminaturals, la biodiversitat i la geodiversitat associada. | D5: 01.1 | E5: Adequar i fer eficient la conservació dels elements objecte de gestió prioritària marcats per la DG a l'ENP | F5: 01.1.1 | G5: Implementar i executar plans de gestió específics per a hàbitats i espècies de conservació prioritària dins l'ENP | H5: Comú | I5: Obligatori | J5: MAP | K5: SFF: Elaboració de plans de gestió específics per a espècies de conservació prioritària i directrius de gestió d'hàbitats. SFF/SENP: Definir a nivell de cluster quins son els que es poden elaborar conjuntament. | L5: Implementar i executar plans i mesures de gestió específiques per a hàbitats i espècies de conservació prioritària dins l'ENP | M5: Canvi de redactat OP. Implementació d'accions no emmarcades en un Pla de gestió específic | N5: Sí | O5: Si | P5: ALTA | Q5: Implementació del PIRE i de millores en el maneig de les activitats agràries_CAG, FPC i DGPA Millora d'hàbitats i espècies de conservació prioritària (espais oberts, fluvials, basses, boscos, etc) d'acord el PPAG_CAG Disseny del pla de seguiment de la biodiversitat de l'Alta Garrotxa_CAG i DGPA Gestió de l'ús públic per protegir hàbitats i espècies de conservació prioritària d'acord amb PPAG i el PUP (escalada, bany, barrancs, etc)_CAG | R5: REVISAR EL MAP I DISTRIBUIR ACCIONS A LA RESTA DE PLA ESTRATÈGIC *Recuperació d'hàbitat6210 i espècies associades a espais oberts (ratpenats, papallones, aus, insectes pol·linitzadors (relacionar amb espècies concretes) *Cartografia i proposta gestió hàbitats fluvials 91E0p, 3250, 3260, 3270 amb perspectiva canvi climàtic *Millora de basses i punts d'aigua * Gestió ús públic gorgues (fonts petrificants 7221) (gestió barrancs i restauració hàbitat) * Seguiment de la regulació de l'escalada per afectació als costers rocosos 8210 i de l'imapcte sobre fauna i flora rupícoles * Seguiment de les comunicacions d'espeleologia per les coves no explotades pel turisme 8310 * Estudi fauna cavernícola i ratpenats 8310 (invertebrats) * Dissenyar Pla de Seguiment de la biodiversitat de l'ALta Garrotxa (identifcar grups de fauna i flora protegida) Cerambix cerdo, Cinclus cinclus, rèptils i tot el que estigui al llistat i no es fa cap seguiment concret, Distribució escarbats saproxilics, guatlla i becada, tortora i ungulats salvatges, escorxador , cotoliu, turó, mustela, gat salvatge * 9120, 9130, 9150, 9160, 9340, 9240 treballs forestals adaptació al canvi climàtic i lliure evolució tendència a la maduresa * Estudi preliminar presència i distribució gasteròpodes amenaçats (prioritat baixa) * Cartografia distribució amfibis * Seguiment amfibis (mig termini) * Seguiment rupícoles en zones escalada * Seguiment àguila daurada * Estudi rata d'aigua Arvicola sapidus (priorita baixa) * Cranc de riu ho fa la Gene (impuls) * Promoure recerca duc (rapis nocturns) * Gestió de la convivència amb el llop (impuls) * Seguiment SEGRE, SOCC, trencalòs * Seguiment flora amenaçada i accions de conservació (6 taxons) *Redacció del projecte executiu d’intervenció forestal per a la millora de l’hàbitat de Polygala vayredae *Seguiment de l'estat ecològic dels prats a l'Alta Garrotxa * Coordinació amb Caça per sp aus cinegetiques i ungulats * restauració bosc ribera * seguiment aufrany * Suport a la FPC en l'elaboració de plans de maneig per la gesitó de pastures i seguiment en les zones on s'han realitzat cremes prescrites (proiecte Foc i Biodiversitat i Projecte Forwards_CAG (en algun cas pot afectar especies i hàbitats interès comunitari. * Millora de la senyalització dels itineraris (zona del Comanegra) per evitar els impactes del senderisme dispers per accedir al cim i l'afectació al 6210. * Coordinació amb els cossos de seguretat i CAR en cas d'incidències sobre habitats forestals protegits (ex. teixedes)_CAG | S5: *Control sanitari de la població de cranc de riu. Ho fa la generalitat *Consolidació del programa de cria en captivitat del cranc de riu autòcton.Ho fa la generalitat *Actuacions de conservació de les zones conegudes de posta regular de les especies de peixos d'interès comunitari.Ho podem parlar amb en Quim Pou. El primer pas és identificar això com una part de l'estudi de seguiment de peixos. *Actuacions de millora d'hàbitat en boscos subalpins amb presència espècies amenaçades. No en tenim. Traslladar al MAP original *Actuacions de manteniment dels matollars d’arç blanc i aranyoner, principals plantes nutrícies d'Eriogaster catax. Es pot dir que ho fem quan fem espais oberts en deixar zona de més baixa intensitat i creant zones ecotons en el perímetre. INtegrar en els criteris d'EEOO aquestes espècies especificament. Integrar en el MAP original aquest aclariment. *Actuacions de manteniment de les masses de lligabosc (Lonicera sp) com a principal planta nutrícia d'Euphydryas aurinia.Es pot dir que ho fem quan fem espais oberts en deixar zona de més baixa intensitat i creant zones ecotons en el perímetre. INtegrar en els criteris d'EEOO aquestes espècies especificament. Integrar en el MAP original aquest aclariment. *Actuacions de manteniment de les masses de Pinus sylvestris i Pinus nigra en les principals àrees de distribució de Graellsia isabelae. Establiment de rodals amb gestió adaptativa pel manteniment dels processos ecològics. *Actuacions de millora de l'habitat de Lutra lutra. L'espècie està en expansió. No es prioritari en aquest Pla estratègic. *Actuacions de restauració de zones de cria d'Emys orbicularis i Mauremys leprosa.No aplica a AG *Actuacions per mantenir una estructura vegetal adequada en zones properes a l'entrada de coves/refugis amb presència de rats-penats. Es va fer alguna actuació a la cova de polí. Si fem un seguiment de ratpenats valorar si és necessari. *Col·locació de caixes refugi per a ratpenats com a mesura transitòria fins que s’aconsegueixi el grau de maduresa i l’abundància de cavitats suficient en el bosc. Ja s'ha fet. Si fem de nou un seguiment de ratpenats valorar l'estat de les caixes existents i valorar si és necessari. Contrastar amb XPuig si aquesta actuació és necessària. *Els instruments de planificació i ordenació dels espais naturals protegits estableixen mesures de protecció específica dels refugis i colònies de rat-penats.El PPAG no ho preveu però es te constància de les coves amb més valors i en base a això es fan les autortizacions. *Execució de mesures de tractaments específics a petita escala en fagedes destinats a incrementar la disponibilitat de microhàbitats potencialment adequats per a Rosalia alpina. Cal un projecte executiu en aquest sentit. *Incorporació de la tórtora europea en els instruments i plans de gestió dels espais de Natura 2000 en què l'espècie estigui considerada. La tenim com a tàxon prioritzat *Creació de zones d'alimentació riques en llavors per a la tórtora europea i altres espècies mitjançant la implantació de zones lliures de sembra i/o sembres específiques per a la fauna. No entenc bén bé que cal fer? *Recuperació de la qualitat de les pastures d'interès comunitari i les espècies associades (10% de la superfície total de 6170, 6210 i 6230). Integrat. *Actuacions de restauració dels indrets més degradats dels hàbitats o les àrees amb presència d'espècies d'interès comunitari en zones de roquissars, dunes o àrees de vegetació esparsa en base a una identificació i valoració de l'estat de conservació. No es una prioritat. NO tenim espècies d'interès comunitari amb hàbitats degradats. No prioritari. *Incorporació de criteris de conservació de l'hàbitat (p.ex. accions de control biològic) en les accions per la prevenció de les malalties del castanyes (xancre i tinta) o plagues (vespeta del castanyer). Es pot fer un estudi de millora hàbitat del xancre a Hortmoier. Parlar amb en QUim Avellà- *Aplicació de mesures físiques per minimitzar el risc d'erosió a les àrees amb presència de l'hàbitat. Millora de la senyalització al Comanegra. Seguiment de l'actuació i implementació de mesures, Algun lloc més? *Redacció del projecte executiu d’intervenció forestal per a la millora de l’hàbitat de Polygala vayredae Ho he afegit | T5: *Altres actuacions de conservació del patrimoni natural i del paisatge. Es contempla de forma transversal a totes les accions planificades *Mesures de foment d’actuacions per la gestió de teixedes, castanyedes i deveses S'ha fet un projecte europeu per millorar les teixedes i es va descartar la possibilitat de fer millores en les castanyedes (es va fer amb Galanthus, demanar a en Quim avellà) | U5: *Accions de conservació de tàxons de flora En curs amb el SFF *Millora d’hàbitats i control de flora invasora | V5: 1) Nombre de plans de gestió específics per a elements prioritaris redactats i implementats 2) Nombre de mesures/actuacions específiques per a elements prioritaris redactades i implementades | W5: 1) 1 2) 5 | X5: 1) 3 2) 7 | Y5: x | Z5: x | AA5: x | AB5: x | AC5: x | AD5: 1550 | AE5: No tenim àrees | AF5: En no tenir àrees no hi ha una unica persona responsable. Per les dimensions de l'entitat i sense quadre de substitució es fa de forma conjunta
D6: 01.1 | E6: Adequar i fer eficient la conservació dels elements objecte de gestió prioritària marcats per la DG a l'ENP | F6: 01.1.2 | G6: Adaptar i executar plans de gestió específics per a elements geològics de conservació prioritària dins l'ENP | H6: Comú | I6: Obligatori | L6: =G6 -> Adaptar i executar plans de gestió específics per a elements geològics de conservació prioritària dins l'ENP | N6: Sí | O6: Si | P6: MITJANA | Q6: Desenvolupament de la Geoestratègia de l'ENPAG_CAG | R6: *Desenvolupament de la Geoestratègia de l'ENPAG_CAG * Estudi hidrpgeològic de l' ENPAG_Contracte Programa entre la DGPA i ICGC | S6: *Redacció d'un pla d'accés públic a les coves d'alt valor natural i geològic_ En el PPAG es va resoldre amb la necessitat de comunicació a les coves i es va descartar cap limitaicó. Traslladar el MAP original. *Actuacions de restauració de les coves degradades. Què hi ha degradat? No en tenim constància. Es descarta per aquest pla estratègic. | U6: *Planificació i execució de les accions de conservació dels elements d’interès geològic inventariats. Es fa amb al seuiment de la geoestratègia. | V6: 1) Nombre d'actuacions/mesures incloses a la geoestratègia | W6: 1) 2 | X6: 1) 6 | Y6: x | Z6: x | AA6: x | AB6: x | AC6: x | AD6: 35
D7: 01.2 | E7: Executar les mesures de gestió directa previstes en els intruments de planificació per la conservació i la gestió adaptativa dels elements clau de l'ENP | F7: 01.2.1 | G7: Implementar la metodologia de gestió adaptativa (Estàndards Oberts de Gestió Adaptativa a Catalunya) en tots els processos de l'ENP | H7: Comú | I7: Obligatori | J7: ESNATURA | K7: SENP: Elaboració d'un manual per la implementació dels OSAM | L7: =G7 -> Implementar la metodologia de gestió adaptativa (Estàndards Oberts de Gestió Adaptativa a Catalunya) en tots els processos de l'ENP | N7: Sí | O7: Si | P7: MITJANA | Q7: Formació específica al personal del CAG sobre els open estàndards _DGPA Implementar els open estàndards a la gestió de l'espai _CAG | R7: *Formació específica al personal del CAG sobre els open estàndards- DGPA | T7: *Programa de seguiment del Pla. Crec que no aplica aquí. HO posaria a la linia 31 *Avaluació de l’efectivitat i actualització del Pla. Crec que no aplica aquí. Ho posaria a la linia 31. | U7: *Reunió taller un cop l’any per fer el seguiment i avaluar l’estratègia de geoconservació., Crec que no aplica aquí. Ho posaria al 01,01,2- | V7: 1) Formació realitzada 2) % de proejectes/accions que incorporen open estandards | W7: 1) 1 2) 50 | X7: 1) 1 2) 75 | AA7: x | AD7: 30
F8: 01.2.2 | G8: Executar les mesures previstes en els plans de conservació o recuperació d'espècies amenaçades de forma coordinada amb el Servei de Flora i Fauna en l'àmbit de l'ENP | H8: Comú | I8: Obligatori | J8: MAP Catàlegs | K8: SFF: Elaboració de plans de conservació o recuperació d'espècies protegides | L8: =G8 -> Executar les mesures previstes en els plans de conservació o recuperació d'espècies amenaçades de forma coordinada amb el Servei de Flora i Fauna en l'àmbit de l'ENP | N8: Sí | O8: Si | P8: ALTA | Q8: Implicació i participació en la redacció dels plans de conservació/recuperació d'epècies amenaçades_DGPA i CAG Execució de les accions contemplades en els plans de conservació/recuperació aprovats dins l'àmbit de l'ENP_CAG | R8: *Execució de les accions pactades amb el SFF per espècies de flora vascular amenaçada (nombrar totes les de la llista) * Participació en el seguiment del SEGRE (aus rapinyaires) i el cens simultari de Gypaetus barbatus valorar si va a coneixement o si ho repetim QUINS MËS PLANS HI HA APROVATA PER ESPÈCIES? | S8: *Aprovació dels Plans de Conservació i/o Recuperació de les espècies de fauna d'interès comunitari. *Realització d'altres mesures vinculades als Plans de Conservació i/o Recuperació de les espècies aquàtiques d'interès comunitari amenaçades.Hi ha plans de conservació associats a espècies aquàtiques. *Execució d'altres mesures incloses als plans de conservació de Callimorpha quadripunctaria i Euphydryas aurinia. *Execució de mesures de desenvolupament del pla de recuperació de rapinyaires. | V8: 1) Nombre de plans de conservació o recuperació en els que s'ha participat 2) Nombre de mesures executades en els plans de conservació o recuperació vigents | W8: 1) 2 2) 2 | X8: 1) 4 2) 4 | Y8: x | Z8: x | AA8: x | AB8: x | AC8: x | AD8: 60
F9: 01.2.3 | G9: Executar les mesures de gestió previstes en els plans de control i erradicació d'espècies exòtiques de forma coordinada amb el Servei de Flora i Fauna en l'àmbit de l'ENP | H9: Comú | I9: Obligatori | J9: ESNATURA MAP | K9: SFF: Elaboració de plans de control i erradicació d'espècies exòtiques | L9: =G9 -> Executar les mesures de gestió previstes en els plans de control i erradicació d'espècies exòtiques de forma coordinada amb el Servei de Flora i Fauna en l'àmbit de l'ENP | N9: Sí | O9: Si | P9: ALTA | Q9: Implicació en la redacció de plans de control i erradicació d'EEI i protocols per la gestió preventiva de vies d'entrada vinculades a sectors d'activitat_DGPA i CAG Execució d'accions de control d'EEI_CAG Suport a una prova pilot per al control de Seneci inaquidens en zones amb presència d'hàbitat i espècies d'interès comunitari o amb impacte sobre l'activitat agroramadera_DGPA i CAG | R9: *Actuacions de manteniment i control d'Ailanthus altissina_CAG *Disseny d'una prova pilot per al control de Seneci inaquidens en zones amb presència d'hàbitat i espècies d'interès comunitari o amb impacte sobre l'activitat agroramadera_CAG i SFF *Protocol comú per als ENPs de protocols per a la gestió preventiva de vies d'entrada vinculada a sectors d'activitat (per exemple, jardineria, aqüicultura, distribució comercial), inclosos codis de conducta i manuals de bones pràctiques_SFF *Plans de control de crancs invasors_DGPA | S9: *Elaboració i execució de plans de control d'espècies exòtiques i prevenció del seu ús en activitats productives en zones fluvials. No és el cas de l'AG *Redacció de protocols per a la gestió preventiva de vies d'entrada vinculada a sectors d'activitat (per exemple, jardineria, aqüicultura, distribució comercial), inclosos codis de conducta i manuals de bones pràctiques. Això ho podria fer la DG? *Execució de plans de control de crancs invasors (Procambarus clarki, Pacifastacus leniusculus i Orconectes limosus). *Elaboració i execució de plans de control d'espècies exòtiques i prevenció del seu ús en activitats productives. CPf?? demanar a en Quim Avellà *Elaboració i execució de plans globals de control d'altres espècies exòtiques i prevenció del seu ús en activitats productives.DGPA. valorar si tot el que es globar ho volem posar o no cal fer referència. | V9: 1) Nombre de plans/ protocols de control d'espècies exòtiques en els que s'ha participat 2) Nombre de mesures executades en els plans de gestió d'espècies exòtiques 3)Execució prova pilot | W9: 1) 2 2) 2 3) 0 | X9: 1) 4 2) 4 3) 1 | Y9: x | Z9: x | AA9: x | AB9: x | AC9: x | AD9: 160
F10: 01.2.4 | G10: Desplegar els objectius i tasques recollits en els instruments de referència i compromisos internacionals | H10: Específic | I10: Optatiu | L10: =G10 -> Desplegar els objectius i tasques recollits en els instruments de referència i compromisos internacionals | N10: Impuls-Suport | O10: Si | P10: MITJANA | Q10: Col·laboració en la implementació pràctica de projectes de l'àrea internacional a petició de la DGPA | R10: *Seguiment dels avenços de la Generalitat en aquest desplegament unitari en territori català. | V10: 1) Nombre de col·laboracions | W10: 1) 1 | X10: 1) 2 | Y10: x | Z10: x | AA10: x | AB10: x | AC10: x | AD10: 30
D11: 01.3 | E11: Crear ecosistemes complexes, resilients, i d'alta biodiversitat per garantir la recuperació dels processos ecosistèmics | F11: 01.3.1 | G11: Identificar espais pel foment de la dinàmica natural i l'aprofitament no extractiu | H11: Comú | I11: Obligatori | J11: ESNATURA | K11: SENP/SFF: Definir criteris metodològics | L11: =G11 -> Identificar espais pel foment de la dinàmica natural i l'aprofitament no extractiu | N11: Realitzat | O11: Si | P11: MITJANA | Q11: Objectiu operatiu assolit, sense mesures continuïstes en el termini del present Pla estratègic | R11: * Projecte de renaturalització_DGPA (PPAG) *Realitzar la signatura de convenis de dinàmica natural amb propietaris_DGPA (PPAG) | S11: *Signatura de convenis de dinàmica naturals Competència de la generalitat en tant que competent. *Identificació efectiva dels rodals madurs que tendeixen a evolució natural en tots els Plans d'Ordenació Forestal. Hi ha estudi de galanthus que identifica els rodals clau de l'espai. No es té una cartografia/buidat de tots els plans però no es considera necessària sino més prioritari el projecte de renaturalització i els convenis de dinàmica natural pròpiament. | T11: *Projecte de renaturalització i valorització en la zona de foment de la dinàmica natural *Mesures de foment de la gestió de finques en règim de dinàmica natural i aprofitament no extractiu | AD11: 0
F12: 01.3.2 | G12: Afavorir la maduresa dels sistemes forestals | H12: Específic | I12: Optatiu | J12: MAP | K12: SENP/SFF: Definir criteris metodològics | L12: =G12 -> Afavorir la maduresa dels sistemes forestals | N12: Impuls-Suport | O12: Si | P12: MITJANA | Q12: Redacció del Projecte de renaturalització i adaptació al canvi climàtic_DGPA (PPAG) Execució del Projecte de renaturalització i adaptació al canvi climàtic_DGPA (PPAG) Signatura de convenis de dinàmica natural amb propietaris_DGPA (PPAG) Incorporació dels criteris del PPAG als IOF_DGPA | R12: * Projecte de renaturalització_DGPA (PPAG) *Signatura de convenis de dinàmica natural amb propietaris_DGPA (PPAG) * Compliment dels informes de SSTT i el compliment de criteris_CPF Demanar Quim Avellà com revisen el compliment dels criteris i si ho fan. | S12: TOTES AQUETES ACCIONS /CRITERIS ES PODEN INTEGRAR A LES DUES ACCIONS DETERMINADES A LA COLUMNA ANTERIOR. *Actuacions per al foment de la maduresa i naturalitat dels boscos_ *Actuacions de gestió forestal dirigida al manteniment de la maduresa i naturalitat de la massa en boscos públics. *Actuacions de manteniment de grans peus de planifolis i altres arbres vells caducifolis per afavorir el manteniment d'espècies forestals d'interès comunitari (Rosalia alpina, Lucanus cervus i Osmoderma eremita). *Actuacions per fomentar la presència de fusta morta en peu o a terra i d'arbres vells o decrèpits en boscos públics. *Actuacions de gestió per augmentar la densitat de cavitats fomentant la presència d’arbres decrèpits o morts. *Actuacions de millora de la maduresa dels boscos dels hàbitats 9160, 9240 i 9540. *Mesures d'adaptació de boscos de 9340 al canvi climàtic i per a l'increment de la maduresa o l'entrada d'espècies de futur (Phyllirea sp, Pistacia sp....). *Realització de tractaments silvícoles en boscos premadurs, tot buscant estructures amb edats irregulars, que garanteixin un equilibri entre les diferents classes d'edat, amb grans diàmetres, amb separació vertical de les copes dels arbres amb els estrats. | T12: *Mesures de foment d’actuacions d’acceleració o millora de la maduresa del bosc | V12: 1) Redacció del projecte 2) Nombre d'actuacions executades del projecte 3) Nombre de convenis signats 4) Incorporació dels criteris als IOF | W12: 1) 1 2) 2 3) 3 4) 1 | X12: 1) 1 2) 4 3) 5 4) 1 (a tots) | Z12: x | AA12: x | AB12: x | AC12: x | AD12: 300
F13: 01.3.3 | G13: Generar pertorbacions controlades | H13: Específic | I13: Optatiu | J13: MAP | K13: SENP/SFF: Definir criteris metodològics | L13: =G13 -> Generar pertorbacions controlades | N13: Impuls-Suport | O13: Si | P13: MITJANA | Q13: Execució d'accions per generar pertorbacions controlades (incloses al PPAG, Pla de cremes prescrites, Projecte de Renaturalització, PIRE, etc)_DGPA i CAG | R13: *Projecte de renaturalització_DGPA (PPAG) * Pla de cremes prescrites_FPC (Ajut entitats) | S13: *Redacció d’un projecte de renaturalització a l’Alta Garrotxa | U13: *Comissió per la coexistència amb cànids i resta de fauna | V13: 1) Nombre d'accions executades a l'ENP | W13: 1) 3 | X13: 2) 6 | Y13: x | Z13: x | AA13: x | AB13: x | AC13: x | AD13: 150
F14: 01.3.4 | G14: Restaurar la dinàmica natural dels rius | H14: Específic | I14: Optatiu | J14: MAP | K14: SENP/SFF: Definir criteris metodològics | L14: Restaurar i conservar la dinàmica i estructura natural dels rius, les zones humides, i altres hàbitats d'aigua dolça | M14: Canvi de redactat OP. Adaptar el redactat per a tot tipus de masses d'aigua | N14: Impuls-Suport | O14: Si | P14: MITJANA | Q14: Suport tècnic en l'execució d'accions de millora de connectivitat fluvial_CAG Foment de la custòdia fluvial_CAG | R14: *Elaboració d'una cartografia d'hàbitats fluvials i un programa d'actuacions per a la millora dels hàbitats (anomenar els hàbitats)_CAG *Seguiment dels treballs de construcció del connector fluvial del Gomarell (riera de Sant Aniol) que realitza l'Ajuntament de Montagut i Oix_CAG * Acord de custòdia fluvial a la conca de la Muga_CAG | S14: *Recuperació de basses. Projecte ponderful. No aplica aquí. Aplica al primer objectiu *Restauració de la morfologia, la connectivitat i les riberes de les masses d'aigua rius del DCFC. Connector fluvial del Gomarelli acord de custòdia fluvial al sector de la Muga *Actuacions de millora de la vegetació ripària a partir de l'aplicació del Programa de Manteniment i conservació de lleres de l'ACA, especialment en àrees que requereixen recuperació de cobertura arbòria. Primer farem la cartografia el programa d'actuacions, a posteriori redacció de projectes executius. *Actuacions pel manteniment de la dinàmica hidrològica pròpia de l'hàbitat 6420, evitant drenatges o inundacions permanents. On en tenim? Seria el qu hi ha a Palomeres?si no ho sabem li podem demanar a en Lluis Benejam. Però seria a l'objectiu 1. Valorar si és el cas d'aques hàbitat específicament. | V14: 1) Nombre d'actuacions executades 2) Nombre d'acords | W14: 1) 1 2) 1 | X14: 1) 2 2) 2 | Y14: x | Z14: x | AA14: x | AB14: x | AC14: x | AD14: 200
F15: 01.3.5 | G15: Fomentar el paisatge en mosaïc | H15: Específic | I15: Optatiu | J15: ESNATURA | K15: SENP/SFF: Definir criteris metodològics | L15: =G15 -> Fomentar el paisatge en mosaïc | N15: Sí | O15: Si | P15: ALTA | Q15: Recuperació d'espais oberts segons PIRE_CAG Execució del Programa de compensacions per afavorir ramaderia extensiva segons PIRE_DGPA | R15: * Projecte de recuperació d'espais oberts_CAG *Desenvolupament del PIRE i del Programa de Compensacions a l'activitat ramadera_CAG i DGPA * Seguiment de l'estat ecològic dels prats de l'Alta Garrotxa_CAG * Anàlisi d'oportunitats per la recuperació de prats de dall_CAG valorar si es factible a ENPAG | S15: *Recuperació de pastures i espais oberts En curs des de 2009. *Manteniment dels espais oberts (conreus i pastures), els prats de dall i un paisatge en mosaic en les zones amb presència destacada d'espècies d'interès comunitariEn curs des de 2009. *Potenciar la ramaderia extensiva per conservar els hàbitats agroforestals i prevenir incendis forestals.En curs des de 2009. *Realització de desbrossades selectives en zones de matollar per a afavorir l'hàbitat de la tórtora europea.Es fa amb els criteris de recuperació EEOO (ecotons, conservació espècies nutrícies, i reducció de la intensitat als marges de l'actuació, períemtres irregulars) *Mesures de conservació de la vegetació arbustiva i de la bardissa en fons de valls mantenint un mosaic de vegetació. Es un hàbitat no en regressió per s'apliquen els criteris abans descrits quan es fa recuperació d'espais oberts. *Els instruments de planificació i ordenació dels espais naturals protegits eviten l'aforestació en nuclis rellevants dels matollars i prats d'interès comunitari.Si, el PPAG preveu àrees atenció condicionada associades a espais oberts. *Recuperació de prats de dall (5% de la superfície actual). Què podriem fer per encara aquesta actuació? | T15: *Mesures de foment d’actuacions de recuperació i manteniment de pastures. | U15: *Recuperació de pastures i d'hàbitsts d'espais oberts *Redacció de Plans de Pastura prescrita *Ampliació i recuperació de pastures | V15: 1) Nombre d'actuacions executades 2) Nombre d'explotacions ramaderes afavorides | W15: 1) 3 2) 2 | X15: 1) 6 2) 4 | Y15: x | Z15: x | AA15: x | AB15: x | AC15: x | AD15: 500
F16: 01.3.6 | G16: Gestionar i intervenir en la dinàmica de poblacions de fauna que no tenen depredador natural | H16: Específic | I16: Optatiu | K16: SENP/SFF: Definir criteris metodològics | L16: =G16 -> Gestionar i intervenir en la dinàmica de poblacions de fauna que no tenen depredador natural | N16: No | O16: Si | P16: BAIXA | Q16: Participació i impuls del control directe de poblacions de fauna d'acord amb l'organisme competent en matèria de gestió cinegètica_CAG i DGPA | V16: 1) Nombre d'accions de control impulsades | W16: 1) 0 | X16: 1) 1 (segons necessitats) | AB16: x | AC16: x | AD16: 25
D17: 01.4 | E17: Alinear l'activitat de propietaris i gestors del territori amb la conservació, millora i restauració dels valors de l'ENP | F17: 01.4.1 | G17: Fomentar acords de custòdia en espais d'alt valor dins l'ENP per a la gestió dels elements prioritaris | H17: Comú | I17: Optatiu | J17: MAP | K17: SENP/SENP: Dissenyar el protocol i elaborar un model d'acord | L17: =G17 -> Fomentar acords de custòdia en espais d'alt valor dins l'ENP per a la gestió dels elements prioritaris | N17: Sí | O17: Si | P17: ALTA | Q17: Foment i signatura d'acords de custòdia amb entitats o el CAG_CAG Signatura de convenis de dinàmica natural amb propietaris_DGPA | R17: * Signatura d'acords de custòdia per realitzar accions de millora d'hàbitat dins ENPAG_CAG * Signatura d'un acord de cusòdia fluvial amb l'ACA per a sector de la Muga_CAG *Signatura de convenis de dinàmica natural amb propietaris_DGPA (PPAG) | T17: *Promoure acords de custòdia del territori | U17: *Diagnosi i proposta d’accions-custodia fluvial a la Muga *Acord de custòdia fluvial per la Reserva Natural Parcial de la Muga | V17: 1) Nombre d'acords de custòdia aconseguits 2) Nombre de convenis de dinàmica natural signats | W17: 1) 3 2) 3 | X17: 1) 6 2) 5 | Y17: x | Z17: x | AA17: x | AB17: x | AC17: x | AD17: 150
F18: 01.4.2 | G18: Fomentar bones pràctiques entre els col·lectius de propietaris i gestors del territori | H18: Comú | I18: Optatiu | L18: =G18 -> Fomentar bones pràctiques entre els col·lectius de propietaris i gestors del territori | N18: Impuls-Suport | O18: Si | P18: MITJANA | Q18: Divulgació de bones pràctiques per la gestió d'hàbitats i espècies (estudi canvi climàtic, maneig de pastures) | R18: * Trasllat als propietaris dels resultats de l'estudi del CREAF sobre l'impacte del canvi climàtic a les masses forestals de l'ENPAG_CAG * Creació una taula de treball per consensuar BBPP de gestió forestal al'ENPAG ¿??? * Creació d'un manual de BBPP de gestió forestal vinculat a l'adaptació del canvi climàtic_CAG * Suport a la FPC en la redacció de Plans de maneig per a la gestió del pastoreig (Projecte Forwards)_CAG | S18: INCLOURE COM A CRITERIS DE BBPP O BÉ FORA DE L'ABAST DAQUEST PLA ESTRATÈGIC*Actuacions per disminuir i substituir els productes fitosanitaris per altres de més selectius i de baixa toxicitat (AAA) tant per a la fauna terrestre com aquàtica. *Actuacions de foment de l'ús de permetrines enlloc d'organoclorats pel tractament de la fusta d'edificacions amb presència de rat-penats. *Actuacions de manteniment dels sistemes tradicionals de gestió de les pastures. Es realitza a trvés del projecte d'EEOO perquè la recuperació espais permet la transhumància dins de l'espai, i s'articula a través del PIRE. | U18: *Implicació de la pagesia en el manteniment d’espais oberts i recuperació d’elements d’interès que acompanyen el patrimoni geològic HO fem en el desenvolupament de l'estratègia | V18: 1) Nombre de sessions de divulgació 2) Elaboració de material divulgatiu | W18: 1) 2 2) 1 | X18: 1) 4 2) 2 | AB18: x | AC18: x | AD18: 64
F19: 01.4.3 | G19: Impulsar la coordinació amb els ens locals en la gestió finques públiques situades dins d’ENP | H19: Específic | I19: Optatiu | J19: ESNATURA | L19: =G19 -> Impulsar la coordinació amb els ens locals en la gestió finques públiques situades dins d’ENP | M19: No aplica, finca pública de la Generalitat | O19: No | Q19: Objectiu no aplicable a l'espai | R19: *Consens en el marc del CP del CAG les accions impulades per l'ens en finca pública. | AD19: 0
B20: 2 | C20: ADAPTAR ELS ECOSISTEMES AL CANVI CLIMÀTIC i millorar-ne la resiliència en front dels riscos associats. | D20: 02.1 | E20: Planificar l'adaptació dels sistemes naturals al canvi climàtic | F20: 02.1.1 | G20: Adaptar i implementar el Pla d'adaptació de l'ENP al canvi climàtic | H20: Comú | I20: Obligatori | K20: OCCC/SENP: Elaboració del model de Pla d'adaptació dels ENP al canvi climàtic | L20: Implementar els resultats de l'estudi d'adaptació dels boscos de l'Alta Garrotxa | M20: Es té una estudi-prova pilot a específic per l'ENPAG | N20: Impuls-Suport | O20: Si | P20: ALTA | Q20: Redacció del Pla d'adaptació al canvi climàtic de l'ENP_DGPA i CAG Foment d'actuacions per a la creació de refugis climàtics_DGPA i CAG Divulgació dels criteris de gestió d'adaptació al canvi climàtic a l'ENP_DGPA i CAG | R20: * Signatura d'acords de custòdia per realitzar accions de millora d'hàbitat dins ENPAG_CAG *Signatura de convenis de dinàmica natural amb propietaris_DGPA (PPAG) *Suport a DGBoscos (SSTT) en la definció i seguiment del projecte de refugis climàtics del MITECO_CAG i DGPA (SSTT) *Integració dels criteris de la prova pilot sobre canvi climàtic en els informes dels SSTT respecte a actuacions forestals_DGPA (SSTT) * Creació d'un manual de BBPP de gestió forestal vinculat a l'adaptació del canvi climàtic_CAG | V20: 1) Redacció del Pla 2) Nombre d'actuacions 3) Nombre de sessions divulgatives CC | W20: 1) 1 2) 3 3) 1 | X20: 1) 1 2) 6 3) 2 | Y20: x | Z20: x | AA20: x | AB20: x | AC20: x | AD20: 120
F21: 02.1.2 | G21: Gestionar i planificar els recursos hídrics de l'ENP | H21: Comú | I21: Obligatori | L21: =G21 -> Gestionar i planificar els recursos hídrics de l'ENP | N21: Impuls-Suport | O21: Si | P21: ALTA | Q21: Redacció del Pla de gestió dels recursos hídrics d'acord amb l'estudi hidrogeològic de l'ENP_DGPA Suport a la regulació de les captacions per ús domèstic_CAG | R21: Podem fer alguna cosa per evitar els impactes del canvi climàtic sobre els recursos hídrics. Què podem fer? HO podem integrar en l'estudi de gestió dels hàbitats de ribera?? Mirar què han fet altres espais. | V21: 1) Redacciódel Pla | W21: 1) 1 | X21: 1) 1 | AB21: x | AC21: x | AD21: 50
F22: 02.1.3 | G22: Participar en la redacció i execució dels instruments d'ordenació forestal sostenible i per la conservació en finques públiques | H22: Específic | I22: Optatiu | K22: DGEFMN: Redacció d'IOF en finques públiques | L22: Promoure la redacció d'instruments d'ordenació forestal sostenible i l'execució d'accions per la conservació i millora dels boscos i els elements d'interès | M22: Canvi de redactat OP. Inclusió d'accions forestals per a la millora de la biodiversitat sense detallar la propietat de la finca | N22: Impuls-Suport | O22: Si | P22: MITJANA | Q22: Suport a la implementació dels IOF en finca pública_CAG i SSTT | R22: *Suport a DGBoscos (SSTT) en la definció i seguiment del projecte de refugis climàtics del MITECO_CAG i DGPA (SSTT) | S22: *Redacció del projecte executiu d’intervenció forestal per a la millora de l’hàbitat de Polygala vayredae Això no aplica en aquest objecitu, va en el primer. Ho he posat al primer objectiu. *Els Plans d’Ordenació Forestal de finques públiques inclouen criteris orientats a la conservació de les millors àrees amb presència d'hàbitats o espècies d'interès comunitari.Hem donat suport amb la info de la que disposem sobre patirmoni natural. *Els instruments de planificació forestal han de tenir en compte la realització de les estassades de forma més selectiva per tal d'evitar la tala d'espècies d'interès especial als boscos d'interès comunitari.Ja està integrat. contrastat amb la Miriam. *Establiment de mesures de gestió per a la conservació en els models de gestió ORGEST. Per exemple, el manteniment d'un mínim de 5 a 10 arbres/ha de més de 40 dn, respecte a Hedera, peus morts, arbres amb cavitats sense tallar, etc.Ja està integrat. contrastat amb la Miriam. *Els instruments de planificació forestal han d’establir una freqüència de nou anys entre estassades en les rouredes d'interès comunitari (9160,9230,9240).Ja està integrat. contrastat amb la Miriam. *Mesures i actuacions d'us de la ramaderia extensiva o d'aclarides selectives per controlar l'excés de sotabosc a pinedes i alzinars.Ja està integrat. contrastat amb la Miriam. *Recuperació de tècniques tradicionals d'aclarida al voltant dels arbres més productius per minimitzar la pertorbació que suposen les estassades generals de l'estrat arbustiu.Ja està integrat. contrastat amb la Miriam. *Actuacions per augmentar la presència d'espècies arbòries i arbustives productores de fruits susceptibles de ser font d'aliment per a la fauna.Ja està integrat. contrastat amb la Miriam. *Realització de les estassades de forma més selectives per tal d'evitar la tala d'espècies d'interès especial.Ja està integrat. contrastat amb la Miriam. *Actuacions de gestió forestal específica per conservació dels rodals de 9580 dins la massa mitjançant tallades selectives.Hi ha teixeda en finca pública? Crec que no aplica. Contrastat amb la Miriam. | V22: 1) Percentatge d'actuacions forestal amb IOF redactat en que s'ha participat a petició de la DGB | W22: 1) 25 | X22: 2) 50 | AD22: 20
F23: 02.1.4 | G23: Promoure la redacció d'instruments d'ordenació forestal per reduir la sensibilitat i vulnerabilitat dels boscos al canvi climàtic en finques privades | H23: Específic | I23: Optatiu | L23: =G23 -> Promoure la redacció d'instruments d'ordenació forestal per reduir la sensibilitat i vulnerabilitat dels boscos al canvi climàtic en finques privades | N23: Impuls-Suport | O23: Si | P23: MITJANA | Q23: Col·laboració amb el CPF per al foment dels IOF per reduir la sensibilitat i vulnerabilitat al canvi climàtic en finca privada_CAG Foment i revisió de les mesures compensatòries i condicions d'execució dels dels IOF perquè no siguin agressius amb l'hàbitat forestal_CAG Foment de la implementació crèdits climàtics forestals_CAG | R23: * Trasllat als propietaris dels resultats de l'estudi del CREAF sobre l'impacte del canvi climàtic a les masses forestals de l'ENPAG_CAG * Sigantura d'acords de custòdia per realitzar accions de millora d'hàbitat dins ENPAG_CAG * Signatura de convenis de dinàmica natural amb propietaris_DGPA (PPAG) *Integració dels criteris de la prova pilot sobre canvi climàtic en els informes dels SSTT respecte a actuacions forestals_DGPA (SSTT) * Creació d' una taula de treball per consensuar BBPP de gestió forestal a l' ENPAG ¿??? * Creació d'un manual de BBPP de gestió forestal vinculat a l'adaptació del canvi climàtic_CAG | V23: 1) Nombre d'accions conjuntes de divulgació | W23: 1) 1 | X23: 1) 3 | Z23: x | AA23: x | AB23: x | AC23: x | AD23: 80
D24: 02.2 | E24: Planificar la prevenció i extinció d’incendis forestals i la gestió del foc de forma coordinada amb els diferents agents del territori | F24: 02.2.1 | G24: Redactar i implementar el Pla de Prevenció d'Incendis | H24: Comú | I24: Obligatori | J24: ESNATURA | K24: Equip de PPI: Disseny del protocol de treball | L24: =G24 -> Redactar i implementar el Pla de Prevenció d'Incendis | N24: Impuls-Suport | O24: Si | P24: MÀXIMA | Q24: Redacció dels PEGs inclosos al PIE_CAG Implementació d'accions del PIE (xarxa viària, espais oberts)_CAG Manteniment i adequació de la xarxa viària per a la prevenció d'incendis_CAG | R24: * Suport a la FPC i la DGPA en el projecte Foc i Biodiversitat a l'Alta Garrotxa_CAG * Redacció dels projectes executius dels PEGs definits pel Cos de Bombers_CAG * Establiment de lligams amb el GPIF (Forestal Catalana) per a l'execució del PIE de l'ENPAG_CAG i DGPA * Impuls de l'aprovació de l'Annex del PIE vinculat als PEGs redefinits_CAG * Millora de la xarxa viària establerta al PIE_CAG * Pagament per serveis ambientals als ramaders_DGPA * Priorització de la recuperació d'EEOO en PEGs i sectors prioritzats al PIE_CAG * Manteniment dels punts d'aigua segons incidències_CAG/Ajuntaments | S24: *Actuacions de prevenció i extinció de grans incendis forestals. | U24: *Construcció i manteniment de vials forestals per a la prevenció d'incendis *Actuacions en punts crítics associats a la xarxa viària per a la prevenció d'incendis *Construcció i manteniment de punts d'aigua de la xarxa bàsica per a la prevenció d'incendis *Protecció, adequació i senyalització de punts d'aigua de la xarxa bàsica per a l'extinció d'incendis *Actuacions sobre la vegetació per a l'obertura de franges auxiliars de trànsit (FAT) i tractament de restes vegetals *Actuacions sobre la vegetació per a la creació d'àrees estratègiques de baixa càrrega de combustible per a la prevenció d'incendis *Implementació d'intraestructures o serveis per als ramats de manteniment de les àrees estratègiques *Manteniment d'àrees estratègiques de baixa càrrega de combustible per a la prevenció d'incendis mitjançant pasturatge amb ramaderia extenisva *Actuacions sobre la vegetació per l'obertura d'àrees de seguretat amb eliminació de restes in situ *Actuacions sobre la vegetació a l'entorn dels punts d'aigua d'extinció d'incendis *Actuacions sobre la vegetació en Zones de Foment de la Gestió (ZFG) | V24: 1) Nombre de PEGs redactats 2) Nombre d'accions implementades | W24: 1) 3 2) 4 | X24: 1) 6 2) 8 | Y24: x | Z24: x | AA24: x | AB24: x | AC24: x | AD24: 450
F25: 02.2.2 | G25: Definir i planificar la gestió del foc per a la millora de l'ENP | H25: Específic | I25: Optatiu | K25: SPEN: Elaboració d'un model de pla de gestió | L25: =G25 -> Definir i planificar la gestió del foc per a la millora de l'ENP | N25: Sí | P25: ALTA | Q25: Suport a la FPC en el seguiment de les zones on s'han realitzat cremes prescrites (proiecte Foc i Biodiversitat i Projecte Forwards_CAG Participació i dinamització de la Taula de foc de l'Alta Garrotxa_CAG Suport a la sensibilització sobre el foc com a eina de gestió_CAG | R25: * Suport a la FPC i la DGPA en el projecte Foc i Biodiversitat a l'Alta Garrotxa (pla de cremes prescrites i execució de treballs forestals en PEGs_CAG * Suport a la FPC en l'elaboració de plans de maneig per la gesitó de pastures i seguiment en les zones on s'han realitzat cremes prescrites (proiecte Foc i Biodiversitat i Projecte Forwards_CAG * Participació i dinamització de la Taula de foc de l'Alta Garrotxa_CAG * Suport a la FPC i participació en les sessions de sensibilització sobre el foc com a eina de gestió_CAG | S25: *Regulació de pràctiques de gestió de pastures (cremes controlades i ramaderia intensiva) que poden comportar una simplificació de l'ecosistema o la desaparició dels hàbitats 4060 i 6420. Plans de maneig del pastoreig que construirem amb la FPC en el projecte Forwards. (si és l'hàbitat ho tindrem en compte). | T25: *Planificació per la prevenció i extinció d’incendis forestals i per la gestió del foc. En curs- | U25: *Constitució d'una Taula de foc i elaboració dels projectes executius dels punts estratègics de gestió per incendis | V25: 1) Nombre d'espais objecte de seguiment 2) Nombre de sessions de la taula de foc 3) Nombre d'accions de sensibilització | W25: 1) 2 2) 4 3) 1 | X25: 1) 4 2) 6 3) 2 | AD25: 180
F26: 02.2.3 | G26: Treballar per a la prevenció d'incendis juntament amb els propietaris, ajuntaments, protecció civil, ADF i bombers. | H26: Comú | I26: Obligatori | L26: =G26 -> Treballar per a la prevenció d'incendis juntament amb els propietaris, ajuntaments, protecció civil, ADF i bombers. | N26: Sí | O26: Si | P26: ALTA | Q26: Participació i dinamització de la Taula de foc de l'Alta Garrotxa_CAG Suport a la sensibilització sobre el foc com a eina de gestió_CAG | R26: * Participació i dinamització de la Taula de foc de l'Alta Garrotxa_CAG * Suport a la FPC i participació en les sessions de sensibilització sobre el foc com a eina de gestió_CAG | V26: 1) Nombre de sessions de la taula de foc 2) Nombre d'accions de sensibilització | W26: 1) 4 2) 1 | X26: 1) 6 2) 2
B27: 3 | C27: PROTEGIR LA BIODIVERSITAT, i especialment els elements fràgils i amenaçats, d’interès comunitari o de major interès natural. | D27: 03.1 | E27: Prevenir, minimitzar i compensar els impactes ambientals dels usos i activitats que es desenvolupin en l'àmbit de l'ENP | F27: 03.1.1 | G27: Participar en les consultes dels procesos d'Avaluació Ambiental que afectin directament o indirectament l’espai del ENP | H27: Comú | I27: Obligatori | L27: =G27 -> Participar en les consultes dels procesos d'Avaluació Ambiental que afectin directament o indirectament l’espai del ENP | N27: Impuls-Suport | O27: Si | P27: ALTA | Q27: Suport i assessorament als SSTT en l'emissió d'informes dins al tramitació de l'AIA de projectes i activitats dins ENPAG_CAG i SSTT | R27: * Tramitació dels DAE necessaris en el desenvolupament de projectes promoguts pel Consorci_CAG * Suport als SSTT en l'emissió d'informes dins al tramitació de l'AIA_CAG i SSTT * Assessorament i interlocució en l'àmbit de l'AIA en el marc de la implementació de planificació /projectes impulsats per tercers_CAG | S27: *L'avaluació ambiental de la creació de nous vials i infraestructures en àrees amb presència d'hàbitats o espècies d'interès comunitari ha de minimitzar la seva afectació evitant l'afectació de les àrees més ben conservades. Es realitza sempre prèvia consulta amb SSTT i OTAA | V27: 1) Percentatge de suport i assessorament realitzat a petició dels SSTT | W27: 1) 65% | X27: 1) 100% | Y27: x | Z27: x | AA27: x | AB27: x | AC27: x | AD27: 25
