Workbook

Sheet ESTRATÈGIA
C3: ESQUEMA CONCEPTUAL PER A LA ELABORACIÓ DEL PLA ESTRATÈGIC EN EL MARC
C4: DELS ESTÀNDARDS OBERTS PER A LA GESTIÓ ADAPTATIVA A CATALUNYA

Sheet INSTRUCCIONS
A1: PESTANYA DE PRIORITZACIÓ
A2: Llistat elements: | B2: Tasca 1: Revisar el llistat d'elements prioritzats per tal d'avaluar si cal afegir-ne algun o treure'n algun. A la columna comentaris cal argumentar, breument, el perquè de la decisió.
A4: Llistat amenaces: | B4: Tasca 2: A partir de la taxonomia d'amenaces que es troba a la pestanya final, cal omplir les tres columnes (E, F i G) amb les tres principals amenaces per a la conservació de l'element. S'afegeixi una darrera columna per si hi ha amenaces que no es troben incloses a la taxonomia.
A6: PESTANYA DEL PLA
A7: Explicacions:
B8: 7 Eixos temàtics
B9: Els objectius generals estan directament associats als objectius generals dels Plans de Protecció del medi naatural i del paisatge. NO ES PODEN RETOCAR
B10: Objectius estratègics: definits en un grup de treball intern de serveis Centrals i dels Parcs durant l'any 2023. NO ES PODEN RETOCAR
B11: Objectius operacionals: definits en un grup de treball intern de serveis Centrals i dels Parcs durant l'any 2023
A14: Tasques a realitzar:
A15: Objectius operacionals: | B15: El llistat d'objectius operacionals té una columna al costa (columna I) on s'indica si l'objectiu és obligatori de mantenir al Pla estratègic o no.
B16: Tasca 1: Columna I. Revisar els que es posa com a obligatoris per veure si són realment aplicables a l'espai o no.
B17: Tasca 2: Columna I. Revisar els que posa "Opcional" per identificar els que són aplicables o no a l'espai. O, també, determinar si algun d'ells seria aplicable o es pot concretar millor el redactat de l'objectiu.
B18: Tasca 3: Columna J. En ambdós casos, cal posar a la columna J, el redactat final de l'objectiu concretat a l'espai. En el cas de que l'objectiu s'elimina, posar "NA". Ara es reprodueix el redactat dels objectius operacionals derivats del grup de treball esmentat
B19: Tasca 4: Columna K. Per tots els casos en que hi ha modificació respecte al redactat original de l'objectiu operatiu -i, també, en el cas que es consideri que s'ha d'eliminar-, a la columna K cal redactar molt breument el motiu pel qual es prèn la decisió.
B20: Tasca 5: Columna L. Incloure un Si/No avaluant si l'objectiu operatiu podria tenir mesures a incorporar a la programació d'actuacions de l'espai (Si) o, per altra banda, el seu assoliment depèn d'altres òrgans, com l'ACA o altres serveis dins la DGPAMN (No).
B21: Tasca 6: Columna M. Definir la prioritat que hauria de tenir l'assoliment de l'objectiu (màxima, si cal assolir en els propers 4 anys, o altrament alta, mitja o baixa). També hi ha l'opció de prioritat a assolir a més llarg termini.
A22: Propostes genèriques d'accions: | B22: Tasca 7: Columna N. En aquest columna cal introduir les accions, de manera genèrica, que caldria aplicar a l'espai per tal d'assolir l'objectiu operatiu. No es tracta d'un llistat d'accions concretes si no, més aviat, accions generals que acabarien concretant-se en la programació anual. PER A INICIAR AMB LA TAULA US PODEU BASAR MOLT EN LA FEINA JA FETA DE PRIORITZACIÓ DE MESURES PEL MAP
B23: En el cas dels objectius operatius que s'ha considerat que no són aplicables a l'espai, cal avaluar si podrien tenir alguna acció que sí tindria sentit d'incloure al Pla estratègic tot i que l'objectiu de manera global no hi ´seria d'aplicació.
A24: Indicadors: | B24: Tasca 8: Columna Q. Posar un indicar SMART per avaluar el compliment de la mesura proposada a la columna N
A25: Fites a assolir en 4 anys: | B25: Tasca 9: Posar un valor de l'indicador a asolir: valor mínim necessari (columna R) o valor desitjable (columna S).
A26: Hores de dedicació: | B26: Tasca 10: Columna T. Realitzar una aproximació el més acurada que es pugui de les hores del personal de gestió de l'espai que cal destinar per a la realització de l'acció.
A27: Àrea responsable: | B27: Tasca 11: Columna U. Indicar quina àrea de l'equip de gestió és responsable de coordinar l'execució de l'acció.
A28: Persona responsable: | B28: Tasca 12: Columna V. Indicar quina persona dins l'àrea seria l'encarregada.
A30: PESTANYA DEL VINCLE
A31: Definir vincle amenaça vs. Obj. Operatiu | B31: Tasca 1: Establir / Revisar el vincle entre les amenaces identificades a la pestanya de priorització i els objectius operatius definits a la columna J de la pestanya Pla. La columna B conté el llistat dels objectius operatius tal i com quedaran definits després de la vostra revisió.
B32: Tasca 2: En cas que es pugui, definir l'amenaça / factor / causa concret a la que atén l'objectiu definit al Pla. Poden ser més d'una.
B33: És important que es visualitzi a quina amenaça es dirigeix l'objectiu operatiu que es proposa al Pla, tot i que, no sempre hi ha d'haver un vincle clar. Pot haver algun objectiu sense amenaça vinculada.

Sheet PRIORITZACIÓ
D2: Llistats corresponent a l'espai de Natura 2000 ES5120008"Estany de Banyoles"
D3: LLISTAT D'ELEMENTS PRESENT A L'ESPAI | J3: AMENACES PER A CADA ELEMENT
D4: Hàbitats d'interès comunitari | E4: Hàbitats d'interès comunitari | F4: Prioritzat | G4: CE | H4: Puntuació índex rellevància | I4: Comentaris en cas de canvi en la priorització | J4: Amenaça 1 segons taxonomia | K4: Amenaça 2 segons taxonomia | L4: Amenaça 3 segons taxonomia | M4: Altres amenaces
D5: 3140 | E5: Aigües oligomesotròfiques calcàries amb vegetació bèntica de Chara spp. | F5: Si | G5: No | H5: 6.75 | J5: Impactes del canvi climàtic relatius a l'alteració del règim de precipitació i sequera | K5: Gestió de l'aigua | L5: Activitat agrícola | O5: Nota: La priorització d'elements actual inclou els Elements Clau que es van determinar en l'instrument de gestió aprovat amb l'Acord de Govern 150/2014 (Annex 6)
D6: 3150 | E6: Estanys naturals eutròfics amb vegetació natant (Hydrocharition) o poblaments submersos d'espigues d'aigua (Potamion) | F6: Si | G6: No | H6: 4.375 | J6: Impactes del canvi climàtic relatius a l'alteració del règim de precipitació i sequera | K6: Gestió de l'aigua | L6: Activitat agrícola | O6: Aquest Acord era per les Zones Especials de Conservació, no per les ZEPA i, per tant, no es va fer l'exercici de priorització de les aus.
D7: 3170p | E7: Basses i tolls temporanis | F7: Si | G7: Si | H7: 4.125 | J7: Impactes del canvi climàtic relatius a l'alteració del règim de precipitació i sequera | K7: Gestió de l'aigua | L7: Activitat agrícola | O7: També inclou el primer quartil de l'exercici de la UIC per prioritzar els elements present a cada espai de Natura 2000, és a dir, el 25% dels
D8: 3190 | E8: Estanys càrstics amb guixos | F8: Si | G8: No | H8: 6.75 | J8: Impactes del canvi climàtic relatius a l'alteració del règim de precipitació i sequera | K8: Gestió de l'aigua | L8: Activitat agrícola | O8: elements amb major índex de rellevància a l'espai. Veure document metodològic aquí:
D9: 3290 | E9: Rius mediterranis intermitents, amb gespes nitròfiles del Paspalo-Agrostidion | F9: Si | G9: No | I9: És d'interès per l'ENP | J9: Impactes del canvi climàtic relatius a l'alteració del règim de precipitació i sequera | K9: Gestió de l'aigua | L9: Activitat agrícola | O9: https://gencat.sharepoint.com/sites/Informaciiconeixementpatrimoninatural2/Documents%20compartits/Forms/AllItems.aspx?csf=1&web=1&e=3x4ZkK&ovuser=3b9427dc%2Dd30e%2D43bc%2D8c06%2Dff7253676fec%2Cjordiparpal%40gencat%2Ecat&OR=Teams%2DHL&CT=1713942253212&clic
D10: 6420 | E10: Jonqueres | F10: Si | G10: No | I10: És d'interès per l'ENP | J10: Impactes del canvi climàtic relatius a l'alteració del règim de precipitació i sequera | K10: Gestió de l'aigua | L10: Activitat agrícola | O10: El llistat original d'elements prové dels llistats que genera l'ACTBIO i té en compte les espècies que surten al formulari normalitzat de dades (FND) de l'espai
D11: 6430 | E11: Herbassars higròfils, tant de marges i vorades com de l'alta muntanya | F11: Si | G11: No | I11: És d'interès per l'ENP per la restauració de boscos de ribera en general | J11: Impactes del canvi climàtic relatius a l'alteració del règim de precipitació i sequera | K11: Gestió de l'aigua | L11: Activitat agrícola
D12: 6510 | E12: Prats de dall de terra baixa | F12: Si | G12: No | I12: L'ENP considera com a prioritari com a zona d'expansió/buffer a l'entorn de zones humides | J12: Desaparició d'activitats tradicionals | K12: Activitat agrícola
D13: 7210p | E13: Aiguamolls calcari de mansega | F13: Si | G13: Si | H13: 5 | J13: Impactes del canvi climàtic relatius a l'alteració del règim de precipitació i sequera | K13: Gestió de l'aigua
D14: 91E0p | E14: Vernedes i altres boscos de ribera | F14: Si | G14: Si | I14: És d'interès per l'ENP per la restauració de boscos de ribera en general | J14: Impactes del canvi climàtic relatius a l'alteració del règim de precipitació i sequera | K14: Gestió de l'aigua | L14: Treballs forestals
D15: 92A0 | E15: Alberedes, salzedes i altres boscos | F15: Si | G15: No | I15: Ídem anterior | J15: Impactes del canvi climàtic relatius a l'alteració del règim de precipitació i sequera | K15: Gestió de l'aigua | L15: Treballs forestals
D16: 9340 | E16: Alzinars i carrascars | F16: Si | G16: No | I16: Interès en algun sector de l'espai a la conca de recepció de l'estany com a alzinars de boscos madurs en recuperació | J16: Treballs forestals | K16: Foc | L16: Impactes del canvi climàtic relatius a l'alteració del règim de precipitació i sequera
D17: 9540 | E17: Pinedes mediterrànies | F17: Si | G17: No | I17: Si es pot fer compra de finques l'ENP també hi intervé | J17: Treballs forestals | K17: Foc | L17: Impactes del canvi climàtic relatius a l'alteració del règim de precipitació i sequera
B21: CATÀLEG | C21: GRUP | D21: Espècies presents a l'espai | F21: Prioritzat | G21: CE | H21: Puntuació índex rellevància | I21: Comentaris en cas de canvi en la priorització | J21: Amenaça 1 segons taxonomia | K21: Amenaça 2 segons taxonomia | L21: Amenaça 3 segons taxonomia | M21: Altres amenaces
C22: Aus | D22: Acrocephalus arundinaceus | F22: No | G22: No
C23: Aus | D23: Acrocephalus melanopogon | F23: No | G23: No
C24: Aus | D24: Acrocephalus scirpaceus | F24: No | G24: No
C25: Aus | D25: Actitis hypoleucos | F25: No | G25: No
B26: VU | C26: Invertebrats | D26: Aeschna isoceles | F26: Si | G26: No | I26: Una de les poques i millors poblacions de Cat | J26: Gestió de l'aigua | K26: Activitat agricola | L26: Impactes del canvi climàtic relatius a l'alteració del règim de precipitació i sequera
B27: VU | C27: Invertebrats | D27: Aeshna afinis | F27: No | G27: No
C28: Aus | D28: Alcedo atthis | F28: No | G28: No
C29: Amfibis | D29: Alytes obstetricans | F29: No | G29: Si | I29: Com a millora d'hàbitat, actualització de la informació | J29: Plagues i patògens | K29: Espècies invasores | L29: Impactes del canvi climàtic relatius a l'alteració del règim de precipitació i sequera | M29: Polució aquàtica
C30: Aus | D30: Anas acuta | F30: No | G30: No
C31: Aus | D31: Anas clypeata | F31: No | G31: No
C32: Aus | D32: Anas crecca | F32: No | G32: No
C33: Aus | D33: Anas penelope | F33: No | G33: No
C34: Aus | D34: Anas platyrhynchos | F34: No | G34: No | I34: Treball en termes d'afectació a cultius propers
C35: Aus | D35: Anas querquedula | F35: No | G35: No
C36: Aus | D36: Anas strepera | F36: No | G36: No
C37: Invertebrats | D37: Anodonta anatina | F37: Si | G37: Si | I37: Cria en captivitat | J37: Espècies invasores | K37: Gestió de l'aigua | L37: Impactes del canvi climàtic relatius a l'alteració del règim de precipitació i sequera
C38: Aus | D38: Ardea alba | F38: No | G38: No
C39: Aus | D39: Ardea cinerea | F39: No | G39: No
C40: Aus | D40: Ardea purpurea | F40: No | G40: No
C41: Aus | D41: Ardeola ralloides | F41: No | G41: No
B42: VU | C42: Mamífers | D42: Arvicola sapidus | F42: Si | G42: Si | I42: Millora de la informació | J42: Gestió de l'aigua | K42: Plagues i patògens | L42: Espècies invasores | M42: Ramaderia
B43: VU | C43: Aus | D43: Athene noctua | F43: Si | G43: Si | I43: Presència a l'espai i oportunitat per millorar el seu hàbitat | J43: Activitat agrícola | K43: Urbanització residencial | L43: Vials de transport
C44: Aus | D44: Aythya ferina | F44: Si | G44: No | H44: 1.75 | I44: Hi és com a hivernant | J44: Activitat agrícola | K44: Polució aquàtica | L44: Caça i recol·lecció d'animals | M44: Espècies invasores
...

Sheet Pla_Exercici
A1: EIXOS | B1: Id_OG | C1: OBJECTIUS Generals (PP) | D1: Id_OE | E1: OBJECTIUS Estratègics | F1: Id_OO | G1: Objectiu operatiu concret a l'espai | H1: Explicació de la decisió presa en el cas de canvis respecte al llistat inicial (columna G) | I1: Objectiu amb mesures incorporables a la planificació anual de la gestió de l'espai? | J1: Propostes d'accions | K1: Indicadors | L1: Àrea responsable | M1: Persona responsable | N1: Contractació externa o mitjans propis | O1: Finançament
A2: NATURA | B2: 1 | C2: CONSERVAR LA NATURA i restaurar els ecosistemes, els processos naturals i seminaturals, la biodiversitat i la geodiversitat associada. | D2: 01.1 | E2: Adequar i fer eficient la conservació dels elements objecte de gestió prioritària marcats per la DG a l'ENP | F2: 01.1.1 | G2: Implementar i executar plans de gestió específics per a hàbitats i espècies de conservació prioritària dins l'ENP | I2: Si | J2: Elaboració d'un pla de gestió de les tortugues aquàtiques autòctones a l'espai natural (Emys orbicularis i Mauremys leprosa) | K2: Sí/No | L2: Àrea coordinació | M2: Tècnic coordinador | N2: Contractació externa | O2: Fons propis
A3: NATURA | B3: 1 | C3: CONSERVAR LA NATURA i restaurar els ecosistemes, els processos naturals i seminaturals, la biodiversitat i la geodiversitat associada. | D3: 01.1 | E3: Adequar i fer eficient la conservació dels elements objecte de gestió prioritària marcats per la DG a l'ENP | F3: 01.1.1 | G3: Implementar i executar plans de gestió específics per a hàbitats i espècies de conservació prioritària dins l'ENP | I3: Si | J3: Elaboració d'un pla de gestió per la conservació i millora de les nàiades de l'espai natural (Unio ravoisieri, Unio mancus, Potomida littoralis i Anodonta anotina) | K3: Sí/No | L3: Àrea coordinació | M3: Tècnic coordinador | N3: Contractació externa | O3: Fons propis
A4: NATURA | B4: 1 | C4: CONSERVAR LA NATURA i restaurar els ecosistemes, els processos naturals i seminaturals, la biodiversitat i la geodiversitat associada. | D4: 01.1 | E4: Adequar i fer eficient la conservació dels elements objecte de gestió prioritària marcats per la DG a l'ENP | F4: 01.1.1 | G4: Implementar i executar plans de gestió específics per a hàbitats i espècies de conservació prioritària dins l'ENP | I4: Si | J4: Elaboració d'un pla de gestió de la falguera dels pantans (Thelypteris palustris) | K4: Sí/No | L4: Àrea coordinació | M4: Tècnic coordinador | N4: Contractació externa | O4: Fons propis
A5: NATURA | B5: 1 | C5: CONSERVAR LA NATURA i restaurar els ecosistemes, els processos naturals i seminaturals, la biodiversitat i la geodiversitat associada. | D5: 01.2 | E5: Executar les mesures de gestió directa previstes en els instruments de planificació per la conservació i la gestió adaptativa dels elements clau de l'ENP | F5: 01.2.1 | G5: Implementar la metodologia de gestió adaptativa (Estàndards Oberts de Gestió Adaptativa a Catalunya) en tots els processos de l'ENP | I5: Si | J5: Redacció d'un protocol per tal d'incorporar la metodologia dels Estàndards Oberts pels processos més rellevants per a la conservació a l'espai | K5: Sí/No | L5: Intervenció | M5: Interventora
A6: NATURA | B6: 1 | C6: CONSERVAR LA NATURA i restaurar els ecosistemes, els processos naturals i seminaturals, la biodiversitat i la geodiversitat associada. | D6: 01.2 | E6: Executar les mesures de gestió directa previstes en els instruments de planificació per la conservació i la gestió adaptativa dels elements clau de l'ENP | F6: 01.2.2 | G6: Executar les mesures previstes en els plans de conservació o recuperació d'espècies amenaçades de forma coordinada amb el Servei de Flora i Fauna en l'àmbit de l'ENP | I6: No | J6: Implicació i participació en la redacció dels plans de conservació /recuperació d'espècies amenaçades | K6: Nombre de reunions | L6: Àrea coordinació | M6: Tècnic coordinador | N6: Mitjans propis | O6: Fons propis
A7: NATURA | B7: 1 | C7: CONSERVAR LA NATURA i restaurar els ecosistemes, els processos naturals i seminaturals, la biodiversitat i la geodiversitat associada. | D7: 01.2 | E7: Executar les mesures de gestió directa previstes en els instruments de planificació per la conservació i la gestió adaptativa dels elements clau de l'ENP | F7: 01.2.2 | G7: Executar les mesures previstes en els plans de conservació o recuperació d'espècies amenaçades de forma coordinada amb el Servei de Flora i Fauna en l'àmbit de l'ENP | I7: Si | J7: Execució de les accions dins els plans de recuperació/conservació aprovats que afectin l'espai | K7: Nombre d'accions executades | L7: Àrea coordinació | M7: Tècnic coordinador | N7: Contractació externa | O7: Subjecte a ajuts
A8: NATURA | B8: 1 | C8: CONSERVAR LA NATURA i restaurar els ecosistemes, els processos naturals i seminaturals, la biodiversitat i la geodiversitat associada. | D8: 01.2 | E8: Executar les mesures de gestió directa previstes en els instruments de planificació per la conservació i la gestió adaptativa dels elements clau de l'ENP | F8: 01.2.2 | G8: Executar les mesures previstes en els plans de conservació o recuperació d'espècies amenaçades de forma coordinada amb el Servei de Flora i Fauna en l'àmbit de l'ENP | I8: Si | J8: Col·laboració en l'obtenció de la informació necessària dins els espais per al desenvolupament dels Plans | K8: Sí/No | L8: Àrea coordinació | M8: Tècnic coordinador | N8: Mitjans propis | O8: Fons propis
A9: NATURA | B9: 1 | C9: CONSERVAR LA NATURA i restaurar els ecosistemes, els processos naturals i seminaturals, la biodiversitat i la geodiversitat associada. | D9: 01.2 | E9: Executar les mesures de gestió directa previstes en els instruments de planificació per la conservació i la gestió adaptativa dels elements clau de l'ENP | F9: 01.2.3 | G9: Executar les mesures de control d'EEI | I9: Si | J9: Redacció del Pla tècnic de control del coipú (Myocastor coypus) | K9: Sí/No | L9: Àrea coordinació | M9: Tècnic coordinador | N9: Mitjans propis | O9: Fons propis
A10: NATURA | B10: 1 | C10: CONSERVAR LA NATURA i restaurar els ecosistemes, els processos naturals i seminaturals, la biodiversitat i la geodiversitat associada. | D10: 01.2 | E10: Executar les mesures de gestió directa previstes en els instruments de planificació per la conservació i la gestió adaptativa dels elements clau de l'ENP | F10: 01.2.3 | G10: Executar les mesures de control d'EEI | I10: Si | J10: Execució del Pla tècnic de control del coipú (Myocastor coypus) | K10: Pla executat | L10: Àrea coordinació | M10: Tècnic coordinador | N10: Mitjans propis | O10: Fons propis
A11: NATURA | B11: 1 | C11: CONSERVAR LA NATURA i restaurar els ecosistemes, els processos naturals i seminaturals, la biodiversitat i la geodiversitat associada. | D11: 01.2 | E11: Executar les mesures de gestió directa previstes en els instruments de planificació per la conservació i la gestió adaptativa dels elements clau de l'ENP | F11: 01.2.3 | G11: Executar les mesures de control d'EEI | I11: Si | J11: Redacció del Pla tècnic de control de la tortugues exòtiques | K11: Sí/No | L11: Àrea coordinació | M11: Tècnic coordinador | N11: Mitjans propis | O11: Fons propis
A12: NATURA | B12: 1 | C12: CONSERVAR LA NATURA i restaurar els ecosistemes, els processos naturals i seminaturals, la biodiversitat i la geodiversitat associada. | D12: 01.2 | E12: Executar les mesures de gestió directa previstes en els instruments de planificació per la conservació i la gestió adaptativa dels elements clau de l'ENP | F12: 01.2.3 | G12: Executar les mesures de control d'EEI | I12: Si | J12: Redacció del Pla tècnic de control de la flora exòtica invasora problemàtica a l'EIN | K12: Sí/No | L12: Àrea coordinació | M12: Tècnic coordinador | N12: Mitjans propis | O12: Fons propis
A13: NATURA | B13: 1 | C13: CONSERVAR LA NATURA i restaurar els ecosistemes, els processos naturals i seminaturals, la biodiversitat i la geodiversitat associada. | D13: 01.2 | E13: Executar les mesures de gestió directa previstes en els instruments de planificació per la conservació i la gestió adaptativa dels elements clau de l'ENP | F13: 01.2.3 | G13: Executar les mesures de control d'EEI | I13: Si | J13: Redacció del Pla tècnic de control dels peixos exòtics | K13: Sí/No | L13: Àrea coordinació | M13: Tècnic coordinador | N13: Mitjans propis | O13: Fons propis
A14: NATURA | B14: 1 | C14: CONSERVAR LA NATURA i restaurar els ecosistemes, els processos naturals i seminaturals, la biodiversitat i la geodiversitat associada. | D14: 01.2 | E14: Executar les mesures de gestió directa previstes en els instruments de planificació per la conservació i la gestió adaptativa dels elements clau de l'ENP | F14: 01.2.3 | G14: Executar les mesures de control d'EEI | I14: No | J14: Obtenció de la informació necessària per avaluar el desenvolupament del pla tècnic de l'ENP | K14: Sí/No | L14: Àrea coordinació | M14: Tècnic coordinador | N14: Mitjans propis | O14: Fons propis
A15: NATURA | B15: 1 | C15: CONSERVAR LA NATURA i restaurar els ecosistemes, els processos naturals i seminaturals, la biodiversitat i la geodiversitat associada. | D15: 01.2 | E15: Executar les mesures de gestió directa previstes en els instruments de planificació per la conservació i la gestió adaptativa dels elements clau de l'ENP | F15: 01.2.3 | G15: Executar les mesures de control d'EEI | I15: Si | J15: Trasllat a la DG de la informació recollida en el procés d'execució dels plans tècnics de control de les espècies exòtiques | K15: Sí/No | L15: Àrea coordinació | M15: Tècnic coordinador | N15: Mitjans propis | O15: Fons propis
A16: NATURA | B16: 1 | C16: CONSERVAR LA NATURA i restaurar els ecosistemes, els processos naturals i seminaturals, la biodiversitat i la geodiversitat associada. | D16: 01.3 | E16: Crear ecosistemes complexes, resilients, i d'alta biodiversitat per garantir la recuperació dels processos ecosistèmics | F16: 01.3.1 | G16: Identificar espais pel foment de la dinàmica natural i l'aprofitament no extractiu | I16: Si | J16: Redacció d'un document d'Identificació d'espais pel foment de la renaturalització i restauració del patrimoni natural i del medi físic de l'ENP | K16: Sí/No | L16: Àrea coordinació | M16: Tècnic coordinador | N16: Mitjans propis | O16: Fons propis
A17: NATURA | B17: 1 | C17: CONSERVAR LA NATURA i restaurar els ecosistemes, els processos naturals i seminaturals, la biodiversitat i la geodiversitat associada. | D17: 01.3 | E17: Crear ecosistemes complexes, resilients, i d'alta biodiversitat per garantir la recuperació dels processos ecosistèmics | F17: 01.3.1 | G17: Identificar espais pel foment de la dinàmica natural i l'aprofitament no extractiu | I17: Si | J17: Execució de projectes de restauració per afavorir la conservació dels hàbitats i espècies d'interès a l'ENP | K17: Nombre de projectes | L17: Àrea coordinació | M17: Tècnic coordinador | N17: Contractació externa | O17: Subjecte a ajuts
... A22: NATURA | B22: 1 | C22: CONSERVAR LA NATURA i restaurar els ecosistemes, els processos naturals i seminaturals, la biodiversitat i la geodiversitat associada. | D22: 01.4 | E22: Alinear l'activitat de propietaris i gestors del territori amb la conservació, millora i restauració dels valors de l'ENP | F22: 01.4.2 | G22: Fomentar bones pràctiques entre els col·lectius de propietaris i gestors del territori | I22: Si | J22: Redacció d'un document tècnic pel foment de bones pràctiques en l'entrenament esportiu dins l'Estany de Banyoles | K22: Sí/No | L22: Àrea tècnica | M22: Tècnic/a | N22: Contractació externa | O22: Subjecte a ajuts
A23: NATURA | B23: 1 | C23: CONSERVAR LA NATURA i restaurar els ecosistemes, els processos naturals i seminaturals, la biodiversitat i la geodiversitat associada. | D23: 01.4 | E23: Alinear l'activitat de propietaris i gestors del territori amb la conservació, millora i restauració dels valors de l'ENP | F23: 01.4.3 | G23: Coordinar i gestionar les propietats públiques o en règim de custòdia de l'espai | H23: El Consorci de l'Estany té definit en els seus estatus la gestió de les finques públiques i en custòdia i ho realitza des de la seva creació. | I23: Si | J23: Gestió de les finques públiques i en règim de custòdia de l'ENPE | K23: Sí/No | L23: Àrea coordinació | M23: Tècnic coordinador | N23: Contractació externa i mitjans propis | O23: Fons propis
A24: NATURA | B24: 2 | C24: ADAPTAR ELS ECOSISTEMES AL CANVI CLIMÀTIC i millorar-ne la resiliència en front dels riscos associats. | D24: 02.1 | E24: Planificar l'adaptació dels sistemes naturals al canvi climàtic | F24: 02.1.2 | G24: Gestionar i planificar els recursos hídrics de l'ENP | I24: Si | J24: Assistència a reunions amb els òrgans competents de gestió de l'aigua (Ajuntament de Banyoles i ACA) aportant directrius de conservació del patrimoni natural i del medi físic | K24: Nombre de reunions | L24: Àrea coordinació | M24: Tècnic coordinador | N24: Mitjans propis | O24: Fons propis
A25: NATURA | B25: 2 | C25: ADAPTAR ELS ECOSISTEMES AL CANVI CLIMÀTIC i millorar-ne la resiliència en front dels riscos associats. | D25: 02.1 | E25: Planificar l'adaptació dels sistemes naturals al canvi climàtic | F25: 02.1.3 | G25: Participar en la redacció i execució dels instruments d'ordenació forestal sostenible i per la conservació en finques públiques | I25: Si | J25: Redacció d'Instrument d'Ordenació Forestal de la finca del Torrent Mal | K25: Sí/No | L25: Àrea tècnica | M25: Tècnic/a | N25: Contractació externa | O25: Fons propis
A26: NATURA | B26: 2 | C26: ADAPTAR ELS ECOSISTEMES AL CANVI CLIMÀTIC i millorar-ne la resiliència en front dels riscos associats. | D26: 02.2 | E26: Planificar la prevenció i extinció d’incendis forestals i la gestió del foc de forma coordinada amb els diferents agents del territori | F26: 02.2.3 | G26: Treballar per a la prevenció d'incendis juntament amb els propietaris, ajuntaments, protecció civil, ADF i bombers. | I26: Si | J26: Assistència i participació en meses de decisió per la prevenció d'incendis | K26: Nombre de reunions | L26: Direcció | M26: Director | N26: Mitjans propis | O26: Fons propis
A27: NATURA | B27: 3 | C27: PROTEGIR LA BIODIVERSITAT, i especialment els elements fràgils i amenaçats, d’interès comunitari o de major interès natural. | D27: 03.1 | E27: Prevenir, minimitzar i compensar els impactes ambientals dels usos i activitats que es desenvolupin en l'àmbit de l'ENP | F27: 03.1.1 | G27: Participar en les consultes dels processos d'Avaluació Ambiental que afectin directament o indirectament l’espai del ENP | I27: Si | J27: Assistència a reunions tècniques amb l'equip de la Oficina Territorial d'Acció i Avaluació Ambiental dels Serveis Territorial de Girona i si s'escau, redacció d'informes | K27: Sí/No | L27: Àrea coordinació | M27: Tècnic coordinador | N27: Mitjans propis | O27: Fons propis
A28: NATURA | B28: 3 | C28: PROTEGIR LA BIODIVERSITAT, i especialment els elements fràgils i amenaçats, d’interès comunitari o de major interès natural. | D28: 03.1 | E28: Prevenir, minimitzar i compensar els impactes ambientals dels usos i activitats que es desenvolupin en l'àmbit de l'ENP | F28: 03.1.2 | G28: Exercir un seguiment efectiu de les obres al Parc juntament amb les Oficines Territorials d'Acció i Avaluació Ambiental als efectes d'assegurar la correcta translació de la tutela administrativa. | I28: Si | J28: Realització de visites als treballs informats per l'òrgan de gestió, en coordinació amb l'Oficina Territorial d'Avaluació Ambiental | K28: Nombre de visites d'inspecció relacionades amb els informes | L28: Àrea coordinació | M28: Tècnic coordinador | N28: Mitjans propis | O28: Fons propis
A29: NATURA | B29: 3 | C29: PROTEGIR LA BIODIVERSITAT, i especialment els elements fràgils i amenaçats, d’interès comunitari o de major interès natural. | D29: 03.2 | E29: Garantir el compliment dels objectius de conservació dotant l'ENP de la planificació adequada segons estableix la normativa vigent (Pla de Protecció, PRUG, plans específics...) | F29: 03.2.1 | G29: Participar en l'elaboració dels instruments de planificació de l'ENP | H29: No estem d'acord en que aquest objectiu operatiu es trobi en aquest apartat. Hauria d'estar a l'EIX de Gestió i Administració dins l'OBJECTIU general 15 i amb un nou objectiu estratègic 15.0 | I29: Si | J29: Realització de reunions tècniques amb el Servei de Planificació d'Espais Naturals de la Generalitat de Catalunya per l'elaboració d'instruments de planificació de l'ENP | K29: Nombre de reunions | L29: Direcció | M29: Director | N29: Mitjans propis | O29: Fons propis
A30: NATURA | B30: 3 | C30: PROTEGIR LA BIODIVERSITAT, i especialment els elements fràgils i amenaçats, d’interès comunitari o de major interès natural. | D30: 03.3 | E30: Vetllar pel manteniment dels cabals ecològics i la bona qualitat dels cursos fluvials de l'ENP de forma coordinada amb l'administració competent | F30: 03.3.1 | G30: Vetllar pel manteniment ecològic dels recs i rieres del Pla sectorial corresponent | H30: Text adaptat a l'espai natural | I30: No | J30: Realització de reunions amb la Comissió Tècnica per la gestió de l'aigua a l'Estany de Banyoles | K30: Nombre de reunions | L30: Àrea coordinació | M30: Tècnic coordinador | N30: Mitjans propis | O30: Fons propis
A31: NATURA | B31: 3 | C31: PROTEGIR LA BIODIVERSITAT, i especialment els elements fràgils i amenaçats, d’interès comunitari o de major interès natural. | D31: 03.3 | E31: Vetllar pel manteniment dels cabals ecològics i la bona qualitat dels cursos fluvials de l'ENP de forma coordinada amb l'administració competent | F31: 03.3.1 | G31: Vetllar pel manteniment ecològic dels recs i rieres del Pla sectorial corresponent | H31: Text adaptat a l'espai natural | I31: Si | J31: Realització del seguiment del cabal en els trams d'interès per la flora i la fauna dins l'ENP en situacions de sequera | K31: Sí/No | L31: Àrea tècnica | M31: Tècnic/a | N31: Mitjans propis | O31: Fons propis
A32: NATURA | B32: 3 | C32: PROTEGIR LA BIODIVERSITAT, i especialment els elements fràgils i amenaçats, d’interès comunitari o de major interès natural. | D32: 03.4 | E32: Incrementar el patrimoni públic destinat a la conservació i millora del patrimoni natural | F32: 03.4.1 | G32: Identificar espais prioritaris per a la compra de terrenys de més valor dins l'ENP | I32: Si | J32: Elaboració d'un catàleg de finques d'interès per a la conservació i/o renaturalització | K32: Sí/No | L32: Àrea tècnica | M32: Tècnic/a | N32: Mitjans propis | O32: Fons propis
A33: NATURA | B33: 3 | C33: PROTEGIR LA BIODIVERSITAT, i especialment els elements fràgils i amenaçats, d’interès comunitari o de major interès natural. | D33: 03.4 | E33: Incrementar el patrimoni públic destinat a la conservació i millora del patrimoni natural | F33: 03.4.2 | G33: Identificar espais prioritaris per a la gestió directa | I33: Si | J33: Redacció d'un inventari de finques públiques i conveniades del Consorci de l'Estany i establir els objectius generals de gestió directa | K33: Sí/No | L33: Àrea tècnica | M33: Tècnic/a | N33: Mitjans propis | O33: Fons propis
A34: CULTURA | B34: 4 | C34: CONSERVAR ELS ELEMENTS CULTURALS materials i immaterials vinculats a la natura | D34: 04.4 | E34: Donar a conèixer els elements culturals com a valors del paisatge de l'ENP en les activitats d'ús públic | F34: 04.4.2 | G34: Incorporar el patrimoni cultural en els plans d’ús públic i educació ambiental per fomentar-ne la seva conservació i divulgació. | I34: Si | J34: Consideració del patrimoni cultural el les activitats d' educació ambiental per fomentar-ne la seva conservació i divulgació. | K34: Sí/No | L34: Àrea tècnica | M34: Tècnic/a | N34: Mitjans propis | O34: Fons propis
A35: CULTURA | B35: 5 | C35: PROTEGIR EL PAISATGE i la qualitat de l'ambient visual, sonor i lumínic. | D35: 05.2 | E35: Millorar la qualitat paisatgística | F35: 05.2.3 | G35: Minimitzar la brutícia, deixalles, vandalisme i males praxis dins l'ENP | H35: Objectiu no necessari en aquest eix. Cal traslladar-lo a mala praxis a l'eix de ús públic | I35: Si | J35: Reforç de la senyalització si es detecten punts conflictius | K35: Sí/No | L35: Àrea tècnica | M35: Tècnic/a | N35: Mitjans propis | O35: Fons propis
A36: CONEIXEMENT | B36: 6 | C36: MILLORAR EL CONEIXEMENT DE L'ENTORN, del patrimoni natural, cultural i social. | D36: 06.1 | E36: Identificar els objectes de gestió prioritària de l'ENP en el marc dels objectius de govern | F36: 06.1.1 | G36: Identificar i prioritzar els elements clau i d'interès per la gestió de la biodiversitat i geodiversitat de Catalunya es troben dins l'ENP (especies amenaçades, espècies exòtiques invasores,.. ) | H36: Depèn dels Serveis Centrals de la Direcció general si ens conviden a participar | I36: No | J36: Participació en la definició dels objectes de conservació clau (hàbitats, espècies, processos i elements d’interès geològic) comuns a nivell de Xarxa d'ENP o clúster territorial | K36: Nombre de reunions | L36: Àrea coordinació | M36: Tècnic coordinador | N36: Mitjans propis | O36: Fons propis
A37: CONEIXEMENT | B37: 6 | C37: MILLORAR EL CONEIXEMENT DE L'ENTORN, del patrimoni natural, cultural i social. | D37: 06.1 | E37: Identificar els objectes de gestió prioritària de l'ENP en el marc dels objectius de govern | F37: 06.1.1 | G37: Identificar i prioritzar els elements clau i d'interès per la gestió de la biodiversitat i geodiversitat de Catalunya es troben dins l'ENP (especies amenaçades, espècies exòtiques invasores,.. ) | I37: Si | J37: Elaboració de l'inventari de fauna de l'ENP | K37: Sí/No | L37: Àrea tècnica | M37: Tècnic/a | N37: Mitjans propis | O37: Fons propis
A38: CONEIXEMENT | B38: 6 | C38: MILLORAR EL CONEIXEMENT DE L'ENTORN, del patrimoni natural, cultural i social. | D38: 06.2 | E38: Conèixer l'estat de conservació i la seva tendència dels hàbitats, les espècies els elements de la gea i els processos ecològics com a eina per avaluar i optimitzar la gestió | F38: 06.2.1 | G38: Participar en l'elaboració de la cartografia que elabora la UIC | I38: Si | J38: Trasllat de la informació a través de seguiments del elements clau i altres d'espècies i hàbitats d'interès per la gestió a la UIC | K38: Sí/No | L38: Àrea tècnica | M38: Tècnic/a | N38: Mitjans propis | O38: Fons propis
A39: CONEIXEMENT | B39: 6 | C39: MILLORAR EL CONEIXEMENT DE L'ENTORN, del patrimoni natural, cultural i social. | D39: 06.2 | E39: Conèixer l'estat de conservació i la seva tendència dels hàbitats, les espècies els elements de la gea i els processos ecològics com a eina per avaluar i optimitzar la gestió | F39: 06.2.2 | G39: Conèixer i estudiar els processos naturals propis de l’espai, la seva funcionalitat, i ecologia en referència als ecosistemes | I39: Si | J39: Foment i coordinació dels estudis el règim hidrològic, la pol·linització, la tipificació i funcionament de les cadenes tròfiques pròpies de l’espai | K39: Nombre d'estudis | L39: Àrea tècnica | M39: Tècnic/a | N39: Mitjans propis | O39: Fons propis
A40: CONEIXEMENT | B40: 6 | C40: MILLORAR EL CONEIXEMENT DE L'ENTORN, del patrimoni natural, cultural i social. | D40: 06.2 | E40: Conèixer l'estat de conservació i la seva tendència dels hàbitats, les espècies els elements de la gea i els processos ecològics com a eina per avaluar i optimitzar la gestió | F40: 06.2.2 | G40: Conèixer i estudiar els processos naturals propis de l’espai, la seva funcionalitat, i ecologia en referència als ecosistemes | I40: Si | J40: Actualització del protocol d’índex ecològics de les diferents masses d’aigua | K40: Sí/No | L40: Àrea coordinació | M40: Tècnic coordinador | N40: Contractació externa | O40: Fons propis
A41: CONEIXEMENT | B41: 6 | C41: MILLORAR EL CONEIXEMENT DE L'ENTORN, del patrimoni natural, cultural i social. | D41: 06.2 | E41: Conèixer l'estat de conservació i la seva tendència dels hàbitats, les espècies els elements de la gea i els processos ecològics com a eina per avaluar i optimitzar la gestió | F41: 06.2.3 | G41: Conèixer els usos i factors de canvi rellevants en l'evolució dels elements de conservació, i avaluar els efectes que generen en l’espai (pressions i amenaces) | I41: Si | J41: Realització d'un estudi d'avaluació de l'impacte del canvi climàtic en l'ENP i la seva capacitat d'adaptació i resiliència | K41: Sí/No | L41: Àrea tècnica | M41: Tècnic/a | N41: Contractació externa | O41: Fons propis
A42: CONEIXEMENT | B42: 6 | C42: MILLORAR EL CONEIXEMENT DE L'ENTORN, del patrimoni natural, cultural i social. | D42: 06.2 | E42: Conèixer l'estat de conservació i la seva tendència dels hàbitats, les espècies els elements de la gea i els processos ecològics com a eina per avaluar i optimitzar la gestió | F42: 06.2.5 | G42: Participar en el coneixement de la tendència d'espècies plaga amb afectacions sobre ecosistemes o activitats econòmiques dins l'ENP | I42: Si | J42: Seguiment de les poblacions de gavians a l'ENP | K42: Sí/No | L42: Àrea tècnica | M42: Tècnic/a | N42: Mitjans propis | O42: Altres aportacions
A43: CONEIXEMENT | B43: 6 | C43: MILLORAR EL CONEIXEMENT DE L'ENTORN, del patrimoni natural, cultural i social. | D43: 06.2 | E43: Conèixer l'estat de conservació i la seva tendència dels hàbitats, les espècies els elements de la gea i els processos ecològics com a eina per avaluar i optimitzar la gestió | F43: 06.2.6 | G43: Conèixer la tendència d'espècies exòtiques invasores amb afectacions sobre ecosistemes o activitats econòmiques dins l'ENP | I43: Si | J43: Planificació d'estudis de forma coordinada amb el Servei Fauna i Flora | K43: Nombre de reunions | L43: Àrea coordinació | M43: Tècnic coordinador | N43: Mitjans propis | O43: Fons propis
A44: CONEIXEMENT | B44: 6 | C44: MILLORAR EL CONEIXEMENT DE L'ENTORN, del patrimoni natural, cultural i social. | D44: 06.3 | E44: Estandarditzar els seguiments periòdics dels grups clau | F44: 06.3.1 | G44: Participar en la definició del sistema estàndard de seguiment de flora, fauna i hàbitats de la DG | I44: No | J44: Assistència a reunions de coordinació amb la UIC per la definició dels sistemes de seguiment | K44: Nombre de reunions | L44: Àrea coordinació | M44: Tècnic coordinador | N44: Mitjans propis | O44: Fons propis
...

Sheet PLA (2)
A1: EIXOS | B1: Id_OG | C1: OBJECTIUS Generals (PP) | D1: Id_OE | E1: OBJECTIUS Estratègics | F1: Id_OO | G1: OBJECTIUS operatius / Línia estratègica | H1: Comú / Específic | I1: Obligatori / Optatiu | J1: Objectiu operatiu concret a l'espai | K1: Explicació de la decisió presa en el cas de canvis respecte al llistat inicial (columna G) | L1: Objectiu amb mesures incorporables a la planificació anual de la gestió de l'espai? | M1: Prioritat | N1: Ordre | O1: Propostes d'accions | P1: Marc de referència | Q1: Resultats derivats | R1: Indicadors | S1: Mínima | T1: Màxim (Desitjable) | U1: Hores de dedicació (hores/anuals) | V1: Total període hores | W1: Àrea responsable | X1: Persona responsable | Y1: Contractació externa o mitjans propis | Z1: Finançament | AA1: 2026 | AB1: 2027 | AC1: 2028 | AD1: 2029
A2: Eix 01 - Natura | B2: OG 01 | C2: CONSERVAR LA NATURA i restaurar els ecosistemes, els processos naturals i seminaturals, la biodiversitat i la geodiversitat associada. | D2: 01.1 | E2: Adequar i fer eficient la conservació dels elements objecte de gestió prioritària marcats per la DG a l'ENP | F2: 01.1.1 | G2: Implementar i executar plans de gestió específics per a hàbitats i espècies de conservació prioritària dins l'ENP | H2: Comú | I2: Obligatori | J2: Implementar i executar plans de gestió específics per a hàbitats i espècies de conservació prioritària dins l'ENP. | L2: Si | M2: Baixa | O2: Elaboració d'un pla de gestió de les tortugues aquàtiques autòctones a l'espai natural (Emys orbicularis i Mauremys leprosa). | R2: Sí/No | T2: Sí | V2: =U2*4 -> 0 | W2: Àrea coordinació | X2: =IF(W2=Llistes!$B$18,Llistes!$D$18,IF(W2=Llistes!$B$20,Llistes!$D$20,IF(W2=Llistes!$B$22,Llistes!$D$22,IF(W2=Llistes!$B$23,Llistes!$D$23,IF(W2=Llistes!$B$24,Llistes!$D$24,IF(W2=Llistes!$B$28,Llistes!$D$28)))))) -> Tècnic coordinador | Y2: Contractació externa | Z2: Fons propis | AC2: X
A3: Eix 01 - Natura | B3: OG 01 | C3: CONSERVAR LA NATURA i restaurar els ecosistemes, els processos naturals i seminaturals, la biodiversitat i la geodiversitat associada. | D3: 01.1 | E3: Adequar i fer eficient la conservació dels elements objecte de gestió prioritària marcats per la DG a l'ENP | F3: 01.1.1 | G3: Implementar i executar plans de gestió específics per a hàbitats i espècies de conservació prioritària dins l'ENP | H3: Comú | I3: Obligatori | J3: Implementar i executar plans de gestió específics per a hàbitats i espècies de conservació prioritària dins l'ENP. | L3: Si | M3: Alta | O3: Elaboració d'un pla de gestió per la conservació i millora de les nàiades de l'espai natural (Unio ravoisieri, Unio mancus, Potomida littoralis i Anodonta anotina). | R3: Sí/No | T3: Sí | V3: =U3*4 -> 0 | W3: Àrea coordinació | X3: =IF(W3=Llistes!$B$18,Llistes!$D$18,IF(W3=Llistes!$B$20,Llistes!$D$20,IF(W3=Llistes!$B$22,Llistes!$D$22,IF(W3=Llistes!$B$23,Llistes!$D$23,IF(W3=Llistes!$B$24,Llistes!$D$24,IF(W3=Llistes!$B$28,Llistes!$D$28)))))) -> Tècnic coordinador | Y3: Contractació externa | Z3: Fons propis | AA3: X
A4: Eix 01 - Natura | B4: OG 01 | C4: CONSERVAR LA NATURA i restaurar els ecosistemes, els processos naturals i seminaturals, la biodiversitat i la geodiversitat associada. | D4: 01.1 | E4: Adequar i fer eficient la conservació dels elements objecte de gestió prioritària marcats per la DG a l'ENP | F4: 01.1.1 | G4: Implementar i executar plans de gestió específics per a hàbitats i espècies de conservació prioritària dins l'ENP | H4: Comú | I4: Obligatori | J4: Implementar i executar plans de gestió específics per a hàbitats i espècies de conservació prioritària dins l'ENP. | L4: Si | M4: Alta | O4: Elaboració d'un pla de gestió de la falguera dels pantans (Thelypteris palustris). | R4: Sí/No | T4: Sí | V4: =U4*4 -> 0 | W4: Àrea coordinació | X4: =IF(W4=Llistes!$B$18,Llistes!$D$18,IF(W4=Llistes!$B$20,Llistes!$D$20,IF(W4=Llistes!$B$22,Llistes!$D$22,IF(W4=Llistes!$B$23,Llistes!$D$23,IF(W4=Llistes!$B$24,Llistes!$D$24,IF(W4=Llistes!$B$28,Llistes!$D$28)))))) -> Tècnic coordinador | Y4: Contractació externa | Z4: Fons propis | AB4: X
A5: Eix 01 - Natura | B5: OG 01 | C5: CONSERVAR LA NATURA i restaurar els ecosistemes, els processos naturals i seminaturals, la biodiversitat i la geodiversitat associada. | D5: 01.1 | E5: Adequar i fer eficient la conservació dels elements objecte de gestió prioritària marcats per la DG a l'ENP | F5: 01.1.1 | G5: Implementar i executar plans de gestió específics per a hàbitats i espècies de conservació prioritària dins l'ENP | H5: Comú | I5: Obligatori | J5: Implementar i executar plans de gestió específics per a hàbitats i espècies de conservació prioritària dins l'ENP. | L5: Si | M5: Alta | O5: Elaboració d'un pla de gestió de Carex elata. | R5: Sí/No | T5: Sí | V5: =U5*4 -> 0 | W5: Àrea coordinació | X5: =IF(W5=Llistes!$B$18,Llistes!$D$18,IF(W5=Llistes!$B$20,Llistes!$D$20,IF(W5=Llistes!$B$22,Llistes!$D$22,IF(W5=Llistes!$B$23,Llistes!$D$23,IF(W5=Llistes!$B$24,Llistes!$D$24,IF(W5=Llistes!$B$28,Llistes!$D$28)))))) -> Tècnic coordinador | Y5: Contractació externa | Z5: Fons propis | AC5: X
A6: Eix 01 - Natura | B6: OG 01 | C6: CONSERVAR LA NATURA i restaurar els ecosistemes, els processos naturals i seminaturals, la biodiversitat i la geodiversitat associada. | D6: 01.1 | E6: Adequar i fer eficient la conservació dels elements objecte de gestió prioritària marcats per la DG a l'ENP | F6: 01.1.1 | G6: Implementar i executar plans de gestió específics per a hàbitats i espècies de conservació prioritària dins l'ENP | H6: Comú | I6: Obligatori | J6: Implementar i executar plans de gestió específics per a hàbitats i espècies de conservació prioritària dins l'ENP. | L6: Si | M6: Alta | O6: Elaboració d'un pla de gestió de potamogèton perfoliat (Potamogeton perfoliatus). | P6: MAP | Q6: SFF: Elaboració de plans de gestió específics per a espècies de conservació prioritària i directrius de gestió d'hàbitats. SFF/SENP: Definir a nivell de cluster quins son els que es poden elaborar conjuntament. | R6: Sí/No | T6: Sí | V6: =U6*4 -> 0 | W6: Àrea coordinació | X6: =IF(W6=Llistes!$B$18,Llistes!$D$18,IF(W6=Llistes!$B$20,Llistes!$D$20,IF(W6=Llistes!$B$22,Llistes!$D$22,IF(W6=Llistes!$B$23,Llistes!$D$23,IF(W6=Llistes!$B$24,Llistes!$D$24,IF(W6=Llistes!$B$28,Llistes!$D$28)))))) -> Tècnic coordinador | Y6: Contractació externa | Z6: Fons propis | AC6: X
A7: Eix 01 - Natura | B7: OG 01 | C7: CONSERVAR LA NATURA i restaurar els ecosistemes, els processos naturals i seminaturals, la biodiversitat i la geodiversitat associada. | D7: 01.1 | E7: Adequar i fer eficient la conservació dels elements objecte de gestió prioritària marcats per la DG a l'ENP | F7: 01.1.1 | G7: Implementar i executar plans de gestió específics per a hàbitats i espècies de conservació prioritària dins l'ENP | H7: Comú | I7: Obligatori | J7: Implementar i executar plans de gestió específics per a hàbitats i espècies de conservació prioritària dins l'ENP. | L7: Si | M7: Alta | O7: Elaboració d'un pla de gestió dels microcargols Vertigo moulinsiana i Vertigo angustior. | R7: Sí/No | T7: Sí | V7: =U7*4 -> 0 | W7: Àrea coordinació | X7: =IF(W7=Llistes!$B$18,Llistes!$D$18,IF(W7=Llistes!$B$20,Llistes!$D$20,IF(W7=Llistes!$B$22,Llistes!$D$22,IF(W7=Llistes!$B$23,Llistes!$D$23,IF(W7=Llistes!$B$24,Llistes!$D$24,IF(W7=Llistes!$B$28,Llistes!$D$28)))))) -> Tècnic coordinador | Y7: Contractació externa | Z7: Fons propis | AC7: X
A8: Eix 01 - Natura | B8: OG 01 | C8: CONSERVAR LA NATURA i restaurar els ecosistemes, els processos naturals i seminaturals, la biodiversitat i la geodiversitat associada. | D8: 01.1 | E8: Adequar i fer eficient la conservació dels elements objecte de gestió prioritària marcats per la DG a l'ENP | F8: 01.1.1 | G8: Implementar i executar plans de gestió específics per a hàbitats i espècies de conservació prioritària dins l'ENP | H8: Comú | I8: Obligatori | J8: Implementar i executar plans de gestió específics per a hàbitats i espècies de conservació prioritària dins l'ENP. | L8: Si | M8: Alta | O8: Elaboració d'un pla de gestió de peixos autòctons protegits (Barbus meridionalis, Salariopsis fluviatilis i Gasterosteus aculeatus) i altres d'interès per a les nàiades. | R8: Sí/No | T8: Si | V8: 0 | W8: Àrea coordinació | X8: =IF(W8=Llistes!$B$18,Llistes!$D$18,IF(W8=Llistes!$B$20,Llistes!$D$20,IF(W8=Llistes!$B$22,Llistes!$D$22,IF(W8=Llistes!$B$23,Llistes!$D$23,IF(W8=Llistes!$B$24,Llistes!$D$24,IF(W8=Llistes!$B$28,Llistes!$D$28)))))) -> Tècnic coordinador | Y8: Mitjans propis | Z8: Fons propis | AB8: X
A9: Eix 01 - Natura | B9: OG 01 | C9: CONSERVAR LA NATURA i restaurar els ecosistemes, els processos naturals i seminaturals, la biodiversitat i la geodiversitat associada. | D9: 01.1 | E9: Adequar i fer eficient la conservació dels elements objecte de gestió prioritària marcats per la DG a l'ENP | F9: 01.1.2 | G9: Adaptar i executar plans de gestió específics per a elements geològics de conservació prioritària dins l'ENP | H9: Comú | I9: Obligatori | J9: Adaptar i executar plans de gestió específics per a elements geològics de conservació prioritària dins l'ENP. | L9: Si | M9: Mitjana | O9: Aplicació de les directrius de gestió de l'inventari de patrimoni geològic (ICGC). | R9: Sí/No | T9: Sí | V9: =U9*4 -> 0 | W9: Àrea coordinació | X9: =IF(W9=Llistes!$B$18,Llistes!$D$18,IF(W9=Llistes!$B$20,Llistes!$D$20,IF(W9=Llistes!$B$22,Llistes!$D$22,IF(W9=Llistes!$B$23,Llistes!$D$23,IF(W9=Llistes!$B$24,Llistes!$D$24,IF(W9=Llistes!$B$28,Llistes!$D$28)))))) -> Tècnic coordinador | Y9: Mitjans propis | Z9: Fons propis | AC9: X
A10: Eix 01 - Natura | B10: OG 01 | C10: CONSERVAR LA NATURA i restaurar els ecosistemes, els processos naturals i seminaturals, la biodiversitat i la geodiversitat associada. | D10: 01.2 | E10: Executar les mesures de gestió directa previstes en els instruments de planificació per la conservació i la gestió adaptativa dels elements clau de l'ENP | F10: 01.2.1 | G10: Implementar la metodologia de gestió adaptativa (Estàndards Oberts de Gestió Adaptativa a Catalunya) en tots els processos de l'ENP | H10: Comú | I10: Obligatori | J10: Implementar la metodologia de gestió adaptativa (Estàndards Oberts de Gestió Adaptativa a Catalunya) en tots els processos de l'ENP. | L10: Si | M10: Màxima | O10: Redacció d'un protocol per tal d'incorporar la metodologia dels Estàndards Oberts pels processos més rellevants per a la conservació a l'espai. | P10: ESNATURA | Q10: SENP: Elaboració d'un manual per la implementació dels OSAM | R10: Sí/No | T10: Sí | V10: =U10*4 -> 0 | W10: Intervenció | X10: =IF(W10=Llistes!$B$18,Llistes!$D$18,IF(W10=Llistes!$B$20,Llistes!$D$20,IF(W10=Llistes!$B$22,Llistes!$D$22,IF(W10=Llistes!$B$23,Llistes!$D$23,IF(W10=Llistes!$B$24,Llistes!$D$24,IF(W10=Llistes!$B$28,Llistes!$D$28)))))) -> Interventora | AB10: X
A11: Eix 01 - Natura | B11: OG 01 | C11: CONSERVAR LA NATURA i restaurar els ecosistemes, els processos naturals i seminaturals, la biodiversitat i la geodiversitat associada. | D11: 01.2 | E11: Executar les mesures de gestió directa previstes en els instruments de planificació per la conservació i la gestió adaptativa dels elements clau de l'ENP | F11: 01.2.1 | G11: Implementar la metodologia de gestió adaptativa (Estàndards Oberts de Gestió Adaptativa a Catalunya) en tots els processos de l'ENP | H11: Comú | I11: Obligatori | J11: Implementar la metodologia de gestió adaptativa (Estàndards Oberts de Gestió Adaptativa a Catalunya) en tots els processos de l'ENP. | L11: Si | M11: Màxima | O11: Implementació del protocol per tal d'incorporar la metodologia dels Estàndards Oberts de Gestió Adaptativa a Catalunya pels processos més rellevants per a la conservació a l'ENP. | R11: Sí/No | T11: Sí | V11: =U11*4 -> 0
A12: Eix 01 - Natura | B12: OG 01 | C12: CONSERVAR LA NATURA i restaurar els ecosistemes, els processos naturals i seminaturals, la biodiversitat i la geodiversitat associada. | D12: 01.2 | E12: Executar les mesures de gestió directa previstes en els instruments de planificació per la conservació i la gestió adaptativa dels elements clau de l'ENP | F12: 01.2.2 | G12: Executar les mesures previstes en els plans de conservació o recuperació d'espècies amenaçades de forma coordinada amb el Servei de Flora i Fauna en l'àmbit de l'ENP | H12: Comú | I12: Obligatori | J12: Executar les mesures previstes en els plans de conservació o recuperació d'espècies amenaçades de forma coordinada amb el Servei de Flora i Fauna en l'àmbit de l'ENP. | L12: No | M12: Màxima | O12: Implicació i participació en la redacció dels plans de conservació /recuperació d'espècies amenaçades. | R12: Nombre de reunions | S12: 2 | T12: 4 | V12: =U12*4 -> 0 | W12: Àrea coordinació | X12: =IF(W12=Llistes!$B$18,Llistes!$D$18,IF(W12=Llistes!$B$20,Llistes!$D$20,IF(W12=Llistes!$B$22,Llistes!$D$22,IF(W12=Llistes!$B$23,Llistes!$D$23,IF(W12=Llistes!$B$24,Llistes!$D$24,IF(W12=Llistes!$B$28,Llistes!$D$28)))))) -> Tècnic coordinador | Y12: Mitjans propis | Z12: Fons propis | AA12: X | AB12: X | AC12: X | AD12: X
A13: Eix 01 - Natura | B13: OG 01 | C13: CONSERVAR LA NATURA i restaurar els ecosistemes, els processos naturals i seminaturals, la biodiversitat i la geodiversitat associada. | D13: 01.2 | E13: Executar les mesures de gestió directa previstes en els instruments de planificació per la conservació i la gestió adaptativa dels elements clau de l'ENP | F13: 01.2.2 | G13: Executar les mesures previstes en els plans de conservació o recuperació d'espècies amenaçades de forma coordinada amb el Servei de Flora i Fauna en l'àmbit de l'ENP | H13: Comú | I13: Obligatori | J13: Executar les mesures previstes en els plans de conservació o recuperació d'espècies amenaçades de forma coordinada amb el Servei de Flora i Fauna en l'àmbit de l'ENP. | L13: Si | M13: Màxima | O13: Execució de les accions dins els plans de recuperació/conservació aprovats que afectin l'ENP. | R13: Nombre d'accions executades | S13: 1 | T13: 3 | V13: =U13*4 -> 0 | W13: Àrea coordinació | X13: =IF(W13=Llistes!$B$18,Llistes!$D$18,IF(W13=Llistes!$B$20,Llistes!$D$20,IF(W13=Llistes!$B$22,Llistes!$D$22,IF(W13=Llistes!$B$23,Llistes!$D$23,IF(W13=Llistes!$B$24,Llistes!$D$24,IF(W13=Llistes!$B$28,Llistes!$D$28)))))) -> Tècnic coordinador | Y13: Contractació externa | Z13: Subjecte a ajuts | AB13: X | AC13: X | AD13: X
A14: Eix 01 - Natura | B14: OG 01 | C14: CONSERVAR LA NATURA i restaurar els ecosistemes, els processos naturals i seminaturals, la biodiversitat i la geodiversitat associada. | D14: 01.2 | E14: Executar les mesures de gestió directa previstes en els instruments de planificació per la conservació i la gestió adaptativa dels elements clau de l'ENP | F14: 01.2.2 | G14: Executar les mesures previstes en els plans de conservació o recuperació d'espècies amenaçades de forma coordinada amb el Servei de Flora i Fauna en l'àmbit de l'ENP | H14: Comú | I14: Obligatori | J14: Executar les mesures previstes en els plans de conservació o recuperació d'espècies amenaçades de forma coordinada amb el Servei de Flora i Fauna en l'àmbit de l'ENP. | L14: Si | M14: Màxima | O14: Col·laboració en l'obtenció de la informació necessària dins l'ENP per al desenvolupament dels Plans de Conservació i Recuperació d'espècies amenaçades. | P14: MAP Catàlegs | Q14: SFF: Elaboració de plans de conservació o recuperació d'espècies protegides | R14: Sí/No | T14: Sí | V14: =U14*4 -> 0 | W14: Àrea coordinació | X14: =IF(W14=Llistes!$B$18,Llistes!$D$18,IF(W14=Llistes!$B$20,Llistes!$D$20,IF(W14=Llistes!$B$22,Llistes!$D$22,IF(W14=Llistes!$B$23,Llistes!$D$23,IF(W14=Llistes!$B$24,Llistes!$D$24,IF(W14=Llistes!$B$28,Llistes!$D$28)))))) -> Tècnic coordinador | Y14: Mitjans propis | Z14: Fons propis | AA14: X | AB14: X | AC14: X | AD14: X
A15: Eix 01 - Natura | B15: OG 01 | C15: CONSERVAR LA NATURA i restaurar els ecosistemes, els processos naturals i seminaturals, la biodiversitat i la geodiversitat associada. | D15: 01.2 | E15: Executar les mesures de gestió directa previstes en els instruments de planificació per la conservació i la gestió adaptativa dels elements clau de l'ENP | F15: 01.2.3 | G15: Executar les mesures de gestió previstes en els plans de control i erradicació d'espècies exòtiques de forma coordinada amb el Servei de Flora i Fauna en l'àmbit de l'ENP | H15: Comú | I15: Obligatori | J15: Executar les mesures de gestió previstes en els plans de control i eradicació d'espècies exòtiques de forma coordinada amb el Servei de Flora i Fauna en l'àmbit de l'ENP | L15: Si | M15: Màxima | O15: Redacció del Pla tècnic de control del coipú (Myocastor coypus). | R15: Sí/No | T15: Sí | V15: =U15*4 -> 0 | W15: Àrea coordinació | X15: =IF(W15=Llistes!$B$18,Llistes!$D$18,IF(W15=Llistes!$B$20,Llistes!$D$20,IF(W15=Llistes!$B$22,Llistes!$D$22,IF(W15=Llistes!$B$23,Llistes!$D$23,IF(W15=Llistes!$B$24,Llistes!$D$24,IF(W15=Llistes!$B$28,Llistes!$D$28)))))) -> Tècnic coordinador | Y15: Mitjans propis | Z15: Fons propis | AA15: X
A16: Eix 01 - Natura | B16: OG 01 | C16: CONSERVAR LA NATURA i restaurar els ecosistemes, els processos naturals i seminaturals, la biodiversitat i la geodiversitat associada. | D16: 01.2 | E16: Executar les mesures de gestió directa previstes en els instruments de planificació per la conservació i la gestió adaptativa dels elements clau de l'ENP | F16: 01.2.3 | G16: Executar les mesures de gestió previstes en els plans de control i erradicació d'espècies exòtiques de forma coordinada amb el Servei de Flora i Fauna en l'àmbit de l'ENP | H16: Comú | I16: Obligatori | J16: Executar les mesures de gestió previstes en els plans de control i eradicació d'espècies exòtiques de forma coordinada amb el Servei de Flora i Fauna en l'àmbit de l'ENP | L16: Si | M16: Màxima | O16: Execució del Pla tècnic de control del coipú (Myocastor coypus). | R16: Pla executat | S16: 4 | T16: 4 | V16: =U16*4 -> 0 | W16: Àrea coordinació | X16: =IF(W16=Llistes!$B$18,Llistes!$D$18,IF(W16=Llistes!$B$20,Llistes!$D$20,IF(W16=Llistes!$B$22,Llistes!$D$22,IF(W16=Llistes!$B$23,Llistes!$D$23,IF(W16=Llistes!$B$24,Llistes!$D$24,IF(W16=Llistes!$B$28,Llistes!$D$28)))))) -> Tècnic coordinador | Y16: Mitjans propis | Z16: Fons propis | AA16: X | AB16: X | AC16: X | AD16: X
A17: Eix 01 - Natura | B17: OG 01 | C17: CONSERVAR LA NATURA i restaurar els ecosistemes, els processos naturals i seminaturals, la biodiversitat i la geodiversitat associada. | D17: 01.2 | E17: Executar les mesures de gestió directa previstes en els instruments de planificació per la conservació i la gestió adaptativa dels elements clau de l'ENP | F17: 01.2.3 | G17: Executar les mesures de gestió previstes en els plans de control i erradicació d'espècies exòtiques de forma coordinada amb el Servei de Flora i Fauna en l'àmbit de l'ENP | H17: Comú | I17: Obligatori | J17: Executar les mesures de gestió previstes en els plans de control i eradicació d'espècies exòtiques de forma coordinada amb el Servei de Flora i Fauna en l'àmbit de l'ENP | L17: Si | M17: Màxima | O17: Redacció del Pla tècnic de control de la tortugues exòtiques. | R17: Sí/No | T17: Sí | V17: =U17*4 -> 0 | W17: Àrea coordinació | X17: =IF(W17=Llistes!$B$18,Llistes!$D$18,IF(W17=Llistes!$B$20,Llistes!$D$20,IF(W17=Llistes!$B$22,Llistes!$D$22,IF(W17=Llistes!$B$23,Llistes!$D$23,IF(W17=Llistes!$B$24,Llistes!$D$24,IF(W17=Llistes!$B$28,Llistes!$D$28)))))) -> Tècnic coordinador | Y17: Mitjans propis | Z17: Fons propis | AC17: X
A18: Eix 01 - Natura | B18: OG 01 | C18: CONSERVAR LA NATURA i restaurar els ecosistemes, els processos naturals i seminaturals, la biodiversitat i la geodiversitat associada. | D18: 01.2 | E18: Executar les mesures de gestió directa previstes en els instruments de planificació per la conservació i la gestió adaptativa dels elements clau de l'ENP | F18: 01.2.3 | G18: Executar les mesures de gestió previstes en els plans de control i erradicació d'espècies exòtiques de forma coordinada amb el Servei de Flora i Fauna en l'àmbit de l'ENP | H18: Comú | I18: Obligatori | J18: Executar les mesures de gestió previstes en els plans de control i eradicació d'espècies exòtiques de forma coordinada amb el Servei de Flora i Fauna en l'àmbit de l'ENP | L18: Si | M18: Màxima | O18: Execució del Pla tècnic de control de la tortugues exòtiques. | R18: Pla executat | S18: 4 | T18: 4 | V18: =U18*4 -> 0 | W18: Àrea coordinació | X18: =IF(W18=Llistes!$B$18,Llistes!$D$18,IF(W18=Llistes!$B$20,Llistes!$D$20,IF(W18=Llistes!$B$22,Llistes!$D$22,IF(W18=Llistes!$B$23,Llistes!$D$23,IF(W18=Llistes!$B$24,Llistes!$D$24,IF(W18=Llistes!$B$28,Llistes!$D$28)))))) -> Tècnic coordinador | Y18: Mitjans propis | Z18: Fons propis | AC18: X | AD18: X
