Workbook

Sheet ESTRATÈGIA
C3: ESQUEMA CONCEPTUAL PER A LA ELABORACIÓ DEL PLA ESTRATÈGIC EN EL MARC
C4: DELS ESTÀNDARDS OBERTS PER A LA GESTIÓ ADAPTATIVA A CATALUNYA

Sheet INSTRUCCIONS
A1: PESTANYA DE PRIORITZACIÓ
A2: Llistat elements: | B2: Tasca 1: Revisar el llistat d'elements prioritzats per tal d'avaluar si cal afegir-ne algun o treure'n algun. A la columna comentaris cal argumentar, breument, el perquè de la decisió.
A4: Llistat amenaces: | B4: Tasca 2: A partir de la taxonomia d'amenaces que es troba a la pestanya final, cal omplir les tres columnes (E, F i G) amb les tres principals amenaces per a la conservació de l'element. S'afegeixi una darrera columna per si hi ha amenaces que no es troben incloses a la taxonomia.
A6: PESTANYA DEL PLA
A7: Explicacions:
B8: 7 Eixos temàtics
B9: Els objectius generals estan directament associats als objectius generals dels Plans de Protecció del medi naatural i del paisatge. NO ES PODEN RETOCAR
B10: Objectius estratègics: definits en un grup de treball intern de serveis Centrals i dels Parcs durant l'any 2023. NO ES PODEN RETOCAR
B11: Objectius operacionals: definits en un grup de treball intern de serveis Centrals i dels Parcs durant l'any 2023
A14: Tasques a realitzar:
A15: Objectius operacionals: | B15: El llistat d'objectius operacionals té una columna al costa (columna I) on s'indica si l'objectiu és obligatori de mantenir al Pla estratègic o no.
B16: Tasca 1: Columna I. Revisar els que es posa com a obligatoris per veure si són realment aplicables a l'espai o no.
B17: Tasca 2: Columna I. Revisar els que posa "Opcional" per identificar els que són aplicables o no a l'espai. O, també, determinar si algun d'ells seria aplicable o es pot concretar millor el redactat de l'objectiu.
B18: Tasca 3: Columna J. En ambdós casos, cal posar a la columna J, el redactat final de l'objectiu concretat a l'espai. En el cas de que l'objectiu s'elimina, posar "NA". Ara es reprodueix el redactat dels objectius operacionals derivats del grup de treball esmentat
B19: Tasca 4: Columna K. Per tots els casos en que hi ha modificació respecte al redactat original de l'objectiu operatiu -i, també, en el cas que es consideri que s'ha d'eliminar-, a la columna K cal redactar molt breument el motiu pel qual es prèn la decisió.
B20: Tasca 5: Columna L. Incloure un Si/No avaluant si l'objectiu operatiu podria tenir mesures a incorporar a la programació d'actuacions de l'espai (Si) o, per altra banda, el seu assoliment depèn d'altres òrgans, com l'ACA o altres serveis dins la DGPAMN (No).
B21: Tasca 6: Columna M. Definir la prioritat que hauria de tenir l'assoliment de l'objectiu (màxima, si cal assolir en els propers 4 anys, o altrament alta, mitja o baixa). També hi ha l'opció de prioritat a assolir a més llarg termini.
A22: Propostes genèriques d'accions: | B22: Tasca 7: Columna N. En aquest columna cal introduir les accions, de manera genèrica, que caldria aplicar a l'espai per tal d'assolir l'objectiu operatiu. No es tracta d'un llistat d'accions concretes si no, més aviat, accions generals que acabarien concretant-se en la programació anual. PER A INICIAR AMB LA TAULA US PODEU BASAR MOLT EN LA FEINA JA FETA DE PRIORITZACIÓ DE MESURES PEL MAP
B23: En el cas dels objectius operatius que s'ha considerat que no són aplicables a l'espai, cal avaluar si podrien tenir alguna acció que sí tindria sentit d'incloure al Pla estratègic tot i que l'objectiu de manera global no hi ´seria d'aplicació.
A24: Indicadors: | B24: Tasca 8: Columna Q. Posar un indicar SMART per avaluar el compliment de la mesura proposada a la columna N
A25: Fites a assolir en 4 anys: | B25: Tasca 9: Posar un valor de l'indicador a asolir: valor mínim necessari (columna R) o valor desitjable (columna S).
A26: Hores de dedicació: | B26: Tasca 10: Columna T. Realitzar una aproximació el més acurada que es pugui de les hores del personal de gestió de l'espai que cal destinar per a la realització de l'acció.
A27: Àrea responsable: | B27: Tasca 11: Columna U. Indicar quina àrea de l'equip de gestió és responsable de coordinar l'execució de l'acció.
A28: Persona responsable: | B28: Tasca 12: Columna V. Indicar quina persona dins l'àrea seria l'encarregada.
A30: PESTANYA DEL VINCLE
A31: Definir vincle amenaça vs. Obj. Operatiu | B31: Tasca 1: Establir / Revisar el vincle entre les amenaces identificades a la pestanya de priorització i els objectius operatius definits a la columna J de la pestanya Pla. La columna B conté el llistat dels objectius operatius tal i com quedaran definits després de la vostra revisió.
B32: Tasca 2: En cas que es pugui, definir l'amenaça / factor / causa concret a la que atén l'objectiu definit al Pla. Poden ser més d'una.
B33: És important que es visualitzi a quina amenaça es dirigeix l'objectiu operatiu que es proposa al Pla, tot i que, no sempre hi ha d'haver un vincle clar. Pot haver algun objectiu sense amenaça vinculada.

Sheet PRIORITZACIÓ
A2: Llistats corresponent a l'espai de Natura 2000 ES5120002"Capçaleres del Ter i del Freser"
A3: LLISTAT D'ELEMENTS PRESENT A L'ESPAI | E3: AMENACES PER A CADA ELEMENT
A4: Hàbitats d'interès comunitari | B4: Prioritzat | C4: Puntuació índex rellevància | D4: Comentaris en cas de canvi en la priorització | E4: Amenaça 1 segons taxonomia | F4: Amenaça 2 segons taxonomia | G4: Amenaça 3 segons taxonomia | H4: Altres amenaces
A5: 3110 - Aigües estagnants oligotròfiques, molt poc mineralitzades (Littorelletalia uniflorae) | J5: Nota: La priorització d'elements actual inclou els Elements Clau que es van determinar en l'instrument de gestió aprovat amb l'Acord de Govern 150/2014 (Annex 6)
A6: 3130 - Aigües estagnants oligotròfiques o mesotròfiques amb vegetació de Littorelletea uniflorae i/o Isoëto-nanojuncetea | J6: Aquest Acord era per les Zones Especials de Conservació, no per les ZEPA i, per tant, no es va fer l'exercici de priorització de les aus.
A7: 3240 - Rius de tipus alpí amb bosquines de muntanya | J7: També inclou el primer quartil de l'exercici de la UIC per prioritzar els elements present a cada espai de Natura 2000, és a dir, el 25% dels
A8: 4030 - Landes atlàntiques i subatlàntiques seques | J8: elements amb major índex de rellevància a l'espai. Veure document metodològic aquí:
A9: 4060 - Matollars alpins i boreals | B9: Si | C9: 2.625 | E9: Impactes del canvi climàtic relatius a l'alteració del règim de precipitació i sequera | F9: Impactes del canvi climàtic relatius a l'alteració del règim de temperatures | J9: https://gencat.sharepoint.com/sites/Informaciiconeixementpatrimoninatural2/Documents%20compartits/Forms/AllItems.aspx?csf=1&web=1&e=3x4ZkK&ovuser=3b9427dc%2Dd30e%2D43bc%2D8c06%2Dff7253676fec%2Cjordiparpal%40gencat%2Ecat&OR=Teams%2DHL&CT=1713942253212&clic
A10: 4090 - Matollars xerocàntics endèmics oromediterranis | B10: No | D10: Hàbitat molt poc present al parc | J10: El llistat original d'elements prové de les taules del MAP que heu estat treballant amb el SENP
A11: 5110 - Boixedes xerotermòfiles permanents, dels vessants rocosos
A12: 5120 - Formacions muntanyenques de bàlec (Genista balansae subsp. europaea = Cytisus purgans)
A13: 5130 - Formacions de Juniperus communis colonitzadores de landes o de pastures calcícoles | B13: No | C13: 3.625 | D13: Hàbitat en expansió en deteriorament d'altres hàbitats que si que es consideren prioritaris
A14: 6110p - Prats calcàris o basòfils d'Alysso-Sedion albi (*)
A15: 6140 - Gespets tancats, silicícoles, dels Pirineus
A16: 6170 - Prats calcícoles alpins i subalpins | B16: Si | C16: 2.625 | E16: Impactes del canvi climàtic relatius a l'alteració del règim de precipitació i sequera | F16: Impactes del canvi climàtic relatius a l'alteració del règim de temperatures | G16: Ramaderia
A17: 6210 - Prats -i fàcies emmatades- medioeuropeus, seminaturals, sobre substrat calcari (Festuco-Brometea)
A18: 6230p - Prats de pèl caní (Nardus stricta), rics florísticament, dels terrenys silicis de la muntanya mitjana atlàntica o subatlàntica | B18: Si | E18: Desaparició d'activitats tradicionals | F18: Impactes del canvi climàtic relatius a l'alteració del règim de precipitació i sequera | G18: Impactes del canvi climàtic relatius a l'alteració del règim de temperatures | H18: Maneig ramader
A19: 6410 - Herbassars de Molinia coerulea en sòls calcaris torbosos o argil·lollimosos (Molinion caeruleae) | B19: No | C19: 2.625 | D19: Hàbitat molt poc present al parc
A20: 6420 - Jonqueres i herbassars graminoides humits, mediterranis, del Molinio-Holoschoenion
A21: 6430 - Herbassars higròfils, tant de marges i vorades com de l'alta muntanya | B21: Si | C21: 5.125 | E21: Impactes del canvi climàtic relatius a l'alteració del règim de precipitació i sequera | F21: Impactes del canvi climàtic relatius a l'alteració del règim de temperatures | G21: Desaparició d'activitats tradicionals
A22: 6510 - Prats de dall de terra baixa i de la muntanya mitjana (Arrhenatherion) | B22: Si | D22: Tot i ser un hàbitat poc present al Parc, es troba en regressió arreu i a més a més és possible conservar-lo amb mesures de gestió activa. | E22: Desaparició d'activitats tradicionals
A23: 6520 - Prats de dall altimontans i subalpins (Triseto-Polygonion bistortae) | B23: Si | C23: 2.625 | E23: Desaparició d'activitats tradicionals
A24: 7110p - Torberes altes actives
A25: 7220p - Fonts petrificants amb formació de travertí (Cratoneurion commutati) | B25: No | C25: 2.75 | D25: Hàbitat molt poc present al parc
A26: 7230 - Molleres alcalines | B26: Si | C26: 2.875 | E26: Ramaderia | F26: Impactes del canvi climàtic relatius a l'alteració del règim de precipitació i sequera | G26: Impactes del canvi climàtic relatius a l'alteració del règim de temperatures
A27: 7240p - Formacions pioneres alpines del Caricion bicoloris-atrofuscae
A28: 8110 - Tarteres silícies medioeuropees i dels indrets freds i humits de l'alta muntanya (Galeopsietalia ladani i Androsacetalia alpinae)
A29: 8130 - Tarteres de l'Europa meridional amb vegetació poc o molt termòfila | B29: Si | E29: Molèsties per activitats recreatives
A30: 8210 - Costers rocosos calcaris amb vegetació rupícola | B30: Dubtós | D30: Hàbitat interessant dins el Parc ja que tan sols es troba en alguns sectors específics i acull espècies de flora d'interès. Tot i així, no presenta amenaces clares
A31: 8220 - Costers rocosos silicis amb vegetació rupícola
A32: 8230 - Terraprims silicis amb vegetació pionera (Sedo-Scleranthion)
A33: 8310 - Coves no explotades pel turisme | B33: Si | E33: Molèsties per activitats recreatives
A34: 8340 - Glaceres permanents | B34: Dubtós | D34: Hàbitat rar a Catalunya, i especialment vulnerable a causa del canvi climàtic. Al Parc el trobem representat per una forma atípica: glaceres rocalloses
A35: 9120 - Fagedes acidòfiles
A36: 9130 - Fagedes neutròfiles
A37: 9180p - Boscos de vessants rostos, tarteres o barrancs, del Tilio-Acerion | B37: Dubtós | D37: Hàbitat molt poc present al parc
A38: 91E0p - Vernedes i altres boscos de ribera afins (Alno-Padion)
A39: 9430 - Boscos de pi negre (Pinus uncinata) sobre substrat silici
A40: 9430p - Boscos de pi negre (Pinus uncinata) sobre substrat calcari | B40: Dubtós | C40: 2.875 | D40: És un hàbitat escàs al Parc i no es coneixen amenaces clares que puguin condicionar la seva persistència.
A42: Espècies d'interès comunitari | B42: Prioritzat | C42: Puntuació índex rellevància | D42: Comentaris en cas de canvi en la priorització | E42: Amenaça 1 segons taxonomia | F42: Amenaça 2 segons taxonomia | G42: Amenaça 3 segons taxonomia | H42: Altres amenaces
...

Sheet PLA
A1: MODEL DE PLA ESTRATÈGIC PELS ENP
B2: Espai natural protegit: | C2: Capçaleres del Ter i del Freser
T3: Fita a assolir en 4 anys | V3: Gestió interna
A4: EIXOS | C4: OBJECTIUS Generals (PP) | E4: OBJECTIUS Estratègics | G4: OBJECTIUS operatius / Línia estratègica | H4: Comú / Específic | I4: Obligatori / Optatiu | J4: Objectiu operatiu concret a l'espai | K4: Explicació de la decisió presa en el cas de canvis respecte al llistat inicial (columna G) | L4: Objectiu amb mesures incorporables a la planificació anual de la gestió de l'espai? | M4: Prioritat | N4: Propostes genèriques d'accions | O4: Vincles amb d'altres accions | P4: MODIFICACIONS PENDENTS | Q4: Marc de referència | R4: Resultats derivats | S4: indicadors | T4: Mínima | U4: Màxim (Desitjable) | V4: Hores de dedicació | W4: Àrea responsable | X4: Persona responsable / Persona a implicar | Y4: Documentació vinculada | Z4: 2025 | AA4: 2026 | AB4: 2027 | AC4: 2028 | AD4: Comentaris
A5: NATURA | B5: 1 | C5: CONSERVAR LA NATURA i restaurar els ecosistemes, els processos naturals i seminaturals, la biodiversitat i la geodiversitat associada. | D5: 01.1 | E5: Adequar i fer eficient la conservació dels elements objecte de gestió prioritària marcats per la DG a l'ENP | F5: 01.1.1 | G5: Implementar i executar plans de gestió específics per a hàbitats i espècies de conservació prioritària dins l'ENP | H5: Comú | I5: Obligatori | J5: =G5 -> Implementar i executar plans de gestió específics per a hàbitats i espècies de conservació prioritària dins l'ENP | L5: Si | M5: MÀXIMA | N5: 1) Realització d'accions per a la millora dels elements prioritzats a l'espai: - Actuacions de millora d'hàbitat per el gall fer - Recuperació de sistemes de mollera - Reducció de l'impacte de la freqüentació en zones d'alta muntanya | Q5: MAP | R5: SFF: Elaboració de plans de gestió específics per a espècies de conservació prioritària i directrius de gestió d'hàbitats. SFF/SENP: Definir a nivell de cluster quins son els que es poden elaborar conjuntament. | S5: 1) Projectes de gestió activa i/o adaptatiu lligat a l'objectiu 1.2.1 duts a terme per a la millora dels elements de conservació prioritària 2) Nombre de seguiments efectuats per diferents tipologies (sòls, espècies herbàcies, interès farratger i invertebrats) en les 23 parcel·les de seguiment establertes 3) classificació de l'estat eològic de pastures altimontanes i subalpines amb elemètode del transsecte (percentage de bon estat, regular i dolent) | T5: 1) 5 2) 4 3) avaluar-ne 30 (>50% bon estat) | U5: 1) 5 2) 8 3) avaluar-ne 50 (> 80% bon estat) | V5: =200+200 -> 400 | W5: Patrimoni natural/Sistemes agropastorals | X5: Anna Planella/Bernat Perramon | Y5: Posar només projectes de seguiment (POCTEFA Redbio) i recuperació espais oberts??? | AD5: Fusionar-lo amb el 6.1.1.
F6: 01.1.2 | G6: Adaptar i executar plans de gestió específics per a elements geològics de conservació prioritària dins l'ENP | H6: Comú | I6: Obligatori | J6: =G6 -> Adaptar i executar plans de gestió específics per a elements geològics de conservació prioritària dins l'ENP | L6: Si | M6: ALTA | N6: 1) Accions de conservació i protecció dels elements geològics: - Retirada d'elements que afecten el patrimoni geològic (creus, làpides...) - Retirada de les construccions de pedres (tipus vivac) i accions de difusió per limitar-les. - Protecció d'elements considerats d'interès (per exemple, protecció del dipòsit morrènic de Queralbs) - Dur a terme una gestió preventiva sobre els usos i activitats que poden afectar la conservació del patrimoni geològic - Divulgació i sensibilització del patrimoni geològic | S6: 1) Percentatge d'elements geològics detectats en mal estat de conservació durant l'inventariat geològic, en els que s'ha actuat 2) Percentatge d'elements geològics que presenten un risc, que disposen d'elements de senyalització. 3) Nombre d'elements que afecten el patrimoni geològic retirats | T6: 1) 75% 2) 50% 3) 10 | U6: 1) 100% 2) 100% 3) 20 | V6: 160 | W6: Patrimoni natural | X6: Anna Planella
D7: 01.2 | E7: Executar les mesures de gestió directa previstes en els intruments de planificació per la conservació i la gestió adaptativa dels elements clau de l'ENP | F7: 01.2.1 | G7: Implementar la metodologia de gestió adaptativa (Estàndards Oberts de Gestió Adaptativa a Catalunya) en tots els processos de l'ENP | H7: Comú | I7: Obligatori | J7: =G7 -> Implementar la metodologia de gestió adaptativa (Estàndards Oberts de Gestió Adaptativa a Catalunya) en tots els processos de l'ENP | L7: Si | M7: ALTA | N7: 1) Definició d'un protocol per tal d'incorporar la metodologia dels Estàndards Oberts pels processos més rellevants per a la conservació a l'espai 2) Creació d'un sistema de seguiment de les accions de gestió de l'espai i un adequat mecanisme de gestió adaptativa de les mateixes | Q7: ESNATURA | R7: SENP: Elaboració d'un manual per la implementació dels OSAM | S7: 1) Percentatge de projectes transversals que incorporin la metodologia d'Estàndards Oberts 2) Percentatge d'accions dutes a terme a l'espai que disposen d'un sistema de seguiment i un adequat mecanisme de gestió adaptativa | T7: 0.75 | U7: 1 | V7: =50*6+100 -> 400 | W7: Transversal | X7: Tots/es
F8: 01.2.2 | G8: Executar les mesures previstes en els plans de conservació o recuperació d'espècies amenaçades de forma coordinada amb el Servei de Flora i Fauna en l'àmbit de l'ENP | H8: Comú | I8: Obligatori | J8: =G8 -> Executar les mesures previstes en els plans de conservació o recuperació d'espècies amenaçades de forma coordinada amb el Servei de Flora i Fauna en l'àmbit de l'ENP | L8: Si | M8: MÀXIMA | N8: 1) Execució de les accions dins els plans que pertoquin a cada espai (incorporar totes les mesures que surten als plans ja aprovats que tenen incidència a l'espai) 2) Implicació i participació en la redacció dels plans de conservació /recuperació d'espècies amenaçades 3) Col.laboració en l'obtenció de la informació necessària dins els espais per al desenvolupament dels Plans | Q8: MAP Catàlegs | R8: SFF: Elaboració de plans de conservació o recuperació d'espècies protegides | S8: 1) Percentatge d'accions executades incloses dins de plans de recuperació/conservació d'espècies amenaçades presents a l'espai 2) Nombre de plans de recuperació/conservació d'espècies amenaçades presents a l'espai en els que s'ha participat de forma activa en la seva redacció | T8: 1) 25% 2) 2 | U8: 1) 50% 2) 4 | V8: 150 | W8: Patrimoni natural | X8: Anna Planella
F9: 01.2.3 | G9: Executar les mesures de gestió previstes en els plans de control i erradicació d'espècies exòtiques de forma coordinada amb el Servei de Flora i Fauna en l'àmbit de l'ENP | H9: Comú | I9: Obligatori | J9: =G9 -> Executar les mesures de gestió previstes en els plans de control i erradicació d'espècies exòtiques de forma coordinada amb el Servei de Flora i Fauna en l'àmbit de l'ENP | L9: Si | M9: MÀXIMA | N9: 1) Implementació anual dels plans de control i erradicació d'espècies de fauna exòtiques invasores. 2) Implementació anual dels plans de control i erradicació d'espècies de flora exòtiques invasores. 3) Establir seguiment de col·lonització del seneci en diferents escencaris com en les zones de recuperació de pastures 4) Elaborar pautes de maneig ramader per reduir la col·lonització de seneci en prats de manera preventiva 5) eliminació flora exòtica invasora de zones sensibles | Q9: ESNATURA MAP | R9: SFF: Elaboració de plans de control i erradicació d'espècies exòtiques | S9: 1) Campanyes de control de fauna exòtica invasora fluvial dutes a terme 2) Nombre d'espècies de fauna exòtica invasora (visó americà, coipú,...) detectada dins el Parc Natural. 3) Seguiments específics per estudiar comportament espècies exòtiques invasores 4) Elaboració d'un pla de control del seneci del cap, orientat a la identificació de zones conflictives per la seva presència (zones amb espècies sensibles, zones d'especial interés per a la ramaderia, etc.) 5) actuacions elliminació flora exòtica invasora | T9: 1) 4 (1/any) 2) 0 3) 1 4) pautes generals 5) suport en actuacions PNCTF (exemple_recuperació espais oberts) | U9: 1) 8 (2/any) 2) 0 3) 2 4) pautes desglossades per hàbitats i gestió associada 5)actuacions específiques d'eliminació | V9: 1 i 2) 30h + equip exòtiques SFF 3) 100h + serveis externs 4) 50h 5) brigades + voluntariat (no es comptabilitzen les h) | W9: Patrimoni natural / Sistemes agropastorals | X9: Anna Planella / Bernat Parramon
F10: 01.2.4 | G10: Desplegar els objectius i tasques recollits en els instruments de referència i compromisos internacionals | H10: Específic | I10: Optatiu | J10: =G10 -> Desplegar els objectius i tasques recollits en els instruments de referència i compromisos internacionals | L10: Si | M10: MITJANA | N10: 1) Participació en l'execució de projectes transfronterers 2) Establir mecanismes de col·laboració transfronterera en diferents formats (jornades de treball, jornades de divulgació, reunions conjuntes, etc.). Article 3 punts 2b i 2c del Decret 211/2015 | S10: 1)Nombre de projectes transfronterers en els que s'ha participat (POCTEFA Red-BIO, POCTEFA Floralab+ i POCTEFA Transmuntanya) 2) Nombre de reunions, activitats, etc/any | T10: 3 | U10: 6 | V10: 460 | W10: Patrimoni natural/Sistemes agropastorals/Millora rural/Direcció/Administració | X10: Anna Planella/Bernat Perramon/Gerard Vila/Santi Farriol/Fàtima
D11: 01.3 | E11: Crear ecosistemes complexes, resilients, i d'alta biodiversitat per garantir la recuperació dels processos ecosistèmics | F11: 01.3.1 | G11: Identificar espais pel foment de la dinàmica natural i l'aprofitament no extractiu | H11: Comú | I11: Obligatori | J11: =G11 -> Identificar espais pel foment de la dinàmica natural i l'aprofitament no extractiu | L11: Si | M11: ALTA | N11: Afavorir la creació d'hàbitats per a la conservació d'espècies | Q11: ESNATURA | R11: SENP/SFF: Definir criteris metodològics | S11: 1) Nombre d'hectàrees gestionades per a la conservació d'espècies (recuperació d'espais oberts, millores forestals, etc.) | T11: 1) 20 | U11: 1) 50 | V11: =(80*2)+50 -> 210 | W11: Patrimoni natural, Sistemes agropastorals, Millora rural | X11: Anna, Bernat, Gerard
F12: 01.3.2 | G12: Afavorir la maduresa dels sistemes forestals | H12: Específic | I12: Optatiu | J12: =G12 -> Afavorir la maduresa dels sistemes forestals | L12: Si | M12: ALTA | N12: Definir criteris per classificació dels boscos madurs Creació d'un catàleg dels rodals amb bosc madur dins del PN Participació projecte Life Uncinata Participació projecte Redbio | Q12: MAP | R12: SENP/SFF: Definir criteris metodològics | S12: Número d'actuacions o projectes destinats afavorir la maduresa forestal | T12: 2 | U12: 4 | V12: 240 | W12: Millora rural | X12: Gerard Vila
F13: 01.3.3 | G13: Generar pertorbacions controlades | H13: Específic | I13: Optatiu | J13: NA | K13: No aplica. No es preveu com a mètode per assolir aquests ecosistemes complexes | Q13: MAP | R13: SENP/SFF: Definir criteris metodològics
F14: 01.3.4 | G14: Restaurar la dinàmica natural dels rius | H14: Específic | I14: Optatiu | J14: NA | K14: No seria una mesura prioritaria dins l'espai natural. Poca superfície de bosc de ribera, de laminació... | M14: FORA DEL TERMINI DEL PLA | N14: Realització i impuls de la renaturalització de lleres i creació de zones de laminació dins l'ENP en base als criteris metodològics predefinits | Q14: MAP | R14: SENP/SFF: Definir criteris metodològics | S14: Superfície (ha) on s'han realitzat actuacions de millora (aclarides, plantacions...) | T14: 20 | U14: 80 | V14: =80*2*4 -> 640 | W14: Patrimoni Natural + Millora rural | X14: Gerard Vila / Anna Planella
F15: 01.3.5 | G15: Fomentar el paisatge en mosaïc | H15: Específic | I15: Optatiu | J15: =G15 -> Fomentar el paisatge en mosaïc | L15: Si | M15: ALTA | N15: Recuperació i manteniment dels espais oberts identificats com a prioritaris segons els estudis previs realitzats des del PN | Q15: ESNATURA | R15: SENP/SFF: Definir criteris metodològics | S15: 1) Actuacions de recuperació en zones identificades com a prioritaries a mantenir obertes o en en zones que es consideren prioritàries a recuperar (estudi Minuàrtia) 2) Ajuts per manteniment d'hàbitats amb pasturatge | T15: 1) 1 2) 10 | U15: 1) 12 2) 30 | V15: =60+60 -> 120 | W15: Sistemes agropastorals / Millora Rural | X15: Bernat Perramon / Gerard Vila
F16: 01.3.6 | G16: Gestionar i intervenir en la dinàmica de poblacions de fauna que no tenen depredador natural | H16: Específic | I16: Optatiu | J16: =G16 -> Gestionar i intervenir en la dinàmica de poblacions de fauna que no tenen depredador natural | L16: Si | M16: ALTA | N16: 1) Participació i impuls en el control directe de poblacions de fauna, en fase a criteris metodològics predefinits, que suposin una amenaça per a la ramaderia, hàbitats o espècies amenaçats | R16: SENP/SFF: Definir criteris metodològics | S16: 1) Hectàrees en les que s'ha dut a terme un control anual de depredadors per a la millora de l'estat de conservació del gall fer o altres espècies amenaçades, segons metodologia predefinida | T16: 0 a 1000 | U16: 4000 | V16: 180 | W16: Patrimoni natural | X16: Anna Planella
D17: 01.4 | E17: Alinear l'activitat de propietaris i gestors del territori amb la conservació, millora i restauració dels valors de l'ENP | F17: 01.4.1 | G17: Fomentar acords de custòdia en espais d'alt valor dins l'ENP per a la gestió dels elements prioritaris | H17: Comú | I17: Optatiu | J17: =G17 -> Fomentar acords de custòdia en espais d'alt valor dins l'ENP per a la gestió dels elements prioritaris | L17: Si | M17: BAIXA | N17: Realització d'acords de custòdia aplicant el model d'acord elaborat per Serveis Centrals | Q17: MAP | R17: SENP/SENP: Dissenyar el protocol i elaborar un model d'acord | S17: Número d'acords de custòdia duts a terme | T17: 1 | U17: 2 | V17: 60 | W17: Patrimoni Natural | X17: Anna Planella
F18: 01.4.2 | G18: Fomentar bones pràctiques entre els col·lectius de propietaris i gestors del territori | H18: Comú | I18: Optatiu | J18: =G18 -> Fomentar bones pràctiques entre els col·lectius de propietaris i gestors del territori | L18: Si | M18: ALTA | N18: Elaboració bones pràctiques de maneig ramader i fauna cinegètica pel desenvolupament actuacions així com participació en projectes conjunts | S18: 1) Treballs sobre bones pràctiques 2) actuacions per fomentar bones pràctiques 3) Coordinació en la gestió 4) Organització de jornades conjuntes 5) Participacií en projectes conjunts | T18: 1) 1 2) 2 3) 2 4) 1 5) 1 | U18: 1) 2 2) 4 3) 4 4) 2 5) 2 | V18: 60 | W18: Sistemes agropastorals | X18: Bernat Perramon
F19: 01.4.3 | G19: Impulsar la coordinació amb els ens locals en la gestió finques públiques situades dins d’ENP | H19: Específic | I19: Optatiu | J19: =G19 -> Impulsar la coordinació amb els ens locals en la gestió finques públiques situades dins d’ENP | L19: Si | M19: MÀXIMA | N19: Realització de projectes de forma col·laborativa amb els ens locals per a la gestió de boscos comunals i lleres i boscos de ribera | Q19: ESNATURA | S19: Nombre de projectes col·laboratius CEINR X PNCTF X GENCAT | T19: 3 | U19: 6 | V19: =20+40+100+100 -> 260 | W19: Transversal | X19: Gerard Vila / Anna Planella/Bernat Perramon/Santi Farriol
B20: 2 | C20: ADAPTAR ELS ECOSISTEMES AL CANVI CLIMÀTIC i millorar-ne la resiliència en front dels riscos associats. | D20: 02.1 | E20: Planificar l'adaptació dels sistemes naturals al canvi climàtic | F20: 02.1.1 | G20: Adaptar i implementar el Pla d'adaptació de l'ENP al canvi climàtic | H20: Comú | I20: Obligatori | J20: =G20 -> Adaptar i implementar el Pla d'adaptació de l'ENP al canvi climàtic | K20: No hi ha perspectiva de fer un pla específic per temes de canvi climàtic. Les actuacions ja estan recollides dins dels objectius de fomentar el paisatge en mosaic i l'objectiu de prevenció d'incendis | M20: FORA DEL TERMINI DEL PLA | R20: OCCC/SENP: Elaboració del model de Pla d'adaptació dels ENP al canvi climàtic
F21: 02.1.2 | G21: Gestionar i planificar els recursos hídrics de l'ENP | H21: Comú | I21: Obligatori | J21: =G21 -> Gestionar i planificar els recursos hídrics de l'ENP | L21: Si | M21: ALTA | N21: Creació de la cartografia dels recursos hídrics de l'ENP i les seves amenaces (per exemple captacions d'aigua) | S21: Cartografia creada que cobreixi tot l'ENP sobre els recursos hídrics existents i les seves amenaces | T21: 1 (cartografia) | U21: 1 (cartografia) | V21: =40+40 -> 80 | W21: Millora rural | X21: Gerard Vila / Anna Planella
F22: 02.1.3 | G22: Participar en la redacció i execució dels instruments d'ordenació forestal sostenible i per la conservació en finques públiques | H22: Específic | I22: Optatiu | J22: =G22 -> Participar en la redacció i execució dels instruments d'ordenació forestal sostenible i per la conservació en finques públiques | K22: Aportació ramaders i proietaris així combsector conservacionista | L22: Si | M22: MITJANA | N22: Participació en la redacció d'IOF de finques públiques Realització de tractaments silvícoles i tallades selectives Promoció de boscos mixtes i de la biodiversitat Foment de la fusta de baixa qualitat per a l'aprofitamet de biomassa Incloure conceptes d'evolució lliure i del manual 11 d'Europarc | R22: DGEFMN: Redacció d'IOF en finques públiques | S22: % d'actuacions forestals (finca pública i dins PN) en les que s'ha participat de forma activa des del PN | T22: 50 | U22: 100 | V22: =20+200+200 -> 420 | W22: Millora rural | X22: Gerard Vila/Anna Planella/Bernat Perramon
F23: 02.1.4 | G23: Promoure la redacció d'instruments d'ordenació forestal per reduir la sensibilitat i vulnerabilitat dels boscos al canvi climàtic en finques privades | H23: Específic | I23: Optatiu | J23: =G23 -> Promoure la redacció d'instruments d'ordenació forestal per reduir la sensibilitat i vulnerabilitat dels boscos al canvi climàtic en finques privades | L23: Si | M23: MITJANA | N23: * Realització d'accions per donar a conèixer subvencions entre propietaris | S23: % de superfície de finques privades amb IOF dins del PN | T23: 60 | U23: 100 | V23: 200 | W23: Millora rural | X23: Gerard Vila
D24: 02.2 | E24: Planificar la prevenció i extinció d’incendis forestals i la gestió del foc de forma coordinada amb els diferents agents del territori | F24: 02.2.1 | G24: Redactar i implementar el Pla de Prevenció d'Incendis | H24: Comú | I24: Obligatori | J24: =G24 -> Redactar i implementar el Pla de Prevenció d'Incendis | L24: Si | M24: MÀXIMA | N24: *Elaboració del Pla de Prevenció d'Incendis *Definició de: xarxa estratègica i complementària de vials forestals, xarxa estratègica i complementària de punts d’aigua, tractaments de vegetació, punts estratègics de gestió | Q24: ESNATURA | R24: Equip de PPI: Disseny del protocol de treball | S24: Aprovació del PPIFF del PNCTF | T24: 1 | U24: 1 | V24: =80*4 -> 320 | W24: Millora rural | X24: Gerard Vila
F25: 02.2.2 | G25: Definir i planificar la gestió del foc per a la millora de l'ENP | H25: Específic | I25: Optatiu | J25: =G25 -> Definir i planificar la gestió del foc per a la millora de l'ENP | L25: Si | M25: ALTA | N25: Integració de criteris sobre zones sensibles al foc i zones no sensibles pels valors naturals que hi alberguen | R25: SPEN: Elaboració d'un model de pla de gestió | S25: % de cartografia compartida amb els diferents departaments per tal de determinar en quines zones cal actuar si hi ha un incendi i en quines no | T25: 60 | U25: 100 | V25: 200 | W25: Millora rural | X25: Gerard Vila
F26: 02.2.3 | G26: Treballar per a la prevenció d'incendis juntament amb els propietaris, ajuntaments, protecció civil, ADF i bombers. | H26: Comú | I26: Obligatori | J26: Treballar per a la prevenció d'incendis juntament amb els propietaris, ajuntaments, protecció civil, ADF i bombers. També amb ramaders i empreses del sector forestal | K26: Aportació sector ranmader i propietat privada | L26: Si | M26: MITJANA | N26: Execució de les actuacions recollides dins del PNCTF / Integrar la variable prevenció d'incendis en la recuperació i manteniment d'espais oberts | S26: Número d'actuacions d'interès per la prevenció IIFF | T26: 2 | U26: 8 | V26: 200 | W26: Millora rural | X26: Gerard Vila
B27: 3 | C27: PROTEGIR LA BIODIVERSITAT, i especialment els elements fràgils i amenaçats, d’interès comunitari o de major interès natural. | D27: 03.1 | E27: Prevenir, minimitzar i compensar els impactes ambientals dels usos i activitats que es desenvolupin en l'àmbit de l'ENP | F27: 03.1.1 | G27: Participar en les consultes dels procesos d'Avaluació Ambiental que afectin directament o indirectament l’espai del ENP | H27: Comú | I27: Obligatori | J27: =G27 -> Participar en les consultes dels procesos d'Avaluació Ambiental que afectin directament o indirectament l’espai del ENP | L27: Si | M27: MITJANA | N27: Participació a les taules d'avaluació | S27: % de participació sobre els processos d'avaluació ambiental | T27: 50 | U27: 100 | V27: =30*4 -> 120 | W27: Millora rural | X27: Gerard Vila/ Anna Planella
F28: 03.1.2 | G28: Exercir un seguiment efectiu de les obres al Parc juntament amb les Oficines Territorials d'Acció i Avaluació Ambiental als efectes d'assegurar la correcta translació de la tutela administrativa. | H28: Comú | I28: Obligatori | J28: =G28 -> Exercir un seguiment efectiu de les obres al Parc juntament amb les Oficines Territorials d'Acció i Avaluació Ambiental als efectes d'assegurar la correcta translació de la tutela administrativa. | L28: Si | M28: MITJANA | N28: Seguiment amb les obres que afectent i es realitzen dins dels límits del PNCTF | S28: % de participació sobre les obres executades | T28: 50 | U28: 100 | V28: 300 | W28: Millora rural | X28: Gerard Vila
F29: 03.1.3 | G29: Participar en la compensació d'impactes residuals durant els processos d'avaluació ambiental mitjançant la identificació de necessitats d'actuació prioritària dins i fora dels límits de l’ENP | H29: Comú | I29: Optatiu | J29: =G29 -> Participar en la compensació d'impactes residuals durant els processos d'avaluació ambiental mitjançant la identificació de necessitats d'actuació prioritària dins i fora dels límits de l’ENP | L29: Si | M29: MITJANA | N29: *Catàleg de possibles actuacions compensatories *Catàleg de sectors amb necessitats d'intervenció (incloent també zones fora dels límits de l'ENP que es considerin importants per al manteniment de la connectivitat ecològica dels espais) | S29: 1) Creació d'un catàleg d'actuacions futures i compensatòries 2) Nombre d'actuacions compensatories realitzades dins del PN | T29: 1) 1 2) 2 | U29: 1) 1 2) 4 | V29: =50+50+(80*4) -> 420 | W29: Transversal | X29: Anna Planella / Tbernat Perramon/Gerard Vila
D30: 03.2 | E30: Garantir el compliment dels objectius de conservació dotant l'ENP de la planificació adequada segons estableix la normativa vigent (Pla de Protecció, PRUG, plans específics...) | F30: 03.2.1 | G30: Participar en l'elaboració dels instruments de planificació de l'ENP | H30: Comú | I30: Obligatori | J30: =G30 -> Participar en l'elaboració dels instruments de planificació de l'ENP | K30: Que s'implementi l'actuació no depèn directament de l'espai | L30: No | R30: SPEN: Elaboració del Pla rector d'usos i gestió. SPEN: Elaboració del Pla rector d'usos i gestió | W30: Transversal | X30: Tots/es
D31: 03.3 | E31: Vetllar pel manteniment dels cabals ecològics i la bona qualitat dels cursos fluvials de l'ENP de forma coordinada amb l'administració competent | F31: 03.3.1 | G31: Vetllar pel manteniment del cabal ecològic dels rius definit al Pla sectorial corresponent | H31: Específic | I31: Optatiu | J31: =G31 -> Vetllar pel manteniment del cabal ecològic dels rius definit al Pla sectorial corresponent | L31: Si | M31: ALTA | N31: 1) Establiment d'una xarxa de control del cabal en els trams de riu dins del Parc 2) Realització d'un inventari de les activitats que poden modificar la llera i el cabal 3) Revisió de les concessions actuals | P31: Revisar les actuacions. L'establiment de punts de control depèn de l'ACA. Es pot incloure la revisió de les concessions, les reunions amb l'ACA,... Afegir indicadors i fites | Q31: ESNATURA | R31: ACA/CHE: Determinar els cabals ecològics en espais naturals protegits | S31: 1) Nombre d'estacions de control de cabal 2) Reunions anuals amb l'ACA 3) Inventari de les activitats que modifiquen la llera i el cabal dels principals rius de l'espai i pla de millora | T31: 1) 2 2) 1 3) 1 | U31: 1) 4 2) 2 3) 1 | V31: =20*4 -> 80 | W31: Patrimoni natural | X31: Anna Planella
F32: 03.3.2 | G32: Vetllar per la regulació dels dragatges, canalitzacions o implantació d'activitats extractives que puguin modificar la llera i el cabal dels rius | H32: Específic | I32: Optatiu | J32: =G32 -> Vetllar per la regulació dels dragatges, canalitzacions o implantació d'activitats extractives que puguin modificar la llera i el cabal dels rius | L32: Si | M32: ALTA | N32: Actuacions incloses en l'objectiu 3.3.1
F33: 03.3.3 | G33: Avaluar i controlar les actuacions que produeixin drenatges, captacions o que puguin impedir l’arribada d’aigua tant superficial com freàtica | H33: Específic | I33: Optatiu | J33: =G33 -> Avaluar i controlar les actuacions que produeixin drenatges, captacions o que puguin impedir l’arribada d’aigua tant superficial com freàtica | L33: Si | M33: ALTA | N33: Actuacions incloses en l'objectiu 3.3.1
F34: 03.3.4 | G34: Vetllar pel compliment de la normativa de depuració dels efluents agroramaders, urbans i industrials que s'aboquen als cursos fluvials | H34: Específic | I34: Optatiu | J34: =G34 -> Vetllar pel compliment de la normativa de depuració dels efluents agroramaders, urbans i industrials que s'aboquen als cursos fluvials | L34: Si | M34: ALTA | N34: 1) Establiment d'una xarxa de control de qualitat de l'aigua | P34: Revisar. Igual que l'anterior potser és competència de l'ACA? | S34: 1) Nombre d'estacions de control de la qualitat | T34: 2 | U34: 4 | V34: =10*4 -> 40 | W34: Patrimoni natural | X34: Anna Planella
D35: 03.4 | E35: Incrementar el patrimoni públic destinat a la conservació i millora del patrimoni natural | F35: 03.4.1 | G35: Identificar espais prioritaris per a la compra de terrenys de més valor dins l'ENP | H35: Comú | I35: Optatiu | J35: =G35 -> Identificar espais prioritaris per a la compra de terrenys de més valor dins l'ENP | L35: Si | M35: ALTA | N35: Vetllar per l'adquisició des del PN o d'altres òrgans públics de finques privades d'interès | R35: SENP/SPEN: Facilitar els criteris a seguir | S35: 1) Llistat de finques potencials classificades per interes 2) Adquisicó de finques d'alt interès | T35: 1) 1 2) 1 | U35: 1) 1 2) 2 | V35: 140 | W35: Transversal | X35: Anna Planella/Gerard Vila/Santi Farriol
F36: 03.4.2 | G36: Identificar espais prioritaris per a la gestió directa | H36: Comú | I36: Optatiu | J36: =G36 -> Identificar espais prioritaris per a la gestió directa | L36: Si | M36: ALTA | N36: Identificació d'espais prioritaris per a la gestió activa | R36: SENP/SPEN: Facilitar els criteris a seguir | S36: 1) Llistat d'espais prioritaris per a gestió activa, ordenats per l'interès 2) Nombre d'actuacions executades | T36: 1) 1 2) 2 | U36: 1) 1 2) 5 | V36: =(50*4)*2 -> 400 | W36: Patrimoni natural / Millora rural | X36: Anna Planella i Gerard Vila
A37: CULTURA | B37: 4 | C37: CONSERVAR ELS ELEMENTS CULTURALS materials i immaterials vinculats a la natura | D37: 04.1 | E37: Millorar el coneixement disponible sobre el patrimoni arquitectònic i cultural (material i immaterial) vinculat al patrimoni natural, el seu estat de conservació i els estils propis dels territoris de l'ENP | F37: 04.1.1 | G37: Elaborar l'inventari i cartografia de patrimoni cultural de l'ENP, que també inclogui el patrimoni etnològic i immaterial | H37: Comú | I37: Optatiu | J37: =G37 -> Elaborar l'inventari i cartografia de patrimoni cultural de l'ENP, que també inclogui el patrimoni etnològic i immaterial | L37: Si | M37: MITJANA | N37: *Redacció d'un full de ruta conjunt amb el Museu Etnogràfic de Ripoll per al desenvolupament d'aquest inventari *Recopilació de la informació dels catàlegs dels ajuntaments de l'ENP i fer diagnosi *Inventari de patrimoni cultural material (arquitectònic /arqueològic / ramader...) *Inventari de patrimoni cultural immaterial (etnològic / espiritual...) (metodologia de l'inventari de la unesco) *Elaboració d'un mapa de tranquil·litat. *Creuar dades amb altres inventaris ja existents (Carta del paisatge, etc.) | S37: Nombre d'inventaris o mapes desenvolupats, juntament amb la cartografia de patrimoni cultural del PNCTF, que també incloguin el patrimoni etnològic i immaterial | T37: 1 | U37: 3 | V37: 50 | W37: Us public | X37: Xavier Grivé
F38: 04.1.2 | G38: Elaborar el catàleg lingüístic (localismes) de patrimoni natural, geografia popular, festes i activitats tradicionals de l'ENP | H38: Comú | I38: Optatiu | J38: =G38 -> Elaborar el catàleg lingüístic (localismes) de patrimoni natural, geografia popular, festes i activitats tradicionals de l'ENP | L38: Si | M38: MITJANA | N38: *Redacció d'un full de ruta conjunt amb el Museu Etnogràfic de Ripoll per al desenvolupament d'aquest inventari *Detecció de les persones i entitats locals de referència en la matèria *Catàleg lingüístic (localismes) de patrimoni natural del PNCTF *Catàleg lingüístic (localismes) de geografia popular, festes i activitats tradicionals del PNCTF *Creuar dades amb altres inventaris ja existents (Carta del paisatge, etc.) | S38: Nombre de catàlegs lingüístics (localismes) desenvolupats de patrimoni natural i de geografia popular, festes i activitats tradicionals del PNCTF | T38: 1 | U38: 2 | V38: 50 | W38: Us public / Patrimoni natural | X38: Xavier Grivé / Anna Planella
F39: 04.1.3 | G39: Elaborar la cartografia de la xarxa de camins ramaders i senders tradicionals de l'ENP | H39: Comú | I39: Optatiu | J39: =G39 -> Elaborar la cartografia de la xarxa de camins ramaders i senders tradicionals de l'ENP | L39: Si | M39: MITJANA | N39: *Redacció d'un full de ruta conjunt amb el Museu Etnogràfic de Ripoll i la xarxa de senders Itinerànnia per al desenvolupament d'aquesta cartografia. *Cartografia de la xarxa de camins ramaders i senders tradicionals de l'ENP * Consensuar amb la propietat (pública o privada) quins senders s'inclouran i, si escau, signatura de convenis | S39: Nombre de mapes desenvolupats de camins ramaders i senders tradicionals | T39: 1 | U39: 1 | V39: 50 | W39: Ús públic / Sistemes agropastorals | X39: Xavier Grivé / Bernat Perramon
D40: 04.2 | E40: Conservar i gestionar el patrimoni cultural de l'ENP de forma coordinada amb els agents responsables i entitats de referència | F40: 04.2.1 | G40: Identificar els ens de referència en patrimoni cultural (entitats, associacions, museus i ecomuseus, etc.) en l'àmbit de l'ENP | H40: Comú | I40: Obligatori | J40: =G40 -> Identificar els ens de referència en patrimoni cultural (entitats, associacions, museus i ecomuseus, etc.) en l'àmbit de l'ENP | L40: Si | M40: MITJANA | N40: *Elaboració d'un mapa d'entitats, associacions, museus, ecomuseus, OPEI (Observatori del Patrimoni Etnològic i Immaterial), etc. *Creuar dades amb altres inventaris ja existents (Carta del paisatge, etc.) | S40: Nombre de mapes desenvolupats d'entitats, associacions, museus, ecomuseus, OPEI (Observatori del Patrimoni Etnològic i Immaterial), etc. | T40: 1 | U40: 1 | V40: 24 | W40: Ús públic | X40: Xavier Grivé i Rai
...

Sheet VINCLE AMENAÇA_OBJ. OPERATIU
A1: TAULA DE VINCLE ENTRE LES AMENACES I ELS OBJECTIUS OPERATIUS DE L'EIX DEL PATRIMONI NATURAL
A3: Eix 1. Natura
A4: Codi | B4: Objectius operatius | C4: Tipologia amenaça | D4: Amenaça concreta
A5: 01.1.1 | B5: =PLA!J5 -> Implementar i executar plans de gestió específics per a hàbitats i espècies de conservació prioritària dins l'ENP | C5: No especificada
A6: 01.1.2 | B6: =PLA!J6 -> Adaptar i executar plans de gestió específics per a elements geològics de conservació prioritària dins l'ENP | C6: No especificada
A7: 01.2.1 | B7: =PLA!J7 -> Implementar la metodologia de gestió adaptativa (Estàndards Oberts de Gestió Adaptativa a Catalunya) en tots els processos de l'ENP | C7: No especificada
A8: 01.2.2 | B8: =PLA!J8 -> Executar les mesures previstes en els plans de conservació o recuperació d'espècies amenaçades de forma coordinada amb el Servei de Flora i Fauna en l'àmbit de l'ENP | C8: No especificada
A9: 01.2.3 | B9: =PLA!J9 -> Executar les mesures de gestió previstes en els plans de control i erradicació d'espècies exòtiques de forma coordinada amb el Servei de Flora i Fauna en l'àmbit de l'ENP | C9: Espècies invasores i patògens
A10: 01.2.4 | B10: =PLA!J10 -> Desplegar els objectius i tasques recollits en els instruments de referència i compromisos internacionals | C10: No especificada
A11: 01.3.1 | B11: =PLA!J11 -> Identificar espais pel foment de la dinàmica natural i l'aprofitament no extractiu | C11: Gestió i modificació de sistemes naturals
A12: 01.3.2 | B12: =PLA!J12 -> Afavorir la maduresa dels sistemes forestals | C12: Gestió i modificació de sistemes naturals
A13: 01.3.3 | B13: =PLA!J13 -> NA | C13: Gestió i modificació de sistemes naturals
A14: 01.3.4 | B14: =PLA!J14 -> NA | C14: Gestió i modificació de sistemes naturals
A15: 01.3.5 | B15: =PLA!J15 -> Fomentar el paisatge en mosaïc | C15: Gestió i modificació de sistemes naturals
A16: 01.3.6 | B16: =PLA!J16 -> Gestionar i intervenir en la dinàmica de poblacions de fauna que no tenen depredador natural | C16: Gestió i modificació de sistemes naturals
... A36: 03.4.2 | B36: =PLA!J36 -> Identificar espais prioritaris per a la gestió directa | C36: No especificada

Sheet Taxonomia Amenaces
A1: Taxonomia d'Amenaces - Xarxa d'ENP Catalunya
A2: Versió 1_revisada pels equips del PNAT Cap de Creus, PNAT Montgrí-Medes, PNAT els Ports, PNIN Poblet, PNAT Delta de l'Ebre, PNAT Alt Pirineu i PNAT Capçaleres del Ter i Freser
A3: Font de dades 1: List of pressures and threats for reporting 2019-2024 v1.1 (Comissió Europea)
A4: Font de dades 2: Llistat de pressions i amenaces del Pla de Protecció del Cadí-Moixeró, inspirat en el llistat de la Comissió Europea
A5: Font de dades 3: IUCN/CMP Threats Classification v 3.3 (2016) i v4.0 draft (2023)
A8: Codi Amenaça | B8: Tipologia d'amenaça | C8: Codi Amenaça | D8: Nom Amenaça | E8: Exemples i descripció del grup
A9: 1 | B9: Urbanització i edificació | C9: 1.1 | D9: Urbanització residencial | E9: Construccions relacionades amb àrees residencials. Tot i que la normativa no permet noves construccions, existeixen edificacions fóra d'ordenació. També casos de remodelacions, reconstruccions o ampliacions d'edificis rurals per usos agrícoles, forestals, ramaders, recreatius, residencials, etc). Restauracions de cabanes i bordes que no deixen forats per ratpenats. cases forestals. Bordes que es canvien d'ús per hosteleria
C10: 1.2 | D10: Urbanització comercial o industrial
C11: 1.3 | D11: Àrees recretives i turístiques | E11: Refugis de muntanya que es remodelen, impacten etc
A12: 2 | B12: Producció primària | C12: 2.1 | D12: Activitat agrícola | E12: Cultius annuals i perennes. Canvis de tipus de cultiu, secà a regadiu o al revés. Canvi d'usos del sòl com cultius de vinya a muntanya, Inclosos el cultiu de l'arròs amb substàncies biocides. Inclòs el cultiu de marihuana
C13: 2.2 | D13: Plantacions forestals
C14: 2.3 | D14: Ramaderia | E14: Ramaderia tan intensiva com extensiva i semi-intensiva (pastura de dia i nit en corral)
C15: 2.4 | D15: Aqüicultura | E15: Aquicultura marina i d'aigua dolça, a l'interior o als voltants del parc
A16: 3 | B16: Producció d'energia i mineria | C16: 3.1 | D16: Activitats de la mineria | E16: Mineria de qualsevol tipus (a cel obert, marina, al·luvial com extracció d'àrids i còdols, subterrània), a l'interior o als voltants del parc. Extracció de torba i salines. Si aplica, extracció d'hidrocarburs terrestres o marins
C17: 3.2 | D17: Producció d'energia renovable | E17: Centrals de producció d'energia renovable (molins eòlics terrestres o marins, instal·lacions solars, hidroelèctriques, geotèrmia inclosos els impactes de fauna contra les instal·lacions). A dins del parc o afectant connectors entre parcs
A18: 4 | B18: Infrastructures de transport i serveis | C18: 4.1 | D18: Vials de transport | E18: Carreteres, pistes forestals, línies fèrries i cremalleres
C19: 4.2 | D19: Conduccions | E19: Conduccions elèctriques, aqueductes, canals de rec, estacions de bombament, conduccions d'aigua o gas
C20: 4.3 | D20: Infrastructures marines | E20: Rutes marines, canals, impactes de vaixells sobre balenes i infrastructura associada. Ports, pantalans, etc
C21: 4.4 | D21: Tancaments i vallats | E21: Tancaments, valles perimetrals i parets de tota mena, en carreteres, per bestiar, estètiques, etc
A22: 5 | B22: Extracció de recursos naturals | C22: 5.1 | D22: Caça i recol·lecció d'animals | E22: Caça i recolecció d'animals, ous, mel silvestre, etc ja sigui per subsistència, esport, tradició, comerç o de forma accidental
C23: 5.2 | D23: Recol·lecció de vegetals | E23: Recolecció de plantes, bolets, resines, líquens, etc
C24: 5.3 | D24: Treballs forestals | E24: Treball forestals de tota mena (arreu, selectiva, carboneig, aclarides, etc)
C25: 5.4 | D25: Pesca i semblants | E25: Pesca i recollida de recursos aquàtics de tota mena i amb qualsevol tècnica (artesanal, xarxa, marisqueig, recollida de corall, pesca accidental, recreativa, etc)
A26: 6 | B26: Molèsties | C26: 6.1 | D26: Molèsties per activitats recreatives | E26: Per activitats recreatives al medi natural de qualsevol tipus (excursionisme, bicicleta, cavall, vehicles a motor, escalada, esquí de muntanya, acampada temporal, pernoctació, ornitòlegs, fotografs, esports nàutics, pesca turisme, àrees recreatives, drons, globus, parapents, buggy-kite, sobrevol amb helicòpters, amb ultralleugers, motos de neu, etc) i tan sigui esporàdica com recurrent
C27: 6.2 | D27: Molèsties per activitats militars | E27: Activitats militars de qualsevol mena (camps militars, assajos amb artilleria, etc)
C28: 6.3 | D28: Altres tipus de molèsties | E28: Qualsevol altra molèstia (per bany en rius i tolles, passeig de gossos, peregrinatges, aplecs, recerca sobre espècies, extraccions arqueològiques, vandalisme, tràfic de drogues, etc)
C29: 6.4 | D29: Molèsties per activitats multitudinàries | E29: Activitats organitzades i multitudinàries, per exemple curses de muntanya, festivals, esdeveniments, filmacions, fins i tot enterraments
A30: 7 | B30: Gestió i modificació de sistemes naturals | C30: 7.1 | D30: Foc | E30: Foc, grans incendis forestals i supressió del foc, incloses activitats de restauració post-foc
C31: 7.2 | D31: Gestió de l'aigua | E31: Construcció i utilització de preses, canals, captacions, pous, dics, etc de qualsevol mena. Extracció / captacions d'aigua per rec, etc. Construcció de basses per fer neu artificial. Dessaladores, potabilitzadores, depuradores, conduccions, trasvassaments, emissaris de salmorres, alteració de cabals, gestió de cabals en rius
C32: 7.3 | D32: Moviments de terres i sediments | E32: Gestió i estabilització de terrenys i sediments (estabilització de dunes, construccions en litorals, remediació de sòls, restauració de mines, dragatges, moviments de sorres, etc)
C33: 7.4 | D33: Modificació del clima | E33: Activitats per modificar el clima o processos naturals (prevenció de gelades, fertilització amb ferro a l'oceà, captura de carboni, etc)
C34: 7.5 | D34: Gestió d'hàbitats | E34: Gestió d'hàbitats: gestió d'aigua dolça de rec i arrossars (que pot afectar a llacunes, etc), retirada de fustes en rius, desbrossades, creació d'esculls artificials, alimentació d'ocells, tancament de coves, barreres elèctriques
C35: 7.6 | D35: Desaparició d'activitats tradicionals | E35: Desaparició de pràctiques tradicionals com pastura extensiva, canvi en el maneig de la pastura, la tipologia de bestiar, caça per control de predadors, etc
A36: 8 | B36: Espècies invasores i patògens | C36: 8.1 | D36: Espècies invasores | E36: Espècies invasores com rates en illes, animals domèstics assilvestrats, musclo zebra, bambú, peixos introduïts com Phoxinus en estanys d'alta muntanya, etc
C37: 8.2 | D37: Espècies desestabilitzades | E37: Espècies natives desestabilitzades com superpoblació de cèrvids, porcs senglars, manca de carnívors, blooms d'algues, plagues d'insectes, o amb impactes puntuals com predadors sobre espècies sensibles com colònies d'ocells, gall fer, etc
C38: 8.3 | D38: Introducció de genotips aliens | E38: Material genètic introduït com cultius resistents a plagues, creuament de gat domèstic amb gat fer, restauracions d'hàbitats fetes amb varietats alienes, arbres o instectes modificats genèticament, aquicultura amb espècies no natives, etc
C39: 8.4 | D39: Plagues i patògens | E39: Malalties que afecten conills, grip aviar, botulisme, castanyers, oliveres, cítrics, amfibis, etc
A40: 9 | B40: Polució | C40: 9.1 | D40: Polució aquàtica | E40: Polució dissolta en aigua (aigües sèptiques, efluents industrials, pesticides, fertilitzants, efluents de la mineria, excès de nutrients en activitats de l'aquicultura, purins, potasses per desfer la neu en pistes i carreteres, etc
C41: 9.2 | D41: Residus sòlids | E41: Residus sòlids de qualsevol orígen i en medi terrestre o marí, inclosos de la caça, pesca, agricultura, aqüicultura, del turisme, construcció, transport, xarxes fantasma i elements abandonats al medi
C42: 9.3 | D42: Polució aèria | E42: Residus en medi aeri com partícules, gasos, o partícules radioactives
...

Sheet Llistes
A1: Llista d'amenaces OS | D1: Si/No | G1: Codi Amenaça | H1: Nom Amenaça
A2: 0 | B2: No especificada | D2: Si | G2: 0 | H2: No especificada
A3: 2 | B3: Urbanització i edificació | D3: No | G3: 1.1 | H3: Urbanització residencial
A4: 3 | B4: Producció primària | D4: Dubtós | G4: 1.2 | H4: Urbanització comercial o industrial
A5: 4 | B5: Producció d'energia i mineria | G5: 1.3 | H5: Àrees recretives i turístiques
A6: 5 | B6: Infrastructures de transport i serveis | G6: 2.1 | H6: Activitat agrícola
A7: 6 | B7: Extracció de recursos naturals | G7: 2.2 | H7: Plantacions forestals
A8: 7 | B8: Molèsties | G8: 2.3 | H8: Ramaderia
A9: 8 | B9: Gestió i modificació de sistemes naturals | G9: 2.4 | H9: Aqüicultura
A10: 9 | B10: Espècies invasores i patògens | G10: 3.1 | H10: Activitats de la mineria
A11: 10 | B11: Polució | G11: 3.2 | H11: Producció d'energia renovable
A12: 11 | B12: Grans pertorbacions naturals | G12: 4.1 | H12: Vials de transport
B13: Canvi global i/o climàtic | G13: 4.2 | H13: Conduccions
G14: 4.3 | H14: Infrastructures marines
G15: 4.4 | H15: Tancaments i vallats
G16: 5.1 | H16: Caça i recol·lecció d'animals
G17: 5.2 | H17: Recol·lecció de vegetals
G18: 5.3 | H18: Treballs forestals
G19: 5.4 | H19: Pesca i semblants
G20: 6.1 | H20: Molèsties per activitats recreatives
G21: 6.2 | H21: Molèsties per activitats militars
G22: 6.3 | H22: Altres tipus de molèsties
G23: 6.4 | H23: Molèsties per activitats multitudinàries
G24: 7.1 | H24: Foc
G25: 7.2 | H25: Gestió de l'aigua
... G43: 11.4 | H43: Pujada del nivell del mar

Sheet Full1
A1: Comú / Específic | B1: Obligatori / Optatiu | C1: Prioritat | E1: Pel POA
A2: Comú | B2: Obligatori | C2: MÀXIMA | E2: Si
A3: Específic | B3: Optatiu | C3: ALTA | E3: No
C4: MITJANA
C5: BAIXA
C6: FORA DEL TERMINI DEL PLA
