Workbook

Sheet ESTRATÈGIA
C3: ESQUEMA CONCEPTUAL PER A LA ELABORACIÓ DEL PLA ESTRATÈGIC EN EL MARC
C4: DELS ESTÀNDARDS OBERTS PER A LA GESTIÓ ADAPTATIVA A CATALUNYA

Sheet INSTRUCCIONS
A1: PESTANYA DE PRIORITZACIÓ
A2: Llistat elements: | B2: Tasca 1: Revisar el llistat d'elements prioritzats per tal d'avaluar si cal afegir-ne algun o treure'n algun. A la columna comentaris cal argumentar, breument, el perquè de la decisió.
A4: Llistat amenaces: | B4: Tasca 2: A partir de la taxonomia d'amenaces que es troba a la pestanya final, cal omplir les tres columnes (E, F i G) amb les tres principals amenaces per a la conservació de l'element. S'afegeixi una darrera columna per si hi ha amenaces que no es troben incloses a la taxonomia.
A6: PESTANYA DEL PLA
A7: Explicacions:
B8: 7 Eixos temàtics
B9: Els objectius generals estan directament associats als objectius generals dels Plans de Protecció del medi naatural i del paisatge. NO ES PODEN RETOCAR
B10: Objectius estratègics: definits en un grup de treball intern de serveis Centrals i dels Parcs durant l'any 2023. NO ES PODEN RETOCAR
B11: Objectius operacionals: definits en un grup de treball intern de serveis Centrals i dels Parcs durant l'any 2023
A14: Tasques a realitzar:
A15: Objectius operacionals: | B15: El llistat d'objectius operacionals té una columna al costa (columna I) on s'indica si l'objectiu és obligatori de mantenir al Pla estratègic o no.
B16: Tasca 1: Columna I. Revisar els que es posa com a obligatoris per veure si són realment aplicables a l'espai o no.
B17: Tasca 2: Columna I. Revisar els que posa "Opcional" per identificar els que són aplicables o no a l'espai. O, també, determinar si algun d'ells seria aplicable o es pot concretar millor el redactat de l'objectiu.
B18: Tasca 3: Columna J. En ambdós casos, cal posar a la columna J, el redactat final de l'objectiu concretat a l'espai. En el cas de que l'objectiu s'elimina, posar "NA". Ara es reprodueix el redactat dels objectius operacionals derivats del grup de treball esmentat
B19: Tasca 4: Columna K. Per tots els casos en que hi ha modificació respecte al redactat original de l'objectiu operatiu -i, també, en el cas que es consideri que s'ha d'eliminar-, a la columna K cal redactar molt breument el motiu pel qual es prèn la decisió.
B20: Tasca 5: Columna L. Incloure un Si/No avaluant si l'objectiu operatiu podria tenir mesures a incorporar a la programació d'actuacions de l'espai (Si) o, per altra banda, el seu assoliment depèn d'altres òrgans, com l'ACA o altres serveis dins la DGPAMN (No).
B21: Tasca 6: Columna M. Definir la prioritat que hauria de tenir l'assoliment de l'objectiu (màxima, si cal assolir en els propers 4 anys, o altrament alta, mitja o baixa). També hi ha l'opció de prioritat a assolir a més llarg termini.
A22: Propostes genèriques d'accions: | B22: Tasca 7: Columna N. En aquest columna cal introduir les accions, de manera genèrica, que caldria aplicar a l'espai per tal d'assolir l'objectiu operatiu. No es tracta d'un llistat d'accions concretes si no, més aviat, accions generals que acabarien concretant-se en la programació anual. PER A INICIAR AMB LA TAULA US PODEU BASAR MOLT EN LA FEINA JA FETA DE PRIORITZACIÓ DE MESURES PEL MAP
B23: En el cas dels objectius operatius que s'ha considerat que no són aplicables a l'espai, cal avaluar si podrien tenir alguna acció que sí tindria sentit d'incloure al Pla estratègic tot i que l'objectiu de manera global no hi ´seria d'aplicació.
A24: Indicadors: | B24: Tasca 8: Columna Q. Posar un indicar SMART per avaluar el compliment de la mesura proposada a la columna N
A25: Fites a assolir en 4 anys: | B25: Tasca 9: Posar un valor de l'indicador a asolir: valor mínim necessari (columna R) o valor desitjable (columna S).
A26: Hores de dedicació: | B26: Tasca 10: Columna T. Realitzar una aproximació el més acurada que es pugui de les hores del personal de gestió de l'espai que cal destinar per a la realització de l'acció.
A27: Àrea responsable: | B27: Tasca 11: Columna U. Indicar quina àrea de l'equip de gestió és responsable de coordinar l'execució de l'acció.
A28: Persona responsable: | B28: Tasca 12: Columna V. Indicar quina persona dins l'àrea seria l'encarregada.
A30: PESTANYA DEL VINCLE
A31: Definir vincle amenaça vs. Obj. Operatiu | B31: Tasca 1: Establir / Revisar el vincle entre les amenaces identificades a la pestanya de priorització i els objectius operatius definits a la columna J de la pestanya Pla. La columna B conté el llistat dels objectius operatius tal i com quedaran definits després de la vostra revisió.
B32: Tasca 2: En cas que es pugui, definir l'amenaça / factor / causa concret a la que atén l'objectiu definit al Pla. Poden ser més d'una.
B33: És important que es visualitzi a quina amenaça es dirigeix l'objectiu operatiu que es proposa al Pla, tot i que, no sempre hi ha d'haver un vincle clar. Pot haver algun objectiu sense amenaça vinculada.

Sheet PRIORITZACIÓ
A2: Llistats corresponent a l'espai de Natura 2000 ES5120004 "Zona volcànica de la Garrotxa"
A3: LLISTAT D'ELEMENTS PRESENT A L'ESPAI | H3: AMENACES PER A CADA ELEMENT
A4: Hàbitats d'interès comunitari | B4: PE | C4: MAP | D4: 25% IdR | E4: Puntuació IdR | F4: PRIORITARI PE | G4: Comentaris en cas de canvi en la priorització | H4: Amenaça 1 segons taxonomia | I4: Amenaça 2 segons taxonomia | J4: Amenaça 3 segons taxonomia | K4: Altres amenaces | L4: Comentari
A5: 3150 - Estanys naturals eutròfics amb vegetació natant (Hydrocharition) o poblaments submersos d'espigues d'aigua (Potamion) | C5: Si | F5: Sí | H5: Gestió de l'aigua | I5: Desaparició d'activitats tradicionals | J5: Impactes del canvi climàtic relatius a l'alteració del règim de precipitació i sequera | K5: Impactes del canvi climàtic relatius a l'alteració del règim de temperatures | L5: Activitat ramadera
A6: 3240 - Rius de tipus alpí amb bosquines de muntanya | C6: Si | F6: Sí | H6: Gestió de l'aigua | I6: Activitat agrícola | J6: Polució aquàtica | K6: Reducció de l'espai fluvial
A7: 3250 - Rius mediterranis amb vegetació del Glaucion flavi | B7: Si | F7: Sí | H7: Gestió de l'aigua | I7: Activitat agrícola | J7: Polució aquàtica | K7: Reducció de l'espai fluvial
A8: 3270 - Rius amb vores llotoses colonitzades per herbassars nitròfils del Chenopodion rubri (p.p.) i del Bidention (p.p.) | B8: Si | C8: Si | D8: Si | E8: 4 | F8: Sí | H8: Gestió de l'aigua | I8: Activitat agrícola | J8: Polució aquàtica | K8: Reducció de l'espai fluvial
A9: 6210 - Prats -i fàcies emmatades- medioeuropeus, seminaturals, sobre substrat calcari (Festuco-Brometea) | B9: Si | C9: Si | F9: Sí | H9: Ramaderia | I9: Espècies desestabilitzades | J9: Espècies invasores | K9: Deute d'extinció | L9: Sobrepastura i abandonament o falta de manteniment d'aquests prats / Entenem per espècie desestabilitzades el porc senglar / deute d'extinció
A10: 6510 - Prats de dall de terra baixa i de la muntanya mitjana (Arrhenatherion) | B10: Si | C10: Si | D10: Si | E10: 3.625 | F10: Sí | H10: Desaparició d'activitats tradicionals | I10: Activitat agrícola | J10: Espècies desestabilitzades | K10: Espècies invasores | L10: Parcel·les petites marginals abandonades / Parcel·les amb millor sòls canvi d'ús /Entenem per espècie desestabilitzades el porc senglar / deute d'extinció
A11: 8210 - Costers rocosos calcaris amb vegetació rupícola | B11: Si | C11: Si | F11: No | G11: No s'observa una amenaça greu.
A12: 8220 - Costers rocosos silicis amb vegetació rupícola | C12: Si | F12: No | G12: No s'observa una amenaça greu.
A13: 8230 - Terraprims silicis amb vegetació pionera (Sedo-Scleranthion) | C13: Si | D13: Si | E13: 4.75 | F13: No | G13: Hàbitat sense presència al Parc Natural | L13: Xavier oliver mirarà si aquest hàbitat està prsent al Parc
A14: 9120 - Fagedes acidòfiles | B14: Si | C14: Si | D14: Si | E14: 3.625 | F14: Sí | H14: Treballs forestals | I14: Impactes del canvi climàtic relatius a l'alteració del règim de precipitació i sequera | L14: Treballs forestals que sobrexploten el bosc
A15: 9130 - Fagedes neutròfiles | C15: Si | D15: Si | E15: 3.625 | F15: Sí | H15: Treballs forestals | I15: Impactes del canvi climàtic relatius a l'alteració del règim de precipitació i sequera | L15: Treballs forestals que sobrexploten el bosc
A16: 9150 - Fagedes calcícoles xerotermòfiles | B16: Si | C16: Si | D16: Si | E16: 3.875 | F16: Sí | H16: Treballs forestals | I16: Impactes del canvi climàtic relatius a l'alteració del règim de precipitació i sequera | L16: Treballs forestals que sobrexploten el bosc
A17: 9160 - Rouredes de roure pènol i boscos mixtos del Carpinion betuli | B17: Si | C17: Si | F17: Sí | H17: Treballs forestals | I17: Impactes del canvi climàtic relatius a l'alteració del règim de precipitació i sequera
A18: 9180p - Boscos de vessants rostos, tarteres o barrancs, del Tilio-Acerion | C18: Si | D18: Si | F18: No | G18: Hàbitat sense presència al Parc Natural. | L18: comprovar si existeix
A19: 91E0p - Vernedes i altres boscos de ribera afins (Alno-Padion) | B19: Si | C19: Si | D19: Si | E19: 3.625 | F19: Sí | H19: Gestió de l'aigua | I19: Activitat agrícola | J19: Polució aquàtica | K19: Reducció de l'espai fluvial / invasores
A20: 9260 - Castanyedes | B20: Si | C20: Si | F20: No | G20: Són plantacions.
A21: 92A0 - Alberedes, salzedes i altres boscos de ribera | B21: Si | C21: Si | F21: Sí | H21: Treballs forestals | I21: Impactes del canvi climàtic relatius a l'alteració del règim de precipitació i sequera
A22: 9340 - Alzinars i carrascars | B22: Si | C22: Si | D22: Si | E22: 4.25 | F22: Sí | H22: Treballs forestals | I22: Impactes del canvi climàtic relatius a l'alteració del règim de precipitació i sequera
A23: 9540 - Pinedes mediterrànies | B23: Si | C23: Si | D23: Si | F23: No | G23: No s'observa una amenaça greu.
A24: 34n Joncedes | B24: Si | F24: Sí | H24: Ramaderia | L24: Abandonament i canvi d'activitat ramadera
A25: 34g Fenassars | F25: Sí | H25: Ramaderia | L25: Abandonament i canvi d'activitat ramadera
A26: 35h Prats silicícoles i xeròfils | F26: Sí | H26: Ramaderia | I26: Espècies invasores
A27: 41.b332+ Altres bedollars, sovint secundaris, pirinencs (i del territori catalanidic septentrional) | B27: Si | F27: Sí | H27: Treballs forestals | I27: Impactes del canvi climàtic relatius a l'alteració del règim de precipitació i sequera
A28: 44.128+ Gatelledes (boscos, generalment baixos, de Salix atrocinerea), amb Equisetum telmateia, Carex pendula..., de fons de barrancs i depressions, amb sòl xop, al territori catalanídic | F28: Sí | H28: Gestió de l'aigua | I28: Activitat agrícola | J28: Polució aquàtica | K28: Reducció de l'espai fluvial
A30: Espècies presents a l'espai | B30: PE | C30: MAP | D30: 25% IdR | E30: Puntuació IdR | F30: PRIORITARI PE | G30: Comentaris en cas de canvi en la priorització | H30: Amenaça 1 segons taxonomia | I30: Amenaça 2 segons taxonomia | J30: Amenaça 3 segons taxonomia | K30: Altres amenaces
A31: Abida secale | B31: Si | F31: Sí | H31: Gestió de l'aigua | I31: Impactes del canvi climàtic relatius a l'alteració del règim de precipitació i sequera
A32: Accipiter gentilis gentilis | C32: Si | F32: No | G32: Espècie forestal rapinyaire amb la massa forestal no pateix
A33: Aconithum pyrenaicum | B33: Si | F33: Sí | H33: Treballs forestals | I33: Activitat agrícola | J33: Impactes del canvi climàtic relatius a l'alteració del règim de precipitació i sequera
A34: Actitis hypoleucos | C34: Si | F34: No | G34: No s'observa una amenaça greu
A35: Alcedo atthis | C35: Si | D35: Si | E35: 1.833 | F35: No | G35: No s'observa una amenaça greu
A36: Alytes obstetricans | C36: Si | F36: Sí | H36: Gestió de l'aigua | I36: Activitat agrícola | J36: Plagues i patògens
A37: Anas platyrhynchos | C37: Si | F37: No | G37: No s'observa una amenaça greu
A38: Asplenium marinum | B38: Si | F38: No
A39: Austropotamobius pallipes | B39: Si | C39: Si | D39: Si | E39: 2.167 | F39: Sí | H39: Plagues i patògens | I39: Gestió de l'aigua | J39: Espècies invasores
A40: Barbastella barbastellus | C40: Si | D40: Si | E40: 2.389 | F40: Sí | H40: Treballs forestals
A41: Barbus meridionalis | C41: Si | D41: Si | E41: 2.389 | F41: Sí | H41: Gestió de l'aigua | I41: Polució aquàtica | J41: Espècies invasores
A42: Belisarius xambeui | B42: Si | F42: Sí | H42: Treballs forestals
...

Sheet PLA_v2025
A1: MODEL DE PLA ESTRATÈGIC PELS ENP
B2: Espai natural protegit: | C2: Zona Volcànica de la Garrotxa
P3: Exemples d'accions | U3: Fita a assolir en 4 anys | X3: Gestió interna | AA3: Gestió externa (AG) | AD3: Calendarització interna (AG)
A4: EIXOS | C4: Objectius generals (PP) | E4: Objectius estratègics | F4: Codi | G4: Objectius operatius | H4: Codi | I4: Comú / Específic | J4: Obligatori / Optatiu | K4: Objectius operatius PNZVG | L4: Justificació del canvi o no inclusió d'un OP | M4: Objectiu aplicable amb accions que depenen directament del PNZVG | N4: Objectiu aplicable amb accions que depenen directament de la Direcció General de PAMN | O4: Prioritat | P4: Propostes genèriques d'accions | Q4: Marc de referència | R4: Resultats derivats | S4: Proposta d'accions | T4: Indicadors | U4: Valor mínim | V4: Valor objectiu | W4: COMENTARIS LAVOLA | X4: Hores de dedicació | Y4: Àrea responsable | Z4: Persona responsable | AA4: Pressupost (€) | AB4: Contractació externa | AC4: Competència DG | AD4: Executat | AE4: 2025 | AF4: 2026 | AG4: 2027 | AH4: 2028
A5: NATURA | B5: 1 | C5: CONSERVAR LA NATURA i restaurar els ecosistemes, els processos naturals i seminaturals, la biodiversitat i la geodiversitat associada. | D5: 01.1 | E5: Adequar i fer eficient la conservació dels elements objecte de gestió prioritària marcats per la DG a l'ENP | F5: 01.1.1 | G5: Implementar i executar plans de gestió específics per a hàbitats i espècies de conservació prioritària dins l'ENP | H5: 01.1.1 | I5: Comú | J5: Obligatori | K5: Implementar i executar plans i mesures de gestió específiques per a hàbitats i espècies de conservació prioritària dins l'ENP | L5: Canvi de redactat OP. Implementació d'accions no emmarcades en un Pla de gestió específic | M5: Sí | N5: Sí | O5: MÀXIMA | P5: *Realització d'accions per a la millora dels elements prioritzats a l'espai *Elaboració de plans de gestió per elements prioritzats a l'espai | Q5: MAP | R5: SFF: Elaboració de plans de gestió específics per a espècies de conservació prioritària i directrius de gestió d'hàbitats. SFF/SENP: Definir a nivell de cluster quins son els que es poden elaborar conjuntament. | S5: 1) Elaboració o actualització de plans, protocols o estratègies de conservació per hàbitats i espècies d'interès (cranc de riu autòcton, nàiade i espècies qualificades de vulnerables al Catàleg de fauna). 2) Actuacions de restauració i millora d'hàbitats i d'espècies d'interès. 3) Treballs de millora i gestió específics pel cranc de riu. | T5: 1) Nombre de plans de gestió específics per a elements prioritaris redactats i implementats. 2) Nombre d'actuacions de restauració 3) Nombre d'exemplars reintroduits | U5: 1) 1 2) 1 3) 100 | V5: 1) 10 2) 4 3) 1000 | X5: 420 420 420 | Y5: Patrimoni Natural | Z5: Emili Bassols Joan Montserrat Bernat Perramon
F6: 01.1.2 | G6: Adaptar i executar plans de gestió específics per a elements geològics de conservació prioritària dins l'ENP | H6: 01.1.2 | I6: Comú | J6: Obligatori | K6: Actualitzar i executar programes de gestió específics per a elements geològics de conservació prioritària dins l'ENP. | L6: Atès que ja es disposa d'una Estratègia de gestió del vulcanisme que cal actualitzar (és del 2000). | M6: Sí | N6: Sí | O6: MÀXIMA | P6: * Elaboració de l'inventari d'elements geològics a l'espai *Aplicació de les directrius de gestió de l'inventari de patrimoni geològic (ICGC) | S6: 1) Asistencia tècnica a la gestió i conservació del patrimoni geològic i la geodiversitat. 2) Actualització de l'Estratègia de conservació del vulcanisme del PNZVG 3) Actuacions de manteniment i conservació d'afloraments d'interès geològic (AIG), per exemple, la cinglera de Castellfollit de la Roca. 4) Restauració d'afloraments d'interès geològic (AIG). Per exemple, tossol del Bosc de Tosca o gredera del volcà del Racó. | T6: 1) Nombre d'hores dedicades a l'assessorament tècnic. 2) Nombre d'actuacions de millora d'elements geològics prioritaris executades. 3) Nombre d'actuacions de manteniment i conservació d'elements geològics prioritaris executades. 4) Nombre d'afloraments restaurats | U6: 1) 50 2) 15 3) 1 4)1 | V6: 1) 150 2) 25 3) 7 4)4 | X6: 150 | Y6: Patrimoni Natural | Z6: Emili Bassols
D7: 01.2 | E7: Executar les mesures de gestió directa previstes en els intruments de planificació per la conservació i la gestió adaptativa dels elements clau de l'ENP | F7: 01.2.1 | G7: Implementar la metodologia de gestió adaptativa (Estàndards Oberts de Gestió Adaptativa a Catalunya) en tots els processos de l'ENP | H7: 01.2.1 | I7: Comú | J7: Obligatori | K7: =G7 -> Implementar la metodologia de gestió adaptativa (Estàndards Oberts de Gestió Adaptativa a Catalunya) en tots els processos de l'ENP | M7: Sí | N7: Sí | O7: ALTA | P7: *Definició d'un protocol per tal d'incorporar la metodologia dels Estàndards Oberts pels processos més rellevants per a la conservació a l'espai | Q7: ESNATURA | R7: SENP: Elaboració d'un manual per la implementació dels OSAM | S7: 1) Definició d'un protocol per incorporar la metodologia dels estandards oberts en els processos més rellevants de conservació de l'espai. 2) Creació d'un sistema de seguiment de les accions de gestió de l'espai. | T7: 1) Percentatge de projectes transversals que incorporen aquesta metodologia. 2) Creació del protocol | U7: 1) 25 2) 1 | V7: 1) 75 2)1 | X7: 100 | Y7: Direcció | Z7: Joan Pijoan
F8: 01.2.2 | G8: Executar les mesures previstes en els plans de conservació o recuperació d'espècies amenaçades de forma coordinada amb el Servei de Flora i Fauna en l'àmbit de l'ENP | H8: 01.2.2 | I8: Comú | J8: Obligatori | K8: =G8 -> Executar les mesures previstes en els plans de conservació o recuperació d'espècies amenaçades de forma coordinada amb el Servei de Flora i Fauna en l'àmbit de l'ENP | M8: Sí | N8: Sí | O8: MÀXIMA | P8: * Implicació i participació en la redacció dels plans de conservació /recuperació d'espècies amenaçades * Execució de les accions dins els plans que pertoquin a cada espai (incorporar totes les mesures que surten als plans ja aprovats que tenen incidència a l'espai) * Col.laboració en l'obtenció de la informació necessària dins els espais per al desenvolupament dels Plans | Q8: MAP Catàlegs | R8: SFF: Elaboració de plans de conservació o recuperació d'espècies protegides | S8: 1) Assistència tècnica en la gestió i conservació de la flora i la vegetació. 2) Col·laboració amb el SFF en l'elaboració de plans de conservació o recuperació d'espècies de fauna i flora. 3) Proporcionar la informació disponible en l'espai en relació a les espècies de les quals s'estigui redactant el pla de conservació o recuperació. 4) Execució de les mesures previstes en els plans de conservació o recuperació aplicables al nostre espai. 5) Obtenció d'informació sobre l'estatus de conservació d'espècies que, en funció de l'evolució de les seves poblacions, podrien ser susceptibles disposar d'un pla de conservació o recuperació en un futur. 6) Treballs de conservació "ex-situ" de flora protegida /amenaçada. 7) Adaptació d'un parell de canals de rescloses Fluvià com a hàbitats aptes a la reproducció de nàiades. 8) Assistència tècnica en la gestió de la fauna | T8: 1) Nombre de plans de conservació o recuperació amb els quals s'ha col·laborat des de l'espai. 2) Nombre de projectes treballats conjutament 3) Informació proporcionada 4) Nombre de mesures 5) Nombre de tàxons els quals obtens informació del seu estat de conservació 6) Nombre de tàxons els quals fas treballs de conservació 7) Nombre de canals o rescloses adaptades 8) Nombre de consultes realitzades | U8: 1) 2 2) 1 3) 1 4) 1 5) 1 6) 1 7) 1 8) 1 | V8: 1) 4 2) 4 3) 10 4) 5 5) 10 6) 10 7) 2 8) 50 | X8: 320 | Y8: Patrimoni Natural | Z8: Emili Bassols
F9: 01.2.3 | G9: Executar les mesures de gestió previstes en els plans de control i erradicació d'espècies exòtiques de forma coordinada amb el Servei de Flora i Fauna en l'àmbit de l'ENP | H9: 01.2.3 | I9: Comú | J9: Obligatori | K9: Rebaixar l'impacte de les espècies exòtiques invasores mitjançant l'execució de les mesures de gestió previstes en els plans de control i erradicació d'espècies exòtiques de forma coordinada amb el Servei de Flora i Fauna en l'àmbit de l'ENP i elaborant documents informatius sobre maneig d'espais d'interès. | L9: Es considera que l'actuació sobre les EEI requereix d'un esforç de gestió més ampli que el simple compliment d'allò que puguin proposar els plans de control i eradicació del SFF. | M9: Sí | N9: Sí | O9: MÀXIMA | P9: * Implicació i participació en la redacció (cal identificar els plans que estan ja en marxa o previstos i posar les mesures concretes) * Execució de les accions dins els plans que pertoquin a cada espai * Col.laboració en l'obtenció de la informació necessària dins els espais per al desenvolupament dels Plans | Q9: ESNATURA MAP | R9: SFF: Elaboració de plans de control i erradicació d'espècies exòtiques | S9: 1) Obtenció d'informació sobre l'evolució de les poblacions d'espècies exòtiques presents a l'espai que podrien ser susceptibles de disposar d'un pla de control i eradicació. 2) Executar accions preventives de control i eradicació d'espècies exòtiques invasores. 3) Elaborar manuals de gestió per evitar la proliferació d'espècies exòtiques invasores en hàbitats d'interès. 4) Col·laboració amb el SFF en l'elaboració de plans de control i eradicació d'espècies exòtiques de fauna i flora. 5) Proporcionar la informació disponible en l'espai en relació a les espècies exòtiques de les quals s'estigui redactant un pla de control i eradicació. 6) Execució de les mesures previstes en els plans de control i eradiació aplicables al nostre espai. | T9: 1) Nombre d'espècies exòtiques invasores de les quals es recull informació de les seves poblacions. 2) Nombre d'accions preventives de control i eradicació. 3) Nombre d'espècies que disposen d'un manual de gestió. 4) Nombre de plans en els quals es col·labora. 5) Nombre d'espècies de les quals es proporciona informació. 6) Nombre d'accions executades. | U9: 1) 1 2) 1 3) 2 4) 1 5) 1 6) 1 | V9: 1) 10 2) 4 3) 5 4) 4 5) 4 6) 4 | X9: 160 | Y9: Patrimoni Natural | Z9: Emili Bassols
F10: 01.2.4 | G10: Desplegar els objectius i tasques recollits en els instruments de referència i compromisos internacionals | H10: 01.2.4 | I10: Específic | J10: Optatiu | K10: =G10 -> Desplegar els objectius i tasques recollits en els instruments de referència i compromisos internacionals | M10: Sí | N10: Sí | O10: MITJANA | P10: * Desplegament dels objectius recollits en l'Estratègia de la Xarxa d'àrees marines protegides del Mediterrani (MedPAN network) * Col·laboració en el compliment dels objectius i tasques derivats de la Mediterranean Climate Action Partnership en matèria de biodiversitat i canvi climàtic i els seus impactes sobre la sequera, calor i incendis * Col·laboració en la implementació pràctica de projectes de l'àrea internacional i dels compromisos amb les entitats membres UICN, Euroregió Pirineus Mediterrània | S10: 1) Participació en projectes d'abast internacional. Per exemple, live ECOAdapt50, FloraLab + POCTEFA. | T10: 1) Nombre de projectes en els que es participa. | U10: 1) 1 | V10: 2) 4 | W10: A columna M marcar que "Si" que té mesures aplicables que depenen del PN. Com a criteri general, encara que sigui participació, si s'incorporen accions/mesures posar que sí a la columna | X10: 160 | Y10: Patrimoni Natural | Z10: Bernat Perramon
D11: 01.3 | E11: Crear ecosistemes complexes, resilients, i d'alta biodiversitat per garantir la recuperació dels processos ecosistèmics | F11: 01.3.1 | G11: Identificar espais pel foment de la dinàmica natural i l'aprofitament no extractiu | H11: 01.3.1 | I11: Comú | J11: Obligatori | K11: =G11 -> Identificar espais pel foment de la dinàmica natural i l'aprofitament no extractiu | M11: Sí | N11: No | O11: MÀXIMA | P11: *Participar en la identificació d'espais pel foment de la dinàmica natural i l'aprofitament no extractiu dins l'ENP en base a uns criteris metodològics predefinits *Afavorir la creació d'hàbitats per a la conservació d'espècies | Q11: ESNATURA | R11: SENP/SFF: Definir criteris metodològics | S11: 1) Elaborar un catàleg d'espais potencials per a ser gestionats en dinàmica natural. | T11: 1) Increment de superfície d'espais gestionats en dinàmica natural. | U11: 1) 1 | V11: 1) 100 | X11: 145 | Y11: Patrimoni Natural | Z11: Joan Montserrat
F12: 01.3.2 | G12: Afavorir la maduresa dels sistemes forestals | H12: 01.3.2 | I12: Específic | J12: Optatiu | K12: =G12 -> Afavorir la maduresa dels sistemes forestals | M12: Sí | N12: Sí | O12: MÀXIMA | P12: *Participar i impulsar la planificació i execució d'accions d'acceleració de la maduresa forestal en zones boscoses dins l'ENP en base als criteris metodològics predefinits | Q12: MAP | R12: SENP/SFF: Definir criteris metodològics | S12: 1) Participar i impulsar la planificació i execució d'accions d'accelaració de la maduresa forestal en zones boscoses dins l'espai natural protegit prioritzant reserves naturals en base a criteris metodològics definits (prioritzar reserves naturals, zones definides pel PEZVG com a protecció de vesants. 2)Diagnosi i pla de custódia i preservació dels boscos d'alt valor ecològic anb prioritat als bosos mdurs del PNZVG | T12: 1) Nombre d'execucions destinades a millorar el grau de maduresa de la massa forestal. 2) Percentatge d'hectàrees potencials a projectes de custòdia. | U12: 1) 1 2) 0 | V12: 1) 5 2)33 | X12: 120 | Y12: Patrimoni Natural Direcció | Z12: Joan Montserrat Joan Pijoan
F13: 01.3.3 | G13: Generar pertorbacions controlades | H13: 01.3.3 | I13: Específic | J13: Optatiu | K13: No aplica | P13: *Elaboració d'una planificació d'actuacions de simulació d'incendis forestals naturals (cremes controlades) dins l'espai en base als criteris metodològics predefinits. *Realització dels estudis necessaris i participació en la reintroducció de grans herbívors, carnívors o carronyaires dins l'ENP en base als criteris metodològics predefinits. | Q13: MAP | R13: SENP/SFF: Definir criteris metodològics | S13: JOAN MONTSERRAT | T13: 1) Informe de les modificacions forestals executades | W13: Pendent definir mesures i valor indicadors. | Y13: Patrimoni Natural | Z13: Joan Montserrat
F14: 01.3.4 | G14: Restaurar la dinàmica natural dels rius | H14: 01.3.4 | I14: Específic | J14: Optatiu | K14: Restaurar i conservar la dinàmica i estructura natural dels rius, les zones humides, i altres hàbitats d'aigua dolça | L14: Canvi de redactat OP. Adaptar el redactat per a tot tipus de masses d'aigua | M14: Sí | P14: *Realització i impuls de la renaturalització de lleres i creació de zones de laminació dins l'ENP en base als criteris metodològics predefinits | Q14: MAP | R14: SENP/SFF: Definir criteris metodològics | S14: 1) Eliminació de rescloses en desús i permeabilitzar les altres per recuperar la qualitat dels sistemes fluvials. 2) Elaboració d'un catàleg de punts d'aigua en l'àmbit del Parc Natural. 3) Execució de les actuacions de recuperació de punts d'aigua per afavorir la biodiversitat previstes en el catàleg. 4) Elaborar un document de proposta per a promoure la incorporació de les zones humides d'interès del Parc Natural en l'Inventari de Zones Humides de Catalunya. Mulladius de Verlets. 5) Elaborar un document de proposta per a Incloure les fonts, les basses i les zones humides del Parc Natural com a elements naturals a protegir en els documents de planificació municipal (POUM i altres). | T14: 1) Nombre de rescloses eliminades 2) Redacció del catàleg 3) Nombre d'actuacions executades 4) Redacció del document 5) Elaborar un document de proposta | U14: 1) 1 2) 1 3) 1 4) 1 5) 1 | V14: 1) 2 2) 1 3) 5 4) 1 5) 1 | W14: Mancaria marcar que "SI" que té mesures aplicables que depenen del PN a columna M. Si volguessiu afegir un indicador més relacionat amb 1) i lligat al compliment de l'objectiu, es podria incorporar "km de riu en dinàmica natural o seminatural" | X14: 380 | Y14: Patrimoni Natural | Z14: Emili Bassols
F15: 01.3.5 | G15: Fomentar el paisatge en mosaïc | H15: 01.3.5 | I15: Específic | J15: Optatiu | K15: =G15 -> Fomentar el paisatge en mosaïc | M15: Sí | O15: MÀXIMA | P15: *Realització d'accions per gestionar l'herbivoria domèstica associada a la ramaderia extensiva *Aplicació dels criteris metodològics predefinits en un manual tècnic de bones pràctiques en ramaderia extensiva i recuperació i manteniment de pastures aplicat a l'ENP. *Coordinació i gestió dels ramats locals en actuacions de restauració de pastures i desembosc. | Q15: ESNATURA | R15: SENP/SFF: Definir criteris metodològics | S15: 1) Identificació cartogràfica dels espais oberts prioritaris. 2) Recuperació d'espais oberts. 3) Mantenir espais d'interès prioritaris i els prats d'interès biológic acord amb el PEZVG 4) Seguiment prats 5) Foment de la ramederia extensiva per a mantenir espais oberts | T15: 1) Nombre d'actuacions executades 2) Relació entre espais oberts i espais forestals / matollars / marges recuperats. Nombre Ha. 3) Nombre d'hectàres 4) Percentatge de prats en bon estat de conservació / Evolució de l'estat de conservació dels prats. 5) Nombre d'accions | U15: 1) 1 2) 5 3) 5 4) 10 5) 1 | V15: 1) 6 2)15 3) 10 4) 25 5) 10 | W15: Mancaria marcar que "SI" que té mesures aplicables que depenen del PN a columna M | X15: 280 | Y15: Patrimoni Natural | Z15: Bernat Perramon
F16: 01.3.6 | G16: Gestionar i intervenir en la dinàmica de poblacions de fauna que no tenen depredador natural | H16: 01.3.6 | I16: Específic | J16: Optatiu | K16: =G16 -> Gestionar i intervenir en la dinàmica de poblacions de fauna que no tenen depredador natural | M16: Sí | N16: Sí | O16: ALTA | P16: *Realització d'acords amb societats de caçadors. *Participació i impuls del control directe de poblacions de fauna en base als criteris metodològics predefinits. | R16: SENP/SFF: Definir criteris metodològics | S16: 1) Participació en el Programa de seguiment de les poblacions de senglar a Catalunya. 2) Coordinació del grup de treball amb les societats de caçadors 3) Participar a la taula entre caçadors, fessolaires i PNZVG | T16: 1) Nombre de colles participants. 2) Nombre de reunions 3) Nombre de reunions | U16: 1) 4 2) 1 3) 1 | V16: 2) 8 2) 4 3) 4 | X16: 225 | Y16: Patrimoni Natural | Z16: Emili Bassols
F17: 01.3.7 | G17: Afavorir la connectivitat ecològica del territori | H17: 01.3.7 | I17: Comú | J17: Obligatori | K17: =G17 -> Afavorir la connectivitat ecològica del territori | M17: Sí | O17: MÀXIMA | S17: 1) Adaptació d'infraestructures viàries per afavorir la connectivitat. 2) Aplicar mesures per minimitzar l'impacte d'ocupació del sòl, concretades en informes preceptius emesos pel Parc Natural, en l'àrea d'influència per a connectivitat definida en el Pla Especial. 3) Connectar hàbitats naturals de superfície reduïda. 4) Millorar la connectivitat en ambients fluvials i zones humides. 5) Adquirir o establir convenis de custòdia en espais naturals rellevants per a la connectivitat ecològica, i impulsar-hi actuacions que l’afavoreixin | T17: 1) Nombre de mesures executades de millora de la connectivitat. 2) Nombre d'informes preceptius emesos en els quals s'incorporen mesures de millora de la connectivitat. 3,4 i 5) Superfície (ha) recuperada per a la connectivitat. | U17: 1) 1 2) 1 3,4) 2 | V17: 1) 4 2) 8 3,4) 10 | W17: Mancaria marcar que "SI" que té mesures aplicables que depenen del PN a columna M | X17: 225 150 150 225 | Y17: Patrimoni Natural | Z17: Emili Bassols Joan Montserrat Bernat Perramon Joan Pijoan
D18: 01.4 | E18: Alinear l'activitat de propietaris i gestors del territori amb la conservació, millora i restauració dels valors de l'ENP | F18: 01.4.1 | G18: Fomentar acords de custòdia en espais d'alt valor dins l'ENP per a la gestió dels elements prioritaris | H18: 01.4.1 | I18: Comú | J18: Optatiu | K18: Fomentar formules de gestió (autoritzacions, convenis, acords de custòdia,...) en espais d'alt valor dins l'ENP per a la gestió dels elements prioritaris. | L18: Per ampliar les possibilitats d'incidir en la gestió de finques privades des del Parc Natural. | M18: Sí | O18: MÀXIMA | P18: *Realització d'acords de custòdia aplicant el model d'acord elaborat per Serveis Centrals | Q18: MAP | R18: SENP/SENP: Dissenyar el protocol i elaborar un model d'acord | S18: 1) Identificació de les finques d'interès que convindria disposar d'algun conveni/autorització/acord amb la propietat. 2) Establiment de convenis/autoritzacions/acords amb propietaris de finques públiques o privades. | T18: 1) Redacció d'un document de porposta de convenis/autoritzacions/acords de custòdia aconseguits. 2) Nombre d'hectàrees conveniades/autoritzades/acordades | U18: 1) 1 2) 50 | V18: 1) 1 2) 200 | X18: 120 120 120 120 | Y18: Patrimoni Natural | Z18: Emili Bassols Joan Montserrat Bernat Perramon Joan Pijoan
F19: 01.4.2 | G19: Fomentar bones pràctiques entre els col·lectius de propietaris i gestors del territori | H19: 01.4.2 | I19: Comú | J19: Optatiu | K19: Fomentar bones pràctiques entre els col·lectius de propietaris i gestors del territori | M19: Sí | O19: MÀXIMA | P19: *Realització d'actuacions demostratives en finques pròpies per al foment de bones pràctiques | S19: 1) Identificar les línies de gestió prioritàries i els sectors implicats per a la promoció de bones pràctiques. 2) Creació d'un model tipus de material informatiu i de comunicació (tipus infografia) de les bones pràctiques. 3) Establiment de camps experimentals i seguiment de prats i divulgació. 4) Millora de la biodiversitat de prats de dall a partir de la sembra amb llavor recollida en prats amb elevada biodiversitat d'espècies. 5) Potenciar millores per a la integració paisatgística de les explotacions. 6) Elaboració de material divulgatiu de bones pràctiques per a la conservació de la biodiversitat en jardins i espais verds. 7) Col·laboració amb les finques col·laboradores del Centre de Conservació de Plantes Cultivades de Can Jordà. 8) Demostració de pràctiques forestals sostenibles (desembosc amb canaletes i altres). | T19: 1) Nombre de línies de gestió en les quals s'incideix. 2) Nombre d'actuacions realitzades (jornades, tríptics, manuals, càpsules,...). 3) Nombre d'accions 4) Superfície 5) Nombre d'explltacions que s'ha actuat 6) Productes elaborats 7) Nombre de finques col·laboradores 8) Nombre de demostracions | U19: 1) 1 2) 1 3) 5 4) 5 5) 4 6) 2 7) 5 8) 2 | V19: 1) 8 2) 4 3) 10 4) 15 5) 10 6) 8 79 8) 6 | W19: Mancaria marcar que "SI" que té mesures aplicables que depenen del PN a columna M | X19: 135 135 135 135 | Y19: Patrimoni Natural | Z19: Emili Bassols Joan Montserrat Bernat Perramon Joan Pijoan
F20: 01.4.3 | G20: Impulsar la coordinació amb els ens locals en la gestió finques públiques situades dins d’ENP | H20: 01.4.3 | I20: Específic | J20: Optatiu | K20: =G20 -> Impulsar la coordinació amb els ens locals en la gestió finques públiques situades dins d’ENP | M20: Sí | O20: MÀXIMA | P20: *Boscos comunals *Medi marí *Lleres i boscos de ribera | Q20: ESNATURA | S20: 1) Coordinació amb ens locals per a la compra de finques d'interès per la conservació. 2) Col·laboració amb els ens locals per a la gestió de les finques públiques. 3) Establir / renovar els convenis de Can Jordà i el volcà de Santa Margarida amb al Diputació de Girona 4) Singar acords de col·laboració amb els ens locals 5) Instar a l’Agència Catalana de l’Aigua l’atermenament del domini públic hidràulic en l’àmbit del Parc natural i de la seva zona d’influència hidràulica del riu Fluvià, el riu Brugent, el riu Ser, la riera de Ridaura, la riera de Bianya i el torrent de Sant Martí (com a mínim) | T20: 1) Nombre de finques adquirides. 2) Nombre de finques en les quals es col·labora. 3) Nombre convenis acordats 4) Nombre acords 5) Nombre d'atermanament | U20: 1) 1 2) 1 3) 1 4) 1 5) 1 | V20: 1) 2 2) 2 3) 4 4) 2 5) 4 | W20: Mancaria marcar que "SI" que té mesures aplicables que depenen del PN a columna M | X20: 262 | Y20: Direcció | Z20: Joan PIjoan
B21: 2 | C21: ADAPTAR ELS ECOSISTEMES AL CANVI CLIMÀTIC i millorar-ne la resiliència en front dels riscos associats. | D21: 02.1 | E21: Planificar l'adaptació dels sistemes naturals al canvi climàtic | F21: 02.1.1 | G21: Adaptar i implementar el Pla d'adaptació de l'ENP al canvi climàtic | H21: 02.1.1 | I21: Comú | J21: Obligatori | K21: =G21 -> Adaptar i implementar el Pla d'adaptació de l'ENP al canvi climàtic | M21: Sí | O21: ALTA | P21: *Planificació del sistema d'espais oberts *Creació de zones de laminació per defensa de inundacions *Creació i manteniment d'espais dunars de protecció de temporals | R21: OCCC/SENP: Elaboració del model de Pla d'adaptació dels ENP al canvi climàtic | S21: 1) Foment dels prats permanents com a sistemes d'adaptació al canvi climàtic en el sector ramader extensiu. 2) Foment del maneig regeneratiu en la ramaderia extensiva. 3) Implementació d'accions de mitigació i adaptació al canvi climàtic previst per les empreses i equipaments acreditades per la CETS. | T21: 1,2,3) Nombre d'actuacions | U21: 1) 1 2) 1 3) 1 | V21: 1) 5 2) 1 3) 10 | W21: Mancaria marcar que "SI" que té mesures aplicables que depenen del PN a columna M | X21: 105 75 | Y21: Patrimoni Natural Ús públic i turisme | Z21: Bernat Perramon Arnau Dorca
F22: 02.1.2 | G22: Gestionar i planificar els recursos hídrics de l'ENP | H22: 02.1.2 | I22: Comú | J22: Obligatori | K22: =G22 -> Gestionar i planificar els recursos hídrics de l'ENP | M22: Sí | O22: MÀXIMA | S22: 1) Assistència tècnica a la gestió de les aigües. 2) Establiment i/o ampliació d'una xarxa de punts de control (aqüífer, aigües superficials i surgències naturals). 3) Fomentar el càlcul de la petjada hídrica de les empreses del Parc Natural altament consumidores d'aigua. | T22: 1) Nombre d'hores d'assessorament tècnic. 2) Nombre de punts de control 2) Nombre d'empreses contactades pel càlcul de la petjada hídrica. | U22: 1) 25 2) 2 3) 5 | V22: 1) 75 2) 5 3)15 | W22: Mancaria marcar que "SI" que té mesures aplicables que depenen del PN a columna M | X22: 150 145 | Y22: Patrimoni Natural Ús públic i turisme | Z22: Emili Bassols Arnau Dorca
F23: 02.1.3 | G23: Participar en la redacció i execució dels instruments d'ordenació forestal sostenible i per la conservació en finques públiques | H23: 02.1.3 | I23: Específic | J23: Optatiu | K23: Promoure la redacció d'instruments d'ordenació forestal sostenible i l'execució d'accions per la conservació i millora dels boscos i els elements d'interès | L23: Canvi de redactat OP. Inclusió d'accions forestals per a la millora de la biodiversitat sense detallar la propietat de la finca | M23: Sí | N23: Sí | O23: ALTA | P23: *Participació en la redacció d'IOF de finques públiques *Realització d'accions demostratives en finca pública o amb acord de custòdia *Realització de tractaments silvícoles i tallades selectives *Promoció de boscos mixtes i de la biodiversitat | R23: DGEFMN: Redacció d'IOF en finques públiques | S23: 1) Treballar en la gestió forestal de les finques públiques del Catàleg d'utilitat pública. 2) Promoure els PTGMF de totes les finques públiques | T23: 1) Percentatge de finques 2) Percentatge de PTGMF | U23: 1) 10% 2) 10% | V23: 1) 80% 2)80% | X23: 680 | Y23: Patrimoni Natural | Z23: Joan Montserrat
F24: 02.1.4 | G24: Promoure la redacció d'instruments d'ordenació forestal per reduir la sensibilitat i vulnerabilitat dels boscos al canvi climàtic en finques privades | H24: 02.1.4 | I24: Específic | J24: Optatiu | K24: =G24 -> Promoure la redacció d'instruments d'ordenació forestal per reduir la sensibilitat i vulnerabilitat dels boscos al canvi climàtic en finques privades | M24: Sí | N24: Sí | P24: * Realització d'accions per donar a conèixer subvencions entre propietaris | S24: 1) Incrementar el nombre de Plans de Gestió i Ordenació Forestal. 2) Elaborar un catàleg de possibles finques protectores (PEZVG) | T24: 1) Percentatge de superfície forestal amb IOF redactat actualment 60% 2) Elaboració catàleg | U24: 1) 60% 2) 1 | V24: 1) 70% 2) 1 | X24: 595 | Y24: Patrimoni Natural | Z24: Joan Montserrat
D25: 02.2 | E25: Planificar la prevenció i extinció d’incendis forestals i la gestió del foc de forma coordinada amb els diferents agents del territori | F25: 02.2.1 | G25: Redactar i implementar el Pla de Prevenció d'Incendis Forestals | H25: 02.2.1 | I25: Comú | J25: Obligatori | K25: Implementar el Pla de Prevenció d'Incendis Forestals | L25: Es treu la paraula redactar perquè el Parc ja disposa de PPI | M25: Sí | N25: Sí | O25: ALTA | P25: *Elaboració del Pla de Prevenció d'Incendis *Definició de: xarxa estratègica i complementària de vials forestals, xarxa estratègica i complementària de punts d’aigua, tractaments de vegetació, punts estratègics de gestió | Q25: ESNATURA | R25: Equip de PPI: Disseny del protocol de treball | S25: 1) Participar i implementar les mesures del PPI | T25: 1) Nombre de mesures que s'ha participat o implementat | U25: 1) 1 | V25: 1) 5 | Y25: Patrimoni Natural | Z25: Joan Montserrat
F26: 02.2.2 | G26: Definir i planificar la gestió del foc per a la millora de l'ENP | H26: 02.2.2 | I26: Específic | J26: Optatiu | K26: =G26 -> Definir i planificar la gestió del foc per a la millora de l'ENP | L26: No aplicable | M26: No | N26: No | P26: *Pla de gestió de foc *Pla de gestió de cremes | R26: SPEN: Elaboració d'un model de pla de gestió
F27: 02.2.3 | G27: Treballar per a la prevenció d'incendis juntament amb els propietaris, ajuntaments, protecció civil, ADF i bombers. | H27: 02.2.3 | I27: Comú | J27: Obligatori | K27: =G27 -> Treballar per a la prevenció d'incendis juntament amb els propietaris, ajuntaments, protecció civil, ADF i bombers. | M27: Sí | N27: No | O27: ALTA | S27: 1) Seguiment de tots els informes forestals 2) Comptar amb un suport pel seguiment dels informes forestals | T27: 1) Percentatge d'informes forestals emesos 2) Hores destinades al seguiment | U27: 1) 1 2) 20 | V27: 1) 100% 2) 50 | X27: 690 | Y27: Patrimoni Natural | Z27: Joan Montserrat
B28: 3 | C28: PROTEGIR LA BIODIVERSITAT, i especialment els elements fràgils i amenaçats, d’interès comunitari o de major interès natural. | D28: 03.1 | E28: Prevenir, minimitzar i compensar els impactes ambientals dels usos i activitats que es desenvolupin en l'àmbit de l'ENP | F28: 03.1.1 | G28: Participar en les consultes dels procesos d'Avaluació Ambiental que afectin directament o indirectament l’espai del ENP | H28: 03.1.1 | I28: Comú | J28: Obligatori | K28: =G28 -> Participar en les consultes dels procesos d'Avaluació Ambiental que afectin directament o indirectament l’espai del ENP | M28: Sí | S28: 1) Redacció d'informes preceptius. 2) Redacció d'informes sol·licitats pels SSTT dins el tràmit d'avaluació ambiental | T28: 1) Percentatge d'informes emesos 2) Percentatge d'informes emesos | U28: 1) 100% 2) 100% | V28: 1) 100% 2) 100% | W28: Mancaria marcar que "SI" que té mesures aplicables que depenen del PN a columna M. Motiu pel qual està en vermell? | X28: 480 125 90 300 | Y28: Patrimoni Natural | Z28: Emili Bassols Joan Montserrat Bernat Perramon Joan Pijoan
F29: 03.1.2 | G29: Exercir un seguiment efectiu de les obres al Parc juntament amb les Oficines Territorials d'Acció i Avaluació Ambiental als efectes d'assegurar la correcta translació de la tutela administrativa. | H29: 03.1.2 | I29: Comú | J29: Obligatori | K29: =G29 -> Exercir un seguiment efectiu de les obres al Parc juntament amb les Oficines Territorials d'Acció i Avaluació Ambiental als efectes d'assegurar la correcta translació de la tutela administrativa. | M29: Sí | S29: 1) Seguiment de les obres amb més impacte sobre el paisatge i el medi natural | T29: 1) Percentatge de seguiments | U29: 1) 80 % | V29: 1) 100% | W29: Mancaria marcar que "SI" que té mesures aplicables que depenen del PN a columna M. Motiu pel qual està en vermell? | X29: 300 | Y29: Direccio | Z29: Joan PIjoan
F30: 03.1.3 | G30: Participar en la compensació d'impactes residuals durant els processos d'avaluació ambiental mitjançant la identificació de necessitats d'actuació prioritària dins i fora dels límits de l’ENP | H30: 03.1.3 | I30: Comú | J30: Optatiu | K30: Correcció i compensació d'impactes residuals mitjançant la identificació de necessitats d'actuació prioritària dins i fora dels límits de l’ENP | L30: Canvi de redactat OP. Correcció i compensació també fora de processos d'avaluació ambiental | M30: Sí | P30: *Catàleg de possibles actuacions compensatories *Catàleg de sectors amb necessitats d'intervenció (incloent també zones fora dels límits de l'ENP que es considerin importants per al manteniment de la connectivitat ecològica dels espais) | S30: 1) Establiment de mesures compensatòries en aquells projectes, plans o programes que ho requereixin, orientades a restaurar impactes o reduir amenaces | T30: 1) Nombre de mesures compensatòries. | U30: !) 1 | V30: 1) 10 | W30: Mancaria marcar que "SI" que té mesures aplicables que depenen del PN a columna M. Motiu pel qual està en vermell? | X30: 50 | Y30: Direccio | Z30: Joan PIjoan
D31: 03.2 | E31: Garantir el compliment dels objectius de conservació dotant l'ENP de la planificació adequada segons estableix la normativa vigent (Pla de Protecció, PRUG, plans específics...) | F31: 03.2.1 | G31: Participar en l'elaboració dels instruments de planificació de l'ENP | H31: 03.2.1 | I31: Comú | J31: Obligatori | K31: Impulsar i participar en l'elaboració dels instruments de planificació de l'ENP | L31: Hi ha plans que són específics i d'interès del propi parc. | M31: Sí | O31: MÀXIMA | P31: *Participació en l'elaboració del Pla de Protecció (PP) juntament amb l'SPEN. *Participació en l'elaboració del Pla Rector d'usos i Gestió (PRUG) juntament amb l'SPEN. *Participació en l'elaboració d'altres instruments de planificació juntament amb l'SPEN. | R31: SPEN: Elaboració del Pla rector d'usos i gestió. SPEN: Elaboració del Pla rector d'usos i gestió | S31: 1) Treballar per la redacció del PRUG. 2) Redacció del Pla Especial del Bosc de Tosca. 3) Participació en la redacció del Pla d'Ús Públic de la comarca de la Garrotxa. 4) Redacció del Pla Estratègic d'Educació Ambiental. 5) Redacció del Pla per a la millora de la fertilització agraria. | T31: 1) Nombre de plans. | U31: 1) 3 | V31: 1) 6 | W31: Mancaria marcar que "SI" que té mesures aplicables que depenen del PN a columna M. Falta indicar la prioritat. | X31: 800 | Y31: Direccio | Z31: Joan PIjoan
D32: 03.3 | E32: Vetllar pel manteniment dels cabals ecològics i la bona qualitat dels cursos fluvials de l'ENP de forma coordinada amb l'administració competent | F32: 03.3.1 | G32: Vetllar pel manteniment del cabal ecològic dels rius definit al Pla sectorial corresponent | H32: 03.3.1 | I32: Específic | J32: Optatiu | K32: =G32 -> Vetllar pel manteniment del cabal ecològic dels rius definit al Pla sectorial corresponent | M32: Sí | O32: MÀXIMA | P32: *Participació en el seguiment del cabal en els trams dins ENP *Impuls del control per incompliment de la normativa i el seu trasllat cap a l'administració competent *Participació en les negociacions sectorials amb incidència a l'espai *Participació en les comissions de desembassament | Q32: ESNATURA | R32: ACA/CHE: Determinar els cabals ecològics en espais naturals protegits | S32: 1) Incidir en l'organisme competent (ACA) per poder disposar de major nombre de punts de control del cabal. 2) Establir un programa de vigilància dels punts de captació d'aigües superficials. | T32: 1) Nombre d'estacions d'aforament construides. 2) Percentatge d'expedients tramitats. 3) Redacció d'un programa | U32: 1) 1 2) 100% 3) 1 | V32: 1) 4 2) 100% 3) 1 | W32: Mancaria marcar que "SI" que té mesures aplicables que depenen del PN a columna M. | X32: 250 | Y32: Patrimoni Natural | Z32: Emili Basols
F33: 03.3.2 | G33: Vetllar per la regulació dels dragatges, canalitzacions o implantació d'activitats extractives que puguin modificar la llera i el cabal dels rius | H33: 03.3.2 | I33: Específic | J33: Optatiu | K33: =G33 -> Vetllar per la regulació dels dragatges, canalitzacions o implantació d'activitats extractives que puguin modificar la llera i el cabal dels rius | M33: Sí | O33: ALTA | S33: 1) Coordinació amb l'organisme competent (ACA). | T33: 1) Nombre de casos gestionats. | U33: 1) 1 | V33: 1) 10 | W33: Mancaria marcar que "SI" que té mesures aplicables que depenen del PN a columna M. Falta indicar la prioritat. | X33: 100 | Y33: Patrimoni Natural | Z33: Emili Basols
F34: 03.3.3 | G34: Avaluar i controlar les actuacions que produeixin drenatges, captacions o que puguin impedir l’arribada d’aigua tant superficial com freàtica | H34: 03.3.3 | I34: Específic | J34: Optatiu | K34: Avaluar i controlar les actuacions que produeixin drenatges, captacions o que puguin impedir l’arribada d’aigua, tant superficial com freàtica, i incidir en la millora de la qualitat de les aigües, subterrànies i superficials. | L34: S'ha modificat l'objectiu per encabir aspectes de qualitat. | M34: Sí | O34: MÀXIMA | P34: *Participació, de forma coordinada amb l'administració competent, en l'avaluació i control d'actuacions dins els límits de l'ENP. *Impuls del control per incompliment de la normativa i el seu trasllat cap a l'administració competent *Participació en les comunitats d'usuaris de les conques | S34: 1) Elaboració d'un estudi de caracterització hidrogeològica i hidrogràfica dels paratges de la Moixina, les Tries-Noc d’en Cols i els Verlets 2) Aplicació de les mesures específiques de conservació de la Reserva Natural Subterrània de la Deu Grossa i els estanys d'en Broc. 3) Seguiment de la qualitat de les aigües subterrànies i superficials de la conca dels Arcs (Santa Pau). | T34: 1) Redacció d'un estudi 2) Nombre d'actuacions identificades / avaluades. 3) Mitjana de concentració de nitrats dels punts seguits (subterranis i superficials). | U34: 1) 1 2) 2 3) X | V34: 1)1 2) 10 3) x | W34: Mancaria marcar que "SI" que té mesures aplicables que depenen del PN a columna M. | X34: 180 | Y34: Patrimoni Natural | Z34: Emili Basols
F35: 03.3.4 | G35: Vetllar pel compliment de la normativa de depuració dels efluents agroramaders, urbans i industrials que s'aboquen als cursos fluvials | H35: 03.3.4 | I35: Específic | J35: Optatiu | K35: =G35 -> Vetllar pel compliment de la normativa de depuració dels efluents agroramaders, urbans i industrials que s'aboquen als cursos fluvials | M35: Sí | O35: MÀXIMA | P35: *Impuls del control per incompliment de la normativa i el seu trasllat cap a l'administració competent | S35: 1) Establir un programa de vigilància d'efluents i punts d'abocament a llera. 2) Analítiques d'autocontrol del punt d'abocament de can Jordà. | T35: 1) Nombre de mesures executades destinades al compliment de la normativa 2) Nombre d'analítiques | U35: 1) 4 1) 10 | V35: 1) 10 2) 30 | W35: Mancaria marcar que "SI" que té mesures aplicables que depenen del PN a columna M. | X35: 225 | Y35: Patrimoni Natural | Z35: Emili Basols
F36: 03.3.5 | G36: Colaborar amb l'òrgan competent per la conservació del domini públic d'acord amb les delimitacions i la normativa d'usos vigent | H36: 03.3.5 | I36: Comú | J36: Optatiu | K36: Col·laborar amb l'òrgan competent per la conservació del domini públic hidràulic d'acord amb les delimitacions i la normativa d'usos vigent | L36: Es concreta en el DPH. | M36: Sí | O36: ALTA | S36: 1) Fer un seguiment periòdic en el marc del programa de vigilància del Parc Natural i coordinació amb els inspectors de l'ACA | T36: 1) Nombre d'expedients oberts. | U36: 1) 0 | V36: 1) 10 | W36: Mancaria marcar que "SI" que té mesures aplicables que depenen del PN a columna M. | X36: 75 | Y36: Patrimoni Natural | Z36: Emili Basols
D37: 03.4 | E37: Incrementar el patrimoni públic destinat a la conservació i millora del patrimoni natural | F37: 03.4.1 | G37: Identificar espais prioritaris per a la compra de terrenys de més valor dins l'ENP | H37: 03.4.1 | J37: Optatiu | K37: =G37 -> Identificar espais prioritaris per a la compra de terrenys de més valor dins l'ENP | M37: Sí | O37: MÀXIMA | P37: *Participació en la identificació de finques prioritàries en base als criteris indicats | R37: SENP/SPEN: Facilitar els criteris a seguir | S37: 1) Elaboració d'un catàleg de finques d'interès prioritari per la seva compra. 2) Suport a les diferents administrcions per l'adquisició de finques ( ajuts, etc) 3) Compra de la reserva natural del volcà de la Garrinada (DTER) i posterior cessió ús i gestió al PNZVG | T37: 1) Superfície de finques prioritaries adquirides 2) Nombre de reunions 3) Acord cessió ús i gestió volcà de la Garrinada | U37: 1) 10 ha. 2) 4 3) 1 | V37: 1) 200 ha 2) 8 3) 1 | W37: Mancaria marcar que "SI" que té mesures aplicables que depenen del PN a columna M. | X37: 200 | Y37: Direcció | Z37: Joan PIjoan
F38: 03.4.2 | G38: Identificar espais prioritaris per a la gestió directa | H38: 03.4.2 | I38: Comú | J38: Optatiu | K38: =G38 -> Identificar espais prioritaris per a la gestió directa | M38: Sí | P38: *Participació en la identificació de finques prioritàries en base als criteris indicats *Participació i foment de la compra o adquisició de drets d’aprofitament | R38: SENP/SPEN: Facilitar els criteris a seguir | S38: 1) Elaboració d'un catàleg de finques d'interès de gestió directa. 2) Establir acords / autortizacions amb propietaris | T38: 1) Superfície identificada per la gestió directa 2) Nombre acords / autoirtzacions | U38: 1) 10 2)1 | V38: 1)100 2) 4 | W38: Mancaria marcar que "SI" que té mesures aplicables que depenen del PN a columna M. Falta indicar la prioritat. | X38: 200 | Y38: Direcció | Z38: Joan Pijoan
A39: CULTURA | B39: 4 | C39: CONSERVAR ELS ELEMENTS CULTURALS materials i immaterials vinculats a la natura | D39: 04.1 | E39: Millorar el coneixement disponible sobre el patrimoni arquitectònic i cultural (material i immaterial) vinculat al patrimoni natural, el seu estat de conservació i els estils propis dels territoris de l'ENP | F39: 04.1.1 | G39: Elaborar l'inventari i cartografia de patrimoni cultural de l'ENP, que també inclogui el patrimoni etnològic i immaterial | H39: 04.1.1 | I39: Comú | J39: Optatiu | K39: Elaborar l'inventari i cartografia de patrimoni cultural de la Garrotxa, que també inclogui el patrimoni etnològic i immaterial | L39: Es treballarà en l'àmbit comarcal més enllà dels límits de l'ENP | M39: Sí | O39: MITJANA | P39: *Recopilació de la informació dels catàlegs dels ajuntaments de l'ENP i fer diagnosi *Inventari de patrimoni cultural material *Inventari de patrimoni cultural immaterial (metodologia de l'inventari de la unesco) *Elaboració d'un mapa de tranquil·litat. | S39: 1) Identificació i priorització dels elements principals que conformen el patrimoni cultural de la Garrotxa. 2) Recull d'informació del patrimoni etnològic i immaterial present de la Garrotxa. 3) Identificació de mancances en el resultat de la recollida d'informació. 4) Elaboració de l'inventari del patrimoni etnològic i immaterial de la Garrotxa 5) Difusió i dinamització de l'inventari 6) Redactar un catàleg de barraques de pedra seca | T39: 1) Nombre d'entitats, associacions i agents locals diversos implicats en el recull d'informació. 2) Nombre d'elements que conformen el patrimoni cultural vinculat a la natura de la Garrotxa. 3) Nombre de persones receptores dels resultats de l'inventari 4) Cataleg de barraques de pedra seca | U39: 1) 15 2) 1000 3) 500 4) 1 | V39: 1) 40 2) 2000 2) 1500 4) 1 | W39: Indiqueu "impuls". Mancaria marcar que "SI" que té mesures aplicables que depenen del PN a columna M. | X39: 280 | Y39: Turisme / SIG | Z39: Arnau Dorca
F40: 04.1.2 | G40: Elaborar el catàleg lingüístic (localismes) de patrimoni natural, geografia popular, festes i activitats tradicionals de l'ENP | H40: 04.1.2 | I40: Comú | J40: Optatiu | K40: NA | L40: Alguns dels elements que es plantegen ja estan recollits en publicacions i alguns dels altres quedaran recollits en l'inventari de patrimoni cultural de l'OP04.1.1 | M40: Sí | O40: FORA DE TERMINI DEL PLA | W40: Més que indicar "Fora de termini del pla" en aquest cas es podria considerar directament l'objetiu com a No aplicable a la columna K (canviat per NA) i deixar la columna de priorització buida.
...

Sheet Hores
B1: Gerard | C1: Manteniment | D1: Montse | E1: Emili | F1: Bernat | G1: Joan Montserrat | H1: Xavier Oliver | I1: Arnau Dorca | J1: Joan Pijoan | K1: Eva Calm | L1: Josep Riera | M1: Hores | N1: 1688x4= 6752
D2: 980 | E2: 420 | F2: 220 | G2: 420 | H2: 85 | I2: 75 | J2: 100 | K2: 880 | L2: 50
D3: 150 | E3: 150 | F3: 160 | G3: 120 | H3: 152 | I3: 145 | J3: 225 | K3: 50 | L3: 300
D4: 300 | E4: 320 | F4: 280 | G4: 145 | H4: 250 | I4: 280 | J4: 120 | K4: 300 | L4: 400
D5: 800 | E5: 160 | F5: 150 | G5: 150 | H5: 300 | I5: 150 | J5: 135 | K5: 400 | L5: 350
D6: 750 | E6: 380 | F6: 120 | G6: 120 | H6: 190 | I6: 85 | J6: 320 | K6: 350 | L6: 200
D7: 850 | E7: 225 | F7: 135 | G7: 135 | H7: 40 | I7: 140 | J7: 300 | K7: 200 | L7: 450
D8: 300 | E8: 225 | F8: 105 | G8: 680 | H8: 60 | I8: 250 | J8: 400 | K8: 450 | L8: 400
D9: 1072 | E9: 120 | F9: 90 | G9: 595 | H9: 300 | I9: 300 | J9: 50 | K9: 400 | L9: 250
D10: 350 | E10: 135 | F10: 680 | G10: 400 | H10: 380 | I10: 350 | J10: 800 | K10: 250 | L10: 300
D11: 400 | E11: 150 | F11: 280 | G11: 690 | H11: 80 | I11: 300 | J11: 200 | K11: 300
D12: 800 | E12: 480 | F12: 450 | G12: 125 | H12: 80 | I12: 40 | J12: 200
E13: 250 | F13: 450 | G13: 140 | H13: 80 | I13: 500 | J13: 40
E14: 100 | F14: 50 | G14: 498 | H14: 150 | I14: 200 | J14: 450
E15: 180 | F15: 995 | G15: 400 | H15: 150 | I15: 200 | J15: 40
E16: 225 | F16: 80 | G16: 120 | H16: 150 | I16: 250 | J16: 262
E17: 75 | F17: 600 | G17: 40 | H17: 150 | I17: 217 | J17: 300
E18: 320 | F18: 50 | G18: 100 | H18: 150 | I18: 100 | J18: 180
E19: 150 | F19: 45 | G19: 100 | H19: 50 | I19: 50 | J19: 60
E20: 177 | F20: 125 | H20: 80 | I20: 950 | J20: 250
E21: 300 | F21: 200 | H21: 200 | I21: 100 | J21: 40
E22: 150 | F22: 40 | H22: 100 | I22: 120 | J22: 45
E23: 450 | F23: 150 | H23: 450 | I23: 400 | J23: 40
E24: 450 | H24: 400 | I24: 80 | J24: 50
E25: 200 | H25: 40 | I25: 50 | J25: 20
E26: 50 | H26: 50 | J26: 150
E27: 75 | H27: 150 | I27: 10 | J27: 40
E28: 20 | H28: 40 | I28: 40 | J28: 80
E29: 150 | H29: 20 | I29: 100 | J29: 80
E30: 20 | H30: 20 | I30: 300 | J30: 125
E31: 50 | H31: 25 | I31: 20 | J31: 20
E32: 45 | H32: 80 | I32: 40 | J32: 50
E33: 40 | H33: 40 | I33: 80 | J33: 10
E34: 40 | H34: 20 | I34: 20 | J34: 100
E35: 10 | H35: 40 | I35: 40 | J35: 40
E36: 80 | H36: 575 | I36: 60 | J36: 100
E37: 40 | H37: 80 | I37: 40 | J37: 60
E38: 200 | H38: 100 | I38: 90 | J38: 200
... E41: 60 | H41: 40 | I41: 40 | J41: 300
H42: 100 | I42: 150 | J42: 200
...

Sheet PLA
A1: MODEL DE PLA ESTRATÈGIC PELS ENP
B2: Espai natural protegit: | C2: Zona Volcànica de la Garrotxa
Q3: Exemples d'accions | V3: Fita a assolir en 4 anys | X3: Calendarització interna | AC3: Gestió interna | AF3: Gestió externa
A4: EIXOS | C4: Objectius generals (PP) | E4: Objectius estratègics | G4: Objectius operatius | H4: Comú / Específic | I4: Obligatori / Optatiu | J4: Marc de referència | K4: Resultats derivats | L4: Objectius operatius PNZVG | M4: Justificació del canvi o no inclusió d'un OP | N4: Objectiu aplicable amb accions que depenen directament del PNZVG | O4: Objectiu aplicable amb accions que depenen directament de la Direcció General de PAMN | P4: Prioritat | Q4: Propostes genèriques d'accions | R4: Mesures MAP | S4: Mesures Pla Especial ZVG | T4: Mesures d'altres plans | U4: Indicadors | V4: Mínima | W4: Màxim (Desitjable) | X4: Executat | Y4: 2025 | Z4: 2026 | AA4: 2027 | AB4: 2028 | AC4: Hores de dedicació | AD4: Àrea responsable | AE4: Persona responsable | AF4: Pressupost (€) | AG4: Contractació externa | AH4: Competència DG
