Workbook

Sheet Instruccions
A1: Programa d'actuacions 2027 — Parc Natural de l'Alt Pirineu
A2: Versió del model: | B2: 1.0
A3: Codi de la unitat al Motor: | B3: PNAP
A4: Pla estratègic de referència: | B4: Alt Pirineu_Pla Estrategic_final.xlsx
A6: COM OMPLIR-LO
A7: 1. Mireu el Pla | B7: La pestanya PLA ESTRATÈGIC porta el pla aprovat del vostre espai (objectius, accions, indicadors i fites). No s'ha de modificar. La pestanya PA 2026 (consulta) porta les actuacions del 2026, per si en voleu repetir o adaptar alguna.
A8: 2. Ompliu PROGRAMA ANUAL 2027 | B8: Una actuació per fila. Les columnes blanques són per omplir i les grises es calculen soles. Gairebé tot són desplegables: no cal escriure codis a mà.
A9: 3. Mireu la columna «Revisió» | B9: Cada fila mostra ✔ si està completa o diu què hi falta (import, partida RAE, gestor, codi RAE repetit…). Abans d'enviar el fitxer, no hauria de quedar cap avís.
A10: 4. Envieu el fitxer | B10: El fitxer s'ha de poder convertir al JSON del Motor. No canvieu els noms de les pestanyes ni les columnes.
A12: COLUMNES DE PROGRAMA ANUAL 2027
A13: Codi (automàtic) | B13: Es genera sol: any 27, eix i número correlatiu (27_NA_01). Depèn de l'ordre de les files; no les reordeneu ni n'esborreu cap un cop enviat el fitxer. Per anul·lar una actuació, buideu-ne les cel·les.
A14: Codi RAE | B14: Només si l'actuació té codi RAE. Ha de ser únic.
A15: Actuació | B15: Què farà el parc el 2027. Ha de derivar d'una acció del Pla estratègic.
A16: Objectiu operatiu principal | B16: Desplegable amb els objectius del vostre Pla. El nom de l'objectiu i l'eix s'omplen sols.
A17: Altres objectius relacionats | B17: Fins a tres, amb desplegable. Opcional.
A18: Tipus de despesa | B18: Desplegable. «Mitjans propis» és per a les actuacions sense contractació externa.
A19: Partida RAE | B19: Només per a «Contracte menor a càrrec del RAE». Obligatòria en aquest cas.
A20: Tipus dactuació segons MAP | B20: Desplegable amb les tipologies del Marc d'Acció Prioritària. Si cap no hi encaixa, «Altres».
A21: Import (€) | B21: Import previst. Si no té cost directe, poseu 0. No s'admeten valors negatius.
A22: Acció i indicador del Pla | B22: Desplegable amb les accions del Pla per a l'objectiu triat. La fita mínima i la màxima s'omplen soles.
A23: Grau de compliment | B23: Percentatge (0–100%) de la fita màxima que aconseguirà l'actuació. Si és qualitatiu, expliqueu-ho a Observacions.
A24: Gestor responsable | B24: Desplegable amb l'equip del parc. Si hi falta algú, es pot escriure el nom.
... A26: Naturalesa del contracte | B26: Opcional: Obra, Servei o Subministrament. Ajuda el Motor a proposar el procediment.
A28: QUÈ HA CANVIAT RESPECTE AL MODEL ANTERIOR
B29: Es porta el Pla estratègic de l'espai amb indicadors i fites; l'objectiu i l'eix es trien i es calculen sols; el codi és automàtic; hi ha validacions i una columna de revisió; s'hi han afegit el gestor, l'actuació recurrent i el tipus de despesa «Mitjans propis».

Sheet PROGRAMA ANUAL 2027
A1: PROGRAMA D'ACTUACIONS 2027 — Parc Natural de l'Alt Pirineu
A2: Unitat: | B2: PNAP | D2: Blanc = per omplir · Gris = automàtic · Reviseu la columna «Revisió» abans d'enviar el fitxer.
A3: Model: | B3: v1.0
A5: Codi (automàtic) | B5: Codi RAE | C5: Actuació | D5: Objectiu operatiu principal | E5: Objectiu concret a l'espai (automàtic) | F5: Altre objectiu relacionat 1 | G5: Altre objectiu relacionat 2 | H5: Altre objectiu relacionat 3 | I5: Eix (automàtic) | J5: Tipus de despesa | K5: Partida RAE | L5: Tipus d'actuació segons MAP | M5: Import (€) | N5: Acció i indicador del Pla | O5: Fita mínima (automàtic) | P5: Fita màxima (automàtic) | Q5: Grau de compliment (% de la fita) | R5: Gestor responsable | S5: Actuació recurrent | T5: Naturalesa del contracte | U5: Observacions | V5: Revisió
A6: =IF($D6="","","27_"&IFERROR(INDEX(Objectius!$E$2:$E$183,MATCH($D6,Objectius!$A$2:$A$183,0)),"??")&"_"&TEXT(COUNTIF($I$6:$I6,$I6),"00")) | E6: =IF($D6="","",IFERROR(INDEX(Objectius!$C$2:$C$183,MATCH($D6,Objectius!$A$2:$A$183,0)),"Objectiu no trobat al Pla")) | I6: =IF($D6="","",IFERROR(INDEX(Objectius!$D$2:$D$183,MATCH($D6,Objectius!$A$2:$A$183,0)),"")) | O6: =IF($N6="","",IFERROR(INDEX('PLA ESTRATÈGIC'!$G$4:$G$452,MATCH($N6,'PLA ESTRATÈGIC'!$Q$4:$Q$452,0)),"")) | P6: =IF($N6="","",IFERROR(INDEX('PLA ESTRATÈGIC'!$H$4:$H$452,MATCH($N6,'PLA ESTRATÈGIC'!$Q$4:$Q$452,0)),"")) | V6: =IF(COUNTA($C6,$D6,$J6,$M6)=0,"",IF(TRIM(IF($C6="","Falta l'actuació. ","")&IF($D6="","Falta l'objectiu. ","")&IF($J6="","Falta el tipus de despesa. ","")&IF(AND($J6<>"",$J6<>"Mitjans propis",$J6<>"Altres",$M6=""),"Falta l'import. ","")&IF(AND($J6="Contracte menor a càrrec del RAE",$K6=""),"Falta la partida RAE. ","")&IF(AND($B6<>"",COUNTIF($B$6:$B$705,$B6)>1),"Codi RAE repetit. ","")&IF(AND($B6<>"",$J6<>"",$J6<>"Contracte menor a càrrec del RAE"),"Té codi RAE però no és de tipus RAE. ","")&IF($N6="","Falta l'indicador del Pla. ","")&IF($R6="","Falta el gestor. ","")&IF($S6="","Falta indicar si és recurrent. ",""))="","✔",TRIM(IF($C6="","Falta l'actuació. ","")&IF($D6="","Falta l'objectiu. ","")&IF($J6="","Falta el tipus de despesa. ","")&IF(AND($J6<>"",$J6<>"Mitjans propis",$J6<>"Altres",$M6=""),"Falta l'import. ","")&IF(AND($J6="Contracte menor a càrrec del RAE",$K6=""),"Falta la partida RAE. ","")&IF(AND($B6<>"",COUNTIF($B$6:$B$705,$B6)>1),"Codi RAE repetit. ","")&IF(AND($B6<>"",$J6<>"",$J6<>"Contracte menor a càrrec del RAE"),"Té codi RAE però no és de tipus RAE. ","")&IF($N6="","Falta l'indicador del Pla. ","")&IF($R6="","Falta el gestor. ","")&IF($S6="","Falta indicar si és recurrent. ",""))))
A7: =IF($D7="","","27_"&IFERROR(INDEX(Objectius!$E$2:$E$183,MATCH($D7,Objectius!$A$2:$A$183,0)),"??")&"_"&TEXT(COUNTIF($I$6:$I7,$I7),"00")) | E7: =IF($D7="","",IFERROR(INDEX(Objectius!$C$2:$C$183,MATCH($D7,Objectius!$A$2:$A$183,0)),"Objectiu no trobat al Pla")) | I7: =IF($D7="","",IFERROR(INDEX(Objectius!$D$2:$D$183,MATCH($D7,Objectius!$A$2:$A$183,0)),"")) | O7: =IF($N7="","",IFERROR(INDEX('PLA ESTRATÈGIC'!$G$4:$G$452,MATCH($N7,'PLA ESTRATÈGIC'!$Q$4:$Q$452,0)),"")) | P7: =IF($N7="","",IFERROR(INDEX('PLA ESTRATÈGIC'!$H$4:$H$452,MATCH($N7,'PLA ESTRATÈGIC'!$Q$4:$Q$452,0)),"")) | V7: =IF(COUNTA($C7,$D7,$J7,$M7)=0,"",IF(TRIM(IF($C7="","Falta l'actuació. ","")&IF($D7="","Falta l'objectiu. ","")&IF($J7="","Falta el tipus de despesa. ","")&IF(AND($J7<>"",$J7<>"Mitjans propis",$J7<>"Altres",$M7=""),"Falta l'import. ","")&IF(AND($J7="Contracte menor a càrrec del RAE",$K7=""),"Falta la partida RAE. ","")&IF(AND($B7<>"",COUNTIF($B$6:$B$705,$B7)>1),"Codi RAE repetit. ","")&IF(AND($B7<>"",$J7<>"",$J7<>"Contracte menor a càrrec del RAE"),"Té codi RAE però no és de tipus RAE. ","")&IF($N7="","Falta l'indicador del Pla. ","")&IF($R7="","Falta el gestor. ","")&IF($S7="","Falta indicar si és recurrent. ",""))="","✔",TRIM(IF($C7="","Falta l'actuació. ","")&IF($D7="","Falta l'objectiu. ","")&IF($J7="","Falta el tipus de despesa. ","")&IF(AND($J7<>"",$J7<>"Mitjans propis",$J7<>"Altres",$M7=""),"Falta l'import. ","")&IF(AND($J7="Contracte menor a càrrec del RAE",$K7=""),"Falta la partida RAE. ","")&IF(AND($B7<>"",COUNTIF($B$6:$B$705,$B7)>1),"Codi RAE repetit. ","")&IF(AND($B7<>"",$J7<>"",$J7<>"Contracte menor a càrrec del RAE"),"Té codi RAE però no és de tipus RAE. ","")&IF($N7="","Falta l'indicador del Pla. ","")&IF($R7="","Falta el gestor. ","")&IF($S7="","Falta indicar si és recurrent. ",""))))
A8: =IF($D8="","","27_"&IFERROR(INDEX(Objectius!$E$2:$E$183,MATCH($D8,Objectius!$A$2:$A$183,0)),"??")&"_"&TEXT(COUNTIF($I$6:$I8,$I8),"00")) | E8: =IF($D8="","",IFERROR(INDEX(Objectius!$C$2:$C$183,MATCH($D8,Objectius!$A$2:$A$183,0)),"Objectiu no trobat al Pla")) | I8: =IF($D8="","",IFERROR(INDEX(Objectius!$D$2:$D$183,MATCH($D8,Objectius!$A$2:$A$183,0)),"")) | O8: =IF($N8="","",IFERROR(INDEX('PLA ESTRATÈGIC'!$G$4:$G$452,MATCH($N8,'PLA ESTRATÈGIC'!$Q$4:$Q$452,0)),"")) | P8: =IF($N8="","",IFERROR(INDEX('PLA ESTRATÈGIC'!$H$4:$H$452,MATCH($N8,'PLA ESTRATÈGIC'!$Q$4:$Q$452,0)),"")) | V8: =IF(COUNTA($C8,$D8,$J8,$M8)=0,"",IF(TRIM(IF($C8="","Falta l'actuació. ","")&IF($D8="","Falta l'objectiu. ","")&IF($J8="","Falta el tipus de despesa. ","")&IF(AND($J8<>"",$J8<>"Mitjans propis",$J8<>"Altres",$M8=""),"Falta l'import. ","")&IF(AND($J8="Contracte menor a càrrec del RAE",$K8=""),"Falta la partida RAE. ","")&IF(AND($B8<>"",COUNTIF($B$6:$B$705,$B8)>1),"Codi RAE repetit. ","")&IF(AND($B8<>"",$J8<>"",$J8<>"Contracte menor a càrrec del RAE"),"Té codi RAE però no és de tipus RAE. ","")&IF($N8="","Falta l'indicador del Pla. ","")&IF($R8="","Falta el gestor. ","")&IF($S8="","Falta indicar si és recurrent. ",""))="","✔",TRIM(IF($C8="","Falta l'actuació. ","")&IF($D8="","Falta l'objectiu. ","")&IF($J8="","Falta el tipus de despesa. ","")&IF(AND($J8<>"",$J8<>"Mitjans propis",$J8<>"Altres",$M8=""),"Falta l'import. ","")&IF(AND($J8="Contracte menor a càrrec del RAE",$K8=""),"Falta la partida RAE. ","")&IF(AND($B8<>"",COUNTIF($B$6:$B$705,$B8)>1),"Codi RAE repetit. ","")&IF(AND($B8<>"",$J8<>"",$J8<>"Contracte menor a càrrec del RAE"),"Té codi RAE però no és de tipus RAE. ","")&IF($N8="","Falta l'indicador del Pla. ","")&IF($R8="","Falta el gestor. ","")&IF($S8="","Falta indicar si és recurrent. ",""))))
A9: =IF($D9="","","27_"&IFERROR(INDEX(Objectius!$E$2:$E$183,MATCH($D9,Objectius!$A$2:$A$183,0)),"??")&"_"&TEXT(COUNTIF($I$6:$I9,$I9),"00")) | E9: =IF($D9="","",IFERROR(INDEX(Objectius!$C$2:$C$183,MATCH($D9,Objectius!$A$2:$A$183,0)),"Objectiu no trobat al Pla")) | I9: =IF($D9="","",IFERROR(INDEX(Objectius!$D$2:$D$183,MATCH($D9,Objectius!$A$2:$A$183,0)),"")) | O9: =IF($N9="","",IFERROR(INDEX('PLA ESTRATÈGIC'!$G$4:$G$452,MATCH($N9,'PLA ESTRATÈGIC'!$Q$4:$Q$452,0)),"")) | P9: =IF($N9="","",IFERROR(INDEX('PLA ESTRATÈGIC'!$H$4:$H$452,MATCH($N9,'PLA ESTRATÈGIC'!$Q$4:$Q$452,0)),"")) | V9: =IF(COUNTA($C9,$D9,$J9,$M9)=0,"",IF(TRIM(IF($C9="","Falta l'actuació. ","")&IF($D9="","Falta l'objectiu. ","")&IF($J9="","Falta el tipus de despesa. ","")&IF(AND($J9<>"",$J9<>"Mitjans propis",$J9<>"Altres",$M9=""),"Falta l'import. ","")&IF(AND($J9="Contracte menor a càrrec del RAE",$K9=""),"Falta la partida RAE. ","")&IF(AND($B9<>"",COUNTIF($B$6:$B$705,$B9)>1),"Codi RAE repetit. ","")&IF(AND($B9<>"",$J9<>"",$J9<>"Contracte menor a càrrec del RAE"),"Té codi RAE però no és de tipus RAE. ","")&IF($N9="","Falta l'indicador del Pla. ","")&IF($R9="","Falta el gestor. ","")&IF($S9="","Falta indicar si és recurrent. ",""))="","✔",TRIM(IF($C9="","Falta l'actuació. ","")&IF($D9="","Falta l'objectiu. ","")&IF($J9="","Falta el tipus de despesa. ","")&IF(AND($J9<>"",$J9<>"Mitjans propis",$J9<>"Altres",$M9=""),"Falta l'import. ","")&IF(AND($J9="Contracte menor a càrrec del RAE",$K9=""),"Falta la partida RAE. ","")&IF(AND($B9<>"",COUNTIF($B$6:$B$705,$B9)>1),"Codi RAE repetit. ","")&IF(AND($B9<>"",$J9<>"",$J9<>"Contracte menor a càrrec del RAE"),"Té codi RAE però no és de tipus RAE. ","")&IF($N9="","Falta l'indicador del Pla. ","")&IF($R9="","Falta el gestor. ","")&IF($S9="","Falta indicar si és recurrent. ",""))))
A10: =IF($D10="","","27_"&IFERROR(INDEX(Objectius!$E$2:$E$183,MATCH($D10,Objectius!$A$2:$A$183,0)),"??")&"_"&TEXT(COUNTIF($I$6:$I10,$I10),"00")) | E10: =IF($D10="","",IFERROR(INDEX(Objectius!$C$2:$C$183,MATCH($D10,Objectius!$A$2:$A$183,0)),"Objectiu no trobat al Pla")) | I10: =IF($D10="","",IFERROR(INDEX(Objectius!$D$2:$D$183,MATCH($D10,Objectius!$A$2:$A$183,0)),"")) | O10: =IF($N10="","",IFERROR(INDEX('PLA ESTRATÈGIC'!$G$4:$G$452,MATCH($N10,'PLA ESTRATÈGIC'!$Q$4:$Q$452,0)),"")) | P10: =IF($N10="","",IFERROR(INDEX('PLA ESTRATÈGIC'!$H$4:$H$452,MATCH($N10,'PLA ESTRATÈGIC'!$Q$4:$Q$452,0)),"")) | V10: =IF(COUNTA($C10,$D10,$J10,$M10)=0,"",IF(TRIM(IF($C10="","Falta l'actuació. ","")&IF($D10="","Falta l'objectiu. ","")&IF($J10="","Falta el tipus de despesa. ","")&IF(AND($J10<>"",$J10<>"Mitjans propis",$J10<>"Altres",$M10=""),"Falta l'import. ","")&IF(AND($J10="Contracte menor a càrrec del RAE",$K10=""),"Falta la partida RAE. ","")&IF(AND($B10<>"",COUNTIF($B$6:$B$705,$B10)>1),"Codi RAE repetit. ","")&IF(AND($B10<>"",$J10<>"",$J10<>"Contracte menor a càrrec del RAE"),"Té codi RAE però no és de tipus RAE. ","")&IF($N10="","Falta l'indicador del Pla. ","")&IF($R10="","Falta el gestor. ","")&IF($S10="","Falta indicar si és recurrent. ",""))="","✔",TRIM(IF($C10="","Falta l'actuació. ","")&IF($D10="","Falta l'objectiu. ","")&IF($J10="","Falta el tipus de despesa. ","")&IF(AND($J10<>"",$J10<>"Mitjans propis",$J10<>"Altres",$M10=""),"Falta l'import. ","")&IF(AND($J10="Contracte menor a càrrec del RAE",$K10=""),"Falta la partida RAE. ","")&IF(AND($B10<>"",COUNTIF($B$6:$B$705,$B10)>1),"Codi RAE repetit. ","")&IF(AND($B10<>"",$J10<>"",$J10<>"Contracte menor a càrrec del RAE"),"Té codi RAE però no és de tipus RAE. ","")&IF($N10="","Falta l'indicador del Pla. ","")&IF($R10="","Falta el gestor. ","")&IF($S10="","Falta indicar si és recurrent. ",""))))
A11: =IF($D11="","","27_"&IFERROR(INDEX(Objectius!$E$2:$E$183,MATCH($D11,Objectius!$A$2:$A$183,0)),"??")&"_"&TEXT(COUNTIF($I$6:$I11,$I11),"00")) | E11: =IF($D11="","",IFERROR(INDEX(Objectius!$C$2:$C$183,MATCH($D11,Objectius!$A$2:$A$183,0)),"Objectiu no trobat al Pla")) | I11: =IF($D11="","",IFERROR(INDEX(Objectius!$D$2:$D$183,MATCH($D11,Objectius!$A$2:$A$183,0)),"")) | O11: =IF($N11="","",IFERROR(INDEX('PLA ESTRATÈGIC'!$G$4:$G$452,MATCH($N11,'PLA ESTRATÈGIC'!$Q$4:$Q$452,0)),"")) | P11: =IF($N11="","",IFERROR(INDEX('PLA ESTRATÈGIC'!$H$4:$H$452,MATCH($N11,'PLA ESTRATÈGIC'!$Q$4:$Q$452,0)),"")) | V11: =IF(COUNTA($C11,$D11,$J11,$M11)=0,"",IF(TRIM(IF($C11="","Falta l'actuació. ","")&IF($D11="","Falta l'objectiu. ","")&IF($J11="","Falta el tipus de despesa. ","")&IF(AND($J11<>"",$J11<>"Mitjans propis",$J11<>"Altres",$M11=""),"Falta l'import. ","")&IF(AND($J11="Contracte menor a càrrec del RAE",$K11=""),"Falta la partida RAE. ","")&IF(AND($B11<>"",COUNTIF($B$6:$B$705,$B11)>1),"Codi RAE repetit. ","")&IF(AND($B11<>"",$J11<>"",$J11<>"Contracte menor a càrrec del RAE"),"Té codi RAE però no és de tipus RAE. ","")&IF($N11="","Falta l'indicador del Pla. ","")&IF($R11="","Falta el gestor. ","")&IF($S11="","Falta indicar si és recurrent. ",""))="","✔",TRIM(IF($C11="","Falta l'actuació. ","")&IF($D11="","Falta l'objectiu. ","")&IF($J11="","Falta el tipus de despesa. ","")&IF(AND($J11<>"",$J11<>"Mitjans propis",$J11<>"Altres",$M11=""),"Falta l'import. ","")&IF(AND($J11="Contracte menor a càrrec del RAE",$K11=""),"Falta la partida RAE. ","")&IF(AND($B11<>"",COUNTIF($B$6:$B$705,$B11)>1),"Codi RAE repetit. ","")&IF(AND($B11<>"",$J11<>"",$J11<>"Contracte menor a càrrec del RAE"),"Té codi RAE però no és de tipus RAE. ","")&IF($N11="","Falta l'indicador del Pla. ","")&IF($R11="","Falta el gestor. ","")&IF($S11="","Falta indicar si és recurrent. ",""))))
A12: =IF($D12="","","27_"&IFERROR(INDEX(Objectius!$E$2:$E$183,MATCH($D12,Objectius!$A$2:$A$183,0)),"??")&"_"&TEXT(COUNTIF($I$6:$I12,$I12),"00")) | E12: =IF($D12="","",IFERROR(INDEX(Objectius!$C$2:$C$183,MATCH($D12,Objectius!$A$2:$A$183,0)),"Objectiu no trobat al Pla")) | I12: =IF($D12="","",IFERROR(INDEX(Objectius!$D$2:$D$183,MATCH($D12,Objectius!$A$2:$A$183,0)),"")) | O12: =IF($N12="","",IFERROR(INDEX('PLA ESTRATÈGIC'!$G$4:$G$452,MATCH($N12,'PLA ESTRATÈGIC'!$Q$4:$Q$452,0)),"")) | P12: =IF($N12="","",IFERROR(INDEX('PLA ESTRATÈGIC'!$H$4:$H$452,MATCH($N12,'PLA ESTRATÈGIC'!$Q$4:$Q$452,0)),"")) | V12: =IF(COUNTA($C12,$D12,$J12,$M12)=0,"",IF(TRIM(IF($C12="","Falta l'actuació. ","")&IF($D12="","Falta l'objectiu. ","")&IF($J12="","Falta el tipus de despesa. ","")&IF(AND($J12<>"",$J12<>"Mitjans propis",$J12<>"Altres",$M12=""),"Falta l'import. ","")&IF(AND($J12="Contracte menor a càrrec del RAE",$K12=""),"Falta la partida RAE. ","")&IF(AND($B12<>"",COUNTIF($B$6:$B$705,$B12)>1),"Codi RAE repetit. ","")&IF(AND($B12<>"",$J12<>"",$J12<>"Contracte menor a càrrec del RAE"),"Té codi RAE però no és de tipus RAE. ","")&IF($N12="","Falta l'indicador del Pla. ","")&IF($R12="","Falta el gestor. ","")&IF($S12="","Falta indicar si és recurrent. ",""))="","✔",TRIM(IF($C12="","Falta l'actuació. ","")&IF($D12="","Falta l'objectiu. ","")&IF($J12="","Falta el tipus de despesa. ","")&IF(AND($J12<>"",$J12<>"Mitjans propis",$J12<>"Altres",$M12=""),"Falta l'import. ","")&IF(AND($J12="Contracte menor a càrrec del RAE",$K12=""),"Falta la partida RAE. ","")&IF(AND($B12<>"",COUNTIF($B$6:$B$705,$B12)>1),"Codi RAE repetit. ","")&IF(AND($B12<>"",$J12<>"",$J12<>"Contracte menor a càrrec del RAE"),"Té codi RAE però no és de tipus RAE. ","")&IF($N12="","Falta l'indicador del Pla. ","")&IF($R12="","Falta el gestor. ","")&IF($S12="","Falta indicar si és recurrent. ",""))))
A13: =IF($D13="","","27_"&IFERROR(INDEX(Objectius!$E$2:$E$183,MATCH($D13,Objectius!$A$2:$A$183,0)),"??")&"_"&TEXT(COUNTIF($I$6:$I13,$I13),"00")) | E13: =IF($D13="","",IFERROR(INDEX(Objectius!$C$2:$C$183,MATCH($D13,Objectius!$A$2:$A$183,0)),"Objectiu no trobat al Pla")) | I13: =IF($D13="","",IFERROR(INDEX(Objectius!$D$2:$D$183,MATCH($D13,Objectius!$A$2:$A$183,0)),"")) | O13: =IF($N13="","",IFERROR(INDEX('PLA ESTRATÈGIC'!$G$4:$G$452,MATCH($N13,'PLA ESTRATÈGIC'!$Q$4:$Q$452,0)),"")) | P13: =IF($N13="","",IFERROR(INDEX('PLA ESTRATÈGIC'!$H$4:$H$452,MATCH($N13,'PLA ESTRATÈGIC'!$Q$4:$Q$452,0)),"")) | V13: =IF(COUNTA($C13,$D13,$J13,$M13)=0,"",IF(TRIM(IF($C13="","Falta l'actuació. ","")&IF($D13="","Falta l'objectiu. ","")&IF($J13="","Falta el tipus de despesa. ","")&IF(AND($J13<>"",$J13<>"Mitjans propis",$J13<>"Altres",$M13=""),"Falta l'import. ","")&IF(AND($J13="Contracte menor a càrrec del RAE",$K13=""),"Falta la partida RAE. ","")&IF(AND($B13<>"",COUNTIF($B$6:$B$705,$B13)>1),"Codi RAE repetit. ","")&IF(AND($B13<>"",$J13<>"",$J13<>"Contracte menor a càrrec del RAE"),"Té codi RAE però no és de tipus RAE. ","")&IF($N13="","Falta l'indicador del Pla. ","")&IF($R13="","Falta el gestor. ","")&IF($S13="","Falta indicar si és recurrent. ",""))="","✔",TRIM(IF($C13="","Falta l'actuació. ","")&IF($D13="","Falta l'objectiu. ","")&IF($J13="","Falta el tipus de despesa. ","")&IF(AND($J13<>"",$J13<>"Mitjans propis",$J13<>"Altres",$M13=""),"Falta l'import. ","")&IF(AND($J13="Contracte menor a càrrec del RAE",$K13=""),"Falta la partida RAE. ","")&IF(AND($B13<>"",COUNTIF($B$6:$B$705,$B13)>1),"Codi RAE repetit. ","")&IF(AND($B13<>"",$J13<>"",$J13<>"Contracte menor a càrrec del RAE"),"Té codi RAE però no és de tipus RAE. ","")&IF($N13="","Falta l'indicador del Pla. ","")&IF($R13="","Falta el gestor. ","")&IF($S13="","Falta indicar si és recurrent. ",""))))
A14: =IF($D14="","","27_"&IFERROR(INDEX(Objectius!$E$2:$E$183,MATCH($D14,Objectius!$A$2:$A$183,0)),"??")&"_"&TEXT(COUNTIF($I$6:$I14,$I14),"00")) | E14: =IF($D14="","",IFERROR(INDEX(Objectius!$C$2:$C$183,MATCH($D14,Objectius!$A$2:$A$183,0)),"Objectiu no trobat al Pla")) | I14: =IF($D14="","",IFERROR(INDEX(Objectius!$D$2:$D$183,MATCH($D14,Objectius!$A$2:$A$183,0)),"")) | O14: =IF($N14="","",IFERROR(INDEX('PLA ESTRATÈGIC'!$G$4:$G$452,MATCH($N14,'PLA ESTRATÈGIC'!$Q$4:$Q$452,0)),"")) | P14: =IF($N14="","",IFERROR(INDEX('PLA ESTRATÈGIC'!$H$4:$H$452,MATCH($N14,'PLA ESTRATÈGIC'!$Q$4:$Q$452,0)),"")) | V14: =IF(COUNTA($C14,$D14,$J14,$M14)=0,"",IF(TRIM(IF($C14="","Falta l'actuació. ","")&IF($D14="","Falta l'objectiu. ","")&IF($J14="","Falta el tipus de despesa. ","")&IF(AND($J14<>"",$J14<>"Mitjans propis",$J14<>"Altres",$M14=""),"Falta l'import. ","")&IF(AND($J14="Contracte menor a càrrec del RAE",$K14=""),"Falta la partida RAE. ","")&IF(AND($B14<>"",COUNTIF($B$6:$B$705,$B14)>1),"Codi RAE repetit. ","")&IF(AND($B14<>"",$J14<>"",$J14<>"Contracte menor a càrrec del RAE"),"Té codi RAE però no és de tipus RAE. ","")&IF($N14="","Falta l'indicador del Pla. ","")&IF($R14="","Falta el gestor. ","")&IF($S14="","Falta indicar si és recurrent. ",""))="","✔",TRIM(IF($C14="","Falta l'actuació. ","")&IF($D14="","Falta l'objectiu. ","")&IF($J14="","Falta el tipus de despesa. ","")&IF(AND($J14<>"",$J14<>"Mitjans propis",$J14<>"Altres",$M14=""),"Falta l'import. ","")&IF(AND($J14="Contracte menor a càrrec del RAE",$K14=""),"Falta la partida RAE. ","")&IF(AND($B14<>"",COUNTIF($B$6:$B$705,$B14)>1),"Codi RAE repetit. ","")&IF(AND($B14<>"",$J14<>"",$J14<>"Contracte menor a càrrec del RAE"),"Té codi RAE però no és de tipus RAE. ","")&IF($N14="","Falta l'indicador del Pla. ","")&IF($R14="","Falta el gestor. ","")&IF($S14="","Falta indicar si és recurrent. ",""))))
A15: =IF($D15="","","27_"&IFERROR(INDEX(Objectius!$E$2:$E$183,MATCH($D15,Objectius!$A$2:$A$183,0)),"??")&"_"&TEXT(COUNTIF($I$6:$I15,$I15),"00")) | E15: =IF($D15="","",IFERROR(INDEX(Objectius!$C$2:$C$183,MATCH($D15,Objectius!$A$2:$A$183,0)),"Objectiu no trobat al Pla")) | I15: =IF($D15="","",IFERROR(INDEX(Objectius!$D$2:$D$183,MATCH($D15,Objectius!$A$2:$A$183,0)),"")) | O15: =IF($N15="","",IFERROR(INDEX('PLA ESTRATÈGIC'!$G$4:$G$452,MATCH($N15,'PLA ESTRATÈGIC'!$Q$4:$Q$452,0)),"")) | P15: =IF($N15="","",IFERROR(INDEX('PLA ESTRATÈGIC'!$H$4:$H$452,MATCH($N15,'PLA ESTRATÈGIC'!$Q$4:$Q$452,0)),"")) | V15: =IF(COUNTA($C15,$D15,$J15,$M15)=0,"",IF(TRIM(IF($C15="","Falta l'actuació. ","")&IF($D15="","Falta l'objectiu. ","")&IF($J15="","Falta el tipus de despesa. ","")&IF(AND($J15<>"",$J15<>"Mitjans propis",$J15<>"Altres",$M15=""),"Falta l'import. ","")&IF(AND($J15="Contracte menor a càrrec del RAE",$K15=""),"Falta la partida RAE. ","")&IF(AND($B15<>"",COUNTIF($B$6:$B$705,$B15)>1),"Codi RAE repetit. ","")&IF(AND($B15<>"",$J15<>"",$J15<>"Contracte menor a càrrec del RAE"),"Té codi RAE però no és de tipus RAE. ","")&IF($N15="","Falta l'indicador del Pla. ","")&IF($R15="","Falta el gestor. ","")&IF($S15="","Falta indicar si és recurrent. ",""))="","✔",TRIM(IF($C15="","Falta l'actuació. ","")&IF($D15="","Falta l'objectiu. ","")&IF($J15="","Falta el tipus de despesa. ","")&IF(AND($J15<>"",$J15<>"Mitjans propis",$J15<>"Altres",$M15=""),"Falta l'import. ","")&IF(AND($J15="Contracte menor a càrrec del RAE",$K15=""),"Falta la partida RAE. ","")&IF(AND($B15<>"",COUNTIF($B$6:$B$705,$B15)>1),"Codi RAE repetit. ","")&IF(AND($B15<>"",$J15<>"",$J15<>"Contracte menor a càrrec del RAE"),"Té codi RAE però no és de tipus RAE. ","")&IF($N15="","Falta l'indicador del Pla. ","")&IF($R15="","Falta el gestor. ","")&IF($S15="","Falta indicar si és recurrent. ",""))))
A16: =IF($D16="","","27_"&IFERROR(INDEX(Objectius!$E$2:$E$183,MATCH($D16,Objectius!$A$2:$A$183,0)),"??")&"_"&TEXT(COUNTIF($I$6:$I16,$I16),"00")) | E16: =IF($D16="","",IFERROR(INDEX(Objectius!$C$2:$C$183,MATCH($D16,Objectius!$A$2:$A$183,0)),"Objectiu no trobat al Pla")) | I16: =IF($D16="","",IFERROR(INDEX(Objectius!$D$2:$D$183,MATCH($D16,Objectius!$A$2:$A$183,0)),"")) | O16: =IF($N16="","",IFERROR(INDEX('PLA ESTRATÈGIC'!$G$4:$G$452,MATCH($N16,'PLA ESTRATÈGIC'!$Q$4:$Q$452,0)),"")) | P16: =IF($N16="","",IFERROR(INDEX('PLA ESTRATÈGIC'!$H$4:$H$452,MATCH($N16,'PLA ESTRATÈGIC'!$Q$4:$Q$452,0)),"")) | V16: =IF(COUNTA($C16,$D16,$J16,$M16)=0,"",IF(TRIM(IF($C16="","Falta l'actuació. ","")&IF($D16="","Falta l'objectiu. ","")&IF($J16="","Falta el tipus de despesa. ","")&IF(AND($J16<>"",$J16<>"Mitjans propis",$J16<>"Altres",$M16=""),"Falta l'import. ","")&IF(AND($J16="Contracte menor a càrrec del RAE",$K16=""),"Falta la partida RAE. ","")&IF(AND($B16<>"",COUNTIF($B$6:$B$705,$B16)>1),"Codi RAE repetit. ","")&IF(AND($B16<>"",$J16<>"",$J16<>"Contracte menor a càrrec del RAE"),"Té codi RAE però no és de tipus RAE. ","")&IF($N16="","Falta l'indicador del Pla. ","")&IF($R16="","Falta el gestor. ","")&IF($S16="","Falta indicar si és recurrent. ",""))="","✔",TRIM(IF($C16="","Falta l'actuació. ","")&IF($D16="","Falta l'objectiu. ","")&IF($J16="","Falta el tipus de despesa. ","")&IF(AND($J16<>"",$J16<>"Mitjans propis",$J16<>"Altres",$M16=""),"Falta l'import. ","")&IF(AND($J16="Contracte menor a càrrec del RAE",$K16=""),"Falta la partida RAE. ","")&IF(AND($B16<>"",COUNTIF($B$6:$B$705,$B16)>1),"Codi RAE repetit. ","")&IF(AND($B16<>"",$J16<>"",$J16<>"Contracte menor a càrrec del RAE"),"Té codi RAE però no és de tipus RAE. ","")&IF($N16="","Falta l'indicador del Pla. ","")&IF($R16="","Falta el gestor. ","")&IF($S16="","Falta indicar si és recurrent. ",""))))
A17: =IF($D17="","","27_"&IFERROR(INDEX(Objectius!$E$2:$E$183,MATCH($D17,Objectius!$A$2:$A$183,0)),"??")&"_"&TEXT(COUNTIF($I$6:$I17,$I17),"00")) | E17: =IF($D17="","",IFERROR(INDEX(Objectius!$C$2:$C$183,MATCH($D17,Objectius!$A$2:$A$183,0)),"Objectiu no trobat al Pla")) | I17: =IF($D17="","",IFERROR(INDEX(Objectius!$D$2:$D$183,MATCH($D17,Objectius!$A$2:$A$183,0)),"")) | O17: =IF($N17="","",IFERROR(INDEX('PLA ESTRATÈGIC'!$G$4:$G$452,MATCH($N17,'PLA ESTRATÈGIC'!$Q$4:$Q$452,0)),"")) | P17: =IF($N17="","",IFERROR(INDEX('PLA ESTRATÈGIC'!$H$4:$H$452,MATCH($N17,'PLA ESTRATÈGIC'!$Q$4:$Q$452,0)),"")) | V17: =IF(COUNTA($C17,$D17,$J17,$M17)=0,"",IF(TRIM(IF($C17="","Falta l'actuació. ","")&IF($D17="","Falta l'objectiu. ","")&IF($J17="","Falta el tipus de despesa. ","")&IF(AND($J17<>"",$J17<>"Mitjans propis",$J17<>"Altres",$M17=""),"Falta l'import. ","")&IF(AND($J17="Contracte menor a càrrec del RAE",$K17=""),"Falta la partida RAE. ","")&IF(AND($B17<>"",COUNTIF($B$6:$B$705,$B17)>1),"Codi RAE repetit. ","")&IF(AND($B17<>"",$J17<>"",$J17<>"Contracte menor a càrrec del RAE"),"Té codi RAE però no és de tipus RAE. ","")&IF($N17="","Falta l'indicador del Pla. ","")&IF($R17="","Falta el gestor. ","")&IF($S17="","Falta indicar si és recurrent. ",""))="","✔",TRIM(IF($C17="","Falta l'actuació. ","")&IF($D17="","Falta l'objectiu. ","")&IF($J17="","Falta el tipus de despesa. ","")&IF(AND($J17<>"",$J17<>"Mitjans propis",$J17<>"Altres",$M17=""),"Falta l'import. ","")&IF(AND($J17="Contracte menor a càrrec del RAE",$K17=""),"Falta la partida RAE. ","")&IF(AND($B17<>"",COUNTIF($B$6:$B$705,$B17)>1),"Codi RAE repetit. ","")&IF(AND($B17<>"",$J17<>"",$J17<>"Contracte menor a càrrec del RAE"),"Té codi RAE però no és de tipus RAE. ","")&IF($N17="","Falta l'indicador del Pla. ","")&IF($R17="","Falta el gestor. ","")&IF($S17="","Falta indicar si és recurrent. ",""))))
... A705: =IF($D705="","","27_"&IFERROR(INDEX(Objectius!$E$2:$E$183,MATCH($D705,Objectius!$A$2:$A$183,0)),"??")&"_"&TEXT(COUNTIF($I$6:$I705,$I705),"00")) | E705: =IF($D705="","",IFERROR(INDEX(Objectius!$C$2:$C$183,MATCH($D705,Objectius!$A$2:$A$183,0)),"Objectiu no trobat al Pla")) | I705: =IF($D705="","",IFERROR(INDEX(Objectius!$D$2:$D$183,MATCH($D705,Objectius!$A$2:$A$183,0)),"")) | O705: =IF($N705="","",IFERROR(INDEX('PLA ESTRATÈGIC'!$G$4:$G$452,MATCH($N705,'PLA ESTRATÈGIC'!$Q$4:$Q$452,0)),"")) | P705: =IF($N705="","",IFERROR(INDEX('PLA ESTRATÈGIC'!$H$4:$H$452,MATCH($N705,'PLA ESTRATÈGIC'!$Q$4:$Q$452,0)),"")) | V705: =IF(COUNTA($C705,$D705,$J705,$M705)=0,"",IF(TRIM(IF($C705="","Falta l'actuació. ","")&IF($D705="","Falta l'objectiu. ","")&IF($J705="","Falta el tipus de despesa. ","")&IF(AND($J705<>"",$J705<>"Mitjans propis",$J705<>"Altres",$M705=""),"Falta l'import. ","")&IF(AND($J705="Contracte menor a càrrec del RAE",$K705=""),"Falta la partida RAE. ","")&IF(AND($B705<>"",COUNTIF($B$6:$B$705,$B705)>1),"Codi RAE repetit. ","")&IF(AND($B705<>"",$J705<>"",$J705<>"Contracte menor a càrrec del RAE"),"Té codi RAE però no és de tipus RAE. ","")&IF($N705="","Falta l'indicador del Pla. ","")&IF($R705="","Falta el gestor. ","")&IF($S705="","Falta indicar si és recurrent. ",""))="","✔",TRIM(IF($C705="","Falta l'actuació. ","")&IF($D705="","Falta l'objectiu. ","")&IF($J705="","Falta el tipus de despesa. ","")&IF(AND($J705<>"",$J705<>"Mitjans propis",$J705<>"Altres",$M705=""),"Falta l'import. ","")&IF(AND($J705="Contracte menor a càrrec del RAE",$K705=""),"Falta la partida RAE. ","")&IF(AND($B705<>"",COUNTIF($B$6:$B$705,$B705)>1),"Codi RAE repetit. ","")&IF(AND($B705<>"",$J705<>"",$J705<>"Contracte menor a càrrec del RAE"),"Té codi RAE però no és de tipus RAE. ","")&IF($N705="","Falta l'indicador del Pla. ","")&IF($R705="","Falta el gestor. ","")&IF($S705="","Falta indicar si és recurrent. ",""))))

Sheet PLA ESTRATÈGIC
A1: PLA ESTRATÈGIC — Parc Natural de l'Alt Pirineu (només consulta: no modificar)
A3: Eix | B3: Codi objectiu operatiu | C3: Objectiu operatiu (estàndard) | D3: Objectiu concret a l'espai | E3: Acció del Pla | F3: Indicador | G3: Fita mínima | H3: Fita màxima | I3: Prioritat | J3: Àrea responsable | K3: Persona responsable | L3: Objectiu general | M3: Objectiu estratègic | N3: Comú / Específic | O3: Obligatori / Optatiu | P3: Incorporable a la planificació anual | Q3: Clau (per als desplegables)
A4: 1. Natura | B4: 01.1.1 | C4: Implementar i executar plans de gestió específics per a hàbitats i espècies de conservació prioritària dins l'ENP | D4: Implementar i executar plans de gestió específics per a hàbitats i espècies de conservació prioritària dins l'ENP | E4: Realització d'accions per a la millora dels elements prioritzats a l'espai, incloent les accions previstes de conservació al Marc d’Acció Prioritària dels espais Xarxa Natura 2000 “Alt Pallars” i “la Torrassa” | F4: Número d'accions | G4: 20 | H4: 60 | I4: MÀXIMA | J4: Patrimoni | K4: Eli | L4: CONSERVAR LA NATURA i restaurar els ecosistemes, els processos naturals i seminaturals, la biodiversitat i la geodiversitat associada. | M4: Adequar i fer eficient la conservació dels elements objecte de gestió prioritària marcats per la DG a l'ENP | N4: Comú | O4: Obligatori | P4: Si | Q4: 01.1.1 · Realització d'accions per a la millora dels elements prioritzats a l'espai, incloent les accions previstes de conservació al Marc d’Acció Prioritària — Número d'accions
A5: 1. Natura | B5: 01.1.1 | C5: Implementar i executar plans de gestió específics per a hàbitats i espècies de conservació prioritària dins l'ENP | D5: Implementar i executar plans de gestió específics per a hàbitats i espècies de conservació prioritària dins l'ENP | E5: Realització d’actuacions de control i eradicació d’espècies invasores (exòtiques o no) que afecten a l’estat de conservació d’hàbitats i espècies | F5: Número d'accions | G5: 4 | H5: 20 | I5: MÀXIMA | L5: CONSERVAR LA NATURA i restaurar els ecosistemes, els processos naturals i seminaturals, la biodiversitat i la geodiversitat associada. | M5: Adequar i fer eficient la conservació dels elements objecte de gestió prioritària marcats per la DG a l'ENP | N5: Comú | O5: Obligatori | P5: Si | Q5: 01.1.1 · Realització d’actuacions de control i eradicació d’espècies invasores (exòtiques o no) que afecten a l’estat de conservació d’hàbitats i espècies — Número d'accions
A6: 1. Natura | B6: 01.1.1 | C6: Implementar i executar plans de gestió específics per a hàbitats i espècies de conservació prioritària dins l'ENP | D6: Implementar i executar plans de gestió específics per a hàbitats i espècies de conservació prioritària dins l'ENP | E6: Realització de les actuacions de conservació d’hàbitats i espècies aquàtiques d’alta muntanya previstes al projecte LIFE RESQUE ALPYR i projectes Next Generation (Pla de Salito, Estanys dels Rosari i Garrabea) | F6: Número d’accions de conservació executades | G6: 4 | H6: 8 | I6: MÀXIMA | L6: CONSERVAR LA NATURA i restaurar els ecosistemes, els processos naturals i seminaturals, la biodiversitat i la geodiversitat associada. | M6: Adequar i fer eficient la conservació dels elements objecte de gestió prioritària marcats per la DG a l'ENP | N6: Comú | O6: Obligatori | P6: Si | Q6: 01.1.1 · Realització de les actuacions de conservació d’hàbitats i espècies aquàtiques d’alta muntanya previstes al projecte LIFE RESQUE ALPYR i projectes Next — Número d’accions de conservació executades
A7: 1. Natura | B7: 01.1.1 | C7: Implementar i executar plans de gestió específics per a hàbitats i espècies de conservació prioritària dins l'ENP | D7: Implementar i executar plans de gestió específics per a hàbitats i espècies de conservació prioritària dins l'ENP | E7: Elaboració de plans de gestió per elements prioritzats a l'espai | F7: Número de plans | G7: 2 | H7: (tots perill extincio + habitats prioritaris) | I7: ALTA | J7: Patrimoni | K7: Eli | L7: CONSERVAR LA NATURA i restaurar els ecosistemes, els processos naturals i seminaturals, la biodiversitat i la geodiversitat associada. | M7: Adequar i fer eficient la conservació dels elements objecte de gestió prioritària marcats per la DG a l'ENP | N7: Comú | O7: Obligatori | P7: Si | Q7: 01.1.1 · Elaboració de plans de gestió per elements prioritzats a l'espai — Número de plans
A8: 1. Natura | B8: 01.1.1 | C8: Implementar i executar plans de gestió específics per a hàbitats i espècies de conservació prioritària dins l'ENP | D8: Implementar i executar plans de gestió específics per a hàbitats i espècies de conservació prioritària dins l'ENP | E8: Afavorir la custòdia del territori amb entitats i potenciar projectes de conservació de forma col·laborativa entre el parc, els ens locals i les entitats de custòdia | F8: Número d’acords de custòdia implementats | G8: 1 | H8: 3 | I8: MITJANA | L8: CONSERVAR LA NATURA i restaurar els ecosistemes, els processos naturals i seminaturals, la biodiversitat i la geodiversitat associada. | M8: Adequar i fer eficient la conservació dels elements objecte de gestió prioritària marcats per la DG a l'ENP | N8: Comú | O8: Obligatori | P8: Si | Q8: 01.1.1 · Afavorir la custòdia del territori amb entitats i potenciar projectes de conservació de forma col·laborativa entre el parc, els ens locals i les entit — Número d’acords de custòdia implementats
A9: 1. Natura | B9: 01.1.2 | C9: Adaptar i executar plans de gestió específics per a elements geològics de conservació prioritària dins l'ENP | D9: Adaptar i executar plans de gestió específics per a elements geològics de conservació prioritària dins l'ENP | E9: Actualitzar i digitalitzar l'inventari d'elements geològics a l'espai | F9: Fitxes noves/actualitzades | G9: 10 | H9: 37 | I9: BAIXA | J9: Direcció | K9: Marc | L9: CONSERVAR LA NATURA i restaurar els ecosistemes, els processos naturals i seminaturals, la biodiversitat i la geodiversitat associada. | M9: Executar les mesures de gestió directa previstes en els intruments de planificació per la conservació i la gestió adaptativa dels elements clau de l'ENP | N9: Comú | O9: Obligatori | P9: Si | Q9: 01.1.2 · Actualitzar i digitalitzar l'inventari d'elements geològics a l'espai — Fitxes noves/actualitzades
A10: 1. Natura | B10: 01.1.2 | C10: Adaptar i executar plans de gestió específics per a elements geològics de conservació prioritària dins l'ENP | D10: Adaptar i executar plans de gestió específics per a elements geològics de conservació prioritària dins l'ENP | E10: Actualitzar i digitalitzat l'inventari d'elements geomorfologic a l'espai | F10: Fitxes noves/actualitzades | G10: 24 | H10: 89 | I10: BAIXA | J10: Patrimoni | K10: Oriol | L10: CONSERVAR LA NATURA i restaurar els ecosistemes, els processos naturals i seminaturals, la biodiversitat i la geodiversitat associada. | M10: Executar les mesures de gestió directa previstes en els intruments de planificació per la conservació i la gestió adaptativa dels elements clau de l'ENP | N10: Comú | O10: Obligatori | P10: Si | Q10: 01.1.2 · Actualitzar i digitalitzat l'inventari d'elements geomorfologic a l'espai — Fitxes noves/actualitzades
A11: 1. Natura | B11: 01.1.2 | C11: Adaptar i executar plans de gestió específics per a elements geològics de conservació prioritària dins l'ENP | D11: Adaptar i executar plans de gestió específics per a elements geològics de conservació prioritària dins l'ENP | E11: Aplicació de les directrius de gestió de l'inventari de patrimoni geològic (ICGC) i els inventaris gologics i geomorfologics de l'espai | F11: Número accions conservació | G11: 2 | H11: 10 | I11: MITJANA | J11: Direcció | K11: Marc | L11: CONSERVAR LA NATURA i restaurar els ecosistemes, els processos naturals i seminaturals, la biodiversitat i la geodiversitat associada. | M11: Executar les mesures de gestió directa previstes en els intruments de planificació per la conservació i la gestió adaptativa dels elements clau de l'ENP | N11: Comú | O11: Obligatori | P11: Si | Q11: 01.1.2 · Aplicació de les directrius de gestió de l'inventari de patrimoni geològic (ICGC) i els inventaris gologics i geomorfologics de l'espai — Número accions conservació
A12: 1. Natura | B12: 01.2.1 | C12: Implementar la metodologia de gestió adaptativa (Estàndards Oberts de Gestió Adaptativa a Catalunya) en tots els processos de l'ENP | D12: Implementar la metodologia de gestió adaptativa (Estàndards Oberts de Gestió Adaptativa a Catalunya) en tots els processos de l'ENP | E12: Implentar metodologia Open Standards als processos més rellevants de l'espai | F12: Número OP | G12: 1 | H12: 10 | I12: MÀXIMA | J12: Direcció | K12: Marc | L12: CONSERVAR LA NATURA i restaurar els ecosistemes, els processos naturals i seminaturals, la biodiversitat i la geodiversitat associada. | M12: Executar les mesures de gestió directa previstes en els intruments de planificació per la conservació i la gestió adaptativa dels elements clau de l'ENP | N12: Comú | O12: Obligatori | P12: No | Q12: 01.2.1 · Implentar metodologia Open Standards als processos més rellevants de l'espai — Número OP
A13: 1. Natura | B13: 01.2.2 | C13: Executar les mesures previstes en els plans de conservació o recuperació d'espècies amenaçades de forma coordinada amb el Servei de Flora i Fauna en l'àmbit de l'ENP | D13: Executar les mesures previstes en els plans de conservació o recuperació d'espècies amenaçades de forma coordinada amb el Servei de Flora i Fauna en l'àmbit de l'ENP | E13: Implicació i participació en la redacció dels plans de conservació /recuperació d'espècies amenaçades. Reforç poblacional quan s'escaigui | F13: Número plans implicats | G13: 1 | H13: 4 | I13: MÀXIMA | J13: Patrimoni | K13: Eli | L13: CONSERVAR LA NATURA i restaurar els ecosistemes, els processos naturals i seminaturals, la biodiversitat i la geodiversitat associada. | M13: Executar les mesures de gestió directa previstes en els intruments de planificació per la conservació i la gestió adaptativa dels elements clau de l'ENP | N13: Comú | O13: Obligatori | P13: Si | Q13: 01.2.2 · Implicació i participació en la redacció dels plans de conservació /recuperació d'espècies amenaçades. Reforç poblacional quan s'escaigui — Número plans implicats
A14: 1. Natura | B14: 01.2.2 | C14: Executar les mesures previstes en els plans de conservació o recuperació d'espècies amenaçades de forma coordinada amb el Servei de Flora i Fauna en l'àmbit de l'ENP | D14: Executar les mesures previstes en els plans de conservació o recuperació d'espècies amenaçades de forma coordinada amb el Servei de Flora i Fauna en l'àmbit de l'ENP | E14: Execució de les accions dins els plans que pertoquin a cada espai (incorporar totes les mesures que surten als plans ja aprovats que tenen incidència a l'espai) | F14: Número accions | G14: 10 | H14: 40 | I14: MÀXIMA | J14: Patrimoni | K14: Eli | L14: CONSERVAR LA NATURA i restaurar els ecosistemes, els processos naturals i seminaturals, la biodiversitat i la geodiversitat associada. | M14: Executar les mesures de gestió directa previstes en els intruments de planificació per la conservació i la gestió adaptativa dels elements clau de l'ENP | N14: Comú | O14: Obligatori | P14: Si | Q14: 01.2.2 · Execució de les accions dins els plans que pertoquin a cada espai (incorporar totes les mesures que surten als plans ja aprovats que tenen incidència — Número accions
A15: 1. Natura | B15: 01.2.2 | C15: Executar les mesures previstes en els plans de conservació o recuperació d'espècies amenaçades de forma coordinada amb el Servei de Flora i Fauna en l'àmbit de l'ENP | D15: Executar les mesures previstes en els plans de conservació o recuperació d'espècies amenaçades de forma coordinada amb el Servei de Flora i Fauna en l'àmbit de l'ENP | E15: Col.laboració en l'obtenció de la informació necessària dins els espais per al desenvolupament dels Plans | F15: Número plans s'ha obtingut informació | G15: 1 | H15: 4 | I15: MÀXIMA | J15: Patrimoni | K15: Eli | L15: CONSERVAR LA NATURA i restaurar els ecosistemes, els processos naturals i seminaturals, la biodiversitat i la geodiversitat associada. | M15: Executar les mesures de gestió directa previstes en els intruments de planificació per la conservació i la gestió adaptativa dels elements clau de l'ENP | N15: Comú | O15: Obligatori | P15: Si | Q15: 01.2.2 · Col.laboració en l'obtenció de la informació necessària dins els espais per al desenvolupament dels Plans — Número plans s'ha obtingut informació
A16: 1. Natura | B16: 01.2.2 | C16: Executar les mesures previstes en els plans de conservació o recuperació d'espècies amenaçades de forma coordinada amb el Servei de Flora i Fauna en l'àmbit de l'ENP | D16: Executar les mesures previstes en els plans de conservació o recuperació d'espècies amenaçades de forma coordinada amb el Servei de Flora i Fauna en l'àmbit de l'ENP | E16: Acompanyament de la Comissió Ramadera amb l’òrgan competent per abordar de forma específica la millora de la convivència entre la ramaderia i la presència de grans depredadors, i l’ús de gossos de protecció | F16: Número de reunions realitzades | G16: 4 | H16: 8 | I16: ALTA | L16: CONSERVAR LA NATURA i restaurar els ecosistemes, els processos naturals i seminaturals, la biodiversitat i la geodiversitat associada. | M16: Executar les mesures de gestió directa previstes en els intruments de planificació per la conservació i la gestió adaptativa dels elements clau de l'ENP | N16: Comú | O16: Obligatori | P16: Si | Q16: 01.2.2 · Acompanyament de la Comissió Ramadera amb l’òrgan competent per abordar de forma específica la millora de la convivència entre la ramaderia i la presè — Número de reunions realitzades
A17: 1. Natura | B17: 01.2.3 | C17: Executar les mesures de gestió previstes en els plans de control i erradicació d'espècies exòtiques de forma coordinada amb el Servei de Flora i Fauna en l'àmbit de l'ENP | D17: Executar les mesures de gestió previstes en els plans de control i erradicació d'espècies exòtiques de forma coordinada amb el Servei de Flora i Fauna en l'àmbit de l'ENP | E17: Implicació i participació en la redacció (cal identificar els plans que estan ja en marxa o previstos i posar les mesures concretes) | F17: Número plans implicats | G17: 1 | H17: 2 | I17: MÀXIMA | J17: Patrimoni | K17: Eli | L17: CONSERVAR LA NATURA i restaurar els ecosistemes, els processos naturals i seminaturals, la biodiversitat i la geodiversitat associada. | M17: Executar les mesures de gestió directa previstes en els intruments de planificació per la conservació i la gestió adaptativa dels elements clau de l'ENP | N17: Comú | O17: Obligatori | P17: Si | Q17: 01.2.3 · Implicació i participació en la redacció (cal identificar els plans que estan ja en marxa o previstos i posar les mesures concretes) — Número plans implicats
A18: 1. Natura | B18: 01.2.3 | C18: Executar les mesures de gestió previstes en els plans de control i erradicació d'espècies exòtiques de forma coordinada amb el Servei de Flora i Fauna en l'àmbit de l'ENP | D18: Executar les mesures de gestió previstes en els plans de control i erradicació d'espècies exòtiques de forma coordinada amb el Servei de Flora i Fauna en l'àmbit de l'ENP | E18: Execució de les accions dins els plans que pertoquin a cada espai | F18: Número accions | G18: 4 | H18: 10 | I18: MÀXIMA | J18: Patrimoni | K18: Eli | L18: CONSERVAR LA NATURA i restaurar els ecosistemes, els processos naturals i seminaturals, la biodiversitat i la geodiversitat associada. | M18: Executar les mesures de gestió directa previstes en els intruments de planificació per la conservació i la gestió adaptativa dels elements clau de l'ENP | N18: Comú | O18: Obligatori | P18: Si | Q18: 01.2.3 · Execució de les accions dins els plans que pertoquin a cada espai — Número accions
A19: 1. Natura | B19: 01.2.3 | C19: Executar les mesures de gestió previstes en els plans de control i erradicació d'espècies exòtiques de forma coordinada amb el Servei de Flora i Fauna en l'àmbit de l'ENP | D19: Executar les mesures de gestió previstes en els plans de control i erradicació d'espècies exòtiques de forma coordinada amb el Servei de Flora i Fauna en l'àmbit de l'ENP | E19: Col.laboració en l'obtenció de la informació necessària dins els espais per al desenvolupament dels Plans | F19: Número plans s'ha obtingut informació | G19: 1 | H19: 2 | I19: ALTA | J19: Patrimoni | K19: Eli | L19: CONSERVAR LA NATURA i restaurar els ecosistemes, els processos naturals i seminaturals, la biodiversitat i la geodiversitat associada. | M19: Executar les mesures de gestió directa previstes en els intruments de planificació per la conservació i la gestió adaptativa dels elements clau de l'ENP | N19: Comú | O19: Obligatori | P19: Si | Q19: 01.2.3 · Col.laboració en l'obtenció de la informació necessària dins els espais per al desenvolupament dels Plans — Número plans s'ha obtingut informació
A20: 1. Natura | B20: 01.2.4 | C20: Desplegar els objectius i tasques recollits en els instruments de referència i compromisos internacionals | D20: Desplegar els objectius i tasques recollits en els instruments de referència i compromisos internacionals | E20: Presentar candidatura a la GREEN List UICN | F20: Execució | G20: no | H20: si | I20: MITJANA | J20: Direcció | K20: Marc | L20: CONSERVAR LA NATURA i restaurar els ecosistemes, els processos naturals i seminaturals, la biodiversitat i la geodiversitat associada. | M20: Executar les mesures de gestió directa previstes en els intruments de planificació per la conservació i la gestió adaptativa dels elements clau de l'ENP | N20: Específic | O20: Optatiu | P20: Si | Q20: 01.2.4 · Presentar candidatura a la GREEN List UICN — Execució
A21: 1. Natura | B21: 01.2.4 | C21: Desplegar els objectius i tasques recollits en els instruments de referència i compromisos internacionals | D21: Desplegar els objectius i tasques recollits en els instruments de referència i compromisos internacionals | E21: Presentar candidatura Wild Rivers Noguera Pallaresa | F21: Execució | G21: no | H21: si | I21: ALTA | J21: Direcció | K21: Marc | L21: CONSERVAR LA NATURA i restaurar els ecosistemes, els processos naturals i seminaturals, la biodiversitat i la geodiversitat associada. | M21: Executar les mesures de gestió directa previstes en els intruments de planificació per la conservació i la gestió adaptativa dels elements clau de l'ENP | N21: Específic | O21: Optatiu | P21: Si | Q21: 01.2.4 · Presentar candidatura Wild Rivers Noguera Pallaresa — Execució
A22: 1. Natura | B22: 01.2.4 | C22: Desplegar els objectius i tasques recollits en els instruments de referència i compromisos internacionals | D22: Desplegar els objectius i tasques recollits en els instruments de referència i compromisos internacionals | E22: Preparar candidatura a Reserva Biosfera Transfronterera o Transboundary Park Europarc PP3N | F22: Execució | G22: no | H22: si | I22: MITJANA | J22: Direcció | K22: Marc | L22: CONSERVAR LA NATURA i restaurar els ecosistemes, els processos naturals i seminaturals, la biodiversitat i la geodiversitat associada. | M22: Executar les mesures de gestió directa previstes en els intruments de planificació per la conservació i la gestió adaptativa dels elements clau de l'ENP | N22: Específic | O22: Optatiu | P22: Si | Q22: 01.2.4 · Preparar candidatura a Reserva Biosfera Transfronterera o Transboundary Park Europarc PP3N — Execució
A23: 1. Natura | B23: 01.3.1 | C23: Identificar espais pel foment de la dinàmica natural i l'aprofitament no extractiu | D23: Identificar espais pel foment de la dinàmica natural i l'aprofitament no extractiu | E23: Participar en la identificació de boscos madurs pel foment de la dinàmica natural i l'aprofitament no extractiu dins l'ENP en base a uns criteris metodològics predefinits (DG Boscos i boscos BAVE POCTEFA RedBio) | F23: Número participacions | G23: 1 | H23: 2 | I23: ALTA | J23: Patrimoni | K23: Eli | L23: CONSERVAR LA NATURA i restaurar els ecosistemes, els processos naturals i seminaturals, la biodiversitat i la geodiversitat associada. | M23: Afavorir ecosistemes complexes, resilients, i d'alta biodiversitat per garantir la recuperació dels processos ecosistèmics | N23: Comú | O23: Obligatori | P23: Si | Q23: 01.3.1 · Participar en la identificació de boscos madurs pel foment de la dinàmica natural i l'aprofitament no extractiu dins l'ENP en base a uns criteris meto — Número participacions
A24: 1. Natura | B24: 01.3.1 | C24: Identificar espais pel foment de la dinàmica natural i l'aprofitament no extractiu | D24: Identificar espais pel foment de la dinàmica natural i l'aprofitament no extractiu | E24: Afavorir la creació o recuperació d'hàbitats per a la conservació d'espècies (Pla de Salito, cua embassament de Boren, llacuna de Llagunes, basses aigua) i ordenació de l’ús públic del seu entorn | F24: Número habitats creats | G24: 1 | H24: 4 | I24: ALTA | J24: Patrimoni | K24: Eli | L24: CONSERVAR LA NATURA i restaurar els ecosistemes, els processos naturals i seminaturals, la biodiversitat i la geodiversitat associada. | M24: Afavorir ecosistemes complexes, resilients, i d'alta biodiversitat per garantir la recuperació dels processos ecosistèmics | N24: Comú | O24: Obligatori | P24: Si | Q24: 01.3.1 · Afavorir la creació o recuperació d'hàbitats per a la conservació d'espècies (Pla de Salito, cua embassament de Boren, llacuna de Llagunes, basses aig — Número habitats creats
A25: 1. Natura | B25: 01.3.2 | C25: Afavorir la maduresa dels sistemes forestals | D25: Afavorir la maduresa dels sistemes forestals | E25: Participar i impulsar la planificació i execució d'accions d'acceleració de la maduresa forestal en zones boscoses dins l'ENP en base als criteris metodològics predefinits | F25: Superficie amb accelaració maduresa | G25: 30 | H25: 100 | I25: ALTA | J25: Patrimoni | K25: Eli | L25: CONSERVAR LA NATURA i restaurar els ecosistemes, els processos naturals i seminaturals, la biodiversitat i la geodiversitat associada. | M25: Afavorir ecosistemes complexes, resilients, i d'alta biodiversitat per garantir la recuperació dels processos ecosistèmics | N25: Específic | O25: Optatiu | P25: Si | Q25: 01.3.2 · Participar i impulsar la planificació i execució d'accions d'acceleració de la maduresa forestal en zones boscoses dins l'ENP en base als criteris met — Superficie amb accelaració maduresa
A26: 1. Natura | B26: 01.3.3 | C26: Procurar un règim de pertorbacions que afavoreixi l'ús sostenible dels recursos, la biodiversitat i el funcionament del ecosistemes | D26: Procurar un règim de pertorbacions que afavoreixi l'ús sostenible dels recursos, la biodiversitat i el funcionament del ecosistemes | E26: Elaboració d'una planificació d'actuacions de simulació d'incendis forestals naturals (cremes controlades i criteris d'actuació en cas d'incendi) dins l'espai en base als criteris metodològics predefinits (POCTEFA Desbosiguem) a través de la figura de Pla de Prevenció d'Incendis Forestals | F26: Redacció i aprovació del Pla | G26: Redacció | H26: Redacció i aprovació | I26: ALTA | J26: Patrimoni | K26: Oriol | L26: CONSERVAR LA NATURA i restaurar els ecosistemes, els processos naturals i seminaturals, la biodiversitat i la geodiversitat associada. | M26: Afavorir ecosistemes complexes, resilients, i d'alta biodiversitat per garantir la recuperació dels processos ecosistèmics | N26: Específic | O26: Optatiu | P26: Si | Q26: 01.3.3 · Elaboració d'una planificació d'actuacions de simulació d'incendis forestals naturals (cremes controlades i criteris d'actuació en cas d'incendi) dins — Redacció i aprovació del Pla
A27: 1. Natura | B27: 01.3.3 | C27: Procurar un règim de pertorbacions que afavoreixi l'ús sostenible dels recursos, la biodiversitat i el funcionament del ecosistemes | D27: Procurar un règim de pertorbacions que afavoreixi l'ús sostenible dels recursos, la biodiversitat i el funcionament del ecosistemes | E27: Realització de cremes controlades impulsades des del Parc | F27: Número de cremes sol·licitades formalment | G27: 1 | H27: 4 | I27: ALTA | J27: Patrimoni | K27: Oriol | L27: CONSERVAR LA NATURA i restaurar els ecosistemes, els processos naturals i seminaturals, la biodiversitat i la geodiversitat associada. | M27: Afavorir ecosistemes complexes, resilients, i d'alta biodiversitat per garantir la recuperació dels processos ecosistèmics | N27: Específic | O27: Optatiu | P27: Si | Q27: 01.3.3 · Realització de cremes controlades impulsades des del Parc — Número de cremes sol·licitades formalment
A28: 1. Natura | B28: 01.3.4 | C28: Restaurar la dinàmica natural dels rius i altres ecosistemes aquàtics que estiguin dregradats | D28: Restaurar la dinàmica natural dels rius i altres ecosistemes aquàtics que estiguin dregradats | E28: Càlcul i sol·licitud implementació de cabals ecològics en aprofitaments hidroelèctrics dels rius del Parc o bé per desviament d'aigua per rec de prats | F28: Número d'aforaments de cabal ecològic calculats i tramitats | G28: 1 | H28: 6 | I28: MITJANA | J28: Patrimoni | K28: Oriol | L28: CONSERVAR LA NATURA i restaurar els ecosistemes, els processos naturals i seminaturals, la biodiversitat i la geodiversitat associada. | M28: Afavorir ecosistemes complexes, resilients, i d'alta biodiversitat per garantir la recuperació dels processos ecosistèmics | N28: Específic | O28: Optatiu | P28: Si | Q28: 01.3.4 · Càlcul i sol·licitud implementació de cabals ecològics en aprofitaments hidroelèctrics dels rius del Parc o bé per desviament d'aigua per rec de prats — Número d'aforaments de cabal ecològic calculats i tramitats
A29: 1. Natura | B29: 01.3.5 | C29: Fomentar mosaics de paisatges resilients i diversos | D29: Fomentar mosaics de paisatges resilients i diversos | E29: Establir taules de treball entre l’equip del Parc i Comissió Ramadera per desenvolupar una proposta de línies d’ajut que respongui de forma més efectiva a les necessitats del sector i a la preservació dels hàbitats i la cultura associada, incloent la possibilitat de subvencionar pastors, vaquers i eugassers | F29: Número de sessions de treball realitzades | G29: 3 | H29: 10 | I29: ALTA | L29: CONSERVAR LA NATURA i restaurar els ecosistemes, els processos naturals i seminaturals, la biodiversitat i la geodiversitat associada. | M29: Afavorir ecosistemes complexes, resilients, i d'alta biodiversitat per garantir la recuperació dels processos ecosistèmics | N29: Específic | O29: Optatiu | P29: Si | Q29: 01.3.5 · Establir taules de treball entre l’equip del Parc i Comissió Ramadera per desenvolupar una proposta de línies d’ajut que respongui de forma més efecti — Número de sessions de treball realitzades
A30: 1. Natura | B30: 01.3.5 | C30: Fomentar mosaics de paisatges resilients i diversos | D30: Fomentar mosaics de paisatges resilients i diversos | E30: Tramitació d'ajuts per explotacions ramaderes per gestionar l'herbivoria domèstica associada a la ramaderia extensiva | F30: Número expedients d'ajut de maneig de pastures | G30: Tots els sol·licitats | H30: Tots els sol·licitats dins del termini establert | I30: ALTA | J30: Patrimoni | K30: Josep | L30: CONSERVAR LA NATURA i restaurar els ecosistemes, els processos naturals i seminaturals, la biodiversitat i la geodiversitat associada. | M30: Afavorir ecosistemes complexes, resilients, i d'alta biodiversitat per garantir la recuperació dels processos ecosistèmics | N30: Específic | O30: Optatiu | P30: Si | Q30: 01.3.5 · Tramitació d'ajuts per explotacions ramaderes per gestionar l'herbivoria domèstica associada a la ramaderia extensiva — Número expedients d'ajut de maneig de pastures
A31: 1. Natura | B31: 01.3.5 | C31: Fomentar mosaics de paisatges resilients i diversos | D31: Fomentar mosaics de paisatges resilients i diversos | E31: Realització d'un manual tècnic de bones pràctiques en ramaderia extensiva i recuperació i manteniment de pastures aplicat a l'ENP (Projecte REPICA) | F31: Progrés del manual tècnic | G31: Redacció | H31: Redacció, aprovació i divulgació | I31: ALTA | J31: Patrimoni | K31: Oriol | L31: CONSERVAR LA NATURA i restaurar els ecosistemes, els processos naturals i seminaturals, la biodiversitat i la geodiversitat associada. | M31: Afavorir ecosistemes complexes, resilients, i d'alta biodiversitat per garantir la recuperació dels processos ecosistèmics | N31: Específic | O31: Optatiu | P31: Si | Q31: 01.3.5 · Realització d'un manual tècnic de bones pràctiques en ramaderia extensiva i recuperació i manteniment de pastures aplicat a l'ENP (Projecte REPICA) — Progrés del manual tècnic
A32: 1. Natura | B32: 01.3.5 | C32: Fomentar mosaics de paisatges resilients i diversos | D32: Fomentar mosaics de paisatges resilients i diversos | E32: Acords amb ramaders locals per actuacions de restauració i manteniment de pastures al voltant de pobles (POCTEFA Desbosiguem) | F32: Número acords implementats | G32: 1 | H32: 3 | I32: MITJANA | J32: Patrimoni | K32: Josep | L32: CONSERVAR LA NATURA i restaurar els ecosistemes, els processos naturals i seminaturals, la biodiversitat i la geodiversitat associada. | M32: Afavorir ecosistemes complexes, resilients, i d'alta biodiversitat per garantir la recuperació dels processos ecosistèmics | N32: Específic | O32: Optatiu | P32: Si | Q32: 01.3.5 · Acords amb ramaders locals per actuacions de restauració i manteniment de pastures al voltant de pobles (POCTEFA Desbosiguem) — Número acords implementats
A33: 1. Natura | B33: 01.3.5 | C33: Fomentar mosaics de paisatges resilients i diversos | D33: Fomentar mosaics de paisatges resilients i diversos | E33: Afavorir la custòdia del territori amb entitats, per tal d’aconseguir fomentar el paisatge en mosaic i potenciar projectes de forma col·laborativa entre el parc, els ens locals i les entitats de custòdia | F33: Número d’acords de custòdia implementats | G33: 1 | H33: 3 | I33: MITJANA | L33: CONSERVAR LA NATURA i restaurar els ecosistemes, els processos naturals i seminaturals, la biodiversitat i la geodiversitat associada. | M33: Afavorir ecosistemes complexes, resilients, i d'alta biodiversitat per garantir la recuperació dels processos ecosistèmics | N33: Específic | O33: Optatiu | P33: Si | Q33: 01.3.5 · Afavorir la custòdia del territori amb entitats, per tal d’aconseguir fomentar el paisatge en mosaic i potenciar projectes de forma col·laborativa ent — Número d’acords de custòdia implementats
A34: 1. Natura | B34: 01.3.6 | C34: Gestionar i intervenir en la dinàmica de poblacions de fauna que no tenen depredador natural | D34: Gestionar i intervenir en la dinàmica de poblacions de fauna que no tenen depredador natural | E34: Realització d'acords amb societats de caçadors mitjançant informes en els PTGMC | F34: Número informes preceptius de PTGMC | G34: Tots els sol·licitats | H34: Tots els sol·licitats dins de termini | I34: MITJANA | J34: Patrimoni | K34: Eli | L34: CONSERVAR LA NATURA i restaurar els ecosistemes, els processos naturals i seminaturals, la biodiversitat i la geodiversitat associada. | M34: Afavorir ecosistemes complexes, resilients, i d'alta biodiversitat per garantir la recuperació dels processos ecosistèmics | N34: Específic | O34: Optatiu | P34: Si | Q34: 01.3.6 · Realització d'acords amb societats de caçadors mitjançant informes en els PTGMC — Número informes preceptius de PTGMC
